<?xml version="1.0"?>
<robot name="myfirst">
    <link name="base_link">
        <visual>
            <geometry>
                <mesh filename="package://quadruped/meshes/body_bottom_plate.stl"/>
            </geometry>
        </visual>
    </link>
    <link name="body_spacer_1">
        <visual>
            <geometry>
                <mesh filename="package://quadruped/meshes/body_spacer.stl"/>
            </geometry>
            <origin xyz="0 0.505 0"/>
        </visual>
    </link>
    <link name="body_spacer_2">
        <visual>
            <geometry>
                <mesh filename="package://quadruped/meshes/body_spacer.stl"/>
            </geometry>
            <origin rpy="0 1.571 0" xyz="0 0.505 0"/>
        </visual>
    </link>
    <link name="body_spacer_3">
        <visual>
            <geometry>
                <mesh filename="package://quadruped/meshes/body_spacer.stl"/>
            </geometry>
            <origin rpy="0 1.571 0" xyz="0 0.505 0"/>
        </visual>
    </link>
    <link name="body_spacer_4">
        <visual>
            <geometry>
                <mesh filename="package://quadruped/meshes/body_spacer.stl"/>
            </geometry>
            <origin xyz="0 0.505 0"/>
        </visual>
    </link>
    <link name="body_top_plate">
        <visual>
            <geometry>
                <mesh filename="package://quadruped/meshes/body_top_plate.stl"/>
            </geometry>
            <origin xyz="0 0 0"/>
        </visual>
    </link>
    <link name="leg_bottom_pivot_plate_1">
        <visual>
            <geometry>
                <mesh filename="package://quadruped/meshes/leg_bottom_pivot_plate.stl"/>
            </geometry>
            <origin rpy="1.571 -0.785 0"/>
        </visual>
    </link>
    <link name="leg_bottom_pivot_plate_2">
        <visual>
            <geometry>
                <mesh filename="package://quadruped/meshes/leg_bottom_pivot_plate.stl"/>
            </geometry>
            <origin rpy="1.571 -2.355 0"/>
        </visual>
    </link>
    <link name="leg_bottom_pivot_plate_3">
        <visual>
            <geometry>
                <mesh filename="package://quadruped/meshes/leg_bottom_pivot_plate.stl"/>
            </geometry>
            <origin rpy="1.571 2.355 0"/>
        </visual>
    </link>
    <link name="leg_bottom_pivot_plate_4">
        <visual>
            <geometry>
                <mesh filename="package://quadruped/meshes/leg_bottom_pivot_plate.stl"/>
            </geometry>
            <origin rpy="1.571 0.785 0"/>
        </visual>
    </link>
    <joint name="base_body_spacer_1" type="fixed">
        <parent link="base_link"/>
        <child link="body_spacer_1"/>
        <origin xyz="0 0 1.700"/>
    </joint>
    <joint name="base_body_spacer_2" type="fixed">
        <parent link="base_link"/>
        <child link="body_spacer_2"/>
        <origin xyz="1.700 0 0"/>
    </joint>
    <joint name="base_body_spacer_3" type="fixed">
        <parent link="base_link"/>
        <child link="body_spacer_3"/>
        <origin xyz="-1.700 0 0"/>
    </joint>
    <joint name="base_body_spacer_4" type="fixed">
        <parent link="base_link"/>
        <child link="body_spacer_4"/>
        <origin xyz="0 0 -1.700"/>
    </joint>
    <joint name="base_top_joint" type="fixed">
        <parent link="base_link"/>
        <child link="body_top_plate"/>
        <origin xyz="0 0.875 0" />
    </joint>
    <joint name="leg_bottom_pivot_plate_1" type="revolute">
        <parent link="base_link"/>
        <child link="leg_bottom_pivot_plate_1"/>
        <origin xyz="1.7806 0 1.7806"/>
        <axis xyz="1.7806 0 1.7806"/>
        <limit lower="-1.571" upper="1.571" velocity="100" effort="100"/>
    </joint>
    <joint name="leg_bottom_pivot_plate_2" type="revolute">
        <parent link="base_link"/>
        <child link="leg_bottom_pivot_plate_2"/>
        <origin xyz="-1.7806 0 1.7806"/>
        <axis xyz="1.7806 0 1.7806"/>
        <limit lower="-1.571" upper="1.571" velocity="100" effort="100"/>
    </joint>
    <joint name="leg_bottom_pivot_plate_3" type="revolute">
        <parent link="base_link"/>
        <child link="leg_bottom_pivot_plate_3"/>
        <origin xyz="-1.7806 0 -1.7806"/>
        <axis xyz="-1.7806 0 -1.7806"/>
        <limit lower="-1.571" upper="1.571" velocity="100" effort="100"/>
    </joint>
    <joint name="leg_bottom_pivot_plate_4" type="revolute">
        <parent link="base_link"/>
        <child link="leg_bottom_pivot_plate_4"/>
        <origin xyz="1.7806 0 -1.7806"/>
        <axis xyz="1.7806 0 -1.7806"/>
        <limit lower="-1.571" upper="1.571" velocity="100" effort="100"/>
    </joint>
</robot>
