<?xml version="1.0" ?>
<robot name="quadruped" xmlns:xacro="http://www.ros.org/wiki/xacro">

<xacro:include filename="$(find quadruped_description)/urdf/materials.xacro" />
<xacro:include filename="$(find quadruped_description)/urdf/quadruped.trans" />
<xacro:include filename="$(find quadruped_description)/urdf/quadruped.gazebo" />
<link name="base_link">
  <inertial>
    <origin rpy="0 0 0" xyz="-2.2540908731132877e-06 0.0006253376048972236 0.00014092055174148312"/>
    <mass value="0.010011445945907962"/>
    <inertia ixx="2e-06" ixy="0.0" ixz="0.0" iyy="2e-06" iyz="-0.0" izz="5e-06"/>
  </inertial>
  <visual>
    <origin rpy="0 0 0" xyz="0 0 0"/>
    <geometry>
      <mesh filename="package://quadruped_description/meshes/base_link.stl" scale="0.001 0.001 0.001"/>
    </geometry>
    <material name="silver"/>
  </visual>
  <collision>
    <origin rpy="0 0 0" xyz="0 0 0"/>
    <geometry>
      <mesh filename="package://quadruped_description/meshes/base_link.stl" scale="0.001 0.001 0.001"/>
    </geometry>
  </collision>
</link>

<link name="body_spacer_v1_1">
  <inertial>
    <origin rpy="0 0 0" xyz="1.748581103809036e-08 3.5470791488745324e-07 -0.0007504977509462498"/>
    <mass value="0.001198596877164021"/>
    <inertia ixx="0.0" ixy="-0.0" ixz="0.0" iyy="0.0" iyz="0.0" izz="0.0"/>
  </inertial>
  <visual>
    <origin rpy="0 0 0" xyz="2e-06 0.016249 -0.005264"/>
    <geometry>
      <mesh filename="package://quadruped_description/meshes/body_spacer_v1_1.stl" scale="0.001 0.001 0.001"/>
    </geometry>
    <material name="silver"/>
  </visual>
  <collision>
    <origin rpy="0 0 0" xyz="2e-06 0.016249 -0.005264"/>
    <geometry>
      <mesh filename="package://quadruped_description/meshes/body_spacer_v1_1.stl" scale="0.001 0.001 0.001"/>
    </geometry>
  </collision>
</link>

<link name="body_spacer_v1_2">
  <inertial>
    <origin rpy="0 0 0" xyz="1.7832426659097255e-08 3.543612991235845e-07 0.0007503392477448277"/>
    <mass value="0.001198596877164021"/>
    <inertia ixx="0.0" ixy="-0.0" ixz="0.0" iyy="0.0" iyz="0.0" izz="0.0"/>
  </inertial>
  <visual>
    <origin rpy="0 0 0" xyz="2e-06 -0.017501 -0.003768"/>
    <geometry>
      <mesh filename="package://quadruped_description/meshes/body_spacer_v1_2.stl" scale="0.001 0.001 0.001"/>
    </geometry>
    <material name="silver"/>
  </visual>
  <collision>
    <origin rpy="0 0 0" xyz="2e-06 -0.017501 -0.003768"/>
    <geometry>
      <mesh filename="package://quadruped_description/meshes/body_spacer_v1_2.stl" scale="0.001 0.001 0.001"/>
    </geometry>
  </collision>
</link>

<link name="body_spacer_v1_3">
  <inertial>
    <origin rpy="0 0 0" xyz="1.7485819511081635e-08 3.54707906299271e-07 0.0007495023086583541"/>
    <mass value="0.001198596877164021"/>
    <inertia ixx="0.0" ixy="-0.0" ixz="-0.0" iyy="0.0" iyz="-0.0" izz="0.0"/>
  </inertial>
  <visual>
    <origin rpy="0 0 0" xyz="-0.016873 -0.000626 -0.003764"/>
    <geometry>
      <mesh filename="package://quadruped_description/meshes/body_spacer_v1_3.stl" scale="0.001 0.001 0.001"/>
    </geometry>
    <material name="silver"/>
  </visual>
  <collision>
    <origin rpy="0 0 0" xyz="-0.016873 -0.000626 -0.003764"/>
    <geometry>
      <mesh filename="package://quadruped_description/meshes/body_spacer_v1_3.stl" scale="0.001 0.001 0.001"/>
    </geometry>
  </collision>
</link>

<link name="body_spacer_v1_4">
  <inertial>
    <origin rpy="0 0 0" xyz="1.783242673317198e-08 3.5436129915936317e-07 0.0007503392477448711"/>
    <mass value="0.001198596877164021"/>
    <inertia ixx="0.0" ixy="-0.0" ixz="-0.0" iyy="0.0" iyz="-0.0" izz="0.0"/>
  </inertial>
  <visual>
    <origin rpy="0 0 0" xyz="0.016877 -0.000626 -0.003768"/>
    <geometry>
      <mesh filename="package://quadruped_description/meshes/body_spacer_v1_4.stl" scale="0.001 0.001 0.001"/>
    </geometry>
    <material name="silver"/>
  </visual>
  <collision>
    <origin rpy="0 0 0" xyz="0.016877 -0.000626 -0.003768"/>
    <geometry>
      <mesh filename="package://quadruped_description/meshes/body_spacer_v1_4.stl" scale="0.001 0.001 0.001"/>
    </geometry>
  </collision>
</link>

<link name="body_top_plate_v1_1">
  <inertial>
    <origin rpy="0 0 0" xyz="-2.713851780610004e-06 6.294142635289001e-08 0.000624921904524971"/>
    <mass value="0.01473051492933994"/>
    <inertia ixx="2e-06" ixy="0.0" ixz="0.0" iyy="2e-06" iyz="-0.0" izz="4e-06"/>
  </inertial>
  <visual>
    <origin rpy="0 0 0" xyz="5e-06 -0.000628 -0.008266"/>
    <geometry>
      <mesh filename="package://quadruped_description/meshes/body_top_plate_v1_1.stl" scale="0.001 0.001 0.001"/>
    </geometry>
    <material name="silver"/>
  </visual>
  <collision>
    <origin rpy="0 0 0" xyz="5e-06 -0.000628 -0.008266"/>
    <geometry>
      <mesh filename="package://quadruped_description/meshes/body_top_plate_v1_1.stl" scale="0.001 0.001 0.001"/>
    </geometry>
  </collision>
</link>

<link name="servo_motor_v1_1">
  <inertial>
    <origin rpy="0 0 0" xyz="-0.0013522686817115312 0.0013516397539906494 -0.006780743568897159"/>
    <mass value="0.0004848665871049835"/>
    <inertia ixx="0.0" ixy="0.0" ixz="-0.0" iyy="0.0" iyz="0.0" izz="0.0"/>
  </inertial>
  <visual>
    <origin rpy="0 0 0" xyz="-0.017806 0.017181 -0.015061"/>
    <geometry>
      <mesh filename="package://quadruped_description/meshes/servo_motor_v1_1.stl" scale="0.001 0.001 0.001"/>
    </geometry>
    <material name="silver"/>
  </visual>
  <collision>
    <origin rpy="0 0 0" xyz="-0.017806 0.017181 -0.015061"/>
    <geometry>
      <mesh filename="package://quadruped_description/meshes/servo_motor_v1_1.stl" scale="0.001 0.001 0.001"/>
    </geometry>
  </collision>
</link>

<link name="servo_motor_v1_2">
  <inertial>
    <origin rpy="0 0 0" xyz="-0.0013522684143736433 -0.0013500106125431677 -0.006781026965683326"/>
    <mass value="0.0004848665871049835"/>
    <inertia ixx="0.0" ixy="-0.0" ixz="-0.0" iyy="0.0" iyz="-0.0" izz="0.0"/>
  </inertial>
  <visual>
    <origin rpy="0 0 0" xyz="-0.017806 -0.018431 -0.015066"/>
    <geometry>
      <mesh filename="package://quadruped_description/meshes/servo_motor_v1_2.stl" scale="0.001 0.001 0.001"/>
    </geometry>
    <material name="silver"/>
  </visual>
  <collision>
    <origin rpy="0 0 0" xyz="-0.017806 -0.018431 -0.015066"/>
    <geometry>
      <mesh filename="package://quadruped_description/meshes/servo_motor_v1_2.stl" scale="0.001 0.001 0.001"/>
    </geometry>
  </collision>
</link>

<link name="servo_motor_v1_3">
  <inertial>
    <origin rpy="0 0 0" xyz="0.0013503745959511024 -0.001350253063540481 -0.006781317275326498"/>
    <mass value="0.0004848665871049835"/>
    <inertia ixx="0.0" ixy="0.0" ixz="0.0" iyy="0.0" iyz="-0.0" izz="0.0"/>
  </inertial>
  <visual>
    <origin rpy="0 0 0" xyz="0.017807 -0.018383 -0.015071"/>
    <geometry>
      <mesh filename="package://quadruped_description/meshes/servo_motor_v1_3.stl" scale="0.001 0.001 0.001"/>
    </geometry>
    <material name="silver"/>
  </visual>
  <collision>
    <origin rpy="0 0 0" xyz="0.017807 -0.018383 -0.015071"/>
    <geometry>
      <mesh filename="package://quadruped_description/meshes/servo_motor_v1_3.stl" scale="0.001 0.001 0.001"/>
    </geometry>
  </collision>
</link>

<link name="servo_motor_v1_4">
  <inertial>
    <origin rpy="0 0 0" xyz="0.001350374329120104 0.0013517551304252605 -0.006781026804738641"/>
    <mass value="0.0004848665871049835"/>
    <inertia ixx="0.0" ixy="-0.0" ixz="0.0" iyy="0.0" iyz="0.0" izz="0.0"/>
  </inertial>
  <visual>
    <origin rpy="0 0 0" xyz="0.017807 0.01718 -0.015066"/>
    <geometry>
      <mesh filename="package://quadruped_description/meshes/servo_motor_v1_4.stl" scale="0.001 0.001 0.001"/>
    </geometry>
    <material name="silver"/>
  </visual>
  <collision>
    <origin rpy="0 0 0" xyz="0.017807 0.01718 -0.015066"/>
    <geometry>
      <mesh filename="package://quadruped_description/meshes/servo_motor_v1_4.stl" scale="0.001 0.001 0.001"/>
    </geometry>
  </collision>
</link>

<link name="leg_servo_retainer_v1_1">
  <inertial>
    <origin rpy="0 0 0" xyz="-7.408030335920648e-05 7.325536984225528e-05 0.0006252705496434755"/>
    <mass value="0.0007120198480863978"/>
    <inertia ixx="0.0" ixy="0.0" ixz="0.0" iyy="0.0" iyz="-0.0" izz="0.0"/>
  </inertial>
  <visual>
    <origin rpy="0 0 0" xyz="-0.016295 0.015672 -0.010811"/>
    <geometry>
      <mesh filename="package://quadruped_description/meshes/leg_servo_retainer_v1_1.stl" scale="0.001 0.001 0.001"/>
    </geometry>
    <material name="silver"/>
  </visual>
  <collision>
    <origin rpy="0 0 0" xyz="-0.016295 0.015672 -0.010811"/>
    <geometry>
      <mesh filename="package://quadruped_description/meshes/leg_servo_retainer_v1_1.stl" scale="0.001 0.001 0.001"/>
    </geometry>
  </collision>
</link>

<link name="leg_servo_retainer_v1_2">
  <inertial>
    <origin rpy="0 0 0" xyz="-7.357848863456459e-05 -7.488610895528894e-05 0.000624921371536382"/>
    <mass value="0.0007120198480863978"/>
    <inertia ixx="0.0" ixy="-0.0" ixz="0.0" iyy="0.0" iyz="-0.0" izz="0.0"/>
  </inertial>
  <visual>
    <origin rpy="0 0 0" xyz="-0.016295 -0.016928 -0.010816"/>
    <geometry>
      <mesh filename="package://quadruped_description/meshes/leg_servo_retainer_v1_2.stl" scale="0.001 0.001 0.001"/>
    </geometry>
    <material name="silver"/>
  </visual>
  <collision>
    <origin rpy="0 0 0" xyz="-0.016295 -0.016928 -0.010816"/>
    <geometry>
      <mesh filename="package://quadruped_description/meshes/leg_servo_retainer_v1_2.stl" scale="0.001 0.001 0.001"/>
    </geometry>
  </collision>
</link>

<link name="leg_servo_retainer_v1_3">
  <inertial>
    <origin rpy="0 0 0" xyz="7.456299017333592e-05 -7.438496078147547e-05 0.0006245723371707708"/>
    <mass value="0.0007120198480863978"/>
    <inertia ixx="0.0" ixy="0.0" ixz="0.0" iyy="0.0" iyz="-0.0" izz="0.0"/>
  </inertial>
  <visual>
    <origin rpy="0 0 0" xyz="0.016305 -0.016928 -0.010821"/>
    <geometry>
      <mesh filename="package://quadruped_description/meshes/leg_servo_retainer_v1_3.stl" scale="0.001 0.001 0.001"/>
    </geometry>
    <material name="silver"/>
  </visual>
  <collision>
    <origin rpy="0 0 0" xyz="0.016305 -0.016928 -0.010821"/>
    <geometry>
      <mesh filename="package://quadruped_description/meshes/leg_servo_retainer_v1_3.stl" scale="0.001 0.001 0.001"/>
    </geometry>
  </collision>
</link>

<link name="leg_servo_retainer_v1_4">
  <inertial>
    <origin rpy="0 0 0" xyz="7.406117544864893e-05 7.375651801607222e-05 0.0006249215152778053"/>
    <mass value="0.0007120198480863978"/>
    <inertia ixx="0.0" ixy="-0.0" ixz="0.0" iyy="0.0" iyz="-0.0" izz="0.0"/>
  </inertial>
  <visual>
    <origin rpy="0 0 0" xyz="0.016305 0.015672 -0.010816"/>
    <geometry>
      <mesh filename="package://quadruped_description/meshes/leg_servo_retainer_v1_4.stl" scale="0.001 0.001 0.001"/>
    </geometry>
    <material name="silver"/>
  </visual>
  <collision>
    <origin rpy="0 0 0" xyz="0.016305 0.015672 -0.010816"/>
    <geometry>
      <mesh filename="package://quadruped_description/meshes/leg_servo_retainer_v1_4.stl" scale="0.001 0.001 0.001"/>
    </geometry>
  </collision>
</link>

<link name="leg_top_pivot_plate_v1_1">
  <inertial>
    <origin rpy="0 0 0" xyz="0.004146012091097932 -0.004177769265927726 -0.0006263762579004958"/>
    <mass value="0.0012497785111649892"/>
    <inertia ixx="0.0" ixy="0.0" ixz="0.0" iyy="0.0" iyz="-0.0" izz="0.0"/>
  </inertial>
  <visual>
    <origin rpy="0 0 0" xyz="-0.017806 0.017181 -0.015061"/>
    <geometry>
      <mesh filename="package://quadruped_description/meshes/leg_top_pivot_plate_v1_1.stl" scale="0.001 0.001 0.001"/>
    </geometry>
    <material name="silver"/>
  </visual>
  <collision>
    <origin rpy="0 0 0" xyz="-0.017806 0.017181 -0.015061"/>
    <geometry>
      <mesh filename="package://quadruped_description/meshes/leg_top_pivot_plate_v1_1.stl" scale="0.001 0.001 0.001"/>
    </geometry>
  </collision>
</link>

<link name="leg_top_pivot_plate_v1_2">
  <inertial>
    <origin rpy="0 0 0" xyz="0.004259743108696236 0.004061596424975791 -0.0006251079237064947"/>
    <mass value="0.0012497785111649892"/>
    <inertia ixx="0.0" ixy="-0.0" ixz="0.0" iyy="0.0" iyz="-0.0" izz="0.0"/>
  </inertial>
  <visual>
    <origin rpy="0 0 0" xyz="-0.017806 -0.018431 -0.015066"/>
    <geometry>
      <mesh filename="package://quadruped_description/meshes/leg_top_pivot_plate_v1_2.stl" scale="0.001 0.001 0.001"/>
    </geometry>
    <material name="silver"/>
  </visual>
  <collision>
    <origin rpy="0 0 0" xyz="-0.017806 -0.018431 -0.015066"/>
    <geometry>
      <mesh filename="package://quadruped_description/meshes/leg_top_pivot_plate_v1_2.stl" scale="0.001 0.001 0.001"/>
    </geometry>
  </collision>
</link>

<link name="leg_top_pivot_plate_v1_3">
  <inertial>
    <origin rpy="0 0 0" xyz="-0.004146111251660332 0.004177421801787366 -0.0006237895654848408"/>
    <mass value="0.0012497785111649892"/>
    <inertia ixx="0.0" ixy="0.0" ixz="0.0" iyy="0.0" iyz="-0.0" izz="0.0"/>
  </inertial>
  <visual>
    <origin rpy="0 0 0" xyz="0.017807 -0.018383 -0.015071"/>
    <geometry>
      <mesh filename="package://quadruped_description/meshes/leg_top_pivot_plate_v1_3.stl" scale="0.001 0.001 0.001"/>
    </geometry>
    <material name="silver"/>
  </visual>
  <collision>
    <origin rpy="0 0 0" xyz="0.017807 -0.018383 -0.015071"/>
    <geometry>
      <mesh filename="package://quadruped_description/meshes/leg_top_pivot_plate_v1_3.stl" scale="0.001 0.001 0.001"/>
    </geometry>
  </collision>
</link>

<link name="leg_top_pivot_plate_v1_4">
  <inertial>
    <origin rpy="0 0 0" xyz="-0.004175696877458824 -0.004148110392408481 -0.000625075285736458"/>
    <mass value="0.0012497785111649892"/>
    <inertia ixx="0.0" ixy="-0.0" ixz="0.0" iyy="0.0" iyz="-0.0" izz="0.0"/>
  </inertial>
  <visual>
    <origin rpy="0 0 0" xyz="0.017807 0.01718 -0.015066"/>
    <geometry>
      <mesh filename="package://quadruped_description/meshes/leg_top_pivot_plate_v1_4.stl" scale="0.001 0.001 0.001"/>
    </geometry>
    <material name="silver"/>
  </visual>
  <collision>
    <origin rpy="0 0 0" xyz="0.017807 0.01718 -0.015066"/>
    <geometry>
      <mesh filename="package://quadruped_description/meshes/leg_top_pivot_plate_v1_4.stl" scale="0.001 0.001 0.001"/>
    </geometry>
  </collision>
</link>

<link name="leg_parallel_plate_v1_1">
  <inertial>
    <origin rpy="0 0 0" xyz="0.00031591444463684865 -0.0003169091906957619 -0.003050661877473837"/>
    <mass value="0.000869495656702597"/>
    <inertia ixx="0.0" ixy="0.0" ixz="-0.0" iyy="0.0" iyz="0.0" izz="0.0"/>
  </inertial>
  <visual>
    <origin rpy="0 0 0" xyz="-0.023855 0.026163 -0.010559"/>
    <geometry>
      <mesh filename="package://quadruped_description/meshes/leg_parallel_plate_v1_1.stl" scale="0.001 0.001 0.001"/>
    </geometry>
    <material name="silver"/>
  </visual>
  <collision>
    <origin rpy="0 0 0" xyz="-0.023855 0.026163 -0.010559"/>
    <geometry>
      <mesh filename="package://quadruped_description/meshes/leg_parallel_plate_v1_1.stl" scale="0.001 0.001 0.001"/>
    </geometry>
  </collision>
</link>

<link name="leg_parallel_plate_v1_2">
  <inertial>
    <origin rpy="0 0 0" xyz="0.00032252003388966166 0.0003109539488441275 -0.003049778338663463"/>
    <mass value="0.000869495656702597"/>
    <inertia ixx="0.0" ixy="-0.0" ixz="-0.0" iyy="0.0" iyz="-0.0" izz="0.0"/>
  </inertial>
  <visual>
    <origin rpy="0 0 0" xyz="-0.026908 -0.024299 -0.010565"/>
    <geometry>
      <mesh filename="package://quadruped_description/meshes/leg_parallel_plate_v1_2.stl" scale="0.001 0.001 0.001"/>
    </geometry>
    <material name="silver"/>
  </visual>
  <collision>
    <origin rpy="0 0 0" xyz="-0.026908 -0.024299 -0.010565"/>
    <geometry>
      <mesh filename="package://quadruped_description/meshes/leg_parallel_plate_v1_2.stl" scale="0.001 0.001 0.001"/>
    </geometry>
  </collision>
</link>

<link name="leg_parallel_plate_v1_3">
  <inertial>
    <origin rpy="0 0 0" xyz="-0.0003169612082061096 0.00031756293888266646 -0.0030499707176077657"/>
    <mass value="0.000869495656702597"/>
    <inertia ixx="0.0" ixy="0.0" ixz="0.0" iyy="0.0" iyz="-0.0" izz="0.0"/>
  </inertial>
  <visual>
    <origin rpy="0 0 0" xyz="0.023857 -0.027366 -0.010573"/>
    <geometry>
      <mesh filename="package://quadruped_description/meshes/leg_parallel_plate_v1_3.stl" scale="0.001 0.001 0.001"/>
    </geometry>
    <material name="silver"/>
  </visual>
  <collision>
    <origin rpy="0 0 0" xyz="0.023857 -0.027366 -0.010573"/>
    <geometry>
      <mesh filename="package://quadruped_description/meshes/leg_parallel_plate_v1_3.stl" scale="0.001 0.001 0.001"/>
    </geometry>
  </collision>
</link>

<link name="leg_parallel_plate_v1_4">
  <inertial>
    <origin rpy="0 0 0" xyz="-0.0003169792815929419 -0.00031695596594204234 -0.0030498931301506105"/>
    <mass value="0.000869495656702597"/>
    <inertia ixx="0.0" ixy="-0.0" ixz="0.0" iyy="0.0" iyz="0.0" izz="0.0"/>
  </inertial>
  <visual>
    <origin rpy="0 0 0" xyz="0.026788 0.023232 -0.010566"/>
    <geometry>
      <mesh filename="package://quadruped_description/meshes/leg_parallel_plate_v1_4.stl" scale="0.001 0.001 0.001"/>
    </geometry>
    <material name="silver"/>
  </visual>
  <collision>
    <origin rpy="0 0 0" xyz="0.026788 0.023232 -0.010566"/>
    <geometry>
      <mesh filename="package://quadruped_description/meshes/leg_parallel_plate_v1_4.stl" scale="0.001 0.001 0.001"/>
    </geometry>
  </collision>
</link>

<link name="leg_servo_mount_v1_1">
  <inertial>
    <origin rpy="0 0 0" xyz="0.002518588687896721 -0.0025210876324369413 -0.003668094567380426"/>
    <mass value="0.001144548758330191"/>
    <inertia ixx="0.0" ixy="0.0" ixz="-0.0" iyy="0.0" iyz="0.0" izz="0.0"/>
  </inertial>
  <visual>
    <origin rpy="0 0 0" xyz="-0.026462 0.022236 -0.010559"/>
    <geometry>
      <mesh filename="package://quadruped_description/meshes/leg_servo_mount_v1_1.stl" scale="0.001 0.001 0.001"/>
    </geometry>
    <material name="silver"/>
  </visual>
  <collision>
    <origin rpy="0 0 0" xyz="-0.026462 0.022236 -0.010559"/>
    <geometry>
      <mesh filename="package://quadruped_description/meshes/leg_servo_mount_v1_1.stl" scale="0.001 0.001 0.001"/>
    </geometry>
  </collision>
</link>

<link name="leg_servo_mount_v1_2">
  <inertial>
    <origin rpy="0 0 0" xyz="0.0025708415423126366 0.0024685000943168653 -0.0036668414812549384"/>
    <mass value="0.001144548758330191"/>
    <inertia ixx="0.0" ixy="-0.0" ixz="-0.0" iyy="0.0" iyz="-0.0" izz="0.0"/>
  </inertial>
  <visual>
    <origin rpy="0 0 0" xyz="-0.023034 -0.026985 -0.010566"/>
    <geometry>
      <mesh filename="package://quadruped_description/meshes/leg_servo_mount_v1_2.stl" scale="0.001 0.001 0.001"/>
    </geometry>
    <material name="silver"/>
  </visual>
  <collision>
    <origin rpy="0 0 0" xyz="-0.023034 -0.026985 -0.010566"/>
    <geometry>
      <mesh filename="package://quadruped_description/meshes/leg_servo_mount_v1_2.stl" scale="0.001 0.001 0.001"/>
    </geometry>
  </collision>
</link>

<link name="leg_servo_mount_v1_3">
  <inertial>
    <origin rpy="0 0 0" xyz="-0.0025198248849201965 0.0025219533502297935 -0.0036665185531136665"/>
    <mass value="0.001144548758330191"/>
    <inertia ixx="0.0" ixy="0.0" ixz="0.0" iyy="0.0" iyz="-0.0" izz="0.0"/>
  </inertial>
  <visual>
    <origin rpy="0 0 0" xyz="0.026464 -0.023439 -0.010573"/>
    <geometry>
      <mesh filename="package://quadruped_description/meshes/leg_servo_mount_v1_3.stl" scale="0.001 0.001 0.001"/>
    </geometry>
    <material name="silver"/>
  </visual>
  <collision>
    <origin rpy="0 0 0" xyz="0.026464 -0.023439 -0.010573"/>
    <geometry>
      <mesh filename="package://quadruped_description/meshes/leg_servo_mount_v1_3.stl" scale="0.001 0.001 0.001"/>
    </geometry>
  </collision>
</link>

<link name="leg_servo_mount_v1_4">
  <inertial>
    <origin rpy="0 0 0" xyz="-0.0025205100308712466 -0.0025199762483761184 -0.003666819779044075"/>
    <mass value="0.001144548758330191"/>
    <inertia ixx="0.0" ixy="-0.0" ixz="0.0" iyy="0.0" iyz="0.0" izz="0.0"/>
  </inertial>
  <visual>
    <origin rpy="0 0 0" xyz="0.02286 0.025838 -0.010565"/>
    <geometry>
      <mesh filename="package://quadruped_description/meshes/leg_servo_mount_v1_4.stl" scale="0.001 0.001 0.001"/>
    </geometry>
    <material name="silver"/>
  </visual>
  <collision>
    <origin rpy="0 0 0" xyz="0.02286 0.025838 -0.010565"/>
    <geometry>
      <mesh filename="package://quadruped_description/meshes/leg_servo_mount_v1_4.stl" scale="0.001 0.001 0.001"/>
    </geometry>
  </collision>
</link>

<link name="bottom_pivot_plate_v1_1">
  <inertial>
    <origin rpy="0 0 0" xyz="0.003940297617400591 -0.00392433325184938 -0.0006263100567686191"/>
    <mass value="0.00131675130911231"/>
    <inertia ixx="0.0" ixy="0.0" ixz="0.0" iyy="0.0" iyz="-0.0" izz="0.0"/>
  </inertial>
  <visual>
    <origin rpy="0 0 0" xyz="-0.017803 0.017179 0.000489"/>
    <geometry>
      <mesh filename="package://quadruped_description/meshes/bottom_pivot_plate_v1_1.stl" scale="0.001 0.001 0.001"/>
    </geometry>
    <material name="silver"/>
  </visual>
  <collision>
    <origin rpy="0 0 0" xyz="-0.017803 0.017179 0.000489"/>
    <geometry>
      <mesh filename="package://quadruped_description/meshes/bottom_pivot_plate_v1_1.stl" scale="0.001 0.001 0.001"/>
    </geometry>
  </collision>
</link>

<link name="bottom_pivot_plate_v1_2">
  <inertial>
    <origin rpy="0 0 0" xyz="0.0039247047001400096 0.0039402484443478505 -0.0006250769011045311"/>
    <mass value="0.00131675130911231"/>
    <inertia ixx="0.0" ixy="-0.0" ixz="0.0" iyy="0.0" iyz="-0.0" izz="0.0"/>
  </inertial>
  <visual>
    <origin rpy="0 0 0" xyz="-0.017803 -0.018433 0.000484"/>
    <geometry>
      <mesh filename="package://quadruped_description/meshes/bottom_pivot_plate_v1_2.stl" scale="0.001 0.001 0.001"/>
    </geometry>
    <material name="silver"/>
  </visual>
  <collision>
    <origin rpy="0 0 0" xyz="-0.017803 -0.018433 0.000484"/>
    <geometry>
      <mesh filename="package://quadruped_description/meshes/bottom_pivot_plate_v1_2.stl" scale="0.001 0.001 0.001"/>
    </geometry>
  </collision>
</link>

<link name="bottom_pivot_plate_v1_3">
  <inertial>
    <origin rpy="0 0 0" xyz="-0.0039398843525865965 0.003924412591725067 -0.0006238551278565155"/>
    <mass value="0.00131675130911231"/>
    <inertia ixx="0.0" ixy="0.0" ixz="0.0" iyy="0.0" iyz="-0.0" izz="0.0"/>
  </inertial>
  <visual>
    <origin rpy="0 0 0" xyz="0.017809 -0.018385 0.000479"/>
    <geometry>
      <mesh filename="package://quadruped_description/meshes/bottom_pivot_plate_v1_3.stl" scale="0.001 0.001 0.001"/>
    </geometry>
    <material name="silver"/>
  </visual>
  <collision>
    <origin rpy="0 0 0" xyz="0.017809 -0.018385 0.000479"/>
    <geometry>
      <mesh filename="package://quadruped_description/meshes/bottom_pivot_plate_v1_3.stl" scale="0.001 0.001 0.001"/>
    </geometry>
  </collision>
</link>

<link name="bottom_pivot_plate_v1_4">
  <inertial>
    <origin rpy="0 0 0" xyz="-0.003924291434819108 -0.003939811277040264 -0.0006250812097189254"/>
    <mass value="0.00131675130911231"/>
    <inertia ixx="0.0" ixy="-0.0" ixz="0.0" iyy="0.0" iyz="-0.0" izz="0.0"/>
  </inertial>
  <visual>
    <origin rpy="0 0 0" xyz="0.017809 0.017178 0.000484"/>
    <geometry>
      <mesh filename="package://quadruped_description/meshes/bottom_pivot_plate_v1_4.stl" scale="0.001 0.001 0.001"/>
    </geometry>
    <material name="silver"/>
  </visual>
  <collision>
    <origin rpy="0 0 0" xyz="0.017809 0.017178 0.000484"/>
    <geometry>
      <mesh filename="package://quadruped_description/meshes/bottom_pivot_plate_v1_4.stl" scale="0.001 0.001 0.001"/>
    </geometry>
  </collision>
</link>

<link name="servo_motor_v1_5">
  <inertial>
    <origin rpy="0 0 0" xyz="0.00221096275125042 0.0022106432735936807 -0.004789635038760779"/>
    <mass value="0.0004848665871049835"/>
    <inertia ixx="0.0" ixy="-0.0" ixz="-0.0" iyy="0.0" iyz="-0.0" izz="0.0"/>
  </inertial>
  <visual>
    <origin rpy="0 0 0" xyz="-0.02984 0.025618 -0.010728"/>
    <geometry>
      <mesh filename="package://quadruped_description/meshes/servo_motor_v1_5.stl" scale="0.001 0.001 0.001"/>
    </geometry>
    <material name="silver"/>
  </visual>
  <collision>
    <origin rpy="0 0 0" xyz="-0.02984 0.025618 -0.010728"/>
    <geometry>
      <mesh filename="package://quadruped_description/meshes/servo_motor_v1_5.stl" scale="0.001 0.001 0.001"/>
    </geometry>
  </collision>
</link>

<link name="servo_motor_v1_6">
  <inertial>
    <origin rpy="0 0 0" xyz="-0.002164823484775844 0.0022556851689711672 -0.004788506932811807"/>
    <mass value="0.0004848665871049835"/>
    <inertia ixx="0.0" ixy="0.0" ixz="0.0" iyy="0.0" iyz="-0.0" izz="0.0"/>
  </inertial>
  <visual>
    <origin rpy="0 0 0" xyz="-0.026482 -0.030295 -0.010736"/>
    <geometry>
      <mesh filename="package://quadruped_description/meshes/servo_motor_v1_6.stl" scale="0.001 0.001 0.001"/>
    </geometry>
    <material name="silver"/>
  </visual>
  <collision>
    <origin rpy="0 0 0" xyz="-0.026482 -0.030295 -0.010736"/>
    <geometry>
      <mesh filename="package://quadruped_description/meshes/servo_motor_v1_6.stl" scale="0.001 0.001 0.001"/>
    </geometry>
  </collision>
</link>

<link name="servo_motor_v1_7">
  <inertial>
    <origin rpy="0 0 0" xyz="-0.002211481759225725 -0.0022084821765191096 -0.004789565747197648"/>
    <mass value="0.0004848665871049835"/>
    <inertia ixx="0.0" ixy="-0.0" ixz="0.0" iyy="0.0" iyz="0.0" izz="0.0"/>
  </inertial>
  <visual>
    <origin rpy="0 0 0" xyz="0.029843 -0.02682 -0.010744"/>
    <geometry>
      <mesh filename="package://quadruped_description/meshes/servo_motor_v1_7.stl" scale="0.001 0.001 0.001"/>
    </geometry>
    <material name="silver"/>
  </visual>
  <collision>
    <origin rpy="0 0 0" xyz="0.029843 -0.02682 -0.010744"/>
    <geometry>
      <mesh filename="package://quadruped_description/meshes/servo_motor_v1_7.stl" scale="0.001 0.001 0.001"/>
    </geometry>
  </collision>
</link>

<link name="servo_motor_v1_8">
  <inertial>
    <origin rpy="0 0 0" xyz="0.00221011266995072 -0.002209838040801042 -0.00478974718224382"/>
    <mass value="0.0004848665871049835"/>
    <inertia ixx="0.0" ixy="0.0" ixz="-0.0" iyy="0.0" iyz="0.0" izz="0.0"/>
  </inertial>
  <visual>
    <origin rpy="0 0 0" xyz="0.02624 0.029218 -0.010735"/>
    <geometry>
      <mesh filename="package://quadruped_description/meshes/servo_motor_v1_8.stl" scale="0.001 0.001 0.001"/>
    </geometry>
    <material name="silver"/>
  </visual>
  <collision>
    <origin rpy="0 0 0" xyz="0.02624 0.029218 -0.010735"/>
    <geometry>
      <mesh filename="package://quadruped_description/meshes/servo_motor_v1_8.stl" scale="0.001 0.001 0.001"/>
    </geometry>
  </collision>
</link>

<link name="leg_servo_arm_v1_1">
  <inertial>
    <origin rpy="0 0 0" xyz="0.0035711227260938373 -0.002689715822478962 -2.3329241953194343e-05"/>
    <mass value="0.0006066560485475096"/>
    <inertia ixx="0.0" ixy="0.0" ixz="0.0" iyy="0.0" iyz="-0.0" izz="0.0"/>
  </inertial>
  <visual>
    <origin rpy="0 0 0" xyz="-0.027254 0.0282 -0.004028"/>
    <geometry>
      <mesh filename="package://quadruped_description/meshes/leg_servo_arm_v1_1.stl" scale="0.001 0.001 0.001"/>
    </geometry>
    <material name="silver"/>
  </visual>
  <collision>
    <origin rpy="0 0 0" xyz="-0.027254 0.0282 -0.004028"/>
    <geometry>
      <mesh filename="package://quadruped_description/meshes/leg_servo_arm_v1_1.stl" scale="0.001 0.001 0.001"/>
    </geometry>
  </collision>
</link>

<link name="leg_parallel_linkage_v1_1">
  <inertial>
    <origin rpy="0 0 0" xyz="0.003976763671940074 -0.0030954961196519165 -3.936130299420082e-06"/>
    <mass value="0.00046200899599845404"/>
    <inertia ixx="0.0" ixy="0.0" ixz="0.0" iyy="0.0" iyz="-0.0" izz="0.0"/>
  </inertial>
  <visual>
    <origin rpy="0 0 0" xyz="-0.027013 0.02844 -0.010983"/>
    <geometry>
      <mesh filename="package://quadruped_description/meshes/leg_parallel_linkage_v1_1.stl" scale="0.001 0.001 0.001"/>
    </geometry>
    <material name="silver"/>
  </visual>
  <collision>
    <origin rpy="0 0 0" xyz="-0.027013 0.02844 -0.010983"/>
    <geometry>
      <mesh filename="package://quadruped_description/meshes/leg_parallel_linkage_v1_1.stl" scale="0.001 0.001 0.001"/>
    </geometry>
  </collision>
</link>

<link name="leg_parallel_plate_v1_1">
  <inertial>
    <origin rpy="0 0 0" xyz="-0.002842085555363149 0.0019600908093042393 -0.003474661877473836"/>
    <mass value="0.000869495656702597"/>
    <inertia ixx="0.0" ixy="0.0" ixz="-0.0" iyy="0.0" iyz="0.0" izz="0.0"/>
  </inertial>
  <visual>
    <origin rpy="0 0 0" xyz="-0.027013 0.02844 -0.010983"/>
    <geometry>
      <mesh filename="package://quadruped_description/meshes/leg_parallel_plate_v1_1.stl" scale="0.001 0.001 0.001"/>
    </geometry>
    <material name="silver"/>
  </visual>
  <collision>
    <origin rpy="0 0 0" xyz="-0.027013 0.02844 -0.010983"/>
    <geometry>
      <mesh filename="package://quadruped_description/meshes/leg_parallel_plate_v1_1.stl" scale="0.001 0.001 0.001"/>
    </geometry>
  </collision>
</link>

<link name="leg_rev_v1_1">
  <inertial>
    <origin rpy="0 0 0" xyz="-0.0001478833884736644 -0.0006870068186052569 -0.002769244655104736"/>
    <mass value="0.001572468577271628"/>
    <inertia ixx="0.0" ixy="0.0" ixz="0.0" iyy="0.0" iyz="-0.0" izz="0.0"/>
  </inertial>
  <visual>
    <origin rpy="0 0 0" xyz="-0.034082 0.035514 -0.003975"/>
    <geometry>
      <mesh filename="package://quadruped_description/meshes/leg_rev_v1_1.stl" scale="0.001 0.001 0.001"/>
    </geometry>
    <material name="silver"/>
  </visual>
  <collision>
    <origin rpy="0 0 0" xyz="-0.034082 0.035514 -0.003975"/>
    <geometry>
      <mesh filename="package://quadruped_description/meshes/leg_rev_v1_1.stl" scale="0.001 0.001 0.001"/>
    </geometry>
  </collision>
</link>

<link name="leg_parallel_linkage_v1_1">
  <inertial>
    <origin rpy="0 0 0" xyz="-0.003092236328059928 0.0039785038803480804 4.063869700579245e-06"/>
    <mass value="0.00046200899599845404"/>
    <inertia ixx="0.0" ixy="0.0" ixz="0.0" iyy="0.0" iyz="-0.0" izz="0.0"/>
  </inertial>
  <visual>
    <origin rpy="0 0 0" xyz="-0.034082 0.035514 -0.010975"/>
    <geometry>
      <mesh filename="package://quadruped_description/meshes/leg_parallel_linkage_v1_1.stl" scale="0.001 0.001 0.001"/>
    </geometry>
    <material name="silver"/>
  </visual>
  <collision>
    <origin rpy="0 0 0" xyz="-0.034082 0.035514 -0.010975"/>
    <geometry>
      <mesh filename="package://quadruped_description/meshes/leg_parallel_linkage_v1_1.stl" scale="0.001 0.001 0.001"/>
    </geometry>
  </collision>
</link>

<link name="leg_servo_arm_v1_2">
  <inertial>
    <origin rpy="0 0 0" xyz="0.002760806793314991 0.003515504970059792 8.607293750825893e-05"/>
    <mass value="0.0006066560485475096"/>
    <inertia ixx="0.0" ixy="-0.0" ixz="-0.0" iyy="0.0" iyz="-0.0" izz="0.0"/>
  </inertial>
  <visual>
    <origin rpy="0 0 0" xyz="-0.029012 -0.027659 -0.004036"/>
    <geometry>
      <mesh filename="package://quadruped_description/meshes/leg_servo_arm_v1_2.stl" scale="0.001 0.001 0.001"/>
    </geometry>
    <material name="silver"/>
  </visual>
  <collision>
    <origin rpy="0 0 0" xyz="-0.029012 -0.027659 -0.004036"/>
    <geometry>
      <mesh filename="package://quadruped_description/meshes/leg_servo_arm_v1_2.stl" scale="0.001 0.001 0.001"/>
    </geometry>
  </collision>
</link>

<link name="leg_rev_v1_2">
  <inertial>
    <origin rpy="0 0 0" xyz="0.0006842236923735381 -0.00016062169912956642 -0.0027701375470659496"/>
    <mass value="0.001572468577271628"/>
    <inertia ixx="0.0" ixy="-0.0" ixz="0.0" iyy="0.0" iyz="0.0" izz="0.0"/>
  </inertial>
  <visual>
    <origin rpy="0 0 0" xyz="-0.036461 -0.034337 -0.004231"/>
    <geometry>
      <mesh filename="package://quadruped_description/meshes/leg_rev_v1_2.stl" scale="0.001 0.001 0.001"/>
    </geometry>
    <material name="silver"/>
  </visual>
  <collision>
    <origin rpy="0 0 0" xyz="-0.036461 -0.034337 -0.004231"/>
    <geometry>
      <mesh filename="package://quadruped_description/meshes/leg_rev_v1_2.stl" scale="0.001 0.001 0.001"/>
    </geometry>
  </collision>
</link>

<link name="leg_parallel_linkage_v1_2">
  <inertial>
    <origin rpy="0 0 0" xyz="0.003173287793338555 0.003912690348411064 0.00011957792665612949"/>
    <mass value="0.00046200899599845404"/>
    <inertia ixx="0.0" ixy="-0.0" ixz="-0.0" iyy="0.0" iyz="-0.0" izz="0.0"/>
  </inertial>
  <visual>
    <origin rpy="0 0 0" xyz="-0.029248 -0.027411 -0.010991"/>
    <geometry>
      <mesh filename="package://quadruped_description/meshes/leg_parallel_linkage_v1_2.stl" scale="0.001 0.001 0.001"/>
    </geometry>
    <material name="silver"/>
  </visual>
  <collision>
    <origin rpy="0 0 0" xyz="-0.029248 -0.027411 -0.010991"/>
    <geometry>
      <mesh filename="package://quadruped_description/meshes/leg_parallel_linkage_v1_2.stl" scale="0.001 0.001 0.001"/>
    </geometry>
  </collision>
</link>

<link name="leg_rev_v1_2">
  <inertial>
    <origin rpy="0 0 0" xyz="0.0006852236923735391 -0.00015762169912957036 -0.009769137547065949"/>
    <mass value="0.001572468577271628"/>
    <inertia ixx="0.0" ixy="-0.0" ixz="0.0" iyy="0.0" iyz="0.0" izz="0.0"/>
  </inertial>
  <visual>
    <origin rpy="0 0 0" xyz="-0.03646 -0.034334 -0.01123"/>
    <geometry>
      <mesh filename="package://quadruped_description/meshes/leg_rev_v1_2.stl" scale="0.001 0.001 0.001"/>
    </geometry>
    <material name="silver"/>
  </visual>
  <collision>
    <origin rpy="0 0 0" xyz="-0.03646 -0.034334 -0.01123"/>
    <geometry>
      <mesh filename="package://quadruped_description/meshes/leg_rev_v1_2.stl" scale="0.001 0.001 0.001"/>
    </geometry>
  </collision>
</link>

<link name="leg_parallel_plate_v1_2">
  <inertial>
    <origin rpy="0 0 0" xyz="-0.0020174799661103367 -0.0028010460511558727 -0.003475778338663464"/>
    <mass value="0.000869495656702597"/>
    <inertia ixx="0.0" ixy="-0.0" ixz="-0.0" iyy="0.0" iyz="-0.0" izz="0.0"/>
  </inertial>
  <visual>
    <origin rpy="0 0 0" xyz="-0.029248 -0.027411 -0.010991"/>
    <geometry>
      <mesh filename="package://quadruped_description/meshes/leg_parallel_plate_v1_2.stl" scale="0.001 0.001 0.001"/>
    </geometry>
    <material name="silver"/>
  </visual>
  <collision>
    <origin rpy="0 0 0" xyz="-0.029248 -0.027411 -0.010991"/>
    <geometry>
      <mesh filename="package://quadruped_description/meshes/leg_parallel_plate_v1_2.stl" scale="0.001 0.001 0.001"/>
    </geometry>
  </collision>
</link>

<link name="leg_servo_arm_v1_3">
  <inertial>
    <origin rpy="0 0 0" xyz="-0.003571080123481514 0.002689360966377577 3.492151037218921e-05"/>
    <mass value="0.0006066560485475096"/>
    <inertia ixx="0.0" ixy="0.0" ixz="0.0" iyy="0.0" iyz="-0.0" izz="0.0"/>
  </inertial>
  <visual>
    <origin rpy="0 0 0" xyz="0.027258 -0.029405 -0.004044"/>
    <geometry>
      <mesh filename="package://quadruped_description/meshes/leg_servo_arm_v1_3.stl" scale="0.001 0.001 0.001"/>
    </geometry>
    <material name="silver"/>
  </visual>
  <collision>
    <origin rpy="0 0 0" xyz="0.027258 -0.029405 -0.004044"/>
    <geometry>
      <mesh filename="package://quadruped_description/meshes/leg_servo_arm_v1_3.stl" scale="0.001 0.001 0.001"/>
    </geometry>
  </collision>
</link>

<link name="leg_parallel_linkage_v1_3">
  <inertial>
    <origin rpy="0 0 0" xyz="-0.003976507641764486 0.0030949335442993463 6.18474038962518e-05"/>
    <mass value="0.00046200899599845404"/>
    <inertia ixx="0.0" ixy="0.0" ixz="0.0" iyy="0.0" iyz="-0.0" izz="0.0"/>
  </inertial>
  <visual>
    <origin rpy="0 0 0" xyz="0.027015 -0.029643 -0.010999"/>
    <geometry>
      <mesh filename="package://quadruped_description/meshes/leg_parallel_linkage_v1_3.stl" scale="0.001 0.001 0.001"/>
    </geometry>
    <material name="silver"/>
  </visual>
  <collision>
    <origin rpy="0 0 0" xyz="0.027015 -0.029643 -0.010999"/>
    <geometry>
      <mesh filename="package://quadruped_description/meshes/leg_parallel_linkage_v1_3.stl" scale="0.001 0.001 0.001"/>
    </geometry>
  </collision>
</link>

<link name="leg_rev_v1_3">
  <inertial>
    <origin rpy="0 0 0" xyz="0.00014707998310453663 0.0006875595158804954 -0.0027695585750146245"/>
    <mass value="0.001572468577271628"/>
    <inertia ixx="0.0" ixy="0.0" ixz="-0.0" iyy="0.0" iyz="0.0" izz="0.0"/>
  </inertial>
  <visual>
    <origin rpy="0 0 0" xyz="0.034086 -0.036719 -0.004123"/>
    <geometry>
      <mesh filename="package://quadruped_description/meshes/leg_rev_v1_3.stl" scale="0.001 0.001 0.001"/>
    </geometry>
    <material name="silver"/>
  </visual>
  <collision>
    <origin rpy="0 0 0" xyz="0.034086 -0.036719 -0.004123"/>
    <geometry>
      <mesh filename="package://quadruped_description/meshes/leg_rev_v1_3.stl" scale="0.001 0.001 0.001"/>
    </geometry>
  </collision>
</link>

<link name="leg_parallel_linkage_v1_3">
  <inertial>
    <origin rpy="0 0 0" xyz="0.0030914923582355154 -0.003978066455700653 -6.215259610374731e-05"/>
    <mass value="0.00046200899599845404"/>
    <inertia ixx="0.0" ixy="0.0" ixz="0.0" iyy="0.0" iyz="-0.0" izz="0.0"/>
  </inertial>
  <visual>
    <origin rpy="0 0 0" xyz="0.034083 -0.036716 -0.011123"/>
    <geometry>
      <mesh filename="package://quadruped_description/meshes/leg_parallel_linkage_v1_3.stl" scale="0.001 0.001 0.001"/>
    </geometry>
    <material name="silver"/>
  </visual>
  <collision>
    <origin rpy="0 0 0" xyz="0.034083 -0.036716 -0.011123"/>
    <geometry>
      <mesh filename="package://quadruped_description/meshes/leg_parallel_linkage_v1_3.stl" scale="0.001 0.001 0.001"/>
    </geometry>
  </collision>
</link>

<link name="leg_parallel_plate_v1_3">
  <inertial>
    <origin rpy="0 0 0" xyz="0.0028410387917938915 -0.0019594370611173313 -0.003475970717607765"/>
    <mass value="0.000869495656702597"/>
    <inertia ixx="0.0" ixy="0.0" ixz="0.0" iyy="0.0" iyz="-0.0" izz="0.0"/>
  </inertial>
  <visual>
    <origin rpy="0 0 0" xyz="0.027015 -0.029643 -0.010999"/>
    <geometry>
      <mesh filename="package://quadruped_description/meshes/leg_parallel_plate_v1_3.stl" scale="0.001 0.001 0.001"/>
    </geometry>
    <material name="silver"/>
  </visual>
  <collision>
    <origin rpy="0 0 0" xyz="0.027015 -0.029643 -0.010999"/>
    <geometry>
      <mesh filename="package://quadruped_description/meshes/leg_parallel_plate_v1_3.stl" scale="0.001 0.001 0.001"/>
    </geometry>
  </collision>
</link>

<link name="leg_servo_arm_v1_4">
  <inertial>
    <origin rpy="0 0 0" xyz="-0.0026882728368581472 -0.003571845796858035 -1.9812613215769957e-05"/>
    <mass value="0.0006066560485475096"/>
    <inertia ixx="0.0" ixy="-0.0" ixz="-0.0" iyy="0.0" iyz="-0.0" izz="0.0"/>
  </inertial>
  <visual>
    <origin rpy="0 0 0" xyz="0.028825 0.026633 -0.004036"/>
    <geometry>
      <mesh filename="package://quadruped_description/meshes/leg_servo_arm_v1_4.stl" scale="0.001 0.001 0.001"/>
    </geometry>
    <material name="silver"/>
  </visual>
  <collision>
    <origin rpy="0 0 0" xyz="0.028825 0.026633 -0.004036"/>
    <geometry>
      <mesh filename="package://quadruped_description/meshes/leg_servo_arm_v1_4.stl" scale="0.001 0.001 0.001"/>
    </geometry>
  </collision>
</link>

<link name="leg_parallel_linkage_v1_4">
  <inertial>
    <origin rpy="0 0 0" xyz="-0.0030939838853246623 -0.003977723604417963 8.69419066081012e-08"/>
    <mass value="0.00046200899599845404"/>
    <inertia ixx="0.0" ixy="-0.0" ixz="-0.0" iyy="0.0" iyz="0.0" izz="0.0"/>
  </inertial>
  <visual>
    <origin rpy="0 0 0" xyz="0.029063 0.026392 -0.010991"/>
    <geometry>
      <mesh filename="package://quadruped_description/meshes/leg_parallel_linkage_v1_4.stl" scale="0.001 0.001 0.001"/>
    </geometry>
    <material name="silver"/>
  </visual>
  <collision>
    <origin rpy="0 0 0" xyz="0.029063 0.026392 -0.010991"/>
    <geometry>
      <mesh filename="package://quadruped_description/meshes/leg_parallel_linkage_v1_4.stl" scale="0.001 0.001 0.001"/>
    </geometry>
  </collision>
</link>

<link name="leg_rev_v1_4">
  <inertial>
    <origin rpy="0 0 0" xyz="-0.000688202836564282 0.0001471271319503087 -0.002769076908361876"/>
    <mass value="0.001572468577271628"/>
    <inertia ixx="0.0" ixy="-0.0" ixz="-0.0" iyy="0.0" iyz="-0.0" izz="0.0"/>
  </inertial>
  <visual>
    <origin rpy="0 0 0" xyz="0.036136 0.033463 -0.003991"/>
    <geometry>
      <mesh filename="package://quadruped_description/meshes/leg_rev_v1_4.stl" scale="0.001 0.001 0.001"/>
    </geometry>
    <material name="silver"/>
  </visual>
  <collision>
    <origin rpy="0 0 0" xyz="0.036136 0.033463 -0.003991"/>
    <geometry>
      <mesh filename="package://quadruped_description/meshes/leg_rev_v1_4.stl" scale="0.001 0.001 0.001"/>
    </geometry>
  </collision>
</link>

<link name="leg_parallel_linkage_v1_4">
  <inertial>
    <origin rpy="0 0 0" xyz="0.0039770161146753386 0.0030932763955820383 8.69419066081012e-08"/>
    <mass value="0.00046200899599845404"/>
    <inertia ixx="0.0" ixy="-0.0" ixz="-0.0" iyy="0.0" iyz="0.0" izz="0.0"/>
  </inertial>
  <visual>
    <origin rpy="0 0 0" xyz="0.036134 0.033463 -0.010991"/>
    <geometry>
      <mesh filename="package://quadruped_description/meshes/leg_parallel_linkage_v1_4.stl" scale="0.001 0.001 0.001"/>
    </geometry>
    <material name="silver"/>
  </visual>
  <collision>
    <origin rpy="0 0 0" xyz="0.036134 0.033463 -0.010991"/>
    <geometry>
      <mesh filename="package://quadruped_description/meshes/leg_parallel_linkage_v1_4.stl" scale="0.001 0.001 0.001"/>
    </geometry>
  </collision>
</link>

<link name="leg_parallel_plate_v1_4">
  <inertial>
    <origin rpy="0 0 0" xyz="0.0019580207184070574 0.0028430440340579573 -0.0034748931301506105"/>
    <mass value="0.000869495656702597"/>
    <inertia ixx="0.0" ixy="-0.0" ixz="0.0" iyy="0.0" iyz="0.0" izz="0.0"/>
  </inertial>
  <visual>
    <origin rpy="0 0 0" xyz="0.029063 0.026392 -0.010991"/>
    <geometry>
      <mesh filename="package://quadruped_description/meshes/leg_parallel_plate_v1_4.stl" scale="0.001 0.001 0.001"/>
    </geometry>
    <material name="silver"/>
  </visual>
  <collision>
    <origin rpy="0 0 0" xyz="0.029063 0.026392 -0.010991"/>
    <geometry>
      <mesh filename="package://quadruped_description/meshes/leg_parallel_plate_v1_4.stl" scale="0.001 0.001 0.001"/>
    </geometry>
  </collision>
</link>

<joint name="Rigid1" type="fixed">
  <origin rpy="0 0 0" xyz="-2e-06 -0.016249 0.005264"/>
  <parent link="base_link"/>
  <child link="body_spacer_v1_1"/>
</joint>

<joint name="Rigid2" type="fixed">
  <origin rpy="0 0 0" xyz="-2e-06 0.017501 0.003768"/>
  <parent link="base_link"/>
  <child link="body_spacer_v1_2"/>
</joint>

<joint name="Rigid3" type="fixed">
  <origin rpy="0 0 0" xyz="0.016873 0.000626 0.003764"/>
  <parent link="base_link"/>
  <child link="body_spacer_v1_3"/>
</joint>

<joint name="Rigid4" type="fixed">
  <origin rpy="0 0 0" xyz="-0.016877 0.000626 0.003768"/>
  <parent link="base_link"/>
  <child link="body_spacer_v1_4"/>
</joint>

<joint name="Rigid5" type="fixed">
  <origin rpy="0 0 0" xyz="-5e-06 0.000628 0.008266"/>
  <parent link="base_link"/>
  <child link="body_top_plate_v1_1"/>
</joint>

<joint name="Rigid6" type="fixed">
  <origin rpy="0 0 0" xyz="0.017806 -0.017181 0.015061"/>
  <parent link="base_link"/>
  <child link="servo_motor_v1_1"/>
</joint>

<joint name="Rigid7" type="fixed">
  <origin rpy="0 0 0" xyz="0.017806 0.018431 0.015066"/>
  <parent link="base_link"/>
  <child link="servo_motor_v1_2"/>
</joint>

<joint name="Rigid8" type="fixed">
  <origin rpy="0 0 0" xyz="-0.017807 0.018383 0.015071"/>
  <parent link="base_link"/>
  <child link="servo_motor_v1_3"/>
</joint>

<joint name="Rigid9" type="fixed">
  <origin rpy="0 0 0" xyz="-0.017807 -0.01718 0.015066"/>
  <parent link="base_link"/>
  <child link="servo_motor_v1_4"/>
</joint>

<joint name="Rigid10" type="fixed">
  <origin rpy="0 0 0" xyz="0.0163 -0.0163 0.002545"/>
  <parent link="body_top_plate_v1_1"/>
  <child link="leg_servo_retainer_v1_1"/>
</joint>

<joint name="Rigid11" type="fixed">
  <origin rpy="0 0 0" xyz="0.0163 0.0163 0.00255"/>
  <parent link="body_top_plate_v1_1"/>
  <child link="leg_servo_retainer_v1_2"/>
</joint>

<joint name="Rigid12" type="fixed">
  <origin rpy="0 0 0" xyz="-0.0163 0.0163 0.002555"/>
  <parent link="body_top_plate_v1_1"/>
  <child link="leg_servo_retainer_v1_3"/>
</joint>

<joint name="Rigid13" type="fixed">
  <origin rpy="0 0 0" xyz="-0.0163 -0.0163 0.00255"/>
  <parent link="body_top_plate_v1_1"/>
  <child link="leg_servo_retainer_v1_4"/>
</joint>

<joint name="Rev14" type="continuous">
  <origin rpy="0 0 0" xyz="0.0 0.0 0.0"/>
  <parent link="servo_motor_v1_1"/>
  <child link="leg_top_pivot_plate_v1_1"/>
  <axis xyz="0.000143 -0.000143 1.0"/>
</joint>

<joint name="Rev15" type="continuous">
  <origin rpy="0 0 0" xyz="0.0 0.0 0.0"/>
  <parent link="servo_motor_v1_2"/>
  <child link="leg_top_pivot_plate_v1_2"/>
  <axis xyz="0.000143 -0.000143 1.0"/>
</joint>

<joint name="Rev16" type="continuous">
  <origin rpy="0 0 0" xyz="0.0 0.0 0.0"/>
  <parent link="servo_motor_v1_3"/>
  <child link="leg_top_pivot_plate_v1_3"/>
  <axis xyz="0.000143 -0.000143 1.0"/>
</joint>

<joint name="Rev17" type="continuous">
  <origin rpy="0 0 0" xyz="0.0 0.0 0.0"/>
  <parent link="servo_motor_v1_4"/>
  <child link="leg_top_pivot_plate_v1_4"/>
  <axis xyz="0.000143 -0.000143 1.0"/>
</joint>

<joint name="Rigid18" type="fixed">
  <origin rpy="0 0 0" xyz="0.009207 -0.011259 -0.004078"/>
  <parent link="leg_top_pivot_plate_v1_1"/>
  <child link="leg_parallel_plate_v1_1"/>
</joint>

<joint name="Rigid19" type="fixed">
  <origin rpy="0 0 0" xyz="0.011442 0.00898 -0.004075"/>
  <parent link="leg_top_pivot_plate_v1_2"/>
  <child link="leg_parallel_plate_v1_2"/>
</joint>

<joint name="Rigid20" type="fixed">
  <origin rpy="0 0 0" xyz="-0.009208 0.01126 -0.004072"/>
  <parent link="leg_top_pivot_plate_v1_3"/>
  <child link="leg_parallel_plate_v1_3"/>
</joint>

<joint name="Rigid21" type="fixed">
  <origin rpy="0 0 0" xyz="-0.011256 -0.009212 -0.004075"/>
  <parent link="leg_top_pivot_plate_v1_4"/>
  <child link="leg_parallel_plate_v1_4"/>
</joint>

<joint name="Rigid22" type="fixed">
  <origin rpy="0 0 0" xyz="0.008656 -0.005055 -0.004502"/>
  <parent link="leg_top_pivot_plate_v1_1"/>
  <child link="leg_servo_mount_v1_1"/>
</joint>

<joint name="Rigid23" type="fixed">
  <origin rpy="0 0 0" xyz="0.005228 0.008554 -0.0045"/>
  <parent link="leg_top_pivot_plate_v1_2"/>
  <child link="leg_servo_mount_v1_2"/>
</joint>

<joint name="Rigid24" type="fixed">
  <origin rpy="0 0 0" xyz="-0.008657 0.005056 -0.004498"/>
  <parent link="leg_top_pivot_plate_v1_3"/>
  <child link="leg_servo_mount_v1_3"/>
</joint>

<joint name="Rigid25" type="fixed">
  <origin rpy="0 0 0" xyz="-0.005053 -0.008658 -0.004501"/>
  <parent link="leg_top_pivot_plate_v1_4"/>
  <child link="leg_servo_mount_v1_4"/>
</joint>

<joint name="Rev26" type="continuous">
  <origin rpy="0 0 0" xyz="0.017803 -0.017179 -0.000489"/>
  <parent link="base_link"/>
  <child link="bottom_pivot_plate_v1_1"/>
  <axis xyz="0.000143 -0.000143 1.0"/>
</joint>

<joint name="Rev27" type="continuous">
  <origin rpy="0 0 0" xyz="0.017803 0.018433 -0.000484"/>
  <parent link="base_link"/>
  <child link="bottom_pivot_plate_v1_2"/>
  <axis xyz="0.000143 -0.000143 1.0"/>
</joint>

<joint name="Rev28" type="continuous">
  <origin rpy="0 0 0" xyz="-0.017809 0.018385 -0.000479"/>
  <parent link="base_link"/>
  <child link="bottom_pivot_plate_v1_3"/>
  <axis xyz="0.000143 -0.000143 1.0"/>
</joint>

<joint name="Rev29" type="continuous">
  <origin rpy="0 0 0" xyz="-0.017809 -0.017178 -0.000484"/>
  <parent link="base_link"/>
  <child link="bottom_pivot_plate_v1_4"/>
  <axis xyz="0.000143 -0.000143 1.0"/>
</joint>

<joint name="Rigid30" type="fixed">
  <origin rpy="0 0 0" xyz="0.003378 -0.003382 0.000169"/>
  <parent link="leg_servo_mount_v1_1"/>
  <child link="servo_motor_v1_5"/>
</joint>

<joint name="Rigid31" type="fixed">
  <origin rpy="0 0 0" xyz="0.003448 0.00331 0.00017"/>
  <parent link="leg_servo_mount_v1_2"/>
  <child link="servo_motor_v1_6"/>
</joint>

<joint name="Rigid32" type="fixed">
  <origin rpy="0 0 0" xyz="-0.003379 0.003381 0.000171"/>
  <parent link="leg_servo_mount_v1_3"/>
  <child link="servo_motor_v1_7"/>
</joint>

<joint name="Rigid33" type="fixed">
  <origin rpy="0 0 0" xyz="-0.00338 -0.00338 0.00017"/>
  <parent link="leg_servo_mount_v1_4"/>
  <child link="servo_motor_v1_8"/>
</joint>

<joint name="Rev34" type="revolute">
  <origin rpy="0 0 0" xyz="-0.002586 -0.002582 -0.0067"/>
  <parent link="servo_motor_v1_5"/>
  <child link="leg_servo_arm_v1_1"/>
  <axis xyz="-0.707375 -0.706838 0.0"/>
  <limit effort="100" lower="-1.047198" upper="1.047198" velocity="100"/>
</joint>

<joint name="Rev35" type="continuous">
  <origin rpy="0 0 0" xyz="0.007069 -0.007074 -8e-06"/>
  <parent link="leg_parallel_plate_v1_1"/>
  <child link="leg_parallel_linkage_v1_1"/>
  <axis xyz="-0.707375 -0.706838 0.0"/>
</joint>

<joint name="Rev36" type="continuous">
  <origin rpy="0 0 0" xyz="-0.007069 0.007074 8e-06"/>
  <parent link="leg_parallel_linkage_v1_1"/>
  <child link="leg_parallel_plate_v1_1"/>
  <axis xyz="0.707375 0.706838 -0.0"/>
</joint>

<joint name="Rev37" type="continuous">
  <origin rpy="0 0 0" xyz="0.006828 -0.007314 -5.3e-05"/>
  <parent link="leg_servo_arm_v1_1"/>
  <child link="leg_rev_v1_1"/>
  <axis xyz="-0.707375 -0.706838 0.0"/>
</joint>

<joint name="Rev38" type="continuous">
  <origin rpy="0 0 0" xyz="0.0 0.0 0.007"/>
  <parent link="leg_rev_v1_1"/>
  <child link="leg_parallel_linkage_v1_1"/>
  <axis xyz="-0.707375 -0.706838 0.0"/>
</joint>

<joint name="Rev39" type="revolute">
  <origin rpy="0 0 0" xyz="0.00253 -0.002636 -0.0067"/>
  <parent link="servo_motor_v1_6"/>
  <child link="leg_servo_arm_v1_2"/>
  <axis xyz="0.69246 -0.721456 -0.000203"/>
  <limit effort="100" lower="-1.047198" upper="1.047198" velocity="100"/>
</joint>

<joint name="Rev40" type="continuous">
  <origin rpy="0 0 0" xyz="0.007448 0.006675 0.007194"/>
  <parent link="leg_servo_arm_v1_2"/>
  <child link="leg_rev_v1_2"/>
  <axis xyz="0.69246 -0.721456 -0.000203"/>
</joint>

<joint name="Rev41" type="continuous">
  <origin rpy="0 0 0" xyz="0.0 0.0 0.0"/>
  <parent link="leg_parallel_plate_v1_2"/>
  <child link="leg_parallel_linkage_v1_2"/>
  <axis xyz="0.69246 -0.721456 -0.000203"/>
</joint>

<joint name="Rev42" type="continuous">
  <origin rpy="0 0 0" xyz="0.007212 0.006923 0.000239"/>
  <parent link="leg_parallel_linkage_v1_2"/>
  <child link="leg_rev_v1_2"/>
  <axis xyz="0.69246 -0.721457 -0.000203"/>
</joint>

<joint name="Rev43" type="continuous">
  <origin rpy="0 0 0" xyz="0.0 0.0 0.0"/>
  <parent link="leg_parallel_linkage_v1_2"/>
  <child link="leg_parallel_plate_v1_2"/>
  <axis xyz="-0.69246 0.721457 0.000203"/>
</joint>

<joint name="Rev44" type="revolute">
  <origin rpy="0 0 0" xyz="0.002585 0.002585 -0.0067"/>
  <parent link="servo_motor_v1_7"/>
  <child link="leg_servo_arm_v1_3"/>
  <axis xyz="0.70738 0.706833 -0.0"/>
  <limit effort="100" lower="-1.047198" upper="1.047198" velocity="100"/>
</joint>

<joint name="Rev45" type="continuous">
  <origin rpy="0 0 0" xyz="-0.007068 0.007073 0.000124"/>
  <parent link="leg_parallel_plate_v1_3"/>
  <child link="leg_parallel_linkage_v1_3"/>
  <axis xyz="0.70738 0.706833 -0.0"/>
</joint>

<joint name="Rev46" type="continuous">
  <origin rpy="0 0 0" xyz="-0.006828 0.007314 7.9e-05"/>
  <parent link="leg_servo_arm_v1_3"/>
  <child link="leg_rev_v1_3"/>
  <axis xyz="-0.70738 -0.706833 0.0"/>
</joint>

<joint name="Rev47" type="continuous">
  <origin rpy="0 0 0" xyz="3e-06 -3e-06 0.007"/>
  <parent link="leg_rev_v1_3"/>
  <child link="leg_parallel_linkage_v1_3"/>
  <axis xyz="0.70738 0.706833 -0.0"/>
</joint>

<joint name="Rev48" type="continuous">
  <origin rpy="0 0 0" xyz="0.007068 -0.007073 -0.000124"/>
  <parent link="leg_parallel_linkage_v1_3"/>
  <child link="leg_parallel_plate_v1_3"/>
  <axis xyz="-0.70738 -0.706833 0.0"/>
</joint>

<joint name="Rev49" type="revolute">
  <origin rpy="0 0 0" xyz="-0.002585 0.002585 -0.006699"/>
  <parent link="servo_motor_v1_8"/>
  <child link="leg_servo_arm_v1_4"/>
  <axis xyz="-0.707107 0.707107 0.000203"/>
  <limit effort="100" lower="-1.047198" upper="1.047198" velocity="100"/>
</joint>

<joint name="Rev50" type="continuous">
  <origin rpy="0 0 0" xyz="-0.007071 -0.007071 0.0"/>
  <parent link="leg_parallel_plate_v1_4"/>
  <child link="leg_parallel_linkage_v1_4"/>
  <axis xyz="-0.707107 0.707107 0.000203"/>
</joint>

<joint name="Rev51" type="continuous">
  <origin rpy="0 0 0" xyz="-0.007311 -0.00683 -4.5e-05"/>
  <parent link="leg_servo_arm_v1_4"/>
  <child link="leg_rev_v1_4"/>
  <axis xyz="-0.707107 0.707107 0.000203"/>
</joint>

<joint name="Rev52" type="continuous">
  <origin rpy="0 0 0" xyz="2e-06 0.0 0.007"/>
  <parent link="leg_rev_v1_4"/>
  <child link="leg_parallel_linkage_v1_4"/>
  <axis xyz="-0.707107 0.707107 0.000203"/>
</joint>

<joint name="Rev53" type="continuous">
  <origin rpy="0 0 0" xyz="0.007071 0.007071 0.0"/>
  <parent link="leg_parallel_linkage_v1_4"/>
  <child link="leg_parallel_plate_v1_4"/>
  <axis xyz="0.707107 -0.707107 -0.000203"/>
</joint>

</robot>
