<?xml version="1.0"?>
<robot name="myfirst">
    <link name="base_link">
        <visual>
            <geometry>
                <mesh filename="package://quadruped/meshes/body_bottom_plate.stl"/>
            </geometry>
        </visual>
    </link>
    <link name="body_spacer_1">
        <visual>
            <geometry>
                <mesh filename="package://quadruped/meshes/body_spacer.stl"/>
            </geometry>
            <origin xyz="0 0.505 0"/>
        </visual>
    </link>
    <link name="body_spacer_2">
        <visual>
            <geometry>
                <mesh filename="package://quadruped/meshes/body_spacer.stl"/>
            </geometry>
            <origin rpy="0 1.57079 0" xyz="0 0.505 0"/>
        </visual>
    </link>
    <link name="body_spacer_3">
        <visual>
            <geometry>
                <mesh filename="package://quadruped/meshes/body_spacer.stl"/>
            </geometry>
            <origin rpy="0 1.57079 0" xyz="0 0.505 0"/>
        </visual>
    </link>
    <link name="body_spacer_4">
        <visual>
            <geometry>
                <mesh filename="package://quadruped/meshes/body_spacer.stl"/>
            </geometry>
            <origin xyz="0 0.505 0"/>
        </visual>
    </link>
    <link name="body_top_plate">
        <visual>
            <geometry>
                <mesh filename="package://quadruped/meshes/body_top_plate.stl"/>
            </geometry>
            <origin xyz="0 0 0"/>
        </visual>
    </link>
    <link name="leg_bottom_pivot_plate_1">
        <visual>
            <geometry>
                <mesh filename="package://quadruped/meshes/leg_bottom_pivot_plate.stl"/>
            </geometry>
            <origin rpy="1.57079 -0.78539 0"/>
        </visual>
    </link>
    <link name="leg_bottom_pivot_plate_2">
        <visual>
            <geometry>
                <mesh filename="package://quadruped/meshes/leg_bottom_pivot_plate.stl"/>
            </geometry>
            <origin rpy="1.57079 -2.35619 0"/>
        </visual>
    </link>
    <link name="leg_bottom_pivot_plate_3">
        <visual>
            <geometry>
                <mesh filename="package://quadruped/meshes/leg_bottom_pivot_plate.stl"/>
            </geometry>
            <origin rpy="1.57079 2.35619 0"/>
        </visual>
    </link>
    <link name="leg_bottom_pivot_plate_4">
        <visual>
            <geometry>
                <mesh filename="package://quadruped/meshes/leg_bottom_pivot_plate.stl"/>
            </geometry>
            <origin rpy="1.57079 0.78539 0"/>
        </visual>
    </link>
    <link name="servo_1">
        <visual>
            <geometry>
                <mesh filename="package://quadruped/meshes/servo_motor.stl" scale="0.1 0.1 0.1"/>
            </geometry>
            <origin rpy="1.57079 2.35619 0"/>
        </visual>
    </link>
    <link name="retainer_1">
        <visual>
            <geometry>
                <mesh filename="package://quadruped/meshes/leg_servo_retainer.stl"/>
            </geometry>
            <origin rpy="1.57079 2.35619 0"/>
        </visual>
    </link>

    <link name="servo_2">
        <visual>
            <geometry>
                <mesh filename="package://quadruped/meshes/servo_motor.stl" scale="0.1 0.1 0.1"/>
            </geometry>
            <origin rpy="1.57079 0.78539 0"/>
        </visual>
    </link>
    <link name="servo_3">
        <visual>
            <geometry>
                <mesh filename="package://quadruped/meshes/servo_motor.stl" scale="0.1 0.1 0.1"/>
            </geometry>
            <origin rpy="1.57079 -0.78539 0"/>
        </visual>
    </link>
    <link name="servo_4">
        <visual>
            <geometry>
                <mesh filename="package://quadruped/meshes/servo_motor.stl" scale="0.1 0.1 0.1"/>
            </geometry>
            <origin rpy="1.57079 -2.35619 0"/>
        </visual>
    </link>
    <link name="leg_top_plate_1">
        <visual>
            <geometry>
                <mesh filename="package://quadruped/meshes/leg_top_plate.stl"/>
            </geometry>
            <origin rpy="1.57079 -0.78539 0"/>
        </visual>
    </link>
    <link name="leg_top_plate_2">
        <visual>
            <geometry>
                <mesh filename="package://quadruped/meshes/leg_top_plate.stl"/>
            </geometry>
            <origin rpy="1.57079 -2.35619 0"/>
        </visual>
    </link>
    <link name="leg_top_plate_3">
        <visual>
            <geometry>
                <mesh filename="package://quadruped/meshes/leg_top_plate.stl"/>
            </geometry>
            <origin rpy="1.57079 2.35619 0"/>
        </visual>
    </link>
    <link name="leg_top_plate_4">
        <visual>
            <geometry>
                <mesh filename="package://quadruped/meshes/leg_top_plate.stl"/>
            </geometry>
            <origin rpy="1.57079 0.78539 0"/>
        </visual>
    </link>
    <link name="leg_parallel_plate_1">
        <visual>
            <geometry>
                <mesh filename="package://quadruped/meshes/leg_parallel_plate.stl"/>
            </geometry>
            <origin rpy="0 5.4977 0"/>
        </visual>
    </link>
    <link name="leg_parallel_plate_2">
        <visual>
            <geometry>
                <mesh filename="package://quadruped/meshes/leg_parallel_plate.stl"/>
            </geometry>
            <origin rpy="0 3.9269 0"/>
        </visual>
    </link>
    <link name="leg_parallel_plate_3">
        <visual>
            <geometry>
                <mesh filename="package://quadruped/meshes/leg_parallel_plate.stl"/>
            </geometry>
            <origin rpy="0 2.3651 0"/>
        </visual>
    </link>
    <link name="leg_parallel_plate_4">
        <visual>
            <geometry>
                <mesh filename="package://quadruped/meshes/leg_parallel_plate.stl"/>
            </geometry>
            <origin rpy="0 0.78539 0"/>
        </visual>
    </link>
    <link name="leg_servo_mount_1">
        <visual>
            <geometry>
                <mesh filename="package://quadruped/meshes/leg_servo_mount.stl"/>
            </geometry>
            <origin rpy="0 2.3554 0"/>
        </visual>
    </link>
    <joint name="base_body_spacer_1" type="fixed">
        <parent link="base_link"/>
        <child link="body_spacer_1"/>
        <origin xyz="0 0 1.700"/>
    </joint>
    <joint name="base_body_spacer_2" type="fixed">
        <parent link="base_link"/>
        <child link="body_spacer_2"/>
        <origin xyz="1.700 0 0"/>
    </joint>
    <joint name="base_body_spacer_3" type="fixed">
        <parent link="base_link"/>
        <child link="body_spacer_3"/>
        <origin xyz="-1.700 0 0"/>
    </joint>
    <joint name="base_body_spacer_4" type="fixed">
        <parent link="base_link"/>
        <child link="body_spacer_4"/>
        <origin xyz="0 0 -1.700"/>
    </joint>
    <joint name="base_top_joint" type="fixed">
        <parent link="base_link"/>
        <child link="body_top_plate"/>
        <origin xyz="0 0.875 0" />
    </joint>
    <joint name="leg_bottom_pivot_plate_1" type="fixed">
        <parent link="leg_top_plate_1"/>
        <child link="leg_bottom_pivot_plate_1"/>
        <origin xyz="0 -1.563 0"/>
    </joint>
    <joint name="leg_bottom_pivot_plate_2" type="fixed">
        <parent link="leg_top_plate_2"/>
        <child link="leg_bottom_pivot_plate_2"/>
        <origin xyz="0 -1.563 0"/>
    </joint>
    <joint name="leg_bottom_pivot_plate_3" type="fixed">
        <parent link="leg_top_plate_3"/>
        <child link="leg_bottom_pivot_plate_3"/>
        <origin xyz="0 -1.563 0"/>
    </joint>
    <joint name="leg_bottom_pivot_plate_4" type="fixed">
        <parent link="leg_top_plate_4"/>
        <child link="leg_bottom_pivot_plate_4"/>
        <origin xyz="0 -1.563 0"/>
    </joint>
    <joint name="servo_top_1" type="fixed">
        <parent link="body_top_plate"/>
        <child link="servo_1"/>
        <origin xyz="1.7806 0.375 1.7806"/>
    </joint>
    <joint name="servo_retainer_1" type="fixed">
        <parent link="servo_1"/>
        <child link="retainer_1"/>
        <orgin xyz="1.485 0 -1.485"/>
    </joint>
    <joint name="servo_top_2" type="fixed">
        <parent link="body_top_plate"/>
        <child link="servo_2"/>
        <origin xyz="-1.7806 0.375 1.7806"/>
    </joint>
    <joint name="servo_top_3" type="fixed">
        <parent link="body_top_plate"/>
        <child link="servo_3"/>
        <origin xyz="-1.7806 0.375 -1.7806"/>
    </joint>
    <joint name="servo_top_4" type="fixed">
        <parent link="body_top_plate"/>
        <child link="servo_4"/>
        <origin xyz="1.7806 0.375 -1.7806"/>
    </joint>
    <joint name="servo_leg_top_plate_1" type="revolute">
        <parent link="servo_1"/>
        <child link="leg_top_plate_1"/>
        <origin xyz="0 0.303 0"/>
        <axis xyz="0 2.5184 0"/>
        <limit lower="-1.57079" upper="1.57079" velocity="100" effort="100"/>
    </joint>
    <joint name="servo_leg_top_plate_2" type="revolute">
        <parent link="servo_2"/>
        <child link="leg_top_plate_2"/>
        <origin xyz="0 0.303 0"/>
        <axis xyz="0 2.5184 0"/>
        <limit lower="-1.57079" upper="1.57079" velocity="100" effort="100"/>
    </joint>
    <joint name="servo_leg_top_plate_3" type="revolute">
        <parent link="servo_3"/>
        <child link="leg_top_plate_3"/>
        <origin xyz="0 0.303 0"/>
        <axis xyz="0 2.5184 0"/>
        <limit lower="-1.57079" upper="1.57079" velocity="100" effort="100"/>
    </joint>
    <joint name="servo_leg_top_plate_4" type="revolute">
        <parent link="servo_4"/>
        <child link="leg_top_plate_4"/>
        <origin xyz="0 0.303 0"/>
        <axis xyz="0 2.5184 0"/>
        <limit lower="-1.57079" upper="1.57079" velocity="100" effort="100"/>
    </joint>
    <joint name="leg_parallel_plate_top_plate_1" type="fixed">
        <parent link="leg_top_plate_1" />
        <child link="leg_parallel_plate_1"/>
        <origin xyz="0.8096 -0.839 0.5168"/>
    </joint>
    <joint name="leg_servo_mount_top_plate_1" type="fixed">
        <parent link="leg_top_plate_1" />
        <child link="leg_servo_mount_1"/>
        <origin xyz="0.5168 -0.839 0.8096"/>
    </joint>
    <joint name="leg_parallel_plate_top_plate_2" type="fixed">
        <parent link="leg_top_plate_2" />
        <child link="leg_parallel_plate_2"/>
        <origin xyz="-0.5168 -0.839 0.8096"/>
    </joint>
    <joint name="leg_parallel_plate_top_plate_3" type="fixed">
        <parent link="leg_top_plate_3" />
        <child link="leg_parallel_plate_3"/>
        <origin xyz="-0.8096 -0.839 -0.5168"/>
    </joint>
    <joint name="leg_parallel_plate_top_plate_4" type="fixed">
        <parent link="leg_top_plate_4"/>
        <child link="leg_parallel_plate_4"/>
        <origin xyz="0.5168 -0.839 -0.8096"/>
    </joint>
</robot>
