<?xml version="1.0" ?>
<robot name="quadruped" xmlns:xacro="http://www.ros.org/wiki/xacro">

<xacro:include filename="$(find quadruped_description)/urdf/materials.xacro" />
<xacro:include filename="$(find quadruped_description)/urdf/quadruped.trans" />
<xacro:include filename="$(find quadruped_description)/urdf/quadruped.gazebo" />
<link name="base_link">
  <inertial>
    <origin rpy="0 0 0" xyz="8.990840418494208e-07 0.0015934088628400953 -3.844423505811462e-06"/>
    <mass value="0.03172042156458545"/>
    <inertia ixx="4.9e-05" ixy="0.0" ixz="-0.0" iyy="4.9e-05" iyz="-0.0" izz="9.8e-05"/>
  </inertial>
  <visual>
    <origin rpy="0 0 0" xyz="0 0 0"/>
    <geometry>
      <mesh filename="package://quadruped_description/meshes/base_link.stl" scale="0.001 0.001 0.001"/>
    </geometry>
    <material name="silver"/>
  </visual>
  <collision>
    <origin rpy="0 0 0" xyz="0 0 0"/>
    <geometry>
      <mesh filename="package://quadruped_description/meshes/base_link.stl" scale="0.001 0.001 0.001"/>
    </geometry>
  </collision>
</link>

<link name="body_spacer_v1_1">
  <inertial>
    <origin rpy="0 0 0" xyz="-6.81883996429006e-10 -1.490891317831866e-07 0.0019124056524901113"/>
    <mass value="0.003797653049825268"/>
    <inertia ixx="0.0" ixy="0.0" ixz="-0.0" iyy="1e-06" iyz="0.0" izz="1e-06"/>
  </inertial>
  <visual>
    <origin rpy="0 0 0" xyz="0.0 -0.044629 -0.00924"/>
    <geometry>
      <mesh filename="package://quadruped_description/meshes/body_spacer_v1_1.stl" scale="0.001 0.001 0.001"/>
    </geometry>
    <material name="silver"/>
  </visual>
  <collision>
    <origin rpy="0 0 0" xyz="0.0 -0.044629 -0.00924"/>
    <geometry>
      <mesh filename="package://quadruped_description/meshes/body_spacer_v1_1.stl" scale="0.001 0.001 0.001"/>
    </geometry>
  </collision>
</link>

<link name="body_spacer_v1_2">
  <inertial>
    <origin rpy="0 0 0" xyz="-1.2978154060811503e-08 3.50910869161003e-07 0.0019124056524900852"/>
    <mass value="0.003797653049825268"/>
    <inertia ixx="0.0" ixy="0.0" ixz="-0.0" iyy="1e-06" iyz="0.0" izz="1e-06"/>
  </inertial>
  <visual>
    <origin rpy="0 0 0" xyz="0.0 0.041434 -0.00924"/>
    <geometry>
      <mesh filename="package://quadruped_description/meshes/body_spacer_v1_2.stl" scale="0.001 0.001 0.001"/>
    </geometry>
    <material name="silver"/>
  </visual>
  <collision>
    <origin rpy="0 0 0" xyz="0.0 0.041434 -0.00924"/>
    <geometry>
      <mesh filename="package://quadruped_description/meshes/body_spacer_v1_2.stl" scale="0.001 0.001 0.001"/>
    </geometry>
  </collision>
</link>

<link name="body_spacer_v1_3">
  <inertial>
    <origin rpy="0 0 0" xyz="2.4316998048501404e-07 -4.052372663944457e-07 0.001912405652490094"/>
    <mass value="0.003797653049825268"/>
    <inertia ixx="1e-06" ixy="-0.0" ixz="-0.0" iyy="0.0" iyz="0.0" izz="1e-06"/>
  </inertial>
  <visual>
    <origin rpy="0 0 0" xyz="-0.043031 -0.001598 -0.00924"/>
    <geometry>
      <mesh filename="package://quadruped_description/meshes/body_spacer_v1_3.stl" scale="0.001 0.001 0.001"/>
    </geometry>
    <material name="silver"/>
  </visual>
  <collision>
    <origin rpy="0 0 0" xyz="-0.043031 -0.001598 -0.00924"/>
    <geometry>
      <mesh filename="package://quadruped_description/meshes/body_spacer_v1_3.stl" scale="0.001 0.001 0.001"/>
    </geometry>
  </collision>
</link>

<link name="body_spacer_v1_4">
  <inertial>
    <origin rpy="0 0 0" xyz="-2.5683001855791865e-07 -3.929409962410979e-07 0.0019124056524901026"/>
    <mass value="0.003797653049825268"/>
    <inertia ixx="1e-06" ixy="-0.0" ixz="0.0" iyy="0.0" iyz="0.0" izz="1e-06"/>
  </inertial>
  <visual>
    <origin rpy="0 0 0" xyz="0.043031 -0.001598 -0.00924"/>
    <geometry>
      <mesh filename="package://quadruped_description/meshes/body_spacer_v1_4.stl" scale="0.001 0.001 0.001"/>
    </geometry>
    <material name="silver"/>
  </visual>
  <collision>
    <origin rpy="0 0 0" xyz="0.043031 -0.001598 -0.00924"/>
    <geometry>
      <mesh filename="package://quadruped_description/meshes/body_spacer_v1_4.stl" scale="0.001 0.001 0.001"/>
    </geometry>
  </collision>
</link>

<link name="body_top_plate_v1_1">
  <inertial>
    <origin rpy="0 0 0" xyz="-6.224116379125583e-06 -7.854114594208969e-07 0.0015936555764941435"/>
    <mass value="0.04667238799634045"/>
    <inertia ixx="4.7e-05" ixy="-0.0" ixz="-0.0" iyy="4.5e-05" iyz="-0.0" izz="9.2e-05"/>
  </inertial>
  <visual>
    <origin rpy="0 0 0" xyz="1e-05 -0.001603 -0.020715"/>
    <geometry>
      <mesh filename="package://quadruped_description/meshes/body_top_plate_v1_1.stl" scale="0.001 0.001 0.001"/>
    </geometry>
    <material name="silver"/>
  </visual>
  <collision>
    <origin rpy="0 0 0" xyz="1e-05 -0.001603 -0.020715"/>
    <geometry>
      <mesh filename="package://quadruped_description/meshes/body_top_plate_v1_1.stl" scale="0.001 0.001 0.001"/>
    </geometry>
  </collision>
</link>

<link name="servo_motor_v1_1">
  <inertial>
    <origin rpy="0 0 0" xyz="0.0034452692547771585 0.0034447558543224954 -0.017291510897469286"/>
    <mass value="0.011377011376072494"/>
    <inertia ixx="1e-06" ixy="-0.0" ixz="0.0" iyy="1e-06" iyz="0.0" izz="1e-06"/>
  </inertial>
  <visual>
    <origin rpy="0 0 0" xyz="0.045406 0.043805 -0.038004"/>
    <geometry>
      <mesh filename="package://quadruped_description/meshes/servo_motor_v1_1.stl" scale="0.001 0.001 0.001"/>
    </geometry>
    <material name="silver"/>
  </visual>
  <collision>
    <origin rpy="0 0 0" xyz="0.045406 0.043805 -0.038004"/>
    <geometry>
      <mesh filename="package://quadruped_description/meshes/servo_motor_v1_1.stl" scale="0.001 0.001 0.001"/>
    </geometry>
  </collision>
</link>

<link name="servo_motor_v1_2">
  <inertial>
    <origin rpy="0 0 0" xyz="0.0034452810470038536 -0.0034447141797240566 -0.01729151089746924"/>
    <mass value="0.011377011376072494"/>
    <inertia ixx="1e-06" ixy="0.0" ixz="0.0" iyy="1e-06" iyz="-0.0" izz="1e-06"/>
  </inertial>
  <visual>
    <origin rpy="0 0 0" xyz="0.045406 -0.04688 -0.038004"/>
    <geometry>
      <mesh filename="package://quadruped_description/meshes/servo_motor_v1_2.stl" scale="0.001 0.001 0.001"/>
    </geometry>
    <material name="silver"/>
  </visual>
  <collision>
    <origin rpy="0 0 0" xyz="0.045406 -0.04688 -0.038004"/>
    <geometry>
      <mesh filename="package://quadruped_description/meshes/servo_motor_v1_2.stl" scale="0.001 0.001 0.001"/>
    </geometry>
  </collision>
</link>

<link name="servo_motor_v1_3">
  <inertial>
    <origin rpy="0 0 0" xyz="-0.0034453077511524474 -0.003444708780636907 -0.01729151089746929"/>
    <mass value="0.011377011376072494"/>
    <inertia ixx="1e-06" ixy="-0.0" ixz="-0.0" iyy="1e-06" iyz="-0.0" izz="1e-06"/>
  </inertial>
  <visual>
    <origin rpy="0 0 0" xyz="-0.045406 -0.047003 -0.038004"/>
    <geometry>
      <mesh filename="package://quadruped_description/meshes/servo_motor_v1_3.stl" scale="0.001 0.001 0.001"/>
    </geometry>
    <material name="silver"/>
  </visual>
  <collision>
    <origin rpy="0 0 0" xyz="-0.045406 -0.047003 -0.038004"/>
    <geometry>
      <mesh filename="package://quadruped_description/meshes/servo_motor_v1_3.stl" scale="0.001 0.001 0.001"/>
    </geometry>
  </collision>
</link>

<link name="servo_motor_v1_4">
  <inertial>
    <origin rpy="0 0 0" xyz="-0.0034453195613619245 0.0034448987921656196 -0.017291510897469282"/>
    <mass value="0.011377011376072494"/>
    <inertia ixx="1e-06" ixy="0.0" ixz="-0.0" iyy="1e-06" iyz="0.0" izz="1e-06"/>
  </inertial>
  <visual>
    <origin rpy="0 0 0" xyz="-0.045406 0.043808 -0.038004"/>
    <geometry>
      <mesh filename="package://quadruped_description/meshes/servo_motor_v1_4.stl" scale="0.001 0.001 0.001"/>
    </geometry>
    <material name="silver"/>
  </visual>
  <collision>
    <origin rpy="0 0 0" xyz="-0.045406 0.043808 -0.038004"/>
    <geometry>
      <mesh filename="package://quadruped_description/meshes/servo_motor_v1_4.stl" scale="0.001 0.001 0.001"/>
    </geometry>
  </collision>
</link>

<link name="leg_servo_retainer_v1_1">
  <inertial>
    <origin rpy="0 0 0" xyz="-0.007975130604850701 -0.007974365433883905 -3.444235058339129e-07"/>
    <mass value="0.002255974797814701"/>
    <inertia ixx="0.0" ixy="-0.0" ixz="0.0" iyy="0.0" iyz="0.0" izz="0.0"/>
  </inertial>
  <visual>
    <origin rpy="0 0 0" xyz="0.033325 0.031724 -0.028684"/>
    <geometry>
      <mesh filename="package://quadruped_description/meshes/leg_servo_retainer_v1_1.stl" scale="0.001 0.001 0.001"/>
    </geometry>
    <material name="silver"/>
  </visual>
  <collision>
    <origin rpy="0 0 0" xyz="0.033325 0.031724 -0.028684"/>
    <geometry>
      <mesh filename="package://quadruped_description/meshes/leg_servo_retainer_v1_1.stl" scale="0.001 0.001 0.001"/>
    </geometry>
  </collision>
</link>

<link name="leg_servo_retainer_v1_2">
  <inertial>
    <origin rpy="0 0 0" xyz="-0.007973840241202512 0.007975685679903782 -3.44423505795749e-07"/>
    <mass value="0.002255974797814701"/>
    <inertia ixx="0.0" ixy="0.0" ixz="0.0" iyy="0.0" iyz="-0.0" izz="0.0"/>
  </inertial>
  <visual>
    <origin rpy="0 0 0" xyz="0.033325 -0.034799 -0.028684"/>
    <geometry>
      <mesh filename="package://quadruped_description/meshes/leg_servo_retainer_v1_2.stl" scale="0.001 0.001 0.001"/>
    </geometry>
    <material name="silver"/>
  </visual>
  <collision>
    <origin rpy="0 0 0" xyz="0.033325 -0.034799 -0.028684"/>
    <geometry>
      <mesh filename="package://quadruped_description/meshes/leg_servo_retainer_v1_2.stl" scale="0.001 0.001 0.001"/>
    </geometry>
  </collision>
</link>

<link name="leg_servo_retainer_v1_3">
  <inertial>
    <origin rpy="0 0 0" xyz="0.007975092108475412 0.007974412507569487 -3.44423505826974e-07"/>
    <mass value="0.002255974797814701"/>
    <inertia ixx="0.0" ixy="-0.0" ixz="-0.0" iyy="0.0" iyz="-0.0" izz="0.0"/>
  </inertial>
  <visual>
    <origin rpy="0 0 0" xyz="-0.033325 -0.034922 -0.028684"/>
    <geometry>
      <mesh filename="package://quadruped_description/meshes/leg_servo_retainer_v1_3.stl" scale="0.001 0.001 0.001"/>
    </geometry>
    <material name="silver"/>
  </visual>
  <collision>
    <origin rpy="0 0 0" xyz="-0.033325 -0.034922 -0.028684"/>
    <geometry>
      <mesh filename="package://quadruped_description/meshes/leg_servo_retainer_v1_3.stl" scale="0.001 0.001 0.001"/>
    </geometry>
  </collision>
</link>

<link name="leg_servo_retainer_v1_4">
  <inertial>
    <origin rpy="0 0 0" xyz="0.007973801726844462 -0.00797550106746222 -3.4442350581656567e-07"/>
    <mass value="0.002255974797814701"/>
    <inertia ixx="0.0" ixy="0.0" ixz="0.0" iyy="0.0" iyz="0.0" izz="0.0"/>
  </inertial>
  <visual>
    <origin rpy="0 0 0" xyz="-0.033325 0.031727 -0.028684"/>
    <geometry>
      <mesh filename="package://quadruped_description/meshes/leg_servo_retainer_v1_4.stl" scale="0.001 0.001 0.001"/>
    </geometry>
    <material name="silver"/>
  </visual>
  <collision>
    <origin rpy="0 0 0" xyz="-0.033325 0.031727 -0.028684"/>
    <geometry>
      <mesh filename="package://quadruped_description/meshes/leg_servo_retainer_v1_4.stl" scale="0.001 0.001 0.001"/>
    </geometry>
  </collision>
</link>

<link name="leg_top_pivot_plate_v1_1">
  <inertial>
    <origin rpy="0 0 0" xyz="-0.010648487401591071 -0.010577625981699847 -0.0015938444235058594"/>
    <mass value="0.003959817737688224"/>
    <inertia ixx="0.0" ixy="-0.0" ixz="-0.0" iyy="0.0" iyz="0.0" izz="1e-06"/>
  </inertial>
  <visual>
    <origin rpy="0 0 0" xyz="0.045406 0.043805 -0.038004"/>
    <geometry>
      <mesh filename="package://quadruped_description/meshes/leg_top_pivot_plate_v1_1.stl" scale="0.001 0.001 0.001"/>
    </geometry>
    <material name="silver"/>
  </visual>
  <collision>
    <origin rpy="0 0 0" xyz="0.045406 0.043805 -0.038004"/>
    <geometry>
      <mesh filename="package://quadruped_description/meshes/leg_top_pivot_plate_v1_1.stl" scale="0.001 0.001 0.001"/>
    </geometry>
  </collision>
</link>

<link name="leg_top_pivot_plate_v1_2">
  <inertial>
    <origin rpy="0 0 0" xyz="-0.010577098036419472 0.010649045210793372 -0.00159384442350579"/>
    <mass value="0.003959817737688224"/>
    <inertia ixx="0.0" ixy="0.0" ixz="0.0" iyy="0.0" iyz="-0.0" izz="1e-06"/>
  </inertial>
  <visual>
    <origin rpy="0 0 0" xyz="0.045406 -0.04688 -0.038004"/>
    <geometry>
      <mesh filename="package://quadruped_description/meshes/leg_top_pivot_plate_v1_2.stl" scale="0.001 0.001 0.001"/>
    </geometry>
    <material name="silver"/>
  </visual>
  <collision>
    <origin rpy="0 0 0" xyz="0.045406 -0.04688 -0.038004"/>
    <geometry>
      <mesh filename="package://quadruped_description/meshes/leg_top_pivot_plate_v1_2.stl" scale="0.001 0.001 0.001"/>
    </geometry>
  </collision>
</link>

<link name="leg_top_pivot_plate_v1_3">
  <inertial>
    <origin rpy="0 0 0" xyz="0.010648457824426617 0.010577664075983234 -0.0015938444235058247"/>
    <mass value="0.003959817737688224"/>
    <inertia ixx="0.0" ixy="-0.0" ixz="0.0" iyy="0.0" iyz="-0.0" izz="1e-06"/>
  </inertial>
  <visual>
    <origin rpy="0 0 0" xyz="-0.045406 -0.047003 -0.038004"/>
    <geometry>
      <mesh filename="package://quadruped_description/meshes/leg_top_pivot_plate_v1_3.stl" scale="0.001 0.001 0.001"/>
    </geometry>
    <material name="silver"/>
  </visual>
  <collision>
    <origin rpy="0 0 0" xyz="-0.045406 -0.047003 -0.038004"/>
    <geometry>
      <mesh filename="package://quadruped_description/meshes/leg_top_pivot_plate_v1_3.stl" scale="0.001 0.001 0.001"/>
    </geometry>
  </collision>
</link>

<link name="leg_top_pivot_plate_v1_4">
  <inertial>
    <origin rpy="0 0 0" xyz="0.01057703172127173 -0.010648888212722349 -0.0015938444235058247"/>
    <mass value="0.003959817737688224"/>
    <inertia ixx="0.0" ixy="0.0" ixz="0.0" iyy="0.0" iyz="0.0" izz="1e-06"/>
  </inertial>
  <visual>
    <origin rpy="0 0 0" xyz="-0.045406 0.043808 -0.038004"/>
    <geometry>
      <mesh filename="package://quadruped_description/meshes/leg_top_pivot_plate_v1_4.stl" scale="0.001 0.001 0.001"/>
    </geometry>
    <material name="silver"/>
  </visual>
  <collision>
    <origin rpy="0 0 0" xyz="-0.045406 0.043808 -0.038004"/>
    <geometry>
      <mesh filename="package://quadruped_description/meshes/leg_top_pivot_plate_v1_4.stl" scale="0.001 0.001 0.001"/>
    </geometry>
  </collision>
</link>

<link name="leg_servo_mount_v1_1">
  <inertial>
    <origin rpy="0 0 0" xyz="-0.0064271966028663155 -0.006426520024797322 -0.009351515125044188"/>
    <mass value="0.003626406146686101"/>
    <inertia ixx="1e-06" ixy="-0.0" ixz="0.0" iyy="1e-06" iyz="0.0" izz="0.0"/>
  </inertial>
  <visual>
    <origin rpy="0 0 0" xyz="0.058289 0.065885 -0.026529"/>
    <geometry>
      <mesh filename="package://quadruped_description/meshes/leg_servo_mount_v1_1.stl" scale="0.001 0.001 0.001"/>
    </geometry>
    <material name="silver"/>
  </visual>
  <collision>
    <origin rpy="0 0 0" xyz="0.058289 0.065885 -0.026529"/>
    <geometry>
      <mesh filename="package://quadruped_description/meshes/leg_servo_mount_v1_1.stl" scale="0.001 0.001 0.001"/>
    </geometry>
  </collision>
</link>

<link name="leg_servo_mount_v1_2">
  <inertial>
    <origin rpy="0 0 0" xyz="-0.006426989840584776 0.0064267590464385516 -0.00935151512504408"/>
    <mass value="0.003626406146686101"/>
    <inertia ixx="1e-06" ixy="0.0" ixz="0.0" iyy="1e-06" iyz="-0.0" izz="0.0"/>
  </inertial>
  <visual>
    <origin rpy="0 0 0" xyz="0.067485 -0.059764 -0.026529"/>
    <geometry>
      <mesh filename="package://quadruped_description/meshes/leg_servo_mount_v1_2.stl" scale="0.001 0.001 0.001"/>
    </geometry>
    <material name="silver"/>
  </visual>
  <collision>
    <origin rpy="0 0 0" xyz="0.067485 -0.059764 -0.026529"/>
    <geometry>
      <mesh filename="package://quadruped_description/meshes/leg_servo_mount_v1_2.stl" scale="0.001 0.001 0.001"/>
    </geometry>
  </collision>
</link>

<link name="leg_servo_mount_v1_3">
  <inertial>
    <origin rpy="0 0 0" xyz="0.006427182143724279 0.006426550815336579 -0.009351515125044178"/>
    <mass value="0.003626406146686101"/>
    <inertia ixx="1e-06" ixy="-0.0" ixz="-0.0" iyy="1e-06" iyz="-0.0" izz="0.0"/>
  </inertial>
  <visual>
    <origin rpy="0 0 0" xyz="-0.058289 -0.069083 -0.026529"/>
    <geometry>
      <mesh filename="package://quadruped_description/meshes/leg_servo_mount_v1_3.stl" scale="0.001 0.001 0.001"/>
    </geometry>
    <material name="silver"/>
  </visual>
  <collision>
    <origin rpy="0 0 0" xyz="-0.058289 -0.069083 -0.026529"/>
    <geometry>
      <mesh filename="package://quadruped_description/meshes/leg_servo_mount_v1_3.stl" scale="0.001 0.001 0.001"/>
    </geometry>
  </collision>
</link>

<link name="leg_servo_mount_v1_4">
  <inertial>
    <origin rpy="0 0 0" xyz="0.006426900912561234 -0.006426648854630061 -0.009351515125044157"/>
    <mass value="0.003626406146686101"/>
    <inertia ixx="1e-06" ixy="0.0" ixz="-0.0" iyy="1e-06" iyz="0.0" izz="0.0"/>
  </inertial>
  <visual>
    <origin rpy="0 0 0" xyz="-0.067485 0.056692 -0.026529"/>
    <geometry>
      <mesh filename="package://quadruped_description/meshes/leg_servo_mount_v1_4.stl" scale="0.001 0.001 0.001"/>
    </geometry>
    <material name="silver"/>
  </visual>
  <collision>
    <origin rpy="0 0 0" xyz="-0.067485 0.056692 -0.026529"/>
    <geometry>
      <mesh filename="package://quadruped_description/meshes/leg_servo_mount_v1_4.stl" scale="0.001 0.001 0.001"/>
    </geometry>
  </collision>
</link>

<link name="servo_motor_v1_5">
  <inertial>
    <origin rpy="0 0 0" xyz="0.005636221032410321 -0.0056360238259114265 -0.01221286445355164"/>
    <mass value="0.011377011376072494"/>
    <inertia ixx="1e-06" ixy="0.0" ixz="-0.0" iyy="1e-06" iyz="0.0" izz="1e-06"/>
  </inertial>
  <visual>
    <origin rpy="0 0 0" xyz="0.066908 0.074504 -0.026962"/>
    <geometry>
      <mesh filename="package://quadruped_description/meshes/servo_motor_v1_5.stl" scale="0.001 0.001 0.001"/>
    </geometry>
    <material name="silver"/>
  </visual>
  <collision>
    <origin rpy="0 0 0" xyz="0.066908 0.074504 -0.026962"/>
    <geometry>
      <mesh filename="package://quadruped_description/meshes/servo_motor_v1_5.stl" scale="0.001 0.001 0.001"/>
    </geometry>
  </collision>
</link>

<link name="servo_motor_v1_6">
  <inertial>
    <origin rpy="0 0 0" xyz="-0.005636494532030675 -0.005636656565279188 -0.012212864453552161"/>
    <mass value="0.011377011376072494"/>
    <inertia ixx="1e-06" ixy="-0.0" ixz="0.0" iyy="1e-06" iyz="0.0" izz="1e-06"/>
  </inertial>
  <visual>
    <origin rpy="0 0 0" xyz="0.076104 -0.068383 -0.026962"/>
    <geometry>
      <mesh filename="package://quadruped_description/meshes/servo_motor_v1_6.stl" scale="0.001 0.001 0.001"/>
    </geometry>
    <material name="silver"/>
  </visual>
  <collision>
    <origin rpy="0 0 0" xyz="0.076104 -0.068383 -0.026962"/>
    <geometry>
      <mesh filename="package://quadruped_description/meshes/servo_motor_v1_6.stl" scale="0.001 0.001 0.001"/>
    </geometry>
  </collision>
</link>

<link name="servo_motor_v1_7">
  <inertial>
    <origin rpy="0 0 0" xyz="-0.00563622889039056 0.005636057520854262 -0.012212864453551317"/>
    <mass value="0.011377011376072494"/>
    <inertia ixx="1e-06" ixy="0.0" ixz="0.0" iyy="1e-06" iyz="-0.0" izz="1e-06"/>
  </inertial>
  <visual>
    <origin rpy="0 0 0" xyz="-0.066908 -0.077702 -0.026962"/>
    <geometry>
      <mesh filename="package://quadruped_description/meshes/servo_motor_v1_7.stl" scale="0.001 0.001 0.001"/>
    </geometry>
    <material name="silver"/>
  </visual>
  <collision>
    <origin rpy="0 0 0" xyz="-0.066908 -0.077702 -0.026962"/>
    <geometry>
      <mesh filename="package://quadruped_description/meshes/servo_motor_v1_7.stl" scale="0.001 0.001 0.001"/>
    </geometry>
  </collision>
</link>

<link name="servo_motor_v1_8">
  <inertial>
    <origin rpy="0 0 0" xyz="0.0056364145961904505 0.005636746319489426 -0.012212864453551261"/>
    <mass value="0.011377011376072494"/>
    <inertia ixx="1e-06" ixy="-0.0" ixz="-0.0" iyy="1e-06" iyz="-0.0" izz="1e-06"/>
  </inertial>
  <visual>
    <origin rpy="0 0 0" xyz="-0.076104 0.065311 -0.026962"/>
    <geometry>
      <mesh filename="package://quadruped_description/meshes/servo_motor_v1_8.stl" scale="0.001 0.001 0.001"/>
    </geometry>
    <material name="silver"/>
  </visual>
  <collision>
    <origin rpy="0 0 0" xyz="-0.076104 0.065311 -0.026962"/>
    <geometry>
      <mesh filename="package://quadruped_description/meshes/servo_motor_v1_8.stl" scale="0.001 0.001 0.001"/>
    </geometry>
  </collision>
</link>

<link name="leg_servo_arm_v1_1">
  <inertial>
    <origin rpy="0 0 0" xyz="-0.006854771887674749 -0.009109126418148955 -1.5242355217090497e-05"/>
    <mass value="0.0019221384911435294"/>
    <inertia ixx="0.0" ixy="-0.0" ixz="-0.0" iyy="0.0" iyz="-0.0" izz="0.0"/>
  </inertial>
  <visual>
    <origin rpy="0 0 0" xyz="0.073499 0.067913 -0.009877"/>
    <geometry>
      <mesh filename="package://quadruped_description/meshes/leg_servo_arm_v1_1.stl" scale="0.001 0.001 0.001"/>
    </geometry>
    <material name="silver"/>
  </visual>
  <collision>
    <origin rpy="0 0 0" xyz="0.073499 0.067913 -0.009877"/>
    <geometry>
      <mesh filename="package://quadruped_description/meshes/leg_servo_arm_v1_1.stl" scale="0.001 0.001 0.001"/>
    </geometry>
  </collision>
</link>

<link name="leg_servo_arm_v1_2">
  <inertial>
    <origin rpy="0 0 0" xyz="-0.009108597341111344 0.006855340698170606 -8.56350209609176e-06"/>
    <mass value="0.0019221384911435294"/>
    <inertia ixx="0.0" ixy="0.0" ixz="-0.0" iyy="0.0" iyz="0.0" izz="0.0"/>
  </inertial>
  <visual>
    <origin rpy="0 0 0" xyz="0.069514 -0.074973 -0.009877"/>
    <geometry>
      <mesh filename="package://quadruped_description/meshes/leg_servo_arm_v1_2.stl" scale="0.001 0.001 0.001"/>
    </geometry>
    <material name="silver"/>
  </visual>
  <collision>
    <origin rpy="0 0 0" xyz="0.069514 -0.074973 -0.009877"/>
    <geometry>
      <mesh filename="package://quadruped_description/meshes/leg_servo_arm_v1_2.stl" scale="0.001 0.001 0.001"/>
    </geometry>
  </collision>
</link>

<link name="leg_servo_arm_v1_3">
  <inertial>
    <origin rpy="0 0 0" xyz="0.00685468898972065 0.009109071612322814 -5.015947458723337e-05"/>
    <mass value="0.0019221384911435294"/>
    <inertia ixx="0.0" ixy="-0.0" ixz="0.0" iyy="0.0" iyz="0.0" izz="0.0"/>
  </inertial>
  <visual>
    <origin rpy="0 0 0" xyz="-0.073499 -0.071111 -0.009877"/>
    <geometry>
      <mesh filename="package://quadruped_description/meshes/leg_servo_arm_v1_3.stl" scale="0.001 0.001 0.001"/>
    </geometry>
    <material name="silver"/>
  </visual>
  <collision>
    <origin rpy="0 0 0" xyz="-0.073499 -0.071111 -0.009877"/>
    <geometry>
      <mesh filename="package://quadruped_description/meshes/leg_servo_arm_v1_3.stl" scale="0.001 0.001 0.001"/>
    </geometry>
  </collision>
</link>

<link name="leg_servo_arm_v1_4">
  <inertial>
    <origin rpy="0 0 0" xyz="0.009109467588439349 -0.006855242803937525 -8.56382352977178e-06"/>
    <mass value="0.0019221384911435294"/>
    <inertia ixx="0.0" ixy="0.0" ixz="0.0" iyy="0.0" iyz="-0.0" izz="0.0"/>
  </inertial>
  <visual>
    <origin rpy="0 0 0" xyz="-0.069513 0.071901 -0.009877"/>
    <geometry>
      <mesh filename="package://quadruped_description/meshes/leg_servo_arm_v1_4.stl" scale="0.001 0.001 0.001"/>
    </geometry>
    <material name="silver"/>
  </visual>
  <collision>
    <origin rpy="0 0 0" xyz="-0.069513 0.071901 -0.009877"/>
    <geometry>
      <mesh filename="package://quadruped_description/meshes/leg_servo_arm_v1_4.stl" scale="0.001 0.001 0.001"/>
    </geometry>
  </collision>
</link>

<link name="leg_rev_v1_1">
  <inertial>
    <origin rpy="0 0 0" xyz="-0.0017567044298134465 0.0003705786927817173 -0.0070616672531270755"/>
    <mass value="0.004982233978749814"/>
    <inertia ixx="3e-06" ixy="-0.0" ixz="-0.0" iyy="3e-06" iyz="-0.0" izz="0.0"/>
  </inertial>
  <visual>
    <origin rpy="0 0 0" xyz="0.09153 0.085944 -0.009842"/>
    <geometry>
      <mesh filename="package://quadruped_description/meshes/leg_rev_v1_1.stl" scale="0.001 0.001 0.001"/>
    </geometry>
    <material name="silver"/>
  </visual>
  <collision>
    <origin rpy="0 0 0" xyz="0.09153 0.085944 -0.009842"/>
    <geometry>
      <mesh filename="package://quadruped_description/meshes/leg_rev_v1_1.stl" scale="0.001 0.001 0.001"/>
    </geometry>
  </collision>
</link>

<link name="leg_rev_v1_2">
  <inertial>
    <origin rpy="0 0 0" xyz="0.000371085724306941 0.0017573008393292205 -0.00706157626423429"/>
    <mass value="0.004982233978749814"/>
    <inertia ixx="3e-06" ixy="0.0" ixz="-0.0" iyy="3e-06" iyz="0.0" izz="0.0"/>
  </inertial>
  <visual>
    <origin rpy="0 0 0" xyz="0.087545 -0.093004 -0.009857"/>
    <geometry>
      <mesh filename="package://quadruped_description/meshes/leg_rev_v1_2.stl" scale="0.001 0.001 0.001"/>
    </geometry>
    <material name="silver"/>
  </visual>
  <collision>
    <origin rpy="0 0 0" xyz="0.087545 -0.093004 -0.009857"/>
    <geometry>
      <mesh filename="package://quadruped_description/meshes/leg_rev_v1_2.stl" scale="0.001 0.001 0.001"/>
    </geometry>
  </collision>
</link>

<link name="leg_rev_v1_3">
  <inertial>
    <origin rpy="0 0 0" xyz="0.0017564387392945968 -0.00037083440591584305 -0.007061563115453126"/>
    <mass value="0.004982233978749814"/>
    <inertia ixx="3e-06" ixy="-0.0" ixz="0.0" iyy="3e-06" iyz="0.0" izz="0.0"/>
  </inertial>
  <visual>
    <origin rpy="0 0 0" xyz="-0.09153 -0.089142 -0.009763"/>
    <geometry>
      <mesh filename="package://quadruped_description/meshes/leg_rev_v1_3.stl" scale="0.001 0.001 0.001"/>
    </geometry>
    <material name="silver"/>
  </visual>
  <collision>
    <origin rpy="0 0 0" xyz="-0.09153 -0.089142 -0.009763"/>
    <geometry>
      <mesh filename="package://quadruped_description/meshes/leg_rev_v1_3.stl" scale="0.001 0.001 0.001"/>
    </geometry>
  </collision>
</link>

<link name="leg_rev_v1_4">
  <inertial>
    <origin rpy="0 0 0" xyz="-0.0003712492417421581 -0.0017572252685212342 -0.007061576989887238"/>
    <mass value="0.004982233978749814"/>
    <inertia ixx="3e-06" ixy="0.0" ixz="0.0" iyy="3e-06" iyz="-0.0" izz="0.0"/>
  </inertial>
  <visual>
    <origin rpy="0 0 0" xyz="-0.087545 0.089932 -0.009857"/>
    <geometry>
      <mesh filename="package://quadruped_description/meshes/leg_rev_v1_4.stl" scale="0.001 0.001 0.001"/>
    </geometry>
    <material name="silver"/>
  </visual>
  <collision>
    <origin rpy="0 0 0" xyz="-0.087545 0.089932 -0.009857"/>
    <geometry>
      <mesh filename="package://quadruped_description/meshes/leg_rev_v1_4.stl" scale="0.001 0.001 0.001"/>
    </geometry>
  </collision>
</link>

<link name="leg_parallel_linkage_v1_1">
  <inertial>
    <origin rpy="0 0 0" xyz="0.010142332542100368 0.007888982808169506 -3.990663834789465e-05"/>
    <mass value="0.007660744416023881"/>
    <inertia ixx="0.0" ixy="-0.0" ixz="0.0" iyy="0.0" iyz="0.0" izz="1e-06"/>
  </inertial>
  <visual>
    <origin rpy="0 0 0" xyz="0.091517 0.085932 -0.027692"/>
    <geometry>
      <mesh filename="package://quadruped_description/meshes/leg_parallel_linkage_v1_1.stl" scale="0.001 0.001 0.001"/>
    </geometry>
    <material name="silver"/>
  </visual>
  <collision>
    <origin rpy="0 0 0" xyz="0.091517 0.085932 -0.027692"/>
    <geometry>
      <mesh filename="package://quadruped_description/meshes/leg_parallel_linkage_v1_1.stl" scale="0.001 0.001 0.001"/>
    </geometry>
  </collision>
</link>

<link name="leg_parallel_linkage_v1_2">
  <inertial>
    <origin rpy="0 0 0" xyz="0.007888535375801087 -0.010142786694544992 -4.736303420217053e-05"/>
    <mass value="0.007660744416023881"/>
    <inertia ixx="0.0" ixy="0.0" ixz="0.0" iyy="0.0" iyz="-0.0" izz="1e-06"/>
  </inertial>
  <visual>
    <origin rpy="0 0 0" xyz="0.087532 -0.092992 -0.027707"/>
    <geometry>
      <mesh filename="package://quadruped_description/meshes/leg_parallel_linkage_v1_2.stl" scale="0.001 0.001 0.001"/>
    </geometry>
    <material name="silver"/>
  </visual>
  <collision>
    <origin rpy="0 0 0" xyz="0.087532 -0.092992 -0.027707"/>
    <geometry>
      <mesh filename="package://quadruped_description/meshes/leg_parallel_linkage_v1_2.stl" scale="0.001 0.001 0.001"/>
    </geometry>
  </collision>
</link>

<link name="leg_parallel_linkage_v1_3">
  <inertial>
    <origin rpy="0 0 0" xyz="-0.010142299038698774 -0.007888922935056511 -3.4469514877816243e-07"/>
    <mass value="0.007660744416023881"/>
    <inertia ixx="0.0" ixy="-0.0" ixz="0.0" iyy="0.0" iyz="0.0" izz="1e-06"/>
  </inertial>
  <visual>
    <origin rpy="0 0 0" xyz="-0.091517 -0.08913 -0.027613"/>
    <geometry>
      <mesh filename="package://quadruped_description/meshes/leg_parallel_linkage_v1_3.stl" scale="0.001 0.001 0.001"/>
    </geometry>
    <material name="silver"/>
  </visual>
  <collision>
    <origin rpy="0 0 0" xyz="-0.091517 -0.08913 -0.027613"/>
    <geometry>
      <mesh filename="package://quadruped_description/meshes/leg_parallel_linkage_v1_3.stl" scale="0.001 0.001 0.001"/>
    </geometry>
  </collision>
</link>

<link name="leg_parallel_linkage_v1_4">
  <inertial>
    <origin rpy="0 0 0" xyz="-0.007888667792505286 0.010142881922515709 -4.736339693783842e-05"/>
    <mass value="0.007660744416023881"/>
    <inertia ixx="0.0" ixy="0.0" ixz="-0.0" iyy="0.0" iyz="0.0" izz="1e-06"/>
  </inertial>
  <visual>
    <origin rpy="0 0 0" xyz="-0.087532 0.08992 -0.027707"/>
    <geometry>
      <mesh filename="package://quadruped_description/meshes/leg_parallel_linkage_v1_4.stl" scale="0.001 0.001 0.001"/>
    </geometry>
    <material name="silver"/>
  </visual>
  <collision>
    <origin rpy="0 0 0" xyz="-0.087532 0.08992 -0.027707"/>
    <geometry>
      <mesh filename="package://quadruped_description/meshes/leg_parallel_linkage_v1_4.stl" scale="0.001 0.001 0.001"/>
    </geometry>
  </collision>
</link>

<link name="bottom_pivot_plate_v1_1">
  <inertial>
    <origin rpy="0 0 0" xyz="-0.010006768454051483 -0.010047098365601526 -0.001593344423505842"/>
    <mass value="0.02183354723813213"/>
    <inertia ixx="2e-06" ixy="-2e-06" ixz="-0.0" iyy="2e-06" iyz="-0.0" izz="5e-06"/>
  </inertial>
  <visual>
    <origin rpy="0 0 0" xyz="0.045406 0.043805 0.001598"/>
    <geometry>
      <mesh filename="package://quadruped_description/meshes/bottom_pivot_plate_v1_1.stl" scale="0.001 0.001 0.001"/>
    </geometry>
    <material name="silver"/>
  </visual>
  <collision>
    <origin rpy="0 0 0" xyz="0.045406 0.043805 0.001598"/>
    <geometry>
      <mesh filename="package://quadruped_description/meshes/bottom_pivot_plate_v1_1.stl" scale="0.001 0.001 0.001"/>
    </geometry>
  </collision>
</link>

<link name="bottom_pivot_plate_v1_2">
  <inertial>
    <origin rpy="0 0 0" xyz="-0.010046570586196575 0.010007326126119827 -0.0015933444235057903"/>
    <mass value="0.02183354723813213"/>
    <inertia ixx="2e-06" ixy="2e-06" ixz="0.0" iyy="2e-06" iyz="-0.0" izz="5e-06"/>
  </inertial>
  <visual>
    <origin rpy="0 0 0" xyz="0.045406 -0.04688 0.001598"/>
    <geometry>
      <mesh filename="package://quadruped_description/meshes/bottom_pivot_plate_v1_2.stl" scale="0.001 0.001 0.001"/>
    </geometry>
    <material name="silver"/>
  </visual>
  <collision>
    <origin rpy="0 0 0" xyz="0.045406 -0.04688 0.001598"/>
    <geometry>
      <mesh filename="package://quadruped_description/meshes/bottom_pivot_plate_v1_2.stl" scale="0.001 0.001 0.001"/>
    </geometry>
  </collision>
</link>

<link name="bottom_pivot_plate_v1_3">
  <inertial>
    <origin rpy="0 0 0" xyz="0.010006738429535082 0.010047137000996208 -0.001593344423505789"/>
    <mass value="0.02183354723813213"/>
    <inertia ixx="2e-06" ixy="-2e-06" ixz="0.0" iyy="2e-06" iyz="-0.0" izz="5e-06"/>
  </inertial>
  <visual>
    <origin rpy="0 0 0" xyz="-0.045406 -0.047003 0.001598"/>
    <geometry>
      <mesh filename="package://quadruped_description/meshes/bottom_pivot_plate_v1_3.stl" scale="0.001 0.001 0.001"/>
    </geometry>
    <material name="silver"/>
  </visual>
  <collision>
    <origin rpy="0 0 0" xyz="-0.045406 -0.047003 0.001598"/>
    <geometry>
      <mesh filename="package://quadruped_description/meshes/bottom_pivot_plate_v1_3.stl" scale="0.001 0.001 0.001"/>
    </geometry>
  </collision>
</link>

<link name="bottom_pivot_plate_v1_4">
  <inertial>
    <origin rpy="0 0 0" xyz="0.010046505946362791 -0.010007167743022634 -0.0015933444235058242"/>
    <mass value="0.02183354723813213"/>
    <inertia ixx="2e-06" ixy="2e-06" ixz="0.0" iyy="2e-06" iyz="-0.0" izz="5e-06"/>
  </inertial>
  <visual>
    <origin rpy="0 0 0" xyz="-0.045406 0.043808 0.001598"/>
    <geometry>
      <mesh filename="package://quadruped_description/meshes/bottom_pivot_plate_v1_4.stl" scale="0.001 0.001 0.001"/>
    </geometry>
    <material name="silver"/>
  </visual>
  <collision>
    <origin rpy="0 0 0" xyz="-0.045406 0.043808 0.001598"/>
    <geometry>
      <mesh filename="package://quadruped_description/meshes/bottom_pivot_plate_v1_4.stl" scale="0.001 0.001 0.001"/>
    </geometry>
  </collision>
</link>

<link name="leg_parallel_plate_v1_1">
  <inertial>
    <origin rpy="0 0 0" xyz="-0.001935591996887323 -0.0019356076519752782 0.012060810010779242"/>
    <mass value="0.014417433544657021"/>
    <inertia ixx="2e-06" ixy="-0.0" ixz="0.0" iyy="2e-06" iyz="0.0" izz="1e-06"/>
  </inertial>
  <visual>
    <origin rpy="0 0 0" xyz="0.067169 0.058102 -0.00669"/>
    <geometry>
      <mesh filename="package://quadruped_description/meshes/leg_parallel_plate_v1_1.stl" scale="0.001 0.001 0.001"/>
    </geometry>
    <material name="silver"/>
  </visual>
  <collision>
    <origin rpy="0 0 0" xyz="0.067169 0.058102 -0.00669"/>
    <geometry>
      <mesh filename="package://quadruped_description/meshes/leg_parallel_plate_v1_1.stl" scale="0.001 0.001 0.001"/>
    </geometry>
  </collision>
</link>

<link name="leg_parallel_plate_v1_2">
  <inertial>
    <origin rpy="0 0 0" xyz="-0.0019350763334238241 0.00193515126782344 0.012060810010779315"/>
    <mass value="0.014417433544657021"/>
    <inertia ixx="2e-06" ixy="0.0" ixz="0.0" iyy="2e-06" iyz="-0.0" izz="1e-06"/>
  </inertial>
  <visual>
    <origin rpy="0 0 0" xyz="0.059703 -0.068644 -0.00669"/>
    <geometry>
      <mesh filename="package://quadruped_description/meshes/leg_parallel_plate_v1_2.stl" scale="0.001 0.001 0.001"/>
    </geometry>
    <material name="silver"/>
  </visual>
  <collision>
    <origin rpy="0 0 0" xyz="0.059703 -0.068644 -0.00669"/>
    <geometry>
      <mesh filename="package://quadruped_description/meshes/leg_parallel_plate_v1_2.stl" scale="0.001 0.001 0.001"/>
    </geometry>
  </collision>
</link>

<link name="leg_parallel_plate_v1_3">
  <inertial>
    <origin rpy="0 0 0" xyz="0.0019355671881192416 0.0019346347421302715 0.012060810010779294"/>
    <mass value="0.014417433544657021"/>
    <inertia ixx="2e-06" ixy="-0.0" ixz="-0.0" iyy="2e-06" iyz="-0.0" izz="1e-06"/>
  </inertial>
  <visual>
    <origin rpy="0 0 0" xyz="-0.067169 -0.061301 -0.00669"/>
    <geometry>
      <mesh filename="package://quadruped_description/meshes/leg_parallel_plate_v1_3.stl" scale="0.001 0.001 0.001"/>
    </geometry>
    <material name="silver"/>
  </visual>
  <collision>
    <origin rpy="0 0 0" xyz="-0.067169 -0.061301 -0.00669"/>
    <geometry>
      <mesh filename="package://quadruped_description/meshes/leg_parallel_plate_v1_3.stl" scale="0.001 0.001 0.001"/>
    </geometry>
  </collision>
</link>

<link name="leg_parallel_plate_v1_4">
  <inertial>
    <origin rpy="0 0 0" xyz="0.0019349759488294024 -0.0019350090329497832 0.012060810010779221"/>
    <mass value="0.014417433544657021"/>
    <inertia ixx="2e-06" ixy="0.0" ixz="-0.0" iyy="2e-06" iyz="0.0" izz="1e-06"/>
  </inertial>
  <visual>
    <origin rpy="0 0 0" xyz="-0.059703 0.065572 -0.00669"/>
    <geometry>
      <mesh filename="package://quadruped_description/meshes/leg_parallel_plate_v1_4.stl" scale="0.001 0.001 0.001"/>
    </geometry>
    <material name="silver"/>
  </visual>
  <collision>
    <origin rpy="0 0 0" xyz="-0.059703 0.065572 -0.00669"/>
    <geometry>
      <mesh filename="package://quadruped_description/meshes/leg_parallel_plate_v1_4.stl" scale="0.001 0.001 0.001"/>
    </geometry>
  </collision>
</link>

<link name="leg_parallel_linkage_v1_1">
  <inertial>
    <origin rpy="0 0 0" xyz="-0.007888667457899637 -0.010142017191830485 3.909336165210803e-05"/>
    <mass value="0.007660744416023881"/>
    <inertia ixx="0.0" ixy="-0.0" ixz="0.0" iyy="0.0" iyz="0.0" izz="1e-06"/>
  </inertial>
  <visual>
    <origin rpy="0 0 0" xyz="0.073486 0.067901 -0.027613"/>
    <geometry>
      <mesh filename="package://quadruped_description/meshes/leg_parallel_linkage_v1_1.stl" scale="0.001 0.001 0.001"/>
    </geometry>
    <material name="silver"/>
  </visual>
  <collision>
    <origin rpy="0 0 0" xyz="0.073486 0.067901 -0.027613"/>
    <geometry>
      <mesh filename="package://quadruped_description/meshes/leg_parallel_linkage_v1_1.stl" scale="0.001 0.001 0.001"/>
    </geometry>
  </collision>
</link>

<link name="leg_parallel_linkage_v1_2">
  <inertial>
    <origin rpy="0 0 0" xyz="-0.010142464624198919 0.007888213305455014 4.6636965797829805e-05"/>
    <mass value="0.007660744416023881"/>
    <inertia ixx="0.0" ixy="0.0" ixz="0.0" iyy="0.0" iyz="-0.0" izz="1e-06"/>
  </inertial>
  <visual>
    <origin rpy="0 0 0" xyz="0.069501 -0.074961 -0.027613"/>
    <geometry>
      <mesh filename="package://quadruped_description/meshes/leg_parallel_linkage_v1_2.stl" scale="0.001 0.001 0.001"/>
    </geometry>
    <material name="silver"/>
  </visual>
  <collision>
    <origin rpy="0 0 0" xyz="0.069501 -0.074961 -0.027613"/>
    <geometry>
      <mesh filename="package://quadruped_description/meshes/leg_parallel_linkage_v1_2.stl" scale="0.001 0.001 0.001"/>
    </geometry>
  </collision>
</link>

<link name="leg_parallel_linkage_v1_3">
  <inertial>
    <origin rpy="0 0 0" xyz="0.007888700961301232 0.010142077064943494 -3.4469514877816243e-07"/>
    <mass value="0.007660744416023881"/>
    <inertia ixx="0.0" ixy="-0.0" ixz="0.0" iyy="0.0" iyz="0.0" izz="1e-06"/>
  </inertial>
  <visual>
    <origin rpy="0 0 0" xyz="-0.073486 -0.071099 -0.027613"/>
    <geometry>
      <mesh filename="package://quadruped_description/meshes/leg_parallel_linkage_v1_3.stl" scale="0.001 0.001 0.001"/>
    </geometry>
    <material name="silver"/>
  </visual>
  <collision>
    <origin rpy="0 0 0" xyz="-0.073486 -0.071099 -0.027613"/>
    <geometry>
      <mesh filename="package://quadruped_description/meshes/leg_parallel_linkage_v1_3.stl" scale="0.001 0.001 0.001"/>
    </geometry>
  </collision>
</link>

<link name="leg_parallel_linkage_v1_4">
  <inertial>
    <origin rpy="0 0 0" xyz="0.01014233220749472 -0.007889118077484297 4.663660306216191e-05"/>
    <mass value="0.007660744416023881"/>
    <inertia ixx="0.0" ixy="0.0" ixz="-0.0" iyy="0.0" iyz="0.0" izz="1e-06"/>
  </inertial>
  <visual>
    <origin rpy="0 0 0" xyz="-0.069501 0.071888 -0.027613"/>
    <geometry>
      <mesh filename="package://quadruped_description/meshes/leg_parallel_linkage_v1_4.stl" scale="0.001 0.001 0.001"/>
    </geometry>
    <material name="silver"/>
  </visual>
  <collision>
    <origin rpy="0 0 0" xyz="-0.069501 0.071888 -0.027613"/>
    <geometry>
      <mesh filename="package://quadruped_description/meshes/leg_parallel_linkage_v1_4.stl" scale="0.001 0.001 0.001"/>
    </geometry>
  </collision>
</link>

<joint name="Rigid1" type="fixed">
  <origin rpy="0 0 0" xyz="0.0 0.044629 0.00924"/>
  <parent link="base_link"/>
  <child link="body_spacer_v1_1"/>
</joint>

<joint name="Rigid2" type="fixed">
  <origin rpy="0 0 0" xyz="0.0 -0.041434 0.00924"/>
  <parent link="base_link"/>
  <child link="body_spacer_v1_2"/>
</joint>

<joint name="Rigid3" type="fixed">
  <origin rpy="0 0 0" xyz="0.043031 0.001598 0.00924"/>
  <parent link="base_link"/>
  <child link="body_spacer_v1_3"/>
</joint>

<joint name="Rigid4" type="fixed">
  <origin rpy="0 0 0" xyz="-0.043031 0.001598 0.00924"/>
  <parent link="base_link"/>
  <child link="body_spacer_v1_4"/>
</joint>

<joint name="Rigid5" type="fixed">
  <origin rpy="0 0 0" xyz="-1e-05 0.001603 0.020715"/>
  <parent link="base_link"/>
  <child link="body_top_plate_v1_1"/>
</joint>

<joint name="servo_body_1" type="fixed">
  <origin rpy="0 0 0" xyz="-0.045406 -0.043805 0.038004"/>
  <parent link="base_link"/>
  <child link="servo_motor_v1_1"/>
</joint>

<joint name="servo_body_2" type="fixed">
  <origin rpy="0 0 0" xyz="-0.045406 0.04688 0.038004"/>
  <parent link="base_link"/>
  <child link="servo_motor_v1_2"/>
</joint>

<joint name="servo_body_3" type="fixed">
  <origin rpy="0 0 0" xyz="0.045406 0.047003 0.038004"/>
  <parent link="base_link"/>
  <child link="servo_motor_v1_3"/>
</joint>

<joint name="servo_body_4" type="fixed">
  <origin rpy="0 0 0" xyz="0.045406 -0.043808 0.038004"/>
  <parent link="base_link"/>
  <child link="servo_motor_v1_4"/>
</joint>

<joint name="Rigid10" type="fixed">
  <origin rpy="0 0 0" xyz="0.012081 0.012081 -0.00932"/>
  <parent link="servo_motor_v1_1"/>
  <child link="leg_servo_retainer_v1_1"/>
</joint>

<joint name="Rigid11" type="fixed">
  <origin rpy="0 0 0" xyz="0.012081 -0.012081 -0.00932"/>
  <parent link="servo_motor_v1_2"/>
  <child link="leg_servo_retainer_v1_2"/>
</joint>

<joint name="Rigid12" type="fixed">
  <origin rpy="0 0 0" xyz="-0.012081 -0.012081 -0.00932"/>
  <parent link="servo_motor_v1_3"/>
  <child link="leg_servo_retainer_v1_3"/>
</joint>

<joint name="Rigid13" type="fixed">
  <origin rpy="0 0 0" xyz="-0.012081 0.012081 -0.00932"/>
  <parent link="servo_motor_v1_4"/>
  <child link="leg_servo_retainer_v1_4"/>
</joint>

<joint name="leg_drive_1" type="revolute">
  <origin rpy="0 0 0" xyz="0.0 0.0 0.0"/>
  <parent link="servo_motor_v1_1"/>
  <child link="leg_top_pivot_plate_v1_1"/>
  <axis xyz="-0.0 -0.0 1.0"/>
  <limit effort="100" lower="-1.570796" upper="1.570796" velocity="100"/>
</joint>

<joint name="leg_drive_2" type="revolute">
  <origin rpy="0 0 0" xyz="0.0 0.0 0.0"/>
  <parent link="servo_motor_v1_2"/>
  <child link="leg_top_pivot_plate_v1_2"/>
  <axis xyz="-0.0 -0.0 1.0"/>
  <limit effort="100" lower="-1.570796" upper="1.570796" velocity="100"/>
</joint>

<joint name="leg_drive_3" type="revolute">
  <origin rpy="0 0 0" xyz="0.0 0.0 0.0"/>
  <parent link="servo_motor_v1_3"/>
  <child link="leg_top_pivot_plate_v1_3"/>
  <axis xyz="-0.0 -0.0 1.0"/>
  <limit effort="100" lower="-1.570796" upper="1.570796" velocity="100"/>
</joint>

<joint name="leg_drive_4" type="revolute">
  <origin rpy="0 0 0" xyz="0.0 0.0 0.0"/>
  <parent link="servo_motor_v1_4"/>
  <child link="leg_top_pivot_plate_v1_4"/>
  <axis xyz="-0.0 -0.0 1.0"/>
  <limit effort="100" lower="-1.570796" upper="1.570796" velocity="100"/>
</joint>

<joint name="Rigid18" type="fixed">
  <origin rpy="0 0 0" xyz="-0.012883 -0.02208 -0.011475"/>
  <parent link="leg_top_pivot_plate_v1_1"/>
  <child link="leg_servo_mount_v1_1"/>
</joint>

<joint name="Rigid19" type="fixed">
  <origin rpy="0 0 0" xyz="-0.022079 0.012884 -0.011475"/>
  <parent link="leg_top_pivot_plate_v1_2"/>
  <child link="leg_servo_mount_v1_2"/>
</joint>

<joint name="Rigid20" type="fixed">
  <origin rpy="0 0 0" xyz="0.012883 0.02208 -0.011475"/>
  <parent link="leg_top_pivot_plate_v1_3"/>
  <child link="leg_servo_mount_v1_3"/>
</joint>

<joint name="Rigid21" type="fixed">
  <origin rpy="0 0 0" xyz="0.022079 -0.012884 -0.011475"/>
  <parent link="leg_top_pivot_plate_v1_4"/>
  <child link="leg_servo_mount_v1_4"/>
</joint>

<joint name="Rigid22" type="fixed">
  <origin rpy="0 0 0" xyz="-0.008619 -0.008619 0.000433"/>
  <parent link="leg_servo_mount_v1_1"/>
  <child link="servo_motor_v1_5"/>
</joint>

<joint name="Rigid23" type="fixed">
  <origin rpy="0 0 0" xyz="-0.008619 0.008619 0.000433"/>
  <parent link="leg_servo_mount_v1_2"/>
  <child link="servo_motor_v1_6"/>
</joint>

<joint name="Rigid24" type="fixed">
  <origin rpy="0 0 0" xyz="0.008619 0.008619 0.000433"/>
  <parent link="leg_servo_mount_v1_3"/>
  <child link="servo_motor_v1_7"/>
</joint>

<joint name="Rigid25" type="fixed">
  <origin rpy="0 0 0" xyz="0.008619 -0.008619 0.000433"/>
  <parent link="leg_servo_mount_v1_4"/>
  <child link="servo_motor_v1_8"/>
</joint>

<joint name="knee_drive_1" type="revolute">
  <origin rpy="0 0 0" xyz="-0.006591 0.006591 -0.017085"/>
  <parent link="servo_motor_v1_5"/>
  <child link="leg_servo_arm_v1_1"/>
  <axis xyz="-0.707105 0.707108 0.0"/>
  <limit effort="100" lower="-0.959931" upper="0.959931" velocity="100"/>
</joint>

<joint name="knee_drive_2" type="revolute">
  <origin rpy="0 0 0" xyz="0.00659 0.00659 -0.017085"/>
  <parent link="servo_motor_v1_6"/>
  <child link="leg_servo_arm_v1_2"/>
  <axis xyz="0.707109 0.707105 0.0"/>
  <limit effort="100" lower="-0.959931" upper="0.959931" velocity="100"/>
</joint>

<joint name="knee_drive_3" type="revolute">
  <origin rpy="0 0 0" xyz="0.006591 -0.006591 -0.017085"/>
  <parent link="servo_motor_v1_7"/>
  <child link="leg_servo_arm_v1_3"/>
  <axis xyz="0.707105 -0.707109 0.0"/>
  <limit effort="100" lower="-0.959931" upper="0.959931" velocity="100"/>
</joint>

<joint name="knee_drive_4" type="revolute">
  <origin rpy="0 0 0" xyz="-0.006591 -0.00659 -0.017085"/>
  <parent link="servo_motor_v1_8"/>
  <child link="leg_servo_arm_v1_4"/>
  <axis xyz="-0.70711 -0.707103 0.0"/>
  <limit effort="100" lower="-0.959931" upper="0.959931" velocity="100"/>
</joint>

<joint name="leg_rev_free_1" type="continuous">
  <origin rpy="0 0 0" xyz="-0.018031 -0.018031 -3.5e-05"/>
  <parent link="leg_servo_arm_v1_1"/>
  <child link="leg_rev_v1_1"/>
  <axis xyz="0.707105 -0.707108 -0.0"/>
</joint>

<joint name="leg_rev_free_2" type="continuous">
  <origin rpy="0 0 0" xyz="-0.018031 0.018031 -2e-05"/>
  <parent link="leg_servo_arm_v1_2"/>
  <child link="leg_rev_v1_2"/>
  <axis xyz="0.707109 0.707105 0.0"/>
</joint>

<joint name="leg_rev_free_3" type="continuous">
  <origin rpy="0 0 0" xyz="0.018031 0.018031 -0.000114"/>
  <parent link="leg_servo_arm_v1_3"/>
  <child link="leg_rev_v1_3"/>
  <axis xyz="0.707105 -0.707109 0.0"/>
</joint>

<joint name="leg_rev_free_4" type="continuous">
  <origin rpy="0 0 0" xyz="0.018032 -0.018031 -2e-05"/>
  <parent link="leg_servo_arm_v1_4"/>
  <child link="leg_rev_v1_4"/>
  <axis xyz="0.70711 0.707103 -0.0"/>
</joint>

<joint name="leg_rev_free_5" type="continuous">
  <origin rpy="0 0 0" xyz="0.018044 0.018043 0.017771"/>
  <parent link="leg_rev_v1_1"/>
  <child link="leg_parallel_linkage_v1_1"/>
  <axis xyz="-0.707105 0.707108 0.0"/>
</joint>

<joint name="leg_rev_free_6" type="continuous">
  <origin rpy="0 0 0" xyz="0.018044 -0.018043 0.017756"/>
  <parent link="leg_rev_v1_2"/>
  <child link="leg_parallel_linkage_v1_2"/>
  <axis xyz="0.707109 0.707105 0.0"/>
</joint>

<joint name="leg_rev_free_7" type="continuous">
  <origin rpy="0 0 0" xyz="-0.018044 -0.018043 0.01785"/>
  <parent link="leg_rev_v1_3"/>
  <child link="leg_parallel_linkage_v1_3"/>
  <axis xyz="0.707105 -0.707109 0.0"/>
</joint>

<joint name="leg_rev_free_8" type="continuous">
  <origin rpy="0 0 0" xyz="-0.018044 0.018044 0.017756"/>
  <parent link="leg_rev_v1_4"/>
  <child link="leg_parallel_linkage_v1_4"/>
  <axis xyz="-0.70711 -0.707103 0.0"/>
</joint>

<joint name="body_leg_free_1" type="continuous">
  <origin rpy="0 0 0" xyz="-0.045406 -0.043805 -0.001598"/>
  <parent link="base_link"/>
  <child link="bottom_pivot_plate_v1_1"/>
  <axis xyz="-0.0 -0.0 1.0"/>
</joint>

<joint name="body_leg_free_2" type="continuous">
  <origin rpy="0 0 0" xyz="-0.045406 0.04688 -0.001598"/>
  <parent link="base_link"/>
  <child link="bottom_pivot_plate_v1_2"/>
  <axis xyz="-0.0 -0.0 1.0"/>
</joint>

<joint name="body_leg_free_3" type="continuous">
  <origin rpy="0 0 0" xyz="0.045406 0.047003 -0.001598"/>
  <parent link="base_link"/>
  <child link="bottom_pivot_plate_v1_3"/>
  <axis xyz="-0.0 -0.0 1.0"/>
</joint>

<joint name="body_leg_free_4" type="continuous">
  <origin rpy="0 0 0" xyz="0.045406 -0.043808 -0.001598"/>
  <parent link="base_link"/>
  <child link="bottom_pivot_plate_v1_4"/>
  <axis xyz="-0.0 -0.0 1.0"/>
</joint>

<joint name="Rigid42" type="fixed">
  <origin rpy="0 0 0" xyz="-0.021763 -0.014297 0.008288"/>
  <parent link="bottom_pivot_plate_v1_1"/>
  <child link="leg_parallel_plate_v1_1"/>
</joint>

<joint name="Rigid43" type="fixed">
  <origin rpy="0 0 0" xyz="-0.014297 0.021764 0.008288"/>
  <parent link="bottom_pivot_plate_v1_2"/>
  <child link="leg_parallel_plate_v1_2"/>
</joint>

<joint name="Rigid44" type="fixed">
  <origin rpy="0 0 0" xyz="0.021763 0.014298 0.008288"/>
  <parent link="bottom_pivot_plate_v1_3"/>
  <child link="leg_parallel_plate_v1_3"/>
</joint>

<joint name="Rigid45" type="fixed">
  <origin rpy="0 0 0" xyz="0.014297 -0.021764 0.008288"/>
  <parent link="bottom_pivot_plate_v1_4"/>
  <child link="leg_parallel_plate_v1_4"/>
</joint>

<joint name="leg_rev_free_9" type="Ball">
  <origin rpy="0 0 0" xyz="-0.006317 -0.009799 0.020923"/>
  <parent link="leg_parallel_plate_v1_1"/>
  <child link="leg_parallel_linkage_v1_1"/>
</joint>

<joint name="leg_rev_free_10" type="Ball">
  <origin rpy="0 0 0" xyz="-0.009798 0.006317 0.020923"/>
  <parent link="leg_parallel_plate_v1_2"/>
  <child link="leg_parallel_linkage_v1_2"/>
</joint>

<joint name="leg_rev_free_11" type="Ball">
  <origin rpy="0 0 0" xyz="0.006317 0.009798 0.020923"/>
  <parent link="leg_parallel_plate_v1_3"/>
  <child link="leg_parallel_linkage_v1_3"/>
</joint>

<joint name="leg_rev_free_12" type="Ball">
  <origin rpy="0 0 0" xyz="0.009798 -0.006316 0.020923"/>
  <parent link="leg_parallel_plate_v1_4"/>
  <child link="leg_parallel_linkage_v1_4"/>
</joint>

</robot>
