<?xml version="1.0" ?>
<robot name="quadruped" xmlns:xacro="http://www.ros.org/wiki/xacro">

<xacro:include filename="$(find quadruped_description)/urdf/materials.xacro" />
<xacro:include filename="$(find quadruped_description)/urdf/quadruped.trans" />
<xacro:include filename="$(find quadruped_description)/urdf/quadruped.gazebo" />
<link name="base_link">
  <inertial>
    <origin rpy="0 0 0" xyz="9.020183166175012e-07 0.0015934100491627728 -3.844423505806882e-06"/>
    <mass value="0.03172042156458545"/>
    <inertia ixx="4.9e-05" ixy="0.0" ixz="-0.0" iyy="4.9e-05" iyz="-0.0" izz="9.8e-05"/>
  </inertial>
  <visual>
    <origin rpy="0 0 0" xyz="0 0 0"/>
    <geometry>
      <mesh filename="package://quadruped_description/meshes/base_link.stl" scale="0.001 0.001 0.001"/>
    </geometry>
    <material name="silver"/>
  </visual>
  <collision>
    <origin rpy="0 0 0" xyz="0 0 0"/>
    <geometry>
      <mesh filename="package://quadruped_description/meshes/base_link.stl" scale="0.001 0.001 0.001"/>
    </geometry>
  </collision>
</link>

<link name="body_spacer_v1_1">
  <inertial>
    <origin rpy="0 0 0" xyz="5.025436629208774e-09 -1.479027513101583e-07 0.0019124056524901286"/>
    <mass value="0.003797653049825268"/>
    <inertia ixx="0.0" ixy="0.0" ixz="-0.0" iyy="1e-06" iyz="-0.0" izz="1e-06"/>
  </inertial>
  <visual>
    <origin rpy="0 0 0" xyz="-0.0 -0.044629 -0.00924"/>
    <geometry>
      <mesh filename="package://quadruped_description/meshes/body_spacer_v1_1.stl" scale="0.001 0.001 0.001"/>
    </geometry>
    <material name="silver"/>
  </visual>
  <collision>
    <origin rpy="0 0 0" xyz="-0.0 -0.044629 -0.00924"/>
    <geometry>
      <mesh filename="package://quadruped_description/meshes/body_spacer_v1_1.stl" scale="0.001 0.001 0.001"/>
    </geometry>
  </collision>
</link>

<link name="body_spacer_v1_2">
  <inertial>
    <origin rpy="0 0 0" xyz="-1.2816384902097095e-08 3.520972508067044e-07 0.0019124056524900766"/>
    <mass value="0.003797653049825268"/>
    <inertia ixx="0.0" ixy="0.0" ixz="-0.0" iyy="1e-06" iyz="-0.0" izz="1e-06"/>
  </inertial>
  <visual>
    <origin rpy="0 0 0" xyz="0.0 0.041434 -0.00924"/>
    <geometry>
      <mesh filename="package://quadruped_description/meshes/body_spacer_v1_2.stl" scale="0.001 0.001 0.001"/>
    </geometry>
    <material name="silver"/>
  </visual>
  <collision>
    <origin rpy="0 0 0" xyz="0.0 0.041434 -0.00924"/>
    <geometry>
      <mesh filename="package://quadruped_description/meshes/body_spacer_v1_2.stl" scale="0.001 0.001 0.001"/>
    </geometry>
  </collision>
</link>

<link name="body_spacer_v1_3">
  <inertial>
    <origin rpy="0 0 0" xyz="2.4610452482171086e-07 -4.0682366106502103e-07 0.0019124056524901026"/>
    <mass value="0.003797653049825268"/>
    <inertia ixx="1e-06" ixy="-0.0" ixz="0.0" iyy="0.0" iyz="0.0" izz="1e-06"/>
  </inertial>
  <visual>
    <origin rpy="0 0 0" xyz="-0.043031 -0.001598 -0.00924"/>
    <geometry>
      <mesh filename="package://quadruped_description/meshes/body_spacer_v1_3.stl" scale="0.001 0.001 0.001"/>
    </geometry>
    <material name="silver"/>
  </visual>
  <collision>
    <origin rpy="0 0 0" xyz="-0.043031 -0.001598 -0.00924"/>
    <geometry>
      <mesh filename="package://quadruped_description/meshes/body_spacer_v1_3.stl" scale="0.001 0.001 0.001"/>
    </geometry>
  </collision>
</link>

<link name="body_spacer_v1_4">
  <inertial>
    <origin rpy="0 0 0" xyz="-2.538954731109988e-07 -3.8898183947152533e-07 0.0019124056524901026"/>
    <mass value="0.003797653049825268"/>
    <inertia ixx="1e-06" ixy="-0.0" ixz="0.0" iyy="0.0" iyz="0.0" izz="1e-06"/>
  </inertial>
  <visual>
    <origin rpy="0 0 0" xyz="0.043031 -0.001598 -0.00924"/>
    <geometry>
      <mesh filename="package://quadruped_description/meshes/body_spacer_v1_4.stl" scale="0.001 0.001 0.001"/>
    </geometry>
    <material name="silver"/>
  </visual>
  <collision>
    <origin rpy="0 0 0" xyz="0.043031 -0.001598 -0.00924"/>
    <geometry>
      <mesh filename="package://quadruped_description/meshes/body_spacer_v1_4.stl" scale="0.001 0.001 0.001"/>
    </geometry>
  </collision>
</link>

<link name="body_top_plate_v1_1">
  <inertial>
    <origin rpy="0 0 0" xyz="-6.221181536960989e-06 -7.842240333725669e-07 0.0015936555764941539"/>
    <mass value="0.04667238799634045"/>
    <inertia ixx="4.7e-05" ixy="-0.0" ixz="-0.0" iyy="4.5e-05" iyz="-0.0" izz="9.2e-05"/>
  </inertial>
  <visual>
    <origin rpy="0 0 0" xyz="1e-05 -0.001603 -0.020715"/>
    <geometry>
      <mesh filename="package://quadruped_description/meshes/body_top_plate_v1_1.stl" scale="0.001 0.001 0.001"/>
    </geometry>
    <material name="silver"/>
  </visual>
  <collision>
    <origin rpy="0 0 0" xyz="1e-05 -0.001603 -0.020715"/>
    <geometry>
      <mesh filename="package://quadruped_description/meshes/body_top_plate_v1_1.stl" scale="0.001 0.001 0.001"/>
    </geometry>
  </collision>
</link>

<link name="servo_motor_v1_1">
  <inertial>
    <origin rpy="0 0 0" xyz="0.003445269485712804 0.0034447597444987113 -0.017291510897469282"/>
    <mass value="0.011377011376072494"/>
    <inertia ixx="1e-06" ixy="-0.0" ixz="0.0" iyy="1e-06" iyz="0.0" izz="1e-06"/>
  </inertial>
  <visual>
    <origin rpy="0 0 0" xyz="0.045406 0.043805 -0.038004"/>
    <geometry>
      <mesh filename="package://quadruped_description/meshes/servo_motor_v1_1.stl" scale="0.001 0.001 0.001"/>
    </geometry>
    <material name="silver"/>
  </visual>
  <collision>
    <origin rpy="0 0 0" xyz="0.045406 0.043805 -0.038004"/>
    <geometry>
      <mesh filename="package://quadruped_description/meshes/servo_motor_v1_1.stl" scale="0.001 0.001 0.001"/>
    </geometry>
  </collision>
</link>

<link name="servo_motor_v1_2">
  <inertial>
    <origin rpy="0 0 0" xyz="0.0034452866774157542 -0.0034447102895489856 -0.01729151089746925"/>
    <mass value="0.011377011376072494"/>
    <inertia ixx="1e-06" ixy="0.0" ixz="0.0" iyy="1e-06" iyz="-0.0" izz="1e-06"/>
  </inertial>
  <visual>
    <origin rpy="0 0 0" xyz="0.045406 -0.04688 -0.038004"/>
    <geometry>
      <mesh filename="package://quadruped_description/meshes/servo_motor_v1_2.stl" scale="0.001 0.001 0.001"/>
    </geometry>
    <material name="silver"/>
  </visual>
  <collision>
    <origin rpy="0 0 0" xyz="0.045406 -0.04688 -0.038004"/>
    <geometry>
      <mesh filename="package://quadruped_description/meshes/servo_motor_v1_2.stl" scale="0.001 0.001 0.001"/>
    </geometry>
  </collision>
</link>

<link name="servo_motor_v1_3">
  <inertial>
    <origin rpy="0 0 0" xyz="-0.0034453021128149353 -0.003444710298049422 -0.017291510897469255"/>
    <mass value="0.011377011376072494"/>
    <inertia ixx="1e-06" ixy="-0.0" ixz="-0.0" iyy="1e-06" iyz="-0.0" izz="1e-06"/>
  </inertial>
  <visual>
    <origin rpy="0 0 0" xyz="-0.045406 -0.047003 -0.038004"/>
    <geometry>
      <mesh filename="package://quadruped_description/meshes/servo_motor_v1_3.stl" scale="0.001 0.001 0.001"/>
    </geometry>
    <material name="silver"/>
  </visual>
  <collision>
    <origin rpy="0 0 0" xyz="-0.045406 -0.047003 -0.038004"/>
    <geometry>
      <mesh filename="package://quadruped_description/meshes/servo_motor_v1_3.stl" scale="0.001 0.001 0.001"/>
    </geometry>
  </collision>
</link>

<link name="servo_motor_v1_4">
  <inertial>
    <origin rpy="0 0 0" xyz="-0.0034453193306107632 0.0034448972747542633 -0.017291510897469272"/>
    <mass value="0.011377011376072494"/>
    <inertia ixx="1e-06" ixy="0.0" ixz="-0.0" iyy="1e-06" iyz="0.0" izz="1e-06"/>
  </inertial>
  <visual>
    <origin rpy="0 0 0" xyz="-0.045406 0.043808 -0.038004"/>
    <geometry>
      <mesh filename="package://quadruped_description/meshes/servo_motor_v1_4.stl" scale="0.001 0.001 0.001"/>
    </geometry>
    <material name="silver"/>
  </visual>
  <collision>
    <origin rpy="0 0 0" xyz="-0.045406 0.043808 -0.038004"/>
    <geometry>
      <mesh filename="package://quadruped_description/meshes/servo_motor_v1_4.stl" scale="0.001 0.001 0.001"/>
    </geometry>
  </collision>
</link>

<link name="leg_servo_retainer_v1_1">
  <inertial>
    <origin rpy="0 0 0" xyz="-0.007975130331266019 -0.007974361586274306 -3.4442350584432124e-07"/>
    <mass value="0.002255974797814701"/>
    <inertia ixx="0.0" ixy="-0.0" ixz="0.0" iyy="0.0" iyz="-0.0" izz="0.0"/>
  </inertial>
  <visual>
    <origin rpy="0 0 0" xyz="0.033325 0.031724 -0.028684"/>
    <geometry>
      <mesh filename="package://quadruped_description/meshes/leg_servo_retainer_v1_1.stl" scale="0.001 0.001 0.001"/>
    </geometry>
    <material name="silver"/>
  </visual>
  <collision>
    <origin rpy="0 0 0" xyz="0.033325 0.031724 -0.028684"/>
    <geometry>
      <mesh filename="package://quadruped_description/meshes/leg_servo_retainer_v1_1.stl" scale="0.001 0.001 0.001"/>
    </geometry>
  </collision>
</link>

<link name="leg_servo_retainer_v1_2">
  <inertial>
    <origin rpy="0 0 0" xyz="-0.00797383465335734 0.007975689527429844 -3.4442350579921843e-07"/>
    <mass value="0.002255974797814701"/>
    <inertia ixx="0.0" ixy="0.0" ixz="0.0" iyy="0.0" iyz="-0.0" izz="0.0"/>
  </inertial>
  <visual>
    <origin rpy="0 0 0" xyz="0.033325 -0.034799 -0.028684"/>
    <geometry>
      <mesh filename="package://quadruped_description/meshes/leg_servo_retainer_v1_2.stl" scale="0.001 0.001 0.001"/>
    </geometry>
    <material name="silver"/>
  </visual>
  <collision>
    <origin rpy="0 0 0" xyz="0.033325 -0.034799 -0.028684"/>
    <geometry>
      <mesh filename="package://quadruped_description/meshes/leg_servo_retainer_v1_2.stl" scale="0.001 0.001 0.001"/>
    </geometry>
  </collision>
</link>

<link name="leg_servo_retainer_v1_3">
  <inertial>
    <origin rpy="0 0 0" xyz="0.00797509770416388 0.007974411032723616 -3.44423505795749e-07"/>
    <mass value="0.002255974797814701"/>
    <inertia ixx="0.0" ixy="-0.0" ixz="0.0" iyy="0.0" iyz="0.0" izz="0.0"/>
  </inertial>
  <visual>
    <origin rpy="0 0 0" xyz="-0.033325 -0.034922 -0.028684"/>
    <geometry>
      <mesh filename="package://quadruped_description/meshes/leg_servo_retainer_v1_3.stl" scale="0.001 0.001 0.001"/>
    </geometry>
    <material name="silver"/>
  </visual>
  <collision>
    <origin rpy="0 0 0" xyz="-0.033325 -0.034922 -0.028684"/>
    <geometry>
      <mesh filename="package://quadruped_description/meshes/leg_servo_retainer_v1_3.stl" scale="0.001 0.001 0.001"/>
    </geometry>
  </collision>
</link>

<link name="leg_servo_retainer_v1_4">
  <inertial>
    <origin rpy="0 0 0" xyz="0.007973802000162254 -0.007975502542224545 -3.444235058026879e-07"/>
    <mass value="0.002255974797814701"/>
    <inertia ixx="0.0" ixy="0.0" ixz="-0.0" iyy="0.0" iyz="-0.0" izz="0.0"/>
  </inertial>
  <visual>
    <origin rpy="0 0 0" xyz="-0.033325 0.031727 -0.028684"/>
    <geometry>
      <mesh filename="package://quadruped_description/meshes/leg_servo_retainer_v1_4.stl" scale="0.001 0.001 0.001"/>
    </geometry>
    <material name="silver"/>
  </visual>
  <collision>
    <origin rpy="0 0 0" xyz="-0.033325 0.031727 -0.028684"/>
    <geometry>
      <mesh filename="package://quadruped_description/meshes/leg_servo_retainer_v1_4.stl" scale="0.001 0.001 0.001"/>
    </geometry>
  </collision>
</link>

<link name="leg_top_pivot_plate_v1_1">
  <inertial>
    <origin rpy="0 0 0" xyz="-0.01064848724631829 -0.0105776220168479 -0.0015938444235058385"/>
    <mass value="0.003959817737688224"/>
    <inertia ixx="0.0" ixy="-0.0" ixz="0.0" iyy="0.0" iyz="0.0" izz="1e-06"/>
  </inertial>
  <visual>
    <origin rpy="0 0 0" xyz="0.045406 0.043805 -0.038004"/>
    <geometry>
      <mesh filename="package://quadruped_description/meshes/leg_top_pivot_plate_v1_1.stl" scale="0.001 0.001 0.001"/>
    </geometry>
    <material name="silver"/>
  </visual>
  <collision>
    <origin rpy="0 0 0" xyz="0.045406 0.043805 -0.038004"/>
    <geometry>
      <mesh filename="package://quadruped_description/meshes/leg_top_pivot_plate_v1_1.stl" scale="0.001 0.001 0.001"/>
    </geometry>
  </collision>
</link>

<link name="leg_top_pivot_plate_v1_2">
  <inertial>
    <origin rpy="0 0 0" xyz="-0.010577097000469049 0.010649044538789065 -0.001593844423505797"/>
    <mass value="0.003959817737688224"/>
    <inertia ixx="0.0" ixy="0.0" ixz="0.0" iyy="0.0" iyz="0.0" izz="1e-06"/>
  </inertial>
  <visual>
    <origin rpy="0 0 0" xyz="0.045406 -0.04688 -0.038004"/>
    <geometry>
      <mesh filename="package://quadruped_description/meshes/leg_top_pivot_plate_v1_2.stl" scale="0.001 0.001 0.001"/>
    </geometry>
    <material name="silver"/>
  </visual>
  <collision>
    <origin rpy="0 0 0" xyz="0.045406 -0.04688 -0.038004"/>
    <geometry>
      <mesh filename="package://quadruped_description/meshes/leg_top_pivot_plate_v1_2.stl" scale="0.001 0.001 0.001"/>
    </geometry>
  </collision>
</link>

<link name="leg_top_pivot_plate_v1_3">
  <inertial>
    <origin rpy="0 0 0" xyz="0.010648463098273768 0.010577662927019234 -0.001593844423505783"/>
    <mass value="0.003959817737688224"/>
    <inertia ixx="0.0" ixy="-0.0" ixz="0.0" iyy="0.0" iyz="0.0" izz="1e-06"/>
  </inertial>
  <visual>
    <origin rpy="0 0 0" xyz="-0.045406 -0.047003 -0.038004"/>
    <geometry>
      <mesh filename="package://quadruped_description/meshes/leg_top_pivot_plate_v1_3.stl" scale="0.001 0.001 0.001"/>
    </geometry>
    <material name="silver"/>
  </visual>
  <collision>
    <origin rpy="0 0 0" xyz="-0.045406 -0.047003 -0.038004"/>
    <geometry>
      <mesh filename="package://quadruped_description/meshes/leg_top_pivot_plate_v1_3.stl" scale="0.001 0.001 0.001"/>
    </geometry>
  </collision>
</link>

<link name="leg_top_pivot_plate_v1_4">
  <inertial>
    <origin rpy="0 0 0" xyz="0.01057703173080353 -0.010648889951357966 -0.0015938444235058316"/>
    <mass value="0.003959817737688224"/>
    <inertia ixx="0.0" ixy="0.0" ixz="0.0" iyy="0.0" iyz="0.0" izz="1e-06"/>
  </inertial>
  <visual>
    <origin rpy="0 0 0" xyz="-0.045406 0.043808 -0.038004"/>
    <geometry>
      <mesh filename="package://quadruped_description/meshes/leg_top_pivot_plate_v1_4.stl" scale="0.001 0.001 0.001"/>
    </geometry>
    <material name="silver"/>
  </visual>
  <collision>
    <origin rpy="0 0 0" xyz="-0.045406 0.043808 -0.038004"/>
    <geometry>
      <mesh filename="package://quadruped_description/meshes/leg_top_pivot_plate_v1_4.stl" scale="0.001 0.001 0.001"/>
    </geometry>
  </collision>
</link>

<link name="leg_servo_mount_v1_1">
  <inertial>
    <origin rpy="0 0 0" xyz="-0.006427196199599618 -0.006426516179754871 -0.009351515125044178"/>
    <mass value="0.003626406146686101"/>
    <inertia ixx="1e-06" ixy="-0.0" ixz="0.0" iyy="1e-06" iyz="0.0" izz="0.0"/>
  </inertial>
  <visual>
    <origin rpy="0 0 0" xyz="0.058289 0.065885 -0.026529"/>
    <geometry>
      <mesh filename="package://quadruped_description/meshes/leg_servo_mount_v1_1.stl" scale="0.001 0.001 0.001"/>
    </geometry>
    <material name="silver"/>
  </visual>
  <collision>
    <origin rpy="0 0 0" xyz="0.058289 0.065885 -0.026529"/>
    <geometry>
      <mesh filename="package://quadruped_description/meshes/leg_servo_mount_v1_1.stl" scale="0.001 0.001 0.001"/>
    </geometry>
  </collision>
</link>

<link name="leg_servo_mount_v1_2">
  <inertial>
    <origin rpy="0 0 0" xyz="-0.006426992722265573 0.006426750265320011 -0.009351515125044087"/>
    <mass value="0.003626406146686101"/>
    <inertia ixx="1e-06" ixy="0.0" ixz="0.0" iyy="1e-06" iyz="-0.0" izz="0.0"/>
  </inertial>
  <visual>
    <origin rpy="0 0 0" xyz="0.067485 -0.059764 -0.026529"/>
    <geometry>
      <mesh filename="package://quadruped_description/meshes/leg_servo_mount_v1_2.stl" scale="0.001 0.001 0.001"/>
    </geometry>
    <material name="silver"/>
  </visual>
  <collision>
    <origin rpy="0 0 0" xyz="0.067485 -0.059764 -0.026529"/>
    <geometry>
      <mesh filename="package://quadruped_description/meshes/leg_servo_mount_v1_2.stl" scale="0.001 0.001 0.001"/>
    </geometry>
  </collision>
</link>

<link name="leg_servo_mount_v1_3">
  <inertial>
    <origin rpy="0 0 0" xyz="0.006427186423519492 0.0064265501466144875 -0.00935151512504414"/>
    <mass value="0.003626406146686101"/>
    <inertia ixx="1e-06" ixy="-0.0" ixz="-0.0" iyy="1e-06" iyz="-0.0" izz="0.0"/>
  </inertial>
  <visual>
    <origin rpy="0 0 0" xyz="-0.058289 -0.069083 -0.026529"/>
    <geometry>
      <mesh filename="package://quadruped_description/meshes/leg_servo_mount_v1_3.stl" scale="0.001 0.001 0.001"/>
    </geometry>
    <material name="silver"/>
  </visual>
  <collision>
    <origin rpy="0 0 0" xyz="-0.058289 -0.069083 -0.026529"/>
    <geometry>
      <mesh filename="package://quadruped_description/meshes/leg_servo_mount_v1_3.stl" scale="0.001 0.001 0.001"/>
    </geometry>
  </collision>
</link>

<link name="leg_servo_mount_v1_4">
  <inertial>
    <origin rpy="0 0 0" xyz="0.006426900922705647 -0.006426650591997658 -0.00935151512504414"/>
    <mass value="0.003626406146686101"/>
    <inertia ixx="1e-06" ixy="0.0" ixz="-0.0" iyy="1e-06" iyz="0.0" izz="0.0"/>
  </inertial>
  <visual>
    <origin rpy="0 0 0" xyz="-0.067485 0.056692 -0.026529"/>
    <geometry>
      <mesh filename="package://quadruped_description/meshes/leg_servo_mount_v1_4.stl" scale="0.001 0.001 0.001"/>
    </geometry>
    <material name="silver"/>
  </visual>
  <collision>
    <origin rpy="0 0 0" xyz="-0.067485 0.056692 -0.026529"/>
    <geometry>
      <mesh filename="package://quadruped_description/meshes/leg_servo_mount_v1_4.stl" scale="0.001 0.001 0.001"/>
    </geometry>
  </collision>
</link>

<link name="servo_motor_v1_5">
  <inertial>
    <origin rpy="0 0 0" xyz="0.005636221543962469 -0.005636019933225447 -0.012212864453551195"/>
    <mass value="0.011377011376072494"/>
    <inertia ixx="1e-06" ixy="0.0" ixz="-0.0" iyy="1e-06" iyz="0.0" izz="1e-06"/>
  </inertial>
  <visual>
    <origin rpy="0 0 0" xyz="0.066908 0.074504 -0.026962"/>
    <geometry>
      <mesh filename="package://quadruped_description/meshes/servo_motor_v1_5.stl" scale="0.001 0.001 0.001"/>
    </geometry>
    <material name="silver"/>
  </visual>
  <collision>
    <origin rpy="0 0 0" xyz="0.066908 0.074504 -0.026962"/>
    <geometry>
      <mesh filename="package://quadruped_description/meshes/servo_motor_v1_5.stl" scale="0.001 0.001 0.001"/>
    </geometry>
  </collision>
</link>

<link name="servo_motor_v1_6">
  <inertial>
    <origin rpy="0 0 0" xyz="-0.005636495855827359 -0.0056366688871758025 -0.01221286445355125"/>
    <mass value="0.011377011376072494"/>
    <inertia ixx="1e-06" ixy="-0.0" ixz="0.0" iyy="1e-06" iyz="0.0" izz="1e-06"/>
  </inertial>
  <visual>
    <origin rpy="0 0 0" xyz="0.076104 -0.068383 -0.026962"/>
    <geometry>
      <mesh filename="package://quadruped_description/meshes/servo_motor_v1_6.stl" scale="0.001 0.001 0.001"/>
    </geometry>
    <material name="silver"/>
  </visual>
  <collision>
    <origin rpy="0 0 0" xyz="0.076104 -0.068383 -0.026962"/>
    <geometry>
      <mesh filename="package://quadruped_description/meshes/servo_motor_v1_6.stl" scale="0.001 0.001 0.001"/>
    </geometry>
  </collision>
</link>

<link name="servo_motor_v1_7">
  <inertial>
    <origin rpy="0 0 0" xyz="-0.005636225044640217 0.005636056661159752 -0.012212864453551278"/>
    <mass value="0.011377011376072494"/>
    <inertia ixx="1e-06" ixy="0.0" ixz="0.0" iyy="1e-06" iyz="-0.0" izz="1e-06"/>
  </inertial>
  <visual>
    <origin rpy="0 0 0" xyz="-0.066908 -0.077702 -0.026962"/>
    <geometry>
      <mesh filename="package://quadruped_description/meshes/servo_motor_v1_7.stl" scale="0.001 0.001 0.001"/>
    </geometry>
    <material name="silver"/>
  </visual>
  <collision>
    <origin rpy="0 0 0" xyz="-0.066908 -0.077702 -0.026962"/>
    <geometry>
      <mesh filename="package://quadruped_description/meshes/servo_motor_v1_7.stl" scale="0.001 0.001 0.001"/>
    </geometry>
  </collision>
</link>

<link name="servo_motor_v1_8">
  <inertial>
    <origin rpy="0 0 0" xyz="0.005636414606091239 0.005636744582675518 -0.012212864453551247"/>
    <mass value="0.011377011376072494"/>
    <inertia ixx="1e-06" ixy="-0.0" ixz="-0.0" iyy="1e-06" iyz="-0.0" izz="1e-06"/>
  </inertial>
  <visual>
    <origin rpy="0 0 0" xyz="-0.076104 0.065311 -0.026962"/>
    <geometry>
      <mesh filename="package://quadruped_description/meshes/servo_motor_v1_8.stl" scale="0.001 0.001 0.001"/>
    </geometry>
    <material name="silver"/>
  </visual>
  <collision>
    <origin rpy="0 0 0" xyz="-0.076104 0.065311 -0.026962"/>
    <geometry>
      <mesh filename="package://quadruped_description/meshes/servo_motor_v1_8.stl" scale="0.001 0.001 0.001"/>
    </geometry>
  </collision>
</link>

<link name="leg_servo_arm_v1_1">
  <inertial>
    <origin rpy="0 0 0" xyz="-0.006854771419713121 -0.009109122789870541 -1.5241881959511538e-05"/>
    <mass value="0.0019221384911435294"/>
    <inertia ixx="0.0" ixy="-0.0" ixz="-0.0" iyy="0.0" iyz="-0.0" izz="0.0"/>
  </inertial>
  <visual>
    <origin rpy="0 0 0" xyz="0.073499 0.067913 -0.009877"/>
    <geometry>
      <mesh filename="package://quadruped_description/meshes/leg_servo_arm_v1_1.stl" scale="0.001 0.001 0.001"/>
    </geometry>
    <material name="silver"/>
  </visual>
  <collision>
    <origin rpy="0 0 0" xyz="0.073499 0.067913 -0.009877"/>
    <geometry>
      <mesh filename="package://quadruped_description/meshes/leg_servo_arm_v1_1.stl" scale="0.001 0.001 0.001"/>
    </geometry>
  </collision>
</link>

<link name="leg_servo_arm_v1_2">
  <inertial>
    <origin rpy="0 0 0" xyz="-0.009108529732796342 0.006855252223375394 -5.016041829563472e-05"/>
    <mass value="0.0019221384911435294"/>
    <inertia ixx="0.0" ixy="0.0" ixz="-0.0" iyy="0.0" iyz="0.0" izz="0.0"/>
  </inertial>
  <visual>
    <origin rpy="0 0 0" xyz="0.069514 -0.074973 -0.009877"/>
    <geometry>
      <mesh filename="package://quadruped_description/meshes/leg_servo_arm_v1_2.stl" scale="0.001 0.001 0.001"/>
    </geometry>
    <material name="silver"/>
  </visual>
  <collision>
    <origin rpy="0 0 0" xyz="0.069514 -0.074973 -0.009877"/>
    <geometry>
      <mesh filename="package://quadruped_description/meshes/leg_servo_arm_v1_2.stl" scale="0.001 0.001 0.001"/>
    </geometry>
  </collision>
</link>

<link name="leg_servo_arm_v1_3">
  <inertial>
    <origin rpy="0 0 0" xyz="0.006854693008861157 0.009109071811125177 -5.015931162896843e-05"/>
    <mass value="0.0019221384911435294"/>
    <inertia ixx="0.0" ixy="-0.0" ixz="0.0" iyy="0.0" iyz="0.0" izz="0.0"/>
  </inertial>
  <visual>
    <origin rpy="0 0 0" xyz="-0.073499 -0.071111 -0.009877"/>
    <geometry>
      <mesh filename="package://quadruped_description/meshes/leg_servo_arm_v1_3.stl" scale="0.001 0.001 0.001"/>
    </geometry>
    <material name="silver"/>
  </visual>
  <collision>
    <origin rpy="0 0 0" xyz="-0.073499 -0.071111 -0.009877"/>
    <geometry>
      <mesh filename="package://quadruped_description/meshes/leg_servo_arm_v1_3.stl" scale="0.001 0.001 0.001"/>
    </geometry>
  </collision>
</link>

<link name="leg_servo_arm_v1_4">
  <inertial>
    <origin rpy="0 0 0" xyz="0.009109467599752036 -0.006855244541034283 -8.563712547647248e-06"/>
    <mass value="0.0019221384911435294"/>
    <inertia ixx="0.0" ixy="0.0" ixz="0.0" iyy="0.0" iyz="-0.0" izz="0.0"/>
  </inertial>
  <visual>
    <origin rpy="0 0 0" xyz="-0.069513 0.071901 -0.009877"/>
    <geometry>
      <mesh filename="package://quadruped_description/meshes/leg_servo_arm_v1_4.stl" scale="0.001 0.001 0.001"/>
    </geometry>
    <material name="silver"/>
  </visual>
  <collision>
    <origin rpy="0 0 0" xyz="-0.069513 0.071901 -0.009877"/>
    <geometry>
      <mesh filename="package://quadruped_description/meshes/leg_servo_arm_v1_4.stl" scale="0.001 0.001 0.001"/>
    </geometry>
  </collision>
</link>

<link name="leg_rev_v1_1">
  <inertial>
    <origin rpy="0 0 0" xyz="-0.0017567038454927159 0.0003705821402470999 -0.007061666183792752"/>
    <mass value="0.004982233978749814"/>
    <inertia ixx="3e-06" ixy="-0.0" ixz="-0.0" iyy="3e-06" iyz="-0.0" izz="0.0"/>
  </inertial>
  <visual>
    <origin rpy="0 0 0" xyz="0.09153 0.085944 -0.009842"/>
    <geometry>
      <mesh filename="package://quadruped_description/meshes/leg_rev_v1_1.stl" scale="0.001 0.001 0.001"/>
    </geometry>
    <material name="silver"/>
  </visual>
  <collision>
    <origin rpy="0 0 0" xyz="0.09153 0.085944 -0.009842"/>
    <geometry>
      <mesh filename="package://quadruped_description/meshes/leg_rev_v1_1.stl" scale="0.001 0.001 0.001"/>
    </geometry>
  </collision>
</link>

<link name="leg_rev_v1_2">
  <inertial>
    <origin rpy="0 0 0" xyz="0.00037136288025488295 0.0017569930987815091 -0.007061565247779419"/>
    <mass value="0.004982233978749814"/>
    <inertia ixx="3e-06" ixy="0.0" ixz="-0.0" iyy="3e-06" iyz="0.0" izz="0.0"/>
  </inertial>
  <visual>
    <origin rpy="0 0 0" xyz="0.087545 -0.093004 -0.009763"/>
    <geometry>
      <mesh filename="package://quadruped_description/meshes/leg_rev_v1_2.stl" scale="0.001 0.001 0.001"/>
    </geometry>
    <material name="silver"/>
  </visual>
  <collision>
    <origin rpy="0 0 0" xyz="0.087545 -0.093004 -0.009763"/>
    <geometry>
      <mesh filename="package://quadruped_description/meshes/leg_rev_v1_2.stl" scale="0.001 0.001 0.001"/>
    </geometry>
  </collision>
</link>

<link name="leg_rev_v1_3">
  <inertial>
    <origin rpy="0 0 0" xyz="0.0017564422854380868 -0.00037083348895713963 -0.0070615627472460345"/>
    <mass value="0.004982233978749814"/>
    <inertia ixx="3e-06" ixy="-0.0" ixz="0.0" iyy="3e-06" iyz="0.0" izz="0.0"/>
  </inertial>
  <visual>
    <origin rpy="0 0 0" xyz="-0.09153 -0.089142 -0.009763"/>
    <geometry>
      <mesh filename="package://quadruped_description/meshes/leg_rev_v1_3.stl" scale="0.001 0.001 0.001"/>
    </geometry>
    <material name="silver"/>
  </visual>
  <collision>
    <origin rpy="0 0 0" xyz="-0.09153 -0.089142 -0.009763"/>
    <geometry>
      <mesh filename="package://quadruped_description/meshes/leg_rev_v1_3.stl" scale="0.001 0.001 0.001"/>
    </geometry>
  </collision>
</link>

<link name="leg_rev_v1_4">
  <inertial>
    <origin rpy="0 0 0" xyz="-0.00037124922912221137 -0.001757227005405787 -0.007061576739121153"/>
    <mass value="0.004982233978749814"/>
    <inertia ixx="3e-06" ixy="0.0" ixz="0.0" iyy="3e-06" iyz="-0.0" izz="0.0"/>
  </inertial>
  <visual>
    <origin rpy="0 0 0" xyz="-0.087545 0.089932 -0.009857"/>
    <geometry>
      <mesh filename="package://quadruped_description/meshes/leg_rev_v1_4.stl" scale="0.001 0.001 0.001"/>
    </geometry>
    <material name="silver"/>
  </visual>
  <collision>
    <origin rpy="0 0 0" xyz="-0.087545 0.089932 -0.009857"/>
    <geometry>
      <mesh filename="package://quadruped_description/meshes/leg_rev_v1_4.stl" scale="0.001 0.001 0.001"/>
    </geometry>
  </collision>
</link>

<link name="leg_parallel_linkage_v1_1">
  <inertial>
    <origin rpy="0 0 0" xyz="0.01014233302581477 0.007888986423959826 -3.990610381444937e-05"/>
    <mass value="0.007660744416023881"/>
    <inertia ixx="0.0" ixy="-0.0" ixz="0.0" iyy="0.0" iyz="0.0" izz="1e-06"/>
  </inertial>
  <visual>
    <origin rpy="0 0 0" xyz="0.091517 0.085932 -0.027692"/>
    <geometry>
      <mesh filename="package://quadruped_description/meshes/leg_parallel_linkage_v1_1.stl" scale="0.001 0.001 0.001"/>
    </geometry>
    <material name="silver"/>
  </visual>
  <collision>
    <origin rpy="0 0 0" xyz="0.091517 0.085932 -0.027692"/>
    <geometry>
      <mesh filename="package://quadruped_description/meshes/leg_parallel_linkage_v1_1.stl" scale="0.001 0.001 0.001"/>
    </geometry>
  </collision>
</link>

<link name="leg_parallel_linkage_v1_2">
  <inertial>
    <origin rpy="0 0 0" xyz="0.007888463752775826 -0.010142736860866697 -3.457620552892171e-07"/>
    <mass value="0.007660744416023881"/>
    <inertia ixx="0.0" ixy="0.0" ixz="-0.0" iyy="0.0" iyz="0.0" izz="1e-06"/>
  </inertial>
  <visual>
    <origin rpy="0 0 0" xyz="0.087532 -0.092992 -0.027613"/>
    <geometry>
      <mesh filename="package://quadruped_description/meshes/leg_parallel_linkage_v1_2.stl" scale="0.001 0.001 0.001"/>
    </geometry>
    <material name="silver"/>
  </visual>
  <collision>
    <origin rpy="0 0 0" xyz="0.087532 -0.092992 -0.027613"/>
    <geometry>
      <mesh filename="package://quadruped_description/meshes/leg_parallel_linkage_v1_2.stl" scale="0.001 0.001 0.001"/>
    </geometry>
  </collision>
</link>

<link name="leg_parallel_linkage_v1_3">
  <inertial>
    <origin rpy="0 0 0" xyz="-0.010142295076683155 -0.00788892268016117 -3.4451109130403945e-07"/>
    <mass value="0.007660744416023881"/>
    <inertia ixx="0.0" ixy="-0.0" ixz="-0.0" iyy="0.0" iyz="-0.0" izz="1e-06"/>
  </inertial>
  <visual>
    <origin rpy="0 0 0" xyz="-0.091517 -0.08913 -0.027613"/>
    <geometry>
      <mesh filename="package://quadruped_description/meshes/leg_parallel_linkage_v1_3.stl" scale="0.001 0.001 0.001"/>
    </geometry>
    <material name="silver"/>
  </visual>
  <collision>
    <origin rpy="0 0 0" xyz="-0.091517 -0.08913 -0.027613"/>
    <geometry>
      <mesh filename="package://quadruped_description/meshes/leg_parallel_linkage_v1_3.stl" scale="0.001 0.001 0.001"/>
    </geometry>
  </collision>
</link>

<link name="leg_parallel_linkage_v1_4">
  <inertial>
    <origin rpy="0 0 0" xyz="-0.007888667781509234 0.010142880185880013 -4.736327158617534e-05"/>
    <mass value="0.007660744416023881"/>
    <inertia ixx="0.0" ixy="0.0" ixz="-0.0" iyy="0.0" iyz="0.0" izz="1e-06"/>
  </inertial>
  <visual>
    <origin rpy="0 0 0" xyz="-0.087532 0.08992 -0.027707"/>
    <geometry>
      <mesh filename="package://quadruped_description/meshes/leg_parallel_linkage_v1_4.stl" scale="0.001 0.001 0.001"/>
    </geometry>
    <material name="silver"/>
  </visual>
  <collision>
    <origin rpy="0 0 0" xyz="-0.087532 0.08992 -0.027707"/>
    <geometry>
      <mesh filename="package://quadruped_description/meshes/leg_parallel_linkage_v1_4.stl" scale="0.001 0.001 0.001"/>
    </geometry>
  </collision>
</link>

<link name="bottom_pivot_plate_v1_1">
  <inertial>
    <origin rpy="0 0 0" xyz="-0.010006768306117034 -0.01004709439187329 -0.0015933444235058398"/>
    <mass value="0.02183354723813213"/>
    <inertia ixx="2e-06" ixy="-2e-06" ixz="-0.0" iyy="2e-06" iyz="-0.0" izz="5e-06"/>
  </inertial>
  <visual>
    <origin rpy="0 0 0" xyz="0.045406 0.043805 0.001598"/>
    <geometry>
      <mesh filename="package://quadruped_description/meshes/bottom_pivot_plate_v1_1.stl" scale="0.001 0.001 0.001"/>
    </geometry>
    <material name="silver"/>
  </visual>
  <collision>
    <origin rpy="0 0 0" xyz="0.045406 0.043805 0.001598"/>
    <geometry>
      <mesh filename="package://quadruped_description/meshes/bottom_pivot_plate_v1_1.stl" scale="0.001 0.001 0.001"/>
    </geometry>
  </collision>
</link>

<link name="bottom_pivot_plate_v1_2">
  <inertial>
    <origin rpy="0 0 0" xyz="-0.010046569260001102 0.010007325694069466 -0.0015933444235057773"/>
    <mass value="0.02183354723813213"/>
    <inertia ixx="2e-06" ixy="2e-06" ixz="0.0" iyy="2e-06" iyz="-0.0" izz="5e-06"/>
  </inertial>
  <visual>
    <origin rpy="0 0 0" xyz="0.045406 -0.04688 0.001598"/>
    <geometry>
      <mesh filename="package://quadruped_description/meshes/bottom_pivot_plate_v1_2.stl" scale="0.001 0.001 0.001"/>
    </geometry>
    <material name="silver"/>
  </visual>
  <collision>
    <origin rpy="0 0 0" xyz="0.045406 -0.04688 0.001598"/>
    <geometry>
      <mesh filename="package://quadruped_description/meshes/bottom_pivot_plate_v1_2.stl" scale="0.001 0.001 0.001"/>
    </geometry>
  </collision>
</link>

<link name="bottom_pivot_plate_v1_3">
  <inertial>
    <origin rpy="0 0 0" xyz="0.010006743732796856 0.010047135816452578 -0.0015933444235057825"/>
    <mass value="0.02183354723813213"/>
    <inertia ixx="2e-06" ixy="-2e-06" ixz="-0.0" iyy="2e-06" iyz="-0.0" izz="5e-06"/>
  </inertial>
  <visual>
    <origin rpy="0 0 0" xyz="-0.045406 -0.047003 0.001598"/>
    <geometry>
      <mesh filename="package://quadruped_description/meshes/bottom_pivot_plate_v1_3.stl" scale="0.001 0.001 0.001"/>
    </geometry>
    <material name="silver"/>
  </visual>
  <collision>
    <origin rpy="0 0 0" xyz="-0.045406 -0.047003 0.001598"/>
    <geometry>
      <mesh filename="package://quadruped_description/meshes/bottom_pivot_plate_v1_3.stl" scale="0.001 0.001 0.001"/>
    </geometry>
  </collision>
</link>

<link name="bottom_pivot_plate_v1_4">
  <inertial>
    <origin rpy="0 0 0" xyz="0.010046505955849314 -0.010007169481695825 -0.001593344423505835"/>
    <mass value="0.02183354723813213"/>
    <inertia ixx="2e-06" ixy="2e-06" ixz="0.0" iyy="2e-06" iyz="-0.0" izz="5e-06"/>
  </inertial>
  <visual>
    <origin rpy="0 0 0" xyz="-0.045406 0.043808 0.001598"/>
    <geometry>
      <mesh filename="package://quadruped_description/meshes/bottom_pivot_plate_v1_4.stl" scale="0.001 0.001 0.001"/>
    </geometry>
    <material name="silver"/>
  </visual>
  <collision>
    <origin rpy="0 0 0" xyz="-0.045406 0.043808 0.001598"/>
    <geometry>
      <mesh filename="package://quadruped_description/meshes/bottom_pivot_plate_v1_4.stl" scale="0.001 0.001 0.001"/>
    </geometry>
  </collision>
</link>

<link name="leg_parallel_plate_v1_1">
  <inertial>
    <origin rpy="0 0 0" xyz="-0.0019355917633943759 -0.0019356038676334314 0.012060810010779232"/>
    <mass value="0.014417433544657021"/>
    <inertia ixx="2e-06" ixy="-0.0" ixz="0.0" iyy="2e-06" iyz="0.0" izz="1e-06"/>
  </inertial>
  <visual>
    <origin rpy="0 0 0" xyz="0.067169 0.058102 -0.00669"/>
    <geometry>
      <mesh filename="package://quadruped_description/meshes/leg_parallel_plate_v1_1.stl" scale="0.001 0.001 0.001"/>
    </geometry>
    <material name="silver"/>
  </visual>
  <collision>
    <origin rpy="0 0 0" xyz="0.067169 0.058102 -0.00669"/>
    <geometry>
      <mesh filename="package://quadruped_description/meshes/leg_parallel_plate_v1_1.stl" scale="0.001 0.001 0.001"/>
    </geometry>
  </collision>
</link>

<link name="leg_parallel_plate_v1_2">
  <inertial>
    <origin rpy="0 0 0" xyz="-0.0019350811999452114 0.0019351480381103597 0.012060810010779311"/>
    <mass value="0.014417433544657021"/>
    <inertia ixx="2e-06" ixy="0.0" ixz="0.0" iyy="2e-06" iyz="-0.0" izz="1e-06"/>
  </inertial>
  <visual>
    <origin rpy="0 0 0" xyz="0.059703 -0.068644 -0.00669"/>
    <geometry>
      <mesh filename="package://quadruped_description/meshes/leg_parallel_plate_v1_2.stl" scale="0.001 0.001 0.001"/>
    </geometry>
    <material name="silver"/>
  </visual>
  <collision>
    <origin rpy="0 0 0" xyz="0.059703 -0.068644 -0.00669"/>
    <geometry>
      <mesh filename="package://quadruped_description/meshes/leg_parallel_plate_v1_2.stl" scale="0.001 0.001 0.001"/>
    </geometry>
  </collision>
</link>

<link name="leg_parallel_plate_v1_3">
  <inertial>
    <origin rpy="0 0 0" xyz="0.001935572148431361 0.0019346343167184546 0.012060810010779287"/>
    <mass value="0.014417433544657021"/>
    <inertia ixx="2e-06" ixy="-0.0" ixz="-0.0" iyy="2e-06" iyz="-0.0" izz="1e-06"/>
  </inertial>
  <visual>
    <origin rpy="0 0 0" xyz="-0.067169 -0.061301 -0.00669"/>
    <geometry>
      <mesh filename="package://quadruped_description/meshes/leg_parallel_plate_v1_3.stl" scale="0.001 0.001 0.001"/>
    </geometry>
    <material name="silver"/>
  </visual>
  <collision>
    <origin rpy="0 0 0" xyz="-0.067169 -0.061301 -0.00669"/>
    <geometry>
      <mesh filename="package://quadruped_description/meshes/leg_parallel_plate_v1_3.stl" scale="0.001 0.001 0.001"/>
    </geometry>
  </collision>
</link>

<link name="leg_parallel_plate_v1_4">
  <inertial>
    <origin rpy="0 0 0" xyz="0.0019349759592842755 -0.001935010771185533 0.012060810010779221"/>
    <mass value="0.014417433544657021"/>
    <inertia ixx="2e-06" ixy="0.0" ixz="-0.0" iyy="2e-06" iyz="0.0" izz="1e-06"/>
  </inertial>
  <visual>
    <origin rpy="0 0 0" xyz="-0.059703 0.065572 -0.00669"/>
    <geometry>
      <mesh filename="package://quadruped_description/meshes/leg_parallel_plate_v1_4.stl" scale="0.001 0.001 0.001"/>
    </geometry>
    <material name="silver"/>
  </visual>
  <collision>
    <origin rpy="0 0 0" xyz="-0.059703 0.065572 -0.00669"/>
    <geometry>
      <mesh filename="package://quadruped_description/meshes/leg_parallel_plate_v1_4.stl" scale="0.001 0.001 0.001"/>
    </geometry>
  </collision>
</link>

<link name="leg_parallel_linkage_v1_1">
  <inertial>
    <origin rpy="0 0 0" xyz="-0.007888666974185235 -0.010142013576040165 3.909389618555331e-05"/>
    <mass value="0.007660744416023881"/>
    <inertia ixx="0.0" ixy="-0.0" ixz="0.0" iyy="0.0" iyz="0.0" izz="1e-06"/>
  </inertial>
  <visual>
    <origin rpy="0 0 0" xyz="0.073486 0.067901 -0.027613"/>
    <geometry>
      <mesh filename="package://quadruped_description/meshes/leg_parallel_linkage_v1_1.stl" scale="0.001 0.001 0.001"/>
    </geometry>
    <material name="silver"/>
  </visual>
  <collision>
    <origin rpy="0 0 0" xyz="0.073486 0.067901 -0.027613"/>
    <geometry>
      <mesh filename="package://quadruped_description/meshes/leg_parallel_linkage_v1_1.stl" scale="0.001 0.001 0.001"/>
    </geometry>
  </collision>
</link>

<link name="leg_parallel_linkage_v1_2">
  <inertial>
    <origin rpy="0 0 0" xyz="-0.01014253624722418 0.007888263139133309 -3.457620552892171e-07"/>
    <mass value="0.007660744416023881"/>
    <inertia ixx="0.0" ixy="0.0" ixz="-0.0" iyy="0.0" iyz="0.0" izz="1e-06"/>
  </inertial>
  <visual>
    <origin rpy="0 0 0" xyz="0.069501 -0.074961 -0.027613"/>
    <geometry>
      <mesh filename="package://quadruped_description/meshes/leg_parallel_linkage_v1_2.stl" scale="0.001 0.001 0.001"/>
    </geometry>
    <material name="silver"/>
  </visual>
  <collision>
    <origin rpy="0 0 0" xyz="0.069501 -0.074961 -0.027613"/>
    <geometry>
      <mesh filename="package://quadruped_description/meshes/leg_parallel_linkage_v1_2.stl" scale="0.001 0.001 0.001"/>
    </geometry>
  </collision>
</link>

<link name="leg_parallel_linkage_v1_3">
  <inertial>
    <origin rpy="0 0 0" xyz="0.00788870492331685 0.010142077319838835 -3.4451109130403945e-07"/>
    <mass value="0.007660744416023881"/>
    <inertia ixx="0.0" ixy="-0.0" ixz="-0.0" iyy="0.0" iyz="-0.0" izz="1e-06"/>
  </inertial>
  <visual>
    <origin rpy="0 0 0" xyz="-0.073486 -0.071099 -0.027613"/>
    <geometry>
      <mesh filename="package://quadruped_description/meshes/leg_parallel_linkage_v1_3.stl" scale="0.001 0.001 0.001"/>
    </geometry>
    <material name="silver"/>
  </visual>
  <collision>
    <origin rpy="0 0 0" xyz="-0.073486 -0.071099 -0.027613"/>
    <geometry>
      <mesh filename="package://quadruped_description/meshes/leg_parallel_linkage_v1_3.stl" scale="0.001 0.001 0.001"/>
    </geometry>
  </collision>
</link>

<link name="leg_parallel_linkage_v1_4">
  <inertial>
    <origin rpy="0 0 0" xyz="0.010142332218490771 -0.007889119814119994 4.663672841382499e-05"/>
    <mass value="0.007660744416023881"/>
    <inertia ixx="0.0" ixy="0.0" ixz="-0.0" iyy="0.0" iyz="0.0" izz="1e-06"/>
  </inertial>
  <visual>
    <origin rpy="0 0 0" xyz="-0.069501 0.071888 -0.027613"/>
    <geometry>
      <mesh filename="package://quadruped_description/meshes/leg_parallel_linkage_v1_4.stl" scale="0.001 0.001 0.001"/>
    </geometry>
    <material name="silver"/>
  </visual>
  <collision>
    <origin rpy="0 0 0" xyz="-0.069501 0.071888 -0.027613"/>
    <geometry>
      <mesh filename="package://quadruped_description/meshes/leg_parallel_linkage_v1_4.stl" scale="0.001 0.001 0.001"/>
    </geometry>
  </collision>
</link>

<link name="leg_parallel_plate_v1_1">
  <inertial>
    <origin rpy="0 0 0" xyz="0.004995408236605617 0.007249396132366567 -0.008862189989220767"/>
    <mass value="0.014417433544657021"/>
    <inertia ixx="2e-06" ixy="-0.0" ixz="0.0" iyy="2e-06" iyz="0.0" izz="1e-06"/>
  </inertial>
  <visual>
    <origin rpy="0 0 0" xyz="0.0741 0.067287 -0.027613"/>
    <geometry>
      <mesh filename="package://quadruped_description/meshes/leg_parallel_plate_v1_1.stl" scale="0.001 0.001 0.001"/>
    </geometry>
    <material name="silver"/>
  </visual>
  <collision>
    <origin rpy="0 0 0" xyz="0.0741 0.067287 -0.027613"/>
    <geometry>
      <mesh filename="package://quadruped_description/meshes/leg_parallel_plate_v1_1.stl" scale="0.001 0.001 0.001"/>
    </geometry>
  </collision>
</link>

<link name="leg_parallel_plate_v1_2">
  <inertial>
    <origin rpy="0 0 0" xyz="0.007248918800054793 -0.004994851961889646 -0.008862189989220687"/>
    <mass value="0.014417433544657021"/>
    <inertia ixx="2e-06" ixy="0.0" ixz="0.0" iyy="2e-06" iyz="-0.0" izz="1e-06"/>
  </inertial>
  <visual>
    <origin rpy="0 0 0" xyz="0.068887 -0.075574 -0.027613"/>
    <geometry>
      <mesh filename="package://quadruped_description/meshes/leg_parallel_plate_v1_2.stl" scale="0.001 0.001 0.001"/>
    </geometry>
    <material name="silver"/>
  </visual>
  <collision>
    <origin rpy="0 0 0" xyz="0.068887 -0.075574 -0.027613"/>
    <geometry>
      <mesh filename="package://quadruped_description/meshes/leg_parallel_plate_v1_2.stl" scale="0.001 0.001 0.001"/>
    </geometry>
  </collision>
</link>

<link name="leg_rev_v1_1">
  <inertial>
    <origin rpy="0 0 0" xyz="-0.001769703845492715 0.0003585821402470879 -0.024911666183792754"/>
    <mass value="0.004982233978749814"/>
    <inertia ixx="3e-06" ixy="-0.0" ixz="-0.0" iyy="3e-06" iyz="-0.0" izz="0.0"/>
  </inertial>
  <visual>
    <origin rpy="0 0 0" xyz="0.091517 0.085932 -0.027692"/>
    <geometry>
      <mesh filename="package://quadruped_description/meshes/leg_rev_v1_1.stl" scale="0.001 0.001 0.001"/>
    </geometry>
    <material name="silver"/>
  </visual>
  <collision>
    <origin rpy="0 0 0" xyz="0.091517 0.085932 -0.027692"/>
    <geometry>
      <mesh filename="package://quadruped_description/meshes/leg_rev_v1_1.stl" scale="0.001 0.001 0.001"/>
    </geometry>
  </collision>
</link>

<link name="leg_rev_v1_2">
  <inertial>
    <origin rpy="0 0 0" xyz="0.00035836288025488383 0.0017689930987815072 -0.02491156524777942"/>
    <mass value="0.004982233978749814"/>
    <inertia ixx="3e-06" ixy="0.0" ixz="-0.0" iyy="3e-06" iyz="0.0" izz="0.0"/>
  </inertial>
  <visual>
    <origin rpy="0 0 0" xyz="0.087532 -0.092992 -0.027613"/>
    <geometry>
      <mesh filename="package://quadruped_description/meshes/leg_rev_v1_2.stl" scale="0.001 0.001 0.001"/>
    </geometry>
    <material name="silver"/>
  </visual>
  <collision>
    <origin rpy="0 0 0" xyz="0.087532 -0.092992 -0.027613"/>
    <geometry>
      <mesh filename="package://quadruped_description/meshes/leg_rev_v1_2.stl" scale="0.001 0.001 0.001"/>
    </geometry>
  </collision>
</link>

<link name="leg_parallel_plate_v1_3">
  <inertial>
    <origin rpy="0 0 0" xyz="-0.004995427851568632 -0.00724936568328155 -0.008862189989220712"/>
    <mass value="0.014417433544657021"/>
    <inertia ixx="2e-06" ixy="-0.0" ixz="-0.0" iyy="2e-06" iyz="-0.0" izz="1e-06"/>
  </inertial>
  <visual>
    <origin rpy="0 0 0" xyz="-0.0741 -0.070485 -0.027613"/>
    <geometry>
      <mesh filename="package://quadruped_description/meshes/leg_parallel_plate_v1_3.stl" scale="0.001 0.001 0.001"/>
    </geometry>
    <material name="silver"/>
  </visual>
  <collision>
    <origin rpy="0 0 0" xyz="-0.0741 -0.070485 -0.027613"/>
    <geometry>
      <mesh filename="package://quadruped_description/meshes/leg_parallel_plate_v1_3.stl" scale="0.001 0.001 0.001"/>
    </geometry>
  </collision>
</link>

<link name="leg_rev_v1_3">
  <inertial>
    <origin rpy="0 0 0" xyz="0.001769442285438086 -0.0003588334889571415 -0.024911562747246034"/>
    <mass value="0.004982233978749814"/>
    <inertia ixx="3e-06" ixy="-0.0" ixz="0.0" iyy="3e-06" iyz="0.0" izz="0.0"/>
  </inertial>
  <visual>
    <origin rpy="0 0 0" xyz="-0.091517 -0.08913 -0.027613"/>
    <geometry>
      <mesh filename="package://quadruped_description/meshes/leg_rev_v1_3.stl" scale="0.001 0.001 0.001"/>
    </geometry>
    <material name="silver"/>
  </visual>
  <collision>
    <origin rpy="0 0 0" xyz="-0.091517 -0.08913 -0.027613"/>
    <geometry>
      <mesh filename="package://quadruped_description/meshes/leg_rev_v1_3.stl" scale="0.001 0.001 0.001"/>
    </geometry>
  </collision>
</link>

<link name="leg_parallel_plate_v1_4">
  <inertial>
    <origin rpy="0 0 0" xyz="-0.007249024040715729 0.004994989228814459 -0.008862189989220778"/>
    <mass value="0.014417433544657021"/>
    <inertia ixx="2e-06" ixy="0.0" ixz="-0.0" iyy="2e-06" iyz="0.0" izz="1e-06"/>
  </inertial>
  <visual>
    <origin rpy="0 0 0" xyz="-0.068887 0.072502 -0.027613"/>
    <geometry>
      <mesh filename="package://quadruped_description/meshes/leg_parallel_plate_v1_4.stl" scale="0.001 0.001 0.001"/>
    </geometry>
    <material name="silver"/>
  </visual>
  <collision>
    <origin rpy="0 0 0" xyz="-0.068887 0.072502 -0.027613"/>
    <geometry>
      <mesh filename="package://quadruped_description/meshes/leg_parallel_plate_v1_4.stl" scale="0.001 0.001 0.001"/>
    </geometry>
  </collision>
</link>

<link name="leg_rev_v1_4">
  <inertial>
    <origin rpy="0 0 0" xyz="-0.00035824922912221224 -0.0017692270054057851 -0.02491157673912115"/>
    <mass value="0.004982233978749814"/>
    <inertia ixx="3e-06" ixy="0.0" ixz="0.0" iyy="3e-06" iyz="-0.0" izz="0.0"/>
  </inertial>
  <visual>
    <origin rpy="0 0 0" xyz="-0.087532 0.08992 -0.027707"/>
    <geometry>
      <mesh filename="package://quadruped_description/meshes/leg_rev_v1_4.stl" scale="0.001 0.001 0.001"/>
    </geometry>
    <material name="silver"/>
  </visual>
  <collision>
    <origin rpy="0 0 0" xyz="-0.087532 0.08992 -0.027707"/>
    <geometry>
      <mesh filename="package://quadruped_description/meshes/leg_rev_v1_4.stl" scale="0.001 0.001 0.001"/>
    </geometry>
  </collision>
</link>

<joint name="Rigid1" type="fixed">
  <origin rpy="0 0 0" xyz="0.0 0.044629 0.00924"/>
  <parent link="base_link"/>
  <child link="body_spacer_v1_1"/>
</joint>

<joint name="Rigid2" type="fixed">
  <origin rpy="0 0 0" xyz="0.0 -0.041434 0.00924"/>
  <parent link="base_link"/>
  <child link="body_spacer_v1_2"/>
</joint>

<joint name="Rigid3" type="fixed">
  <origin rpy="0 0 0" xyz="0.043031 0.001598 0.00924"/>
  <parent link="base_link"/>
  <child link="body_spacer_v1_3"/>
</joint>

<joint name="Rigid4" type="fixed">
  <origin rpy="0 0 0" xyz="-0.043031 0.001598 0.00924"/>
  <parent link="base_link"/>
  <child link="body_spacer_v1_4"/>
</joint>

<joint name="Rigid5" type="fixed">
  <origin rpy="0 0 0" xyz="-1e-05 0.001603 0.020715"/>
  <parent link="base_link"/>
  <child link="body_top_plate_v1_1"/>
</joint>

<joint name="servo_body_1" type="fixed">
  <origin rpy="0 0 0" xyz="-0.045406 -0.043805 0.038004"/>
  <parent link="base_link"/>
  <child link="servo_motor_v1_1"/>
</joint>

<joint name="servo_body_2" type="fixed">
  <origin rpy="0 0 0" xyz="-0.045406 0.04688 0.038004"/>
  <parent link="base_link"/>
  <child link="servo_motor_v1_2"/>
</joint>

<joint name="servo_body_3" type="fixed">
  <origin rpy="0 0 0" xyz="0.045406 0.047003 0.038004"/>
  <parent link="base_link"/>
  <child link="servo_motor_v1_3"/>
</joint>

<joint name="servo_body_4" type="fixed">
  <origin rpy="0 0 0" xyz="0.045406 -0.043808 0.038004"/>
  <parent link="base_link"/>
  <child link="servo_motor_v1_4"/>
</joint>

<joint name="Rigid10" type="fixed">
  <origin rpy="0 0 0" xyz="0.012081 0.012081 -0.00932"/>
  <parent link="servo_motor_v1_1"/>
  <child link="leg_servo_retainer_v1_1"/>
</joint>

<joint name="Rigid11" type="fixed">
  <origin rpy="0 0 0" xyz="0.012081 -0.012081 -0.00932"/>
  <parent link="servo_motor_v1_2"/>
  <child link="leg_servo_retainer_v1_2"/>
</joint>

<joint name="Rigid12" type="fixed">
  <origin rpy="0 0 0" xyz="-0.012081 -0.012081 -0.00932"/>
  <parent link="servo_motor_v1_3"/>
  <child link="leg_servo_retainer_v1_3"/>
</joint>

<joint name="Rigid13" type="fixed">
  <origin rpy="0 0 0" xyz="-0.012081 0.012081 -0.00932"/>
  <parent link="servo_motor_v1_4"/>
  <child link="leg_servo_retainer_v1_4"/>
</joint>

<joint name="leg_drive_1" type="revolute">
  <origin rpy="0 0 0" xyz="0.0 0.0 0.0"/>
  <parent link="servo_motor_v1_1"/>
  <child link="leg_top_pivot_plate_v1_1"/>
  <axis xyz="-0.0 -0.0 1.0"/>
  <limit effort="100" lower="-1.570796" upper="1.570796" velocity="100"/>
</joint>

<joint name="leg_drive_2" type="revolute">
  <origin rpy="0 0 0" xyz="0.0 0.0 0.0"/>
  <parent link="servo_motor_v1_2"/>
  <child link="leg_top_pivot_plate_v1_2"/>
  <axis xyz="-0.0 -0.0 1.0"/>
  <limit effort="100" lower="-1.570796" upper="1.570796" velocity="100"/>
</joint>

<joint name="leg_drive_3" type="revolute">
  <origin rpy="0 0 0" xyz="0.0 0.0 0.0"/>
  <parent link="servo_motor_v1_3"/>
  <child link="leg_top_pivot_plate_v1_3"/>
  <axis xyz="-0.0 -0.0 1.0"/>
  <limit effort="100" lower="-1.570796" upper="1.570796" velocity="100"/>
</joint>

<joint name="leg_drive_4" type="revolute">
  <origin rpy="0 0 0" xyz="0.0 0.0 0.0"/>
  <parent link="servo_motor_v1_4"/>
  <child link="leg_top_pivot_plate_v1_4"/>
  <axis xyz="-0.0 -0.0 1.0"/>
  <limit effort="100" lower="-1.570796" upper="1.570796" velocity="100"/>
</joint>

<joint name="Rigid18" type="fixed">
  <origin rpy="0 0 0" xyz="-0.012883 -0.02208 -0.011475"/>
  <parent link="leg_top_pivot_plate_v1_1"/>
  <child link="leg_servo_mount_v1_1"/>
</joint>

<joint name="Rigid19" type="fixed">
  <origin rpy="0 0 0" xyz="-0.022079 0.012884 -0.011475"/>
  <parent link="leg_top_pivot_plate_v1_2"/>
  <child link="leg_servo_mount_v1_2"/>
</joint>

<joint name="Rigid20" type="fixed">
  <origin rpy="0 0 0" xyz="0.012883 0.02208 -0.011475"/>
  <parent link="leg_top_pivot_plate_v1_3"/>
  <child link="leg_servo_mount_v1_3"/>
</joint>

<joint name="Rigid21" type="fixed">
  <origin rpy="0 0 0" xyz="0.022079 -0.012884 -0.011475"/>
  <parent link="leg_top_pivot_plate_v1_4"/>
  <child link="leg_servo_mount_v1_4"/>
</joint>

<joint name="Rigid22" type="fixed">
  <origin rpy="0 0 0" xyz="-0.008619 -0.008619 0.000433"/>
  <parent link="leg_servo_mount_v1_1"/>
  <child link="servo_motor_v1_5"/>
</joint>

<joint name="Rigid23" type="fixed">
  <origin rpy="0 0 0" xyz="-0.008619 0.008619 0.000433"/>
  <parent link="leg_servo_mount_v1_2"/>
  <child link="servo_motor_v1_6"/>
</joint>

<joint name="Rigid24" type="fixed">
  <origin rpy="0 0 0" xyz="0.008619 0.008619 0.000433"/>
  <parent link="leg_servo_mount_v1_3"/>
  <child link="servo_motor_v1_7"/>
</joint>

<joint name="Rigid25" type="fixed">
  <origin rpy="0 0 0" xyz="0.008619 -0.008619 0.000433"/>
  <parent link="leg_servo_mount_v1_4"/>
  <child link="servo_motor_v1_8"/>
</joint>

<joint name="knee_drive_1" type="revolute">
  <origin rpy="0 0 0" xyz="-0.006591 0.006591 -0.017085"/>
  <parent link="servo_motor_v1_5"/>
  <child link="leg_servo_arm_v1_1"/>
  <axis xyz="-0.707105 0.707108 -0.0"/>
  <limit effort="100" lower="-0.959931" upper="0.959931" velocity="100"/>
</joint>

<joint name="knee_drive_2" type="revolute">
  <origin rpy="0 0 0" xyz="0.00659 0.00659 -0.017085"/>
  <parent link="servo_motor_v1_6"/>
  <child link="leg_servo_arm_v1_2"/>
  <axis xyz="0.707108 0.707105 0.0"/>
  <limit effort="100" lower="-0.959931" upper="0.959931" velocity="100"/>
</joint>

<joint name="knee_drive_3" type="revolute">
  <origin rpy="0 0 0" xyz="0.006591 -0.006591 -0.017085"/>
  <parent link="servo_motor_v1_7"/>
  <child link="leg_servo_arm_v1_3"/>
  <axis xyz="0.707105 -0.707109 0.0"/>
  <limit effort="100" lower="-0.959931" upper="0.959931" velocity="100"/>
</joint>

<joint name="knee_drive_4" type="revolute">
  <origin rpy="0 0 0" xyz="-0.006591 -0.00659 -0.017085"/>
  <parent link="servo_motor_v1_8"/>
  <child link="leg_servo_arm_v1_4"/>
  <axis xyz="-0.70711 -0.707103 0.0"/>
  <limit effort="100" lower="-0.959931" upper="0.959931" velocity="100"/>
</joint>

<joint name="leg_rev_free_1" type="continuous">
  <origin rpy="0 0 0" xyz="-0.018018 -0.018019 0.017815"/>
  <parent link="leg_servo_arm_v1_1"/>
  <child link="leg_rev_v1_1"/>
  <axis xyz="0.707105 -0.707108 0.0"/>
</joint>

<joint name="leg_rev_free_2" type="continuous">
  <origin rpy="0 0 0" xyz="-0.018018 0.018019 0.017736"/>
  <parent link="leg_servo_arm_v1_2"/>
  <child link="leg_rev_v1_2"/>
  <axis xyz="0.707108 0.707105 0.0"/>
</joint>

<joint name="leg_rev_free_3" type="continuous">
  <origin rpy="0 0 0" xyz="0.018018 0.018019 0.017736"/>
  <parent link="leg_servo_arm_v1_3"/>
  <child link="leg_rev_v1_3"/>
  <axis xyz="0.707105 -0.707109 0.0"/>
</joint>

<joint name="leg_rev_free_4" type="continuous">
  <origin rpy="0 0 0" xyz="0.018019 -0.018019 0.01783"/>
  <parent link="leg_servo_arm_v1_4"/>
  <child link="leg_rev_v1_4"/>
  <axis xyz="0.70711 0.707103 -0.0"/>
</joint>

<joint name="leg_rev_free_5" type="continuous">
  <origin rpy="0 0 0" xyz="0.018031 0.018031 -7.9e-05"/>
  <parent link="leg_rev_v1_1"/>
  <child link="leg_parallel_linkage_v1_1"/>
  <axis xyz="-0.707105 0.707108 -0.0"/>
</joint>

<joint name="leg_rev_free_6" type="continuous">
  <origin rpy="0 0 0" xyz="0.018031 -0.018031 0.0"/>
  <parent link="leg_rev_v1_2"/>
  <child link="leg_parallel_linkage_v1_2"/>
  <axis xyz="0.707108 0.707105 0.0"/>
</joint>

<joint name="leg_rev_free_7" type="continuous">
  <origin rpy="0 0 0" xyz="-0.018031 -0.018031 0.0"/>
  <parent link="leg_rev_v1_3"/>
  <child link="leg_parallel_linkage_v1_3"/>
  <axis xyz="0.707105 -0.707109 0.0"/>
</joint>

<joint name="leg_rev_free_8" type="continuous">
  <origin rpy="0 0 0" xyz="-0.018031 0.018032 -9.4e-05"/>
  <parent link="leg_rev_v1_4"/>
  <child link="leg_parallel_linkage_v1_4"/>
  <axis xyz="-0.70711 -0.707103 0.0"/>
</joint>

<joint name="body_leg_free_1" type="continuous">
  <origin rpy="0 0 0" xyz="-0.045406 -0.043805 -0.001598"/>
  <parent link="base_link"/>
  <child link="bottom_pivot_plate_v1_1"/>
  <axis xyz="-0.0 -0.0 1.0"/>
</joint>

<joint name="body_leg_free_2" type="continuous">
  <origin rpy="0 0 0" xyz="-0.045406 0.04688 -0.001598"/>
  <parent link="base_link"/>
  <child link="bottom_pivot_plate_v1_2"/>
  <axis xyz="-0.0 -0.0 1.0"/>
</joint>

<joint name="body_leg_free_3" type="continuous">
  <origin rpy="0 0 0" xyz="0.045406 0.047003 -0.001598"/>
  <parent link="base_link"/>
  <child link="bottom_pivot_plate_v1_3"/>
  <axis xyz="-0.0 -0.0 1.0"/>
</joint>

<joint name="body_leg_free_4" type="continuous">
  <origin rpy="0 0 0" xyz="0.045406 -0.043808 -0.001598"/>
  <parent link="base_link"/>
  <child link="bottom_pivot_plate_v1_4"/>
  <axis xyz="-0.0 -0.0 1.0"/>
</joint>

<joint name="Rigid42" type="fixed">
  <origin rpy="0 0 0" xyz="-0.028694 -0.023482 0.029211"/>
  <parent link="bottom_pivot_plate_v1_1"/>
  <child link="leg_parallel_plate_v1_1"/>
</joint>

<joint name="Rigid43" type="fixed">
  <origin rpy="0 0 0" xyz="-0.023481 0.028694 0.029211"/>
  <parent link="bottom_pivot_plate_v1_2"/>
  <child link="leg_parallel_plate_v1_2"/>
</joint>

<joint name="Rigid44" type="fixed">
  <origin rpy="0 0 0" xyz="0.028694 0.023482 0.029211"/>
  <parent link="bottom_pivot_plate_v1_3"/>
  <child link="leg_parallel_plate_v1_3"/>
</joint>

<joint name="Rigid45" type="fixed">
  <origin rpy="0 0 0" xyz="0.023481 -0.028694 0.029211"/>
  <parent link="bottom_pivot_plate_v1_4"/>
  <child link="leg_parallel_plate_v1_4"/>
</joint>

<joint name="leg_rev_free_9" type="Ball">
  <origin rpy="0 0 0" xyz="0.000614 -0.000614 0.0"/>
  <parent link="leg_parallel_plate_v1_1"/>
  <child link="leg_parallel_linkage_v1_1"/>
</joint>

<joint name="leg_rev_free_10" type="Ball">
  <origin rpy="0 0 0" xyz="-0.000614 -0.000613 0.0"/>
  <parent link="leg_parallel_plate_v1_2"/>
  <child link="leg_parallel_linkage_v1_2"/>
</joint>

<joint name="leg_rev_free_11" type="Ball">
  <origin rpy="0 0 0" xyz="-0.000614 0.000614 0.0"/>
  <parent link="leg_parallel_plate_v1_3"/>
  <child link="leg_parallel_linkage_v1_3"/>
</joint>

<joint name="leg_rev_free_12" type="Ball">
  <origin rpy="0 0 0" xyz="0.000614 0.000614 0.0"/>
  <parent link="leg_parallel_plate_v1_4"/>
  <child link="leg_parallel_linkage_v1_4"/>
</joint>

<joint name="Rev59" type="continuous">
  <origin rpy="0 0 0" xyz="-0.000614 0.000614 0.0"/>
  <parent link="leg_parallel_linkage_v1_1"/>
  <child link="leg_parallel_plate_v1_1"/>
  <axis xyz="0.707105 -0.707108 0.0"/>
</joint>

<joint name="Rev67" type="continuous">
  <origin rpy="0 0 0" xyz="0.000614 0.000613 0.0"/>
  <parent link="leg_parallel_linkage_v1_2"/>
  <child link="leg_parallel_plate_v1_2"/>
  <axis xyz="0.707108 0.707105 0.0"/>
</joint>

<joint name="Rev68" type="continuous">
  <origin rpy="0 0 0" xyz="-0.018031 -0.018031 7.9e-05"/>
  <parent link="leg_parallel_linkage_v1_1"/>
  <child link="leg_rev_v1_1"/>
  <axis xyz="-0.707105 0.707108 -0.0"/>
</joint>

<joint name="Rev69" type="continuous">
  <origin rpy="0 0 0" xyz="-0.018031 0.018031 0.0"/>
  <parent link="leg_parallel_linkage_v1_2"/>
  <child link="leg_rev_v1_2"/>
  <axis xyz="-0.707108 -0.707105 -0.0"/>
</joint>

<joint name="Rev70" type="continuous">
  <origin rpy="0 0 0" xyz="0.000614 -0.000614 0.0"/>
  <parent link="leg_parallel_linkage_v1_3"/>
  <child link="leg_parallel_plate_v1_3"/>
  <axis xyz="-0.707105 0.707109 -0.0"/>
</joint>

<joint name="Rev71" type="continuous">
  <origin rpy="0 0 0" xyz="0.018031 0.018031 0.0"/>
  <parent link="leg_parallel_linkage_v1_3"/>
  <child link="leg_rev_v1_3"/>
  <axis xyz="0.707105 -0.707109 0.0"/>
</joint>

<joint name="Rev72" type="continuous">
  <origin rpy="0 0 0" xyz="-0.000614 -0.000614 0.0"/>
  <parent link="leg_parallel_linkage_v1_4"/>
  <child link="leg_parallel_plate_v1_4"/>
  <axis xyz="-0.70711 -0.707103 0.0"/>
</joint>

<joint name="Rev73" type="continuous">
  <origin rpy="0 0 0" xyz="0.018031 -0.018032 9.4e-05"/>
  <parent link="leg_parallel_linkage_v1_4"/>
  <child link="leg_rev_v1_4"/>
  <axis xyz="0.70711 0.707103 -0.0"/>
</joint>

</robot>
