<?xml version="1.0" ?>
<robot name="quadruped" xmlns:xacro="http://www.ros.org/wiki/xacro">

<xacro:include filename="$(find quadruped_description)/urdf/materials.xacro" />
<xacro:include filename="$(find quadruped_description)/urdf/quadruped.trans" />
<xacro:include filename="$(find quadruped_description)/urdf/quadruped.gazebo" />
<link name="base_link">
  <inertial>
    <origin rpy="0 0 0" xyz="9.059146598178436e-07 0.0015934023756066268 -3.844423505793004e-06"/>
    <mass value="0.1660035395213305"/>
    <inertia ixx="0.000257" ixy="0.0" ixz="0.0" iyy="0.000257" iyz="-0.0" izz="0.000514"/>
  </inertial>
  <visual>
    <origin rpy="0 0 0" xyz="0 0 0"/>
    <geometry>
      <mesh filename="package://quadruped_description/meshes/base_link.stl" scale="0.001 0.001 0.001"/>
    </geometry>
    <material name="silver"/>
  </visual>
  <collision>
    <origin rpy="0 0 0" xyz="0 0 0"/>
    <geometry>
      <mesh filename="package://quadruped_description/meshes/base_link.stl" scale="0.001 0.001 0.001"/>
    </geometry>
  </collision>
</link>

<link name="body_spacer_v1_1">
  <inertial>
    <origin rpy="0 0 0" xyz="2.7755575615628914e-19 3.4442350579921843e-07 0.0019124056524901113"/>
    <mass value="0.01987438429408557"/>
    <inertia ixx="1e-06" ixy="-0.0" ixz="0.0" iyy="4e-06" iyz="0.0" izz="3e-06"/>
  </inertial>
  <visual>
    <origin rpy="0 0 0" xyz="-0.0 0.041434 -0.00924"/>
    <geometry>
      <mesh filename="package://quadruped_description/meshes/body_spacer_v1_1.stl" scale="0.001 0.001 0.001"/>
    </geometry>
    <material name="silver"/>
  </visual>
  <collision>
    <origin rpy="0 0 0" xyz="-0.0 0.041434 -0.00924"/>
    <geometry>
      <mesh filename="package://quadruped_description/meshes/body_spacer_v1_1.stl" scale="0.001 0.001 0.001"/>
    </geometry>
  </collision>
</link>

<link name="body_spacer_v1_2">
  <inertial>
    <origin rpy="0 0 0" xyz="-6.938893903907229e-19 -1.555764942082205e-07 0.001912405652490139"/>
    <mass value="0.01987438429408557"/>
    <inertia ixx="1e-06" ixy="-0.0" ixz="0.0" iyy="4e-06" iyz="0.0" izz="3e-06"/>
  </inertial>
  <visual>
    <origin rpy="0 0 0" xyz="0.0 -0.044629 -0.00924"/>
    <geometry>
      <mesh filename="package://quadruped_description/meshes/body_spacer_v1_2.stl" scale="0.001 0.001 0.001"/>
    </geometry>
    <material name="silver"/>
  </visual>
  <collision>
    <origin rpy="0 0 0" xyz="0.0 -0.044629 -0.00924"/>
    <geometry>
      <mesh filename="package://quadruped_description/meshes/body_spacer_v1_2.stl" scale="0.001 0.001 0.001"/>
    </geometry>
  </collision>
</link>

<link name="body_spacer_v1_3">
  <inertial>
    <origin rpy="0 0 0" xyz="-2.4999999999331113e-07 -4.0557649421128945e-07 0.0019124056524901182"/>
    <mass value="0.01987438429408557"/>
    <inertia ixx="4e-06" ixy="0.0" ixz="0.0" iyy="1e-06" iyz="-0.0" izz="3e-06"/>
  </inertial>
  <visual>
    <origin rpy="0 0 0" xyz="0.043031 -0.001598 -0.00924"/>
    <geometry>
      <mesh filename="package://quadruped_description/meshes/body_spacer_v1_3.stl" scale="0.001 0.001 0.001"/>
    </geometry>
    <material name="silver"/>
  </visual>
  <collision>
    <origin rpy="0 0 0" xyz="0.043031 -0.001598 -0.00924"/>
    <geometry>
      <mesh filename="package://quadruped_description/meshes/body_spacer_v1_3.stl" scale="0.001 0.001 0.001"/>
    </geometry>
  </collision>
</link>

<link name="body_spacer_v1_4">
  <inertial>
    <origin rpy="0 0 0" xyz="2.4999999999331113e-07 -4.0557649421020525e-07 0.0019124056524901182"/>
    <mass value="0.01987438429408557"/>
    <inertia ixx="4e-06" ixy="0.0" ixz="0.0" iyy="1e-06" iyz="-0.0" izz="3e-06"/>
  </inertial>
  <visual>
    <origin rpy="0 0 0" xyz="-0.043031 -0.001598 -0.00924"/>
    <geometry>
      <mesh filename="package://quadruped_description/meshes/body_spacer_v1_4.stl" scale="0.001 0.001 0.001"/>
    </geometry>
    <material name="silver"/>
  </visual>
  <collision>
    <origin rpy="0 0 0" xyz="-0.043031 -0.001598 -0.00924"/>
    <geometry>
      <mesh filename="package://quadruped_description/meshes/body_spacer_v1_4.stl" scale="0.001 0.001 0.001"/>
    </geometry>
  </collision>
</link>

<link name="body_top_plate_v1_1">
  <inertial>
    <origin rpy="0 0 0" xyz="-6.217287019302714e-06 -7.919011395236646e-07 -0.0015933444235057825"/>
    <mass value="0.2442521638475155"/>
    <inertia ixx="0.000246" ixy="-0.0" ixz="0.0" iyy="0.000236" iyz="-0.0" izz="0.000482"/>
  </inertial>
  <visual>
    <origin rpy="0 0 0" xyz="1e-05 -0.001603 -0.023902"/>
    <geometry>
      <mesh filename="package://quadruped_description/meshes/body_top_plate_v1_1.stl" scale="0.001 0.001 0.001"/>
    </geometry>
    <material name="silver"/>
  </visual>
  <collision>
    <origin rpy="0 0 0" xyz="1e-05 -0.001603 -0.023902"/>
    <geometry>
      <mesh filename="package://quadruped_description/meshes/body_top_plate_v1_1.stl" scale="0.001 0.001 0.001"/>
    </geometry>
  </collision>
</link>

<link name="servo_motor_v1_1">
  <inertial>
    <origin rpy="0 0 0" xyz="-0.0034453069163115357 -0.003444709272821221 -0.01729151089746925"/>
    <mass value="0.008039754705757893"/>
    <inertia ixx="1e-06" ixy="-0.0" ixz="-0.0" iyy="1e-06" iyz="-0.0" izz="1e-06"/>
  </inertial>
  <visual>
    <origin rpy="0 0 0" xyz="-0.045406 -0.047003 -0.038004"/>
    <geometry>
      <mesh filename="package://quadruped_description/meshes/servo_motor_v1_1.stl" scale="0.001 0.001 0.001"/>
    </geometry>
    <material name="silver"/>
  </visual>
  <collision>
    <origin rpy="0 0 0" xyz="-0.045406 -0.047003 -0.038004"/>
    <geometry>
      <mesh filename="package://quadruped_description/meshes/servo_motor_v1_1.stl" scale="0.001 0.001 0.001"/>
    </geometry>
  </collision>
</link>

<link name="servo_motor_v1_2">
  <inertial>
    <origin rpy="0 0 0" xyz="0.00344528207956777 0.003444743371777498 -0.01729151089746927"/>
    <mass value="0.008039754705757893"/>
    <inertia ixx="1e-06" ixy="-0.0" ixz="0.0" iyy="1e-06" iyz="0.0" izz="1e-06"/>
  </inertial>
  <visual>
    <origin rpy="0 0 0" xyz="0.045406 0.043805 -0.038004"/>
    <geometry>
      <mesh filename="package://quadruped_description/meshes/servo_motor_v1_2.stl" scale="0.001 0.001 0.001"/>
    </geometry>
    <material name="silver"/>
  </visual>
  <collision>
    <origin rpy="0 0 0" xyz="0.045406 0.043805 -0.038004"/>
    <geometry>
      <mesh filename="package://quadruped_description/meshes/servo_motor_v1_2.stl" scale="0.001 0.001 0.001"/>
    </geometry>
  </collision>
</link>

<link name="servo_motor_v1_3">
  <inertial>
    <origin rpy="0 0 0" xyz="-0.003445306736163896 0.0034448982999804242 -0.017291510897469293"/>
    <mass value="0.008039754705757893"/>
    <inertia ixx="1e-06" ixy="0.0" ixz="-0.0" iyy="1e-06" iyz="0.0" izz="1e-06"/>
  </inertial>
  <visual>
    <origin rpy="0 0 0" xyz="-0.045406 0.043808 -0.038004"/>
    <geometry>
      <mesh filename="package://quadruped_description/meshes/servo_motor_v1_3.stl" scale="0.001 0.001 0.001"/>
    </geometry>
    <material name="silver"/>
  </visual>
  <collision>
    <origin rpy="0 0 0" xyz="-0.045406 0.043808 -0.038004"/>
    <geometry>
      <mesh filename="package://quadruped_description/meshes/servo_motor_v1_3.stl" scale="0.001 0.001 0.001"/>
    </geometry>
  </collision>
</link>

<link name="servo_motor_v1_4">
  <inertial>
    <origin rpy="0 0 0" xyz="0.003445281899420151 -0.0034447266622682007 -0.01729151089746927"/>
    <mass value="0.008039754705757893"/>
    <inertia ixx="1e-06" ixy="0.0" ixz="0.0" iyy="1e-06" iyz="-0.0" izz="1e-06"/>
  </inertial>
  <visual>
    <origin rpy="0 0 0" xyz="0.045406 -0.04688 -0.038004"/>
    <geometry>
      <mesh filename="package://quadruped_description/meshes/servo_motor_v1_4.stl" scale="0.001 0.001 0.001"/>
    </geometry>
    <material name="silver"/>
  </visual>
  <collision>
    <origin rpy="0 0 0" xyz="0.045406 -0.04688 -0.038004"/>
    <geometry>
      <mesh filename="package://quadruped_description/meshes/servo_motor_v1_4.stl" scale="0.001 0.001 0.001"/>
    </geometry>
  </collision>
</link>

<link name="leg_servo_retainer_v1_1">
  <inertial>
    <origin rpy="0 0 0" xyz="0.007924108380789871 0.007923419580222739 -3.444235058061573e-07"/>
    <mass value="0.011735752466802122"/>
    <inertia ixx="1e-06" ixy="-0.0" ixz="-0.0" iyy="1e-06" iyz="0.0" izz="2e-06"/>
  </inertial>
  <visual>
    <origin rpy="0 0 0" xyz="-0.033325 -0.034922 -0.028684"/>
    <geometry>
      <mesh filename="package://quadruped_description/meshes/leg_servo_retainer_v1_1.stl" scale="0.001 0.001 0.001"/>
    </geometry>
    <material name="silver"/>
  </visual>
  <collision>
    <origin rpy="0 0 0" xyz="-0.033325 -0.034922 -0.028684"/>
    <geometry>
      <mesh filename="package://quadruped_description/meshes/leg_servo_retainer_v1_1.stl" scale="0.001 0.001 0.001"/>
    </geometry>
  </collision>
</link>

<link name="leg_servo_retainer_v1_2">
  <inertial>
    <origin rpy="0 0 0" xyz="-0.007924133217533623 -0.007923385481266518 -3.4442350583044345e-07"/>
    <mass value="0.011735752466802122"/>
    <inertia ixx="1e-06" ixy="-0.0" ixz="-0.0" iyy="1e-06" iyz="-0.0" izz="2e-06"/>
  </inertial>
  <visual>
    <origin rpy="0 0 0" xyz="0.033325 0.031724 -0.028684"/>
    <geometry>
      <mesh filename="package://quadruped_description/meshes/leg_servo_retainer_v1_2.stl" scale="0.001 0.001 0.001"/>
    </geometry>
    <material name="silver"/>
  </visual>
  <collision>
    <origin rpy="0 0 0" xyz="0.033325 0.031724 -0.028684"/>
    <geometry>
      <mesh filename="package://quadruped_description/meshes/leg_servo_retainer_v1_2.stl" scale="0.001 0.001 0.001"/>
    </geometry>
  </collision>
</link>

<link name="leg_servo_retainer_v1_3">
  <inertial>
    <origin rpy="0 0 0" xyz="0.007922822116880057 -0.00792451699712099 -3.444235058547296e-07"/>
    <mass value="0.011735752466802122"/>
    <inertia ixx="1e-06" ixy="0.0" ixz="-0.0" iyy="1e-06" iyz="0.0" izz="2e-06"/>
  </inertial>
  <visual>
    <origin rpy="0 0 0" xyz="-0.033325 0.031727 -0.028684"/>
    <geometry>
      <mesh filename="package://quadruped_description/meshes/leg_servo_retainer_v1_3.stl" scale="0.001 0.001 0.001"/>
    </geometry>
    <material name="silver"/>
  </visual>
  <collision>
    <origin rpy="0 0 0" xyz="-0.033325 0.031727 -0.028684"/>
    <geometry>
      <mesh filename="package://quadruped_description/meshes/leg_servo_retainer_v1_3.stl" scale="0.001 0.001 0.001"/>
    </geometry>
  </collision>
</link>

<link name="leg_servo_retainer_v1_4">
  <inertial>
    <origin rpy="0 0 0" xyz="-0.007922846953623781 0.007924688634833164 -3.444235058130962e-07"/>
    <mass value="0.011735752466802122"/>
    <inertia ixx="1e-06" ixy="0.0" ixz="0.0" iyy="1e-06" iyz="-0.0" izz="2e-06"/>
  </inertial>
  <visual>
    <origin rpy="0 0 0" xyz="0.033325 -0.034799 -0.028684"/>
    <geometry>
      <mesh filename="package://quadruped_description/meshes/leg_servo_retainer_v1_4.stl" scale="0.001 0.001 0.001"/>
    </geometry>
    <material name="silver"/>
  </visual>
  <collision>
    <origin rpy="0 0 0" xyz="0.033325 -0.034799 -0.028684"/>
    <geometry>
      <mesh filename="package://quadruped_description/meshes/leg_servo_retainer_v1_4.stl" scale="0.001 0.001 0.001"/>
    </geometry>
  </collision>
</link>

<link name="leg_top_pivot_plate_v1_1">
  <inertial>
    <origin rpy="0 0 0" xyz="0.010648424399168688 0.010577698071700989 -0.0015938444235058177"/>
    <mass value="0.020723046160568363"/>
    <inertia ixx="2e-06" ixy="-1e-06" ixz="0.0" iyy="2e-06" iyz="0.0" izz="4e-06"/>
  </inertial>
  <visual>
    <origin rpy="0 0 0" xyz="-0.045406 -0.047003 -0.038004"/>
    <geometry>
      <mesh filename="package://quadruped_description/meshes/leg_top_pivot_plate_v1_1.stl" scale="0.001 0.001 0.001"/>
    </geometry>
    <material name="silver"/>
  </visual>
  <collision>
    <origin rpy="0 0 0" xyz="-0.045406 -0.047003 -0.038004"/>
    <geometry>
      <mesh filename="package://quadruped_description/meshes/leg_top_pivot_plate_v1_1.stl" scale="0.001 0.001 0.001"/>
    </geometry>
  </collision>
</link>

<link name="leg_top_pivot_plate_v1_2">
  <inertial>
    <origin rpy="0 0 0" xyz="-0.010648449235912509 -0.010577663972744698 -0.0015938444235058594"/>
    <mass value="0.020723046160568363"/>
    <inertia ixx="2e-06" ixy="-1e-06" ixz="0.0" iyy="2e-06" iyz="0.0" izz="4e-06"/>
  </inertial>
  <visual>
    <origin rpy="0 0 0" xyz="0.045406 0.043805 -0.038004"/>
    <geometry>
      <mesh filename="package://quadruped_description/meshes/leg_top_pivot_plate_v1_2.stl" scale="0.001 0.001 0.001"/>
    </geometry>
    <material name="silver"/>
  </visual>
  <collision>
    <origin rpy="0 0 0" xyz="0.045406 0.043805 -0.038004"/>
    <geometry>
      <mesh filename="package://quadruped_description/meshes/leg_top_pivot_plate_v1_2.stl" scale="0.001 0.001 0.001"/>
    </geometry>
  </collision>
</link>

<link name="leg_top_pivot_plate_v1_3">
  <inertial>
    <origin rpy="0 0 0" xyz="0.010577100608358356 -0.010648833015499792 -0.0015938444235058871"/>
    <mass value="0.020723046160568363"/>
    <inertia ixx="2e-06" ixy="1e-06" ixz="0.0" iyy="2e-06" iyz="-0.0" izz="4e-06"/>
  </inertial>
  <visual>
    <origin rpy="0 0 0" xyz="-0.045406 0.043808 -0.038004"/>
    <geometry>
      <mesh filename="package://quadruped_description/meshes/leg_top_pivot_plate_v1_3.stl" scale="0.001 0.001 0.001"/>
    </geometry>
    <material name="silver"/>
  </visual>
  <collision>
    <origin rpy="0 0 0" xyz="-0.045406 0.043808 -0.038004"/>
    <geometry>
      <mesh filename="package://quadruped_description/meshes/leg_top_pivot_plate_v1_3.stl" scale="0.001 0.001 0.001"/>
    </geometry>
  </collision>
</link>

<link name="leg_top_pivot_plate_v1_4">
  <inertial>
    <origin rpy="0 0 0" xyz="-0.010577125445102108 0.010649004653212044 -0.0015938444235058385"/>
    <mass value="0.020723046160568363"/>
    <inertia ixx="2e-06" ixy="1e-06" ixz="0.0" iyy="2e-06" iyz="0.0" izz="4e-06"/>
  </inertial>
  <visual>
    <origin rpy="0 0 0" xyz="0.045406 -0.04688 -0.038004"/>
    <geometry>
      <mesh filename="package://quadruped_description/meshes/leg_top_pivot_plate_v1_4.stl" scale="0.001 0.001 0.001"/>
    </geometry>
    <material name="silver"/>
  </visual>
  <collision>
    <origin rpy="0 0 0" xyz="0.045406 -0.04688 -0.038004"/>
    <geometry>
      <mesh filename="package://quadruped_description/meshes/leg_top_pivot_plate_v1_4.stl" scale="0.001 0.001 0.001"/>
    </geometry>
  </collision>
</link>

<link name="leg_servo_mount_v1_1">
  <inertial>
    <origin rpy="0 0 0" xyz="0.006427091482037066 0.006426612462751682 -0.009351515125044133"/>
    <mass value="0.018978192167657257"/>
    <inertia ixx="3e-06" ixy="-1e-06" ixz="-0.0" iyy="3e-06" iyz="-0.0" izz="2e-06"/>
  </inertial>
  <visual>
    <origin rpy="0 0 0" xyz="-0.058289 -0.069083 -0.026529"/>
    <geometry>
      <mesh filename="package://quadruped_description/meshes/leg_servo_mount_v1_1.stl" scale="0.001 0.001 0.001"/>
    </geometry>
    <material name="silver"/>
  </visual>
  <collision>
    <origin rpy="0 0 0" xyz="-0.058289 -0.069083 -0.026529"/>
    <geometry>
      <mesh filename="package://quadruped_description/meshes/leg_servo_mount_v1_1.stl" scale="0.001 0.001 0.001"/>
    </geometry>
  </collision>
</link>

<link name="leg_servo_mount_v1_2">
  <inertial>
    <origin rpy="0 0 0" xyz="-0.0064271163187809635 -0.006426578363795399 -0.009351515125044209"/>
    <mass value="0.018978192167657257"/>
    <inertia ixx="3e-06" ixy="-1e-06" ixz="0.0" iyy="3e-06" iyz="0.0" izz="2e-06"/>
  </inertial>
  <visual>
    <origin rpy="0 0 0" xyz="0.058289 0.065885 -0.026529"/>
    <geometry>
      <mesh filename="package://quadruped_description/meshes/leg_servo_mount_v1_2.stl" scale="0.001 0.001 0.001"/>
    </geometry>
    <material name="silver"/>
  </visual>
  <collision>
    <origin rpy="0 0 0" xyz="0.058289 0.065885 -0.026529"/>
    <geometry>
      <mesh filename="package://quadruped_description/meshes/leg_servo_mount_v1_2.stl" scale="0.001 0.001 0.001"/>
    </geometry>
  </collision>
</link>

<link name="leg_servo_mount_v1_3">
  <inertial>
    <origin rpy="0 0 0" xyz="0.006427014999409009 -0.006426500098368142 -0.009351515125044268"/>
    <mass value="0.018978192167657257"/>
    <inertia ixx="3e-06" ixy="1e-06" ixz="-0.0" iyy="3e-06" iyz="0.0" izz="2e-06"/>
  </inertial>
  <visual>
    <origin rpy="0 0 0" xyz="-0.067485 0.056692 -0.026529"/>
    <geometry>
      <mesh filename="package://quadruped_description/meshes/leg_servo_mount_v1_3.stl" scale="0.001 0.001 0.001"/>
    </geometry>
    <material name="silver"/>
  </visual>
  <collision>
    <origin rpy="0 0 0" xyz="-0.067485 0.056692 -0.026529"/>
    <geometry>
      <mesh filename="package://quadruped_description/meshes/leg_servo_mount_v1_3.stl" scale="0.001 0.001 0.001"/>
    </geometry>
  </collision>
</link>

<link name="leg_servo_mount_v1_4">
  <inertial>
    <origin rpy="0 0 0" xyz="-0.0064270398361530034 0.006426671736080497 -0.009351515125044122"/>
    <mass value="0.018978192167657257"/>
    <inertia ixx="3e-06" ixy="1e-06" ixz="0.0" iyy="3e-06" iyz="-0.0" izz="2e-06"/>
  </inertial>
  <visual>
    <origin rpy="0 0 0" xyz="0.067485 -0.059764 -0.026529"/>
    <geometry>
      <mesh filename="package://quadruped_description/meshes/leg_servo_mount_v1_4.stl" scale="0.001 0.001 0.001"/>
    </geometry>
    <material name="silver"/>
  </visual>
  <collision>
    <origin rpy="0 0 0" xyz="0.067485 -0.059764 -0.026529"/>
    <geometry>
      <mesh filename="package://quadruped_description/meshes/leg_servo_mount_v1_4.stl" scale="0.001 0.001 0.001"/>
    </geometry>
  </collision>
</link>

<link name="servo_motor_v1_5">
  <inertial>
    <origin rpy="0 0 0" xyz="-0.005636344543875585 0.0056361081722518525 -0.012212864453551207"/>
    <mass value="0.008039754705757893"/>
    <inertia ixx="1e-06" ixy="0.0" ixz="0.0" iyy="1e-06" iyz="-0.0" izz="1e-06"/>
  </inertial>
  <visual>
    <origin rpy="0 0 0" xyz="-0.066908 -0.077702 -0.026962"/>
    <geometry>
      <mesh filename="package://quadruped_description/meshes/servo_motor_v1_5.stl" scale="0.001 0.001 0.001"/>
    </geometry>
    <material name="silver"/>
  </visual>
  <collision>
    <origin rpy="0 0 0" xyz="-0.066908 -0.077702 -0.026962"/>
    <geometry>
      <mesh filename="package://quadruped_description/meshes/servo_motor_v1_5.stl" scale="0.001 0.001 0.001"/>
    </geometry>
  </collision>
</link>

<link name="servo_motor_v1_6">
  <inertial>
    <origin rpy="0 0 0" xyz="0.005636319707131535 -0.005636074073295541 -0.01221286445355131"/>
    <mass value="0.008039754705757893"/>
    <inertia ixx="1e-06" ixy="0.0" ixz="-0.0" iyy="1e-06" iyz="0.0" izz="1e-06"/>
  </inertial>
  <visual>
    <origin rpy="0 0 0" xyz="0.066908 0.074504 -0.026962"/>
    <geometry>
      <mesh filename="package://quadruped_description/meshes/servo_motor_v1_6.stl" scale="0.001 0.001 0.001"/>
    </geometry>
    <material name="silver"/>
  </visual>
  <collision>
    <origin rpy="0 0 0" xyz="0.066908 0.074504 -0.026962"/>
    <geometry>
      <mesh filename="package://quadruped_description/meshes/servo_motor_v1_6.stl" scale="0.001 0.001 0.001"/>
    </geometry>
  </collision>
</link>

<link name="servo_motor_v1_7">
  <inertial>
    <origin rpy="0 0 0" xyz="0.0056365107089090954 0.0056369359275444605 -0.012212864453551344"/>
    <mass value="0.008039754705757893"/>
    <inertia ixx="1e-06" ixy="-0.0" ixz="-0.0" iyy="1e-06" iyz="-0.0" izz="1e-06"/>
  </inertial>
  <visual>
    <origin rpy="0 0 0" xyz="-0.076104 0.065311 -0.026962"/>
    <geometry>
      <mesh filename="package://quadruped_description/meshes/servo_motor_v1_7.stl" scale="0.001 0.001 0.001"/>
    </geometry>
    <material name="silver"/>
  </visual>
  <collision>
    <origin rpy="0 0 0" xyz="-0.076104 0.065311 -0.026962"/>
    <geometry>
      <mesh filename="package://quadruped_description/meshes/servo_motor_v1_7.stl" scale="0.001 0.001 0.001"/>
    </geometry>
  </collision>
</link>

<link name="servo_motor_v1_8">
  <inertial>
    <origin rpy="0 0 0" xyz="-0.005636535545653257 -0.005636764289832091 -0.012212864453551107"/>
    <mass value="0.008039754705757893"/>
    <inertia ixx="1e-06" ixy="-0.0" ixz="0.0" iyy="1e-06" iyz="0.0" izz="1e-06"/>
  </inertial>
  <visual>
    <origin rpy="0 0 0" xyz="0.076104 -0.068383 -0.026962"/>
    <geometry>
      <mesh filename="package://quadruped_description/meshes/servo_motor_v1_8.stl" scale="0.001 0.001 0.001"/>
    </geometry>
    <material name="silver"/>
  </visual>
  <collision>
    <origin rpy="0 0 0" xyz="0.076104 -0.068383 -0.026962"/>
    <geometry>
      <mesh filename="package://quadruped_description/meshes/servo_motor_v1_8.stl" scale="0.001 0.001 0.001"/>
    </geometry>
  </collision>
</link>

<link name="leg_servo_arm_v1_1">
  <inertial>
    <origin rpy="0 0 0" xyz="0.006854663369280561 0.009109263260319495 4.051724359632747e-07"/>
    <mass value="0.01005919143698447"/>
    <inertia ixx="1e-06" ixy="-1e-06" ixz="0.0" iyy="1e-06" iyz="0.0" izz="1e-06"/>
  </inertial>
  <visual>
    <origin rpy="0 0 0" xyz="-0.073499 -0.071111 -0.009877"/>
    <geometry>
      <mesh filename="package://quadruped_description/meshes/leg_servo_arm_v1_1.stl" scale="0.001 0.001 0.001"/>
    </geometry>
    <material name="silver"/>
  </visual>
  <collision>
    <origin rpy="0 0 0" xyz="-0.073499 -0.071111 -0.009877"/>
    <geometry>
      <mesh filename="package://quadruped_description/meshes/leg_servo_arm_v1_1.stl" scale="0.001 0.001 0.001"/>
    </geometry>
  </collision>
</link>

<link name="leg_servo_arm_v1_2">
  <inertial>
    <origin rpy="0 0 0" xyz="-0.006854688206024612 -0.009109229161363155 4.0517271572906854e-07"/>
    <mass value="0.01005919143698447"/>
    <inertia ixx="1e-06" ixy="-1e-06" ixz="0.0" iyy="1e-06" iyz="0.0" izz="1e-06"/>
  </inertial>
  <visual>
    <origin rpy="0 0 0" xyz="0.073499 0.067913 -0.009877"/>
    <geometry>
      <mesh filename="package://quadruped_description/meshes/leg_servo_arm_v1_2.stl" scale="0.001 0.001 0.001"/>
    </geometry>
    <material name="silver"/>
  </visual>
  <collision>
    <origin rpy="0 0 0" xyz="0.073499 0.067913 -0.009877"/>
    <geometry>
      <mesh filename="package://quadruped_description/meshes/leg_servo_arm_v1_2.stl" scale="0.001 0.001 0.001"/>
    </geometry>
  </collision>
</link>

<link name="leg_servo_arm_v1_3">
  <inertial>
    <origin rpy="0 0 0" xyz="0.00910866579697693 -0.0068550719856114856 4.0517271559029067e-07"/>
    <mass value="0.01005919143698447"/>
    <inertia ixx="1e-06" ixy="1e-06" ixz="-0.0" iyy="1e-06" iyz="0.0" izz="1e-06"/>
  </inertial>
  <visual>
    <origin rpy="0 0 0" xyz="-0.069514 0.071901 -0.009877"/>
    <geometry>
      <mesh filename="package://quadruped_description/meshes/leg_servo_arm_v1_3.stl" scale="0.001 0.001 0.001"/>
    </geometry>
    <material name="silver"/>
  </visual>
  <collision>
    <origin rpy="0 0 0" xyz="-0.069514 0.071901 -0.009877"/>
    <geometry>
      <mesh filename="package://quadruped_description/meshes/leg_servo_arm_v1_3.stl" scale="0.001 0.001 0.001"/>
    </geometry>
  </collision>
</link>

<link name="leg_servo_arm_v1_4">
  <inertial>
    <origin rpy="0 0 0" xyz="-0.00910869063372105 0.006855243623324084 4.051724360847053e-07"/>
    <mass value="0.01005919143698447"/>
    <inertia ixx="1e-06" ixy="1e-06" ixz="-0.0" iyy="1e-06" iyz="0.0" izz="1e-06"/>
  </inertial>
  <visual>
    <origin rpy="0 0 0" xyz="0.069514 -0.074973 -0.009877"/>
    <geometry>
      <mesh filename="package://quadruped_description/meshes/leg_servo_arm_v1_4.stl" scale="0.001 0.001 0.001"/>
    </geometry>
    <material name="silver"/>
  </visual>
  <collision>
    <origin rpy="0 0 0" xyz="0.069514 -0.074973 -0.009877"/>
    <geometry>
      <mesh filename="package://quadruped_description/meshes/leg_servo_arm_v1_4.stl" scale="0.001 0.001 0.001"/>
    </geometry>
  </collision>
</link>

<link name="leg_rev_v1_1">
  <inertial>
    <origin rpy="0 0 0" xyz="0.0017515473433343393 -0.0003754399481460252 -0.007062305223846311"/>
    <mass value="0.02607369115545735"/>
    <inertia ixx="1.5e-05" ixy="-0.0" ixz="1e-06" iyy="1.5e-05" iyz="1e-06" izz="1e-06"/>
  </inertial>
  <visual>
    <origin rpy="0 0 0" xyz="-0.09153 -0.089142 -0.009877"/>
    <geometry>
      <mesh filename="package://quadruped_description/meshes/leg_rev_v1_1.stl" scale="0.001 0.001 0.001"/>
    </geometry>
    <material name="silver"/>
  </visual>
  <collision>
    <origin rpy="0 0 0" xyz="-0.09153 -0.089142 -0.009877"/>
    <geometry>
      <mesh filename="package://quadruped_description/meshes/leg_rev_v1_1.stl" scale="0.001 0.001 0.001"/>
    </geometry>
  </collision>
</link>

<link name="leg_rev_v1_2">
  <inertial>
    <origin rpy="0 0 0" xyz="-0.0017515721800784034 0.00037547404710240595 -0.007062305223846182"/>
    <mass value="0.02607369115545735"/>
    <inertia ixx="1.5e-05" ixy="-0.0" ixz="-1e-06" iyy="1.5e-05" iyz="-1e-06" izz="1e-06"/>
  </inertial>
  <visual>
    <origin rpy="0 0 0" xyz="0.09153 0.085944 -0.009877"/>
    <geometry>
      <mesh filename="package://quadruped_description/meshes/leg_rev_v1_2.stl" scale="0.001 0.001 0.001"/>
    </geometry>
    <material name="silver"/>
  </visual>
  <collision>
    <origin rpy="0 0 0" xyz="0.09153 0.085944 -0.009877"/>
    <geometry>
      <mesh filename="package://quadruped_description/meshes/leg_rev_v1_2.stl" scale="0.001 0.001 0.001"/>
    </geometry>
  </collision>
</link>

<link name="leg_rev_v1_3">
  <inertial>
    <origin rpy="0 0 0" xyz="-0.0003760374114884779 -0.0017519559596650691 -0.007062305223846422"/>
    <mass value="0.02607369115545735"/>
    <inertia ixx="1.5e-05" ixy="0.0" ixz="1e-06" iyy="1.5e-05" iyz="-1e-06" izz="1e-06"/>
  </inertial>
  <visual>
    <origin rpy="0 0 0" xyz="-0.087545 0.089932 -0.009877"/>
    <geometry>
      <mesh filename="package://quadruped_description/meshes/leg_rev_v1_3.stl" scale="0.001 0.001 0.001"/>
    </geometry>
    <material name="silver"/>
  </visual>
  <collision>
    <origin rpy="0 0 0" xyz="-0.087545 0.089932 -0.009877"/>
    <geometry>
      <mesh filename="package://quadruped_description/meshes/leg_rev_v1_3.stl" scale="0.001 0.001 0.001"/>
    </geometry>
  </collision>
</link>

<link name="leg_rev_v1_4">
  <inertial>
    <origin rpy="0 0 0" xyz="0.00037601257474453864 0.0017521275973778755 -0.007062305223845981"/>
    <mass value="0.02607369115545735"/>
    <inertia ixx="1.5e-05" ixy="0.0" ixz="-1e-06" iyy="1.5e-05" iyz="1e-06" izz="1e-06"/>
  </inertial>
  <visual>
    <origin rpy="0 0 0" xyz="0.087545 -0.093004 -0.009877"/>
    <geometry>
      <mesh filename="package://quadruped_description/meshes/leg_rev_v1_4.stl" scale="0.001 0.001 0.001"/>
    </geometry>
    <material name="silver"/>
  </visual>
  <collision>
    <origin rpy="0 0 0" xyz="0.087545 -0.093004 -0.009877"/>
    <geometry>
      <mesh filename="package://quadruped_description/meshes/leg_rev_v1_4.stl" scale="0.001 0.001 0.001"/>
    </geometry>
  </collision>
</link>

<link name="bottom_pivot_plate_v1_1">
  <inertial>
    <origin rpy="0 0 0" xyz="0.01000675765330758 0.010047118194641755 -0.0015933444235057773"/>
    <mass value="0.02183354723813213"/>
    <inertia ixx="2e-06" ixy="-2e-06" ixz="-0.0" iyy="2e-06" iyz="0.0" izz="5e-06"/>
  </inertial>
  <visual>
    <origin rpy="0 0 0" xyz="-0.045406 -0.047003 0.001598"/>
    <geometry>
      <mesh filename="package://quadruped_description/meshes/bottom_pivot_plate_v1_1.stl" scale="0.001 0.001 0.001"/>
    </geometry>
    <material name="silver"/>
  </visual>
  <collision>
    <origin rpy="0 0 0" xyz="-0.045406 -0.047003 0.001598"/>
    <geometry>
      <mesh filename="package://quadruped_description/meshes/bottom_pivot_plate_v1_1.stl" scale="0.001 0.001 0.001"/>
    </geometry>
  </collision>
</link>

<link name="bottom_pivot_plate_v1_2">
  <inertial>
    <origin rpy="0 0 0" xyz="-0.010006782490051366 -0.010047084095685513 -0.0015933444235059395"/>
    <mass value="0.02183354723813213"/>
    <inertia ixx="2e-06" ixy="-2e-06" ixz="-0.0" iyy="2e-06" iyz="-0.0" izz="5e-06"/>
  </inertial>
  <visual>
    <origin rpy="0 0 0" xyz="0.045406 0.043805 0.001598"/>
    <geometry>
      <mesh filename="package://quadruped_description/meshes/bottom_pivot_plate_v1_2.stl" scale="0.001 0.001 0.001"/>
    </geometry>
    <material name="silver"/>
  </visual>
  <collision>
    <origin rpy="0 0 0" xyz="0.045406 0.043805 0.001598"/>
    <geometry>
      <mesh filename="package://quadruped_description/meshes/bottom_pivot_plate_v1_2.stl" scale="0.001 0.001 0.001"/>
    </geometry>
  </collision>
</link>

<link name="bottom_pivot_plate_v1_3">
  <inertial>
    <origin rpy="0 0 0" xyz="0.010046520731299087 -0.01000716626963865 -0.0015933444235056798"/>
    <mass value="0.02183354723813213"/>
    <inertia ixx="2e-06" ixy="2e-06" ixz="-0.0" iyy="2e-06" iyz="0.0" izz="5e-06"/>
  </inertial>
  <visual>
    <origin rpy="0 0 0" xyz="-0.045406 0.043808 0.001598"/>
    <geometry>
      <mesh filename="package://quadruped_description/meshes/bottom_pivot_plate_v1_3.stl" scale="0.001 0.001 0.001"/>
    </geometry>
    <material name="silver"/>
  </visual>
  <collision>
    <origin rpy="0 0 0" xyz="-0.045406 0.043808 0.001598"/>
    <geometry>
      <mesh filename="package://quadruped_description/meshes/bottom_pivot_plate_v1_3.stl" scale="0.001 0.001 0.001"/>
    </geometry>
  </collision>
</link>

<link name="bottom_pivot_plate_v1_4">
  <inertial>
    <origin rpy="0 0 0" xyz="-0.01004654556804302 0.01000733790735086 -0.001593344423504354"/>
    <mass value="0.02183354723813213"/>
    <inertia ixx="2e-06" ixy="2e-06" ixz="0.0" iyy="2e-06" iyz="-0.0" izz="5e-06"/>
  </inertial>
  <visual>
    <origin rpy="0 0 0" xyz="0.045406 -0.04688 0.001598"/>
    <geometry>
      <mesh filename="package://quadruped_description/meshes/bottom_pivot_plate_v1_4.stl" scale="0.001 0.001 0.001"/>
    </geometry>
    <material name="silver"/>
  </visual>
  <collision>
    <origin rpy="0 0 0" xyz="0.045406 -0.04688 0.001598"/>
    <geometry>
      <mesh filename="package://quadruped_description/meshes/bottom_pivot_plate_v1_4.stl" scale="0.001 0.001 0.001"/>
    </geometry>
  </collision>
</link>

<link name="leg_parallel_linkage_v1_1">
  <inertial>
    <origin rpy="0 0 0" xyz="-0.01014265742637048 -0.007889057535331215 -5.5744720088134886e-05"/>
    <mass value="0.007660744416023878"/>
    <inertia ixx="0.0" ixy="-0.0" ixz="-0.0" iyy="0.0" iyz="-0.0" izz="1e-06"/>
  </inertial>
  <visual>
    <origin rpy="0 0 0" xyz="-0.09153 -0.089143 -0.027727"/>
    <geometry>
      <mesh filename="package://quadruped_description/meshes/leg_parallel_linkage_v1_1.stl" scale="0.001 0.001 0.001"/>
    </geometry>
    <material name="silver"/>
  </visual>
  <collision>
    <origin rpy="0 0 0" xyz="-0.09153 -0.089143 -0.027727"/>
    <geometry>
      <mesh filename="package://quadruped_description/meshes/leg_parallel_linkage_v1_1.stl" scale="0.001 0.001 0.001"/>
    </geometry>
  </collision>
</link>

<link name="leg_parallel_plate_v1_1">
  <inertial>
    <origin rpy="0 0 0" xyz="-0.004995391768741628 -0.007248720766343711 -0.00886222232295589"/>
    <mass value="0.014417433544657016"/>
    <inertia ixx="2e-06" ixy="-0.0" ixz="-0.0" iyy="2e-06" iyz="-0.0" izz="1e-06"/>
  </inertial>
  <visual>
    <origin rpy="0 0 0" xyz="-0.074112 -0.070498 -0.027616"/>
    <geometry>
      <mesh filename="package://quadruped_description/meshes/leg_parallel_plate_v1_1.stl" scale="0.001 0.001 0.001"/>
    </geometry>
    <material name="silver"/>
  </visual>
  <collision>
    <origin rpy="0 0 0" xyz="-0.074112 -0.070498 -0.027616"/>
    <geometry>
      <mesh filename="package://quadruped_description/meshes/leg_parallel_plate_v1_1.stl" scale="0.001 0.001 0.001"/>
    </geometry>
  </collision>
</link>

<link name="leg_parallel_linkage_v1_2">
  <inertial>
    <origin rpy="0 0 0" xyz="0.010142632589629483 0.007888091634290911 -5.5744719077953364e-05"/>
    <mass value="0.007660744416023878"/>
    <inertia ixx="0.0" ixy="-0.0" ixz="0.0" iyy="0.0" iyz="0.0" izz="1e-06"/>
  </inertial>
  <visual>
    <origin rpy="0 0 0" xyz="0.09153 0.085944 -0.027727"/>
    <geometry>
      <mesh filename="package://quadruped_description/meshes/leg_parallel_linkage_v1_2.stl" scale="0.001 0.001 0.001"/>
    </geometry>
    <material name="silver"/>
  </visual>
  <collision>
    <origin rpy="0 0 0" xyz="0.09153 0.085944 -0.027727"/>
    <geometry>
      <mesh filename="package://quadruped_description/meshes/leg_parallel_linkage_v1_2.stl" scale="0.001 0.001 0.001"/>
    </geometry>
  </collision>
</link>

<link name="leg_parallel_plate_v1_2">
  <inertial>
    <origin rpy="0 0 0" xyz="0.004995366931997147 0.007248754865300619 -0.008862222322955901"/>
    <mass value="0.014417433544657016"/>
    <inertia ixx="2e-06" ixy="-0.0" ixz="0.0" iyy="2e-06" iyz="0.0" izz="1e-06"/>
  </inertial>
  <visual>
    <origin rpy="0 0 0" xyz="0.074112 0.0673 -0.027616"/>
    <geometry>
      <mesh filename="package://quadruped_description/meshes/leg_parallel_plate_v1_2.stl" scale="0.001 0.001 0.001"/>
    </geometry>
    <material name="silver"/>
  </visual>
  <collision>
    <origin rpy="0 0 0" xyz="0.074112 0.0673 -0.027616"/>
    <geometry>
      <mesh filename="package://quadruped_description/meshes/leg_parallel_plate_v1_2.stl" scale="0.001 0.001 0.001"/>
    </geometry>
  </collision>
</link>

<link name="leg_parallel_linkage_v1_3">
  <inertial>
    <origin rpy="0 0 0" xyz="-0.00788865499867318 0.010142248810039722 -5.574472008828754e-05"/>
    <mass value="0.007660744416023878"/>
    <inertia ixx="0.0" ixy="0.0" ixz="-0.0" iyy="0.0" iyz="0.0" izz="1e-06"/>
  </inertial>
  <visual>
    <origin rpy="0 0 0" xyz="-0.087545 0.089932 -0.027727"/>
    <geometry>
      <mesh filename="package://quadruped_description/meshes/leg_parallel_linkage_v1_3.stl" scale="0.001 0.001 0.001"/>
    </geometry>
    <material name="silver"/>
  </visual>
  <collision>
    <origin rpy="0 0 0" xyz="-0.087545 0.089932 -0.027727"/>
    <geometry>
      <mesh filename="package://quadruped_description/meshes/leg_parallel_linkage_v1_3.stl" scale="0.001 0.001 0.001"/>
    </geometry>
  </collision>
</link>

<link name="leg_parallel_plate_v1_3">
  <inertial>
    <origin rpy="0 0 0" xyz="-0.007249318229685893 0.004994983152410759 -0.008862222322955901"/>
    <mass value="0.014417433544657016"/>
    <inertia ixx="2e-06" ixy="0.0" ixz="-0.0" iyy="2e-06" iyz="0.0" izz="1e-06"/>
  </inertial>
  <visual>
    <origin rpy="0 0 0" xyz="-0.068901 0.072514 -0.027616"/>
    <geometry>
      <mesh filename="package://quadruped_description/meshes/leg_parallel_plate_v1_3.stl" scale="0.001 0.001 0.001"/>
    </geometry>
    <material name="silver"/>
  </visual>
  <collision>
    <origin rpy="0 0 0" xyz="-0.068901 0.072514 -0.027616"/>
    <geometry>
      <mesh filename="package://quadruped_description/meshes/leg_parallel_plate_v1_3.stl" scale="0.001 0.001 0.001"/>
    </geometry>
  </collision>
</link>

<link name="leg_parallel_linkage_v1_4">
  <inertial>
    <origin rpy="0 0 0" xyz="0.007888630161932808 -0.010142077172330191 -5.574471907780418e-05"/>
    <mass value="0.007660744416023878"/>
    <inertia ixx="0.0" ixy="0.0" ixz="0.0" iyy="0.0" iyz="-0.0" izz="1e-06"/>
  </inertial>
  <visual>
    <origin rpy="0 0 0" xyz="0.087545 -0.093004 -0.027727"/>
    <geometry>
      <mesh filename="package://quadruped_description/meshes/leg_parallel_linkage_v1_4.stl" scale="0.001 0.001 0.001"/>
    </geometry>
    <material name="silver"/>
  </visual>
  <collision>
    <origin rpy="0 0 0" xyz="0.087545 -0.093004 -0.027727"/>
    <geometry>
      <mesh filename="package://quadruped_description/meshes/leg_parallel_linkage_v1_4.stl" scale="0.001 0.001 0.001"/>
    </geometry>
  </collision>
</link>

<link name="leg_parallel_plate_v1_4">
  <inertial>
    <origin rpy="0 0 0" xyz="0.007249293392942328 -0.004994811514697758 -0.008862222322955852"/>
    <mass value="0.014417433544657016"/>
    <inertia ixx="2e-06" ixy="0.0" ixz="0.0" iyy="2e-06" iyz="-0.0" izz="1e-06"/>
  </inertial>
  <visual>
    <origin rpy="0 0 0" xyz="0.068901 -0.075586 -0.027616"/>
    <geometry>
      <mesh filename="package://quadruped_description/meshes/leg_parallel_plate_v1_4.stl" scale="0.001 0.001 0.001"/>
    </geometry>
    <material name="silver"/>
  </visual>
  <collision>
    <origin rpy="0 0 0" xyz="0.068901 -0.075586 -0.027616"/>
    <geometry>
      <mesh filename="package://quadruped_description/meshes/leg_parallel_plate_v1_4.stl" scale="0.001 0.001 0.001"/>
    </geometry>
  </collision>
</link>

<joint name="Rigid1" type="fixed">
  <origin rpy="0 0 0" xyz="0.0 -0.041434 0.00924"/>
  <parent link="base_link"/>
  <child link="body_spacer_v1_1"/>
</joint>

<joint name="Rigid2" type="fixed">
  <origin rpy="0 0 0" xyz="0.0 0.044629 0.00924"/>
  <parent link="base_link"/>
  <child link="body_spacer_v1_2"/>
</joint>

<joint name="Rigid3" type="fixed">
  <origin rpy="0 0 0" xyz="-0.043031 0.001598 0.00924"/>
  <parent link="base_link"/>
  <child link="body_spacer_v1_3"/>
</joint>

<joint name="Rigid4" type="fixed">
  <origin rpy="0 0 0" xyz="0.043031 0.001598 0.00924"/>
  <parent link="base_link"/>
  <child link="body_spacer_v1_4"/>
</joint>

<joint name="Rigid5" type="fixed">
  <origin rpy="0 0 0" xyz="-1e-05 0.001603 0.023902"/>
  <parent link="base_link"/>
  <child link="body_top_plate_v1_1"/>
</joint>

<joint name="Rigid6" type="fixed">
  <origin rpy="0 0 0" xyz="0.045406 0.047003 0.038004"/>
  <parent link="base_link"/>
  <child link="servo_motor_v1_1"/>
</joint>

<joint name="Rigid7" type="fixed">
  <origin rpy="0 0 0" xyz="-0.045406 -0.043805 0.038004"/>
  <parent link="base_link"/>
  <child link="servo_motor_v1_2"/>
</joint>

<joint name="Rigid8" type="fixed">
  <origin rpy="0 0 0" xyz="0.045406 -0.043808 0.038004"/>
  <parent link="base_link"/>
  <child link="servo_motor_v1_3"/>
</joint>

<joint name="Rigid9" type="fixed">
  <origin rpy="0 0 0" xyz="-0.045406 0.04688 0.038004"/>
  <parent link="base_link"/>
  <child link="servo_motor_v1_4"/>
</joint>

<joint name="Rigid10" type="fixed">
  <origin rpy="0 0 0" xyz="-0.012081 -0.012081 -0.00932"/>
  <parent link="servo_motor_v1_1"/>
  <child link="leg_servo_retainer_v1_1"/>
</joint>

<joint name="Rigid11" type="fixed">
  <origin rpy="0 0 0" xyz="0.012081 0.012081 -0.00932"/>
  <parent link="servo_motor_v1_2"/>
  <child link="leg_servo_retainer_v1_2"/>
</joint>

<joint name="Rigid12" type="fixed">
  <origin rpy="0 0 0" xyz="-0.012081 0.012081 -0.00932"/>
  <parent link="servo_motor_v1_3"/>
  <child link="leg_servo_retainer_v1_3"/>
</joint>

<joint name="Rigid13" type="fixed">
  <origin rpy="0 0 0" xyz="0.012081 -0.012081 -0.00932"/>
  <parent link="servo_motor_v1_4"/>
  <child link="leg_servo_retainer_v1_4"/>
</joint>

<joint name="Rev14" type="continuous">
  <origin rpy="0 0 0" xyz="0.0 0.0 0.0"/>
  <parent link="servo_motor_v1_1"/>
  <child link="leg_top_pivot_plate_v1_1"/>
  <axis xyz="0.0 -0.0 1.0"/>
</joint>

<joint name="Rev15" type="continuous">
  <origin rpy="0 0 0" xyz="0.0 0.0 0.0"/>
  <parent link="servo_motor_v1_2"/>
  <child link="leg_top_pivot_plate_v1_2"/>
  <axis xyz="-0.0 -0.0 1.0"/>
</joint>

<joint name="Rev16" type="continuous">
  <origin rpy="0 0 0" xyz="0.0 0.0 0.0"/>
  <parent link="servo_motor_v1_3"/>
  <child link="leg_top_pivot_plate_v1_3"/>
  <axis xyz="0.0 -0.0 1.0"/>
</joint>

<joint name="Rev17" type="continuous">
  <origin rpy="0 0 0" xyz="0.0 0.0 0.0"/>
  <parent link="servo_motor_v1_4"/>
  <child link="leg_top_pivot_plate_v1_4"/>
  <axis xyz="0.0 -0.0 1.0"/>
</joint>

<joint name="Rigid18" type="fixed">
  <origin rpy="0 0 0" xyz="0.012883 0.02208 -0.011475"/>
  <parent link="leg_top_pivot_plate_v1_1"/>
  <child link="leg_servo_mount_v1_1"/>
</joint>

<joint name="Rigid19" type="fixed">
  <origin rpy="0 0 0" xyz="-0.012883 -0.02208 -0.011475"/>
  <parent link="leg_top_pivot_plate_v1_2"/>
  <child link="leg_servo_mount_v1_2"/>
</joint>

<joint name="Rigid20" type="fixed">
  <origin rpy="0 0 0" xyz="0.022079 -0.012884 -0.011475"/>
  <parent link="leg_top_pivot_plate_v1_3"/>
  <child link="leg_servo_mount_v1_3"/>
</joint>

<joint name="Rigid21" type="fixed">
  <origin rpy="0 0 0" xyz="-0.022079 0.012884 -0.011475"/>
  <parent link="leg_top_pivot_plate_v1_4"/>
  <child link="leg_servo_mount_v1_4"/>
</joint>

<joint name="Rigid22" type="fixed">
  <origin rpy="0 0 0" xyz="0.008619 0.008619 0.000433"/>
  <parent link="leg_servo_mount_v1_1"/>
  <child link="servo_motor_v1_5"/>
</joint>

<joint name="Rigid23" type="fixed">
  <origin rpy="0 0 0" xyz="-0.008619 -0.008619 0.000433"/>
  <parent link="leg_servo_mount_v1_2"/>
  <child link="servo_motor_v1_6"/>
</joint>

<joint name="Rigid24" type="fixed">
  <origin rpy="0 0 0" xyz="0.008619 -0.008619 0.000433"/>
  <parent link="leg_servo_mount_v1_3"/>
  <child link="servo_motor_v1_7"/>
</joint>

<joint name="Rigid25" type="fixed">
  <origin rpy="0 0 0" xyz="-0.008619 0.008619 0.000433"/>
  <parent link="leg_servo_mount_v1_4"/>
  <child link="servo_motor_v1_8"/>
</joint>

<joint name="Rev26" type="continuous">
  <origin rpy="0 0 0" xyz="0.006591 -0.006591 -0.017085"/>
  <parent link="servo_motor_v1_5"/>
  <child link="leg_servo_arm_v1_1"/>
  <axis xyz="0.707107 -0.707107 -0.0"/>
</joint>

<joint name="Rev27" type="continuous">
  <origin rpy="0 0 0" xyz="-0.006591 0.006591 -0.017085"/>
  <parent link="servo_motor_v1_6"/>
  <child link="leg_servo_arm_v1_2"/>
  <axis xyz="-0.707107 0.707107 0.0"/>
</joint>

<joint name="Rev28" type="continuous">
  <origin rpy="0 0 0" xyz="-0.00659 -0.00659 -0.017085"/>
  <parent link="servo_motor_v1_7"/>
  <child link="leg_servo_arm_v1_3"/>
  <axis xyz="-0.707107 -0.707107 0.0"/>
</joint>

<joint name="Rev29" type="continuous">
  <origin rpy="0 0 0" xyz="0.00659 0.00659 -0.017085"/>
  <parent link="servo_motor_v1_8"/>
  <child link="leg_servo_arm_v1_4"/>
  <axis xyz="0.707107 0.707107 -0.0"/>
</joint>

<joint name="Rev30" type="continuous">
  <origin rpy="0 0 0" xyz="0.018031 0.018031 0.0"/>
  <parent link="leg_servo_arm_v1_1"/>
  <child link="leg_rev_v1_1"/>
  <axis xyz="-0.707107 0.707107 0.0"/>
</joint>

<joint name="Rev31" type="continuous">
  <origin rpy="0 0 0" xyz="-0.018031 -0.018031 0.0"/>
  <parent link="leg_servo_arm_v1_2"/>
  <child link="leg_rev_v1_2"/>
  <axis xyz="-0.707107 0.707107 0.0"/>
</joint>

<joint name="Rev32" type="continuous">
  <origin rpy="0 0 0" xyz="0.018031 -0.018031 0.0"/>
  <parent link="leg_servo_arm_v1_3"/>
  <child link="leg_rev_v1_3"/>
  <axis xyz="-0.707107 -0.707107 0.0"/>
</joint>

<joint name="Rev33" type="continuous">
  <origin rpy="0 0 0" xyz="-0.018031 0.018031 0.0"/>
  <parent link="leg_servo_arm_v1_4"/>
  <child link="leg_rev_v1_4"/>
  <axis xyz="-0.707107 -0.707107 0.0"/>
</joint>

<joint name="Rev34" type="continuous">
  <origin rpy="0 0 0" xyz="0.045406 0.047003 -0.001598"/>
  <parent link="base_link"/>
  <child link="bottom_pivot_plate_v1_1"/>
  <axis xyz="0.0 -0.0 1.0"/>
</joint>

<joint name="Rev35" type="continuous">
  <origin rpy="0 0 0" xyz="-0.045406 -0.043805 -0.001598"/>
  <parent link="base_link"/>
  <child link="bottom_pivot_plate_v1_2"/>
  <axis xyz="0.0 -0.0 1.0"/>
</joint>

<joint name="Rev36" type="continuous">
  <origin rpy="0 0 0" xyz="0.045406 -0.043808 -0.001598"/>
  <parent link="base_link"/>
  <child link="bottom_pivot_plate_v1_3"/>
  <axis xyz="0.0 -0.0 1.0"/>
</joint>

<joint name="Rev37" type="continuous">
  <origin rpy="0 0 0" xyz="-0.045406 0.04688 -0.001598"/>
  <parent link="base_link"/>
  <child link="bottom_pivot_plate_v1_4"/>
  <axis xyz="0.0 -0.0 1.0"/>
</joint>

<joint name="Rev42" type="continuous">
  <origin rpy="0 0 0" xyz="0.0 1e-06 0.01785"/>
  <parent link="leg_rev_v1_1"/>
  <child link="leg_parallel_linkage_v1_1"/>
  <axis xyz="0.707107 -0.707107 -0.0"/>
</joint>

<joint name="Rev43" type="continuous">
  <origin rpy="0 0 0" xyz="-0.017418 -0.018645 -0.000111"/>
  <parent link="leg_parallel_linkage_v1_1"/>
  <child link="leg_parallel_plate_v1_1"/>
  <axis xyz="0.707107 -0.707107 -0.0"/>
</joint>

<joint name="Rev44" type="continuous">
  <origin rpy="0 0 0" xyz="0.0 0.0 0.01785"/>
  <parent link="leg_rev_v1_2"/>
  <child link="leg_parallel_linkage_v1_2"/>
  <axis xyz="-0.707107 0.707107 0.0"/>
</joint>

<joint name="Rev45" type="continuous">
  <origin rpy="0 0 0" xyz="0.017418 0.018644 -0.000111"/>
  <parent link="leg_parallel_linkage_v1_2"/>
  <child link="leg_parallel_plate_v1_2"/>
  <axis xyz="0.707107 -0.707107 -0.0"/>
</joint>

<joint name="Rev46" type="continuous">
  <origin rpy="0 0 0" xyz="0.0 0.0 0.01785"/>
  <parent link="leg_rev_v1_3"/>
  <child link="leg_parallel_linkage_v1_3"/>
  <axis xyz="-0.707107 -0.707107 0.0"/>
</joint>

<joint name="Rev47" type="continuous">
  <origin rpy="0 0 0" xyz="-0.018644 0.017418 -0.000111"/>
  <parent link="leg_parallel_linkage_v1_3"/>
  <child link="leg_parallel_plate_v1_3"/>
  <axis xyz="-0.707107 -0.707107 0.0"/>
</joint>

<joint name="Rev48" type="continuous">
  <origin rpy="0 0 0" xyz="0.0 0.0 0.01785"/>
  <parent link="leg_rev_v1_4"/>
  <child link="leg_parallel_linkage_v1_4"/>
  <axis xyz="0.707107 0.707107 -0.0"/>
</joint>

<joint name="Rev49" type="continuous">
  <origin rpy="0 0 0" xyz="0.018644 -0.017418 -0.000111"/>
  <parent link="leg_parallel_linkage_v1_4"/>
  <child link="leg_parallel_plate_v1_4"/>
  <axis xyz="-0.707107 -0.707107 0.0"/>
</joint>

</robot>
