<?xml version="1.0" ?>
<robot name="quadruped" xmlns:xacro="http://www.ros.org/wiki/xacro">

<xacro:include filename="$(find quadruped_description)/urdf/materials.xacro" />
<xacro:include filename="$(find quadruped_description)/urdf/quadruped.trans" />
<xacro:include filename="$(find quadruped_description)/urdf/quadruped.gazebo" />
<link name="base_link">
  <inertial>
    <origin rpy="0 0 0" xyz="9.059146598001685e-07 0.0015934023756066099 0.049996155576494214"/>
    <mass value="0.1660035395213305"/>
    <inertia ixx="0.000257" ixy="0.0" ixz="0.0" iyy="0.000257" iyz="-0.0" izz="0.000514"/>
  </inertial>
  <visual>
    <origin rpy="0 0 0" xyz="0 0 0"/>
    <geometry>
      <mesh filename="package://quadruped_description/meshes/base_link.stl" scale="0.001 0.001 0.001"/>
    </geometry>
    <material name="silver"/>
  </visual>
  <collision>
    <origin rpy="0 0 0" xyz="0 0 0"/>
    <geometry>
      <mesh filename="package://quadruped_description/meshes/base_link.stl" scale="0.001 0.001 0.001"/>
    </geometry>
  </collision>
</link>

<link name="body_spacer_v1_1">
  <inertial>
    <origin rpy="0 0 0" xyz="-2.3037127760971997e-17 3.4442350579921843e-07 0.0019124056524901095"/>
    <mass value="0.01987438429408557"/>
    <inertia ixx="1e-06" ixy="0.0" ixz="0.0" iyy="4e-06" iyz="0.0" izz="3e-06"/>
  </inertial>
  <visual>
    <origin rpy="0 0 0" xyz="0.0 0.041434 -0.05924"/>
    <geometry>
      <mesh filename="package://quadruped_description/meshes/body_spacer_v1_1.stl" scale="0.001 0.001 0.001"/>
    </geometry>
    <material name="silver"/>
  </visual>
  <collision>
    <origin rpy="0 0 0" xyz="0.0 0.041434 -0.05924"/>
    <geometry>
      <mesh filename="package://quadruped_description/meshes/body_spacer_v1_1.stl" scale="0.001 0.001 0.001"/>
    </geometry>
  </collision>
</link>

<link name="body_spacer_v1_2">
  <inertial>
    <origin rpy="0 0 0" xyz="-1.762479051592436e-17 -1.555764942290372e-07 0.0019124056524901373"/>
    <mass value="0.01987438429408557"/>
    <inertia ixx="1e-06" ixy="0.0" ixz="0.0" iyy="4e-06" iyz="0.0" izz="3e-06"/>
  </inertial>
  <visual>
    <origin rpy="0 0 0" xyz="0.0 -0.044629 -0.05924"/>
    <geometry>
      <mesh filename="package://quadruped_description/meshes/body_spacer_v1_2.stl" scale="0.001 0.001 0.001"/>
    </geometry>
    <material name="silver"/>
  </visual>
  <collision>
    <origin rpy="0 0 0" xyz="0.0 -0.044629 -0.05924"/>
    <geometry>
      <mesh filename="package://quadruped_description/meshes/body_spacer_v1_2.stl" scale="0.001 0.001 0.001"/>
    </geometry>
  </collision>
</link>

<link name="body_spacer_v1_3">
  <inertial>
    <origin rpy="0 0 0" xyz="-2.500000000071889e-07 -4.055764942221315e-07 0.0019124056524901165"/>
    <mass value="0.01987438429408557"/>
    <inertia ixx="4e-06" ixy="0.0" ixz="-0.0" iyy="1e-06" iyz="-0.0" izz="3e-06"/>
  </inertial>
  <visual>
    <origin rpy="0 0 0" xyz="0.043031 -0.001598 -0.05924"/>
    <geometry>
      <mesh filename="package://quadruped_description/meshes/body_spacer_v1_3.stl" scale="0.001 0.001 0.001"/>
    </geometry>
    <material name="silver"/>
  </visual>
  <collision>
    <origin rpy="0 0 0" xyz="0.043031 -0.001598 -0.05924"/>
    <geometry>
      <mesh filename="package://quadruped_description/meshes/body_spacer_v1_3.stl" scale="0.001 0.001 0.001"/>
    </geometry>
  </collision>
</link>

<link name="body_spacer_v1_4">
  <inertial>
    <origin rpy="0 0 0" xyz="2.4999999997249445e-07 -4.0557649422690197e-07 0.0019124056524901165"/>
    <mass value="0.01987438429408557"/>
    <inertia ixx="4e-06" ixy="0.0" ixz="0.0" iyy="1e-06" iyz="-0.0" izz="3e-06"/>
  </inertial>
  <visual>
    <origin rpy="0 0 0" xyz="-0.043031 -0.001598 -0.05924"/>
    <geometry>
      <mesh filename="package://quadruped_description/meshes/body_spacer_v1_4.stl" scale="0.001 0.001 0.001"/>
    </geometry>
    <material name="silver"/>
  </visual>
  <collision>
    <origin rpy="0 0 0" xyz="-0.043031 -0.001598 -0.05924"/>
    <geometry>
      <mesh filename="package://quadruped_description/meshes/body_spacer_v1_4.stl" scale="0.001 0.001 0.001"/>
    </geometry>
  </collision>
</link>

<link name="body_top_plate_v1_1">
  <inertial>
    <origin rpy="0 0 0" xyz="-6.217287019304255e-06 -7.919011395336392e-07 -0.0015933444235057687"/>
    <mass value="0.2442521638475155"/>
    <inertia ixx="0.000246" ixy="-0.0" ixz="0.0" iyy="0.000236" iyz="-0.0" izz="0.000482"/>
  </inertial>
  <visual>
    <origin rpy="0 0 0" xyz="1e-05 -0.001603 -0.073902"/>
    <geometry>
      <mesh filename="package://quadruped_description/meshes/body_top_plate_v1_1.stl" scale="0.001 0.001 0.001"/>
    </geometry>
    <material name="silver"/>
  </visual>
  <collision>
    <origin rpy="0 0 0" xyz="1e-05 -0.001603 -0.073902"/>
    <geometry>
      <mesh filename="package://quadruped_description/meshes/body_top_plate_v1_1.stl" scale="0.001 0.001 0.001"/>
    </geometry>
  </collision>
</link>

<link name="servo_motor_v1_1">
  <inertial>
    <origin rpy="0 0 0" xyz="-0.0034453069163115357 -0.003444709272821242 -0.017291510897469234"/>
    <mass value="0.008039754705757893"/>
    <inertia ixx="1e-06" ixy="-0.0" ixz="-0.0" iyy="1e-06" iyz="-0.0" izz="1e-06"/>
  </inertial>
  <visual>
    <origin rpy="0 0 0" xyz="-0.045406 -0.047003 -0.088004"/>
    <geometry>
      <mesh filename="package://quadruped_description/meshes/servo_motor_v1_1.stl" scale="0.001 0.001 0.001"/>
    </geometry>
    <material name="silver"/>
  </visual>
  <collision>
    <origin rpy="0 0 0" xyz="-0.045406 -0.047003 -0.088004"/>
    <geometry>
      <mesh filename="package://quadruped_description/meshes/servo_motor_v1_1.stl" scale="0.001 0.001 0.001"/>
    </geometry>
  </collision>
</link>

<link name="servo_motor_v1_2">
  <inertial>
    <origin rpy="0 0 0" xyz="0.00344528207956777 0.00344474337177747 -0.017291510897469248"/>
    <mass value="0.008039754705757893"/>
    <inertia ixx="1e-06" ixy="-0.0" ixz="0.0" iyy="1e-06" iyz="0.0" izz="1e-06"/>
  </inertial>
  <visual>
    <origin rpy="0 0 0" xyz="0.045406 0.043805 -0.088004"/>
    <geometry>
      <mesh filename="package://quadruped_description/meshes/servo_motor_v1_2.stl" scale="0.001 0.001 0.001"/>
    </geometry>
    <material name="silver"/>
  </visual>
  <collision>
    <origin rpy="0 0 0" xyz="0.045406 0.043805 -0.088004"/>
    <geometry>
      <mesh filename="package://quadruped_description/meshes/servo_motor_v1_2.stl" scale="0.001 0.001 0.001"/>
    </geometry>
  </collision>
</link>

<link name="servo_motor_v1_3">
  <inertial>
    <origin rpy="0 0 0" xyz="-0.0034453067361639236 0.0034448982999804242 -0.01729151089746929"/>
    <mass value="0.008039754705757893"/>
    <inertia ixx="1e-06" ixy="0.0" ixz="-0.0" iyy="1e-06" iyz="0.0" izz="1e-06"/>
  </inertial>
  <visual>
    <origin rpy="0 0 0" xyz="-0.045406 0.043808 -0.088004"/>
    <geometry>
      <mesh filename="package://quadruped_description/meshes/servo_motor_v1_3.stl" scale="0.001 0.001 0.001"/>
    </geometry>
    <material name="silver"/>
  </visual>
  <collision>
    <origin rpy="0 0 0" xyz="-0.045406 0.043808 -0.088004"/>
    <geometry>
      <mesh filename="package://quadruped_description/meshes/servo_motor_v1_3.stl" scale="0.001 0.001 0.001"/>
    </geometry>
  </collision>
</link>

<link name="servo_motor_v1_4">
  <inertial>
    <origin rpy="0 0 0" xyz="0.003445281899420137 -0.0034447266622682077 -0.017291510897469248"/>
    <mass value="0.008039754705757893"/>
    <inertia ixx="1e-06" ixy="0.0" ixz="0.0" iyy="1e-06" iyz="-0.0" izz="1e-06"/>
  </inertial>
  <visual>
    <origin rpy="0 0 0" xyz="0.045406 -0.04688 -0.088004"/>
    <geometry>
      <mesh filename="package://quadruped_description/meshes/servo_motor_v1_4.stl" scale="0.001 0.001 0.001"/>
    </geometry>
    <material name="silver"/>
  </visual>
  <collision>
    <origin rpy="0 0 0" xyz="0.045406 -0.04688 -0.088004"/>
    <geometry>
      <mesh filename="package://quadruped_description/meshes/servo_motor_v1_4.stl" scale="0.001 0.001 0.001"/>
    </geometry>
  </collision>
</link>

<link name="leg_servo_retainer_v1_1">
  <inertial>
    <origin rpy="0 0 0" xyz="0.007924108380789864 0.007923419580222718 -3.4442350579921843e-07"/>
    <mass value="0.011735752466802122"/>
    <inertia ixx="1e-06" ixy="-0.0" ixz="-0.0" iyy="1e-06" iyz="0.0" izz="2e-06"/>
  </inertial>
  <visual>
    <origin rpy="0 0 0" xyz="-0.033325 -0.034922 -0.078684"/>
    <geometry>
      <mesh filename="package://quadruped_description/meshes/leg_servo_retainer_v1_1.stl" scale="0.001 0.001 0.001"/>
    </geometry>
    <material name="silver"/>
  </visual>
  <collision>
    <origin rpy="0 0 0" xyz="-0.033325 -0.034922 -0.078684"/>
    <geometry>
      <mesh filename="package://quadruped_description/meshes/leg_servo_retainer_v1_1.stl" scale="0.001 0.001 0.001"/>
    </geometry>
  </collision>
</link>

<link name="leg_servo_retainer_v1_2">
  <inertial>
    <origin rpy="0 0 0" xyz="-0.007924133217533623 -0.007923385481266532 -3.444235058408518e-07"/>
    <mass value="0.011735752466802122"/>
    <inertia ixx="1e-06" ixy="-0.0" ixz="0.0" iyy="1e-06" iyz="-0.0" izz="2e-06"/>
  </inertial>
  <visual>
    <origin rpy="0 0 0" xyz="0.033325 0.031724 -0.078684"/>
    <geometry>
      <mesh filename="package://quadruped_description/meshes/leg_servo_retainer_v1_2.stl" scale="0.001 0.001 0.001"/>
    </geometry>
    <material name="silver"/>
  </visual>
  <collision>
    <origin rpy="0 0 0" xyz="0.033325 0.031724 -0.078684"/>
    <geometry>
      <mesh filename="package://quadruped_description/meshes/leg_servo_retainer_v1_2.stl" scale="0.001 0.001 0.001"/>
    </geometry>
  </collision>
</link>

<link name="leg_servo_retainer_v1_3">
  <inertial>
    <origin rpy="0 0 0" xyz="0.007922822116880023 -0.00792451699712099 -3.444235058547296e-07"/>
    <mass value="0.011735752466802122"/>
    <inertia ixx="1e-06" ixy="0.0" ixz="0.0" iyy="1e-06" iyz="-0.0" izz="2e-06"/>
  </inertial>
  <visual>
    <origin rpy="0 0 0" xyz="-0.033325 0.031727 -0.078684"/>
    <geometry>
      <mesh filename="package://quadruped_description/meshes/leg_servo_retainer_v1_3.stl" scale="0.001 0.001 0.001"/>
    </geometry>
    <material name="silver"/>
  </visual>
  <collision>
    <origin rpy="0 0 0" xyz="-0.033325 0.031727 -0.078684"/>
    <geometry>
      <mesh filename="package://quadruped_description/meshes/leg_servo_retainer_v1_3.stl" scale="0.001 0.001 0.001"/>
    </geometry>
  </collision>
</link>

<link name="leg_servo_retainer_v1_4">
  <inertial>
    <origin rpy="0 0 0" xyz="-0.007922846953623795 0.007924688634833157 -3.444235058130962e-07"/>
    <mass value="0.011735752466802122"/>
    <inertia ixx="1e-06" ixy="0.0" ixz="0.0" iyy="1e-06" iyz="0.0" izz="2e-06"/>
  </inertial>
  <visual>
    <origin rpy="0 0 0" xyz="0.033325 -0.034799 -0.078684"/>
    <geometry>
      <mesh filename="package://quadruped_description/meshes/leg_servo_retainer_v1_4.stl" scale="0.001 0.001 0.001"/>
    </geometry>
    <material name="silver"/>
  </visual>
  <collision>
    <origin rpy="0 0 0" xyz="0.033325 -0.034799 -0.078684"/>
    <geometry>
      <mesh filename="package://quadruped_description/meshes/leg_servo_retainer_v1_4.stl" scale="0.001 0.001 0.001"/>
    </geometry>
  </collision>
</link>

<link name="leg_top_pivot_plate_v1_1">
  <inertial>
    <origin rpy="0 0 0" xyz="0.010648424399168653 0.010577698071700968 -0.0015938444235058108"/>
    <mass value="0.020723046160568363"/>
    <inertia ixx="2e-06" ixy="-1e-06" ixz="-0.0" iyy="2e-06" iyz="-0.0" izz="4e-06"/>
  </inertial>
  <visual>
    <origin rpy="0 0 0" xyz="-0.045406 -0.047003 -0.088004"/>
    <geometry>
      <mesh filename="package://quadruped_description/meshes/leg_top_pivot_plate_v1_1.stl" scale="0.001 0.001 0.001"/>
    </geometry>
    <material name="silver"/>
  </visual>
  <collision>
    <origin rpy="0 0 0" xyz="-0.045406 -0.047003 -0.088004"/>
    <geometry>
      <mesh filename="package://quadruped_description/meshes/leg_top_pivot_plate_v1_1.stl" scale="0.001 0.001 0.001"/>
    </geometry>
  </collision>
</link>

<link name="leg_top_pivot_plate_v1_2">
  <inertial>
    <origin rpy="0 0 0" xyz="-0.010648449235912537 -0.010577663972744698 -0.0015938444235058524"/>
    <mass value="0.020723046160568363"/>
    <inertia ixx="2e-06" ixy="-1e-06" ixz="-0.0" iyy="2e-06" iyz="-0.0" izz="4e-06"/>
  </inertial>
  <visual>
    <origin rpy="0 0 0" xyz="0.045406 0.043805 -0.088004"/>
    <geometry>
      <mesh filename="package://quadruped_description/meshes/leg_top_pivot_plate_v1_2.stl" scale="0.001 0.001 0.001"/>
    </geometry>
    <material name="silver"/>
  </visual>
  <collision>
    <origin rpy="0 0 0" xyz="0.045406 0.043805 -0.088004"/>
    <geometry>
      <mesh filename="package://quadruped_description/meshes/leg_top_pivot_plate_v1_2.stl" scale="0.001 0.001 0.001"/>
    </geometry>
  </collision>
</link>

<link name="leg_top_pivot_plate_v1_3">
  <inertial>
    <origin rpy="0 0 0" xyz="0.010577100608358335 -0.010648833015499813 -0.001593844423505894"/>
    <mass value="0.020723046160568363"/>
    <inertia ixx="2e-06" ixy="1e-06" ixz="0.0" iyy="2e-06" iyz="0.0" izz="4e-06"/>
  </inertial>
  <visual>
    <origin rpy="0 0 0" xyz="-0.045406 0.043808 -0.088004"/>
    <geometry>
      <mesh filename="package://quadruped_description/meshes/leg_top_pivot_plate_v1_3.stl" scale="0.001 0.001 0.001"/>
    </geometry>
    <material name="silver"/>
  </visual>
  <collision>
    <origin rpy="0 0 0" xyz="-0.045406 0.043808 -0.088004"/>
    <geometry>
      <mesh filename="package://quadruped_description/meshes/leg_top_pivot_plate_v1_3.stl" scale="0.001 0.001 0.001"/>
    </geometry>
  </collision>
</link>

<link name="leg_top_pivot_plate_v1_4">
  <inertial>
    <origin rpy="0 0 0" xyz="-0.010577125445102108 0.010649004653212023 -0.0015938444235058247"/>
    <mass value="0.020723046160568363"/>
    <inertia ixx="2e-06" ixy="1e-06" ixz="0.0" iyy="2e-06" iyz="0.0" izz="4e-06"/>
  </inertial>
  <visual>
    <origin rpy="0 0 0" xyz="0.045406 -0.04688 -0.088004"/>
    <geometry>
      <mesh filename="package://quadruped_description/meshes/leg_top_pivot_plate_v1_4.stl" scale="0.001 0.001 0.001"/>
    </geometry>
    <material name="silver"/>
  </visual>
  <collision>
    <origin rpy="0 0 0" xyz="0.045406 -0.04688 -0.088004"/>
    <geometry>
      <mesh filename="package://quadruped_description/meshes/leg_top_pivot_plate_v1_4.stl" scale="0.001 0.001 0.001"/>
    </geometry>
  </collision>
</link>

<link name="leg_servo_mount_v1_1">
  <inertial>
    <origin rpy="0 0 0" xyz="0.006427091482037052 0.006426612462751641 -0.009351515125044133"/>
    <mass value="0.018978192167657257"/>
    <inertia ixx="3e-06" ixy="-1e-06" ixz="-0.0" iyy="3e-06" iyz="-0.0" izz="2e-06"/>
  </inertial>
  <visual>
    <origin rpy="0 0 0" xyz="-0.058289 -0.069083 -0.076529"/>
    <geometry>
      <mesh filename="package://quadruped_description/meshes/leg_servo_mount_v1_1.stl" scale="0.001 0.001 0.001"/>
    </geometry>
    <material name="silver"/>
  </visual>
  <collision>
    <origin rpy="0 0 0" xyz="-0.058289 -0.069083 -0.076529"/>
    <geometry>
      <mesh filename="package://quadruped_description/meshes/leg_servo_mount_v1_1.stl" scale="0.001 0.001 0.001"/>
    </geometry>
  </collision>
</link>

<link name="leg_servo_mount_v1_2">
  <inertial>
    <origin rpy="0 0 0" xyz="-0.006427116318780936 -0.006426578363795371 -0.009351515125044202"/>
    <mass value="0.018978192167657257"/>
    <inertia ixx="3e-06" ixy="-1e-06" ixz="0.0" iyy="3e-06" iyz="0.0" izz="2e-06"/>
  </inertial>
  <visual>
    <origin rpy="0 0 0" xyz="0.058289 0.065885 -0.076529"/>
    <geometry>
      <mesh filename="package://quadruped_description/meshes/leg_servo_mount_v1_2.stl" scale="0.001 0.001 0.001"/>
    </geometry>
    <material name="silver"/>
  </visual>
  <collision>
    <origin rpy="0 0 0" xyz="0.058289 0.065885 -0.076529"/>
    <geometry>
      <mesh filename="package://quadruped_description/meshes/leg_servo_mount_v1_2.stl" scale="0.001 0.001 0.001"/>
    </geometry>
  </collision>
</link>

<link name="leg_servo_mount_v1_3">
  <inertial>
    <origin rpy="0 0 0" xyz="0.006427014999408981 -0.006426500098368142 -0.009351515125044257"/>
    <mass value="0.018978192167657257"/>
    <inertia ixx="3e-06" ixy="1e-06" ixz="-0.0" iyy="3e-06" iyz="0.0" izz="2e-06"/>
  </inertial>
  <visual>
    <origin rpy="0 0 0" xyz="-0.067485 0.056692 -0.076529"/>
    <geometry>
      <mesh filename="package://quadruped_description/meshes/leg_servo_mount_v1_3.stl" scale="0.001 0.001 0.001"/>
    </geometry>
    <material name="silver"/>
  </visual>
  <collision>
    <origin rpy="0 0 0" xyz="-0.067485 0.056692 -0.076529"/>
    <geometry>
      <mesh filename="package://quadruped_description/meshes/leg_servo_mount_v1_3.stl" scale="0.001 0.001 0.001"/>
    </geometry>
  </collision>
</link>

<link name="leg_servo_mount_v1_4">
  <inertial>
    <origin rpy="0 0 0" xyz="-0.0064270398361530034 0.006426671736080497 -0.009351515125044133"/>
    <mass value="0.018978192167657257"/>
    <inertia ixx="3e-06" ixy="1e-06" ixz="0.0" iyy="3e-06" iyz="-0.0" izz="2e-06"/>
  </inertial>
  <visual>
    <origin rpy="0 0 0" xyz="0.067485 -0.059764 -0.076529"/>
    <geometry>
      <mesh filename="package://quadruped_description/meshes/leg_servo_mount_v1_4.stl" scale="0.001 0.001 0.001"/>
    </geometry>
    <material name="silver"/>
  </visual>
  <collision>
    <origin rpy="0 0 0" xyz="0.067485 -0.059764 -0.076529"/>
    <geometry>
      <mesh filename="package://quadruped_description/meshes/leg_servo_mount_v1_4.stl" scale="0.001 0.001 0.001"/>
    </geometry>
  </collision>
</link>

<link name="servo_motor_v1_5">
  <inertial>
    <origin rpy="0 0 0" xyz="-0.005636344543875599 0.005636108172251839 -0.012212864453551214"/>
    <mass value="0.008039754705757893"/>
    <inertia ixx="1e-06" ixy="0.0" ixz="0.0" iyy="1e-06" iyz="-0.0" izz="1e-06"/>
  </inertial>
  <visual>
    <origin rpy="0 0 0" xyz="-0.066908 -0.077702 -0.076962"/>
    <geometry>
      <mesh filename="package://quadruped_description/meshes/servo_motor_v1_5.stl" scale="0.001 0.001 0.001"/>
    </geometry>
    <material name="silver"/>
  </visual>
  <collision>
    <origin rpy="0 0 0" xyz="-0.066908 -0.077702 -0.076962"/>
    <geometry>
      <mesh filename="package://quadruped_description/meshes/servo_motor_v1_5.stl" scale="0.001 0.001 0.001"/>
    </geometry>
  </collision>
</link>

<link name="servo_motor_v1_6">
  <inertial>
    <origin rpy="0 0 0" xyz="0.0056363197071315554 -0.005636074073295541 -0.012212864453551311"/>
    <mass value="0.008039754705757893"/>
    <inertia ixx="1e-06" ixy="0.0" ixz="-0.0" iyy="1e-06" iyz="0.0" izz="1e-06"/>
  </inertial>
  <visual>
    <origin rpy="0 0 0" xyz="0.066908 0.074504 -0.076962"/>
    <geometry>
      <mesh filename="package://quadruped_description/meshes/servo_motor_v1_6.stl" scale="0.001 0.001 0.001"/>
    </geometry>
    <material name="silver"/>
  </visual>
  <collision>
    <origin rpy="0 0 0" xyz="0.066908 0.074504 -0.076962"/>
    <geometry>
      <mesh filename="package://quadruped_description/meshes/servo_motor_v1_6.stl" scale="0.001 0.001 0.001"/>
    </geometry>
  </collision>
</link>

<link name="servo_motor_v1_7">
  <inertial>
    <origin rpy="0 0 0" xyz="0.00563651070890904 0.005636935927544447 -0.012212864453551353"/>
    <mass value="0.008039754705757893"/>
    <inertia ixx="1e-06" ixy="-0.0" ixz="-0.0" iyy="1e-06" iyz="-0.0" izz="1e-06"/>
  </inertial>
  <visual>
    <origin rpy="0 0 0" xyz="-0.076104 0.065311 -0.076962"/>
    <geometry>
      <mesh filename="package://quadruped_description/meshes/servo_motor_v1_7.stl" scale="0.001 0.001 0.001"/>
    </geometry>
    <material name="silver"/>
  </visual>
  <collision>
    <origin rpy="0 0 0" xyz="-0.076104 0.065311 -0.076962"/>
    <geometry>
      <mesh filename="package://quadruped_description/meshes/servo_motor_v1_7.stl" scale="0.001 0.001 0.001"/>
    </geometry>
  </collision>
</link>

<link name="servo_motor_v1_8">
  <inertial>
    <origin rpy="0 0 0" xyz="-0.005636535545653271 -0.005636764289832105 -0.012212864453551117"/>
    <mass value="0.008039754705757893"/>
    <inertia ixx="1e-06" ixy="-0.0" ixz="0.0" iyy="1e-06" iyz="0.0" izz="1e-06"/>
  </inertial>
  <visual>
    <origin rpy="0 0 0" xyz="0.076104 -0.068383 -0.076962"/>
    <geometry>
      <mesh filename="package://quadruped_description/meshes/servo_motor_v1_8.stl" scale="0.001 0.001 0.001"/>
    </geometry>
    <material name="silver"/>
  </visual>
  <collision>
    <origin rpy="0 0 0" xyz="0.076104 -0.068383 -0.076962"/>
    <geometry>
      <mesh filename="package://quadruped_description/meshes/servo_motor_v1_8.stl" scale="0.001 0.001 0.001"/>
    </geometry>
  </collision>
</link>

<link name="leg_servo_arm_v1_1">
  <inertial>
    <origin rpy="0 0 0" xyz="0.006854663369280534 0.009109263260319467 4.051724359702136e-07"/>
    <mass value="0.01005919143698447"/>
    <inertia ixx="1e-06" ixy="-1e-06" ixz="0.0" iyy="1e-06" iyz="0.0" izz="1e-06"/>
  </inertial>
  <visual>
    <origin rpy="0 0 0" xyz="-0.073499 -0.071111 -0.059877"/>
    <geometry>
      <mesh filename="package://quadruped_description/meshes/leg_servo_arm_v1_1.stl" scale="0.001 0.001 0.001"/>
    </geometry>
    <material name="silver"/>
  </visual>
  <collision>
    <origin rpy="0 0 0" xyz="-0.073499 -0.071111 -0.059877"/>
    <geometry>
      <mesh filename="package://quadruped_description/meshes/leg_servo_arm_v1_1.stl" scale="0.001 0.001 0.001"/>
    </geometry>
  </collision>
</link>

<link name="leg_servo_arm_v1_2">
  <inertial>
    <origin rpy="0 0 0" xyz="-0.006854688206024598 -0.009109229161363128 4.051727157394769e-07"/>
    <mass value="0.01005919143698447"/>
    <inertia ixx="1e-06" ixy="-1e-06" ixz="0.0" iyy="1e-06" iyz="0.0" izz="1e-06"/>
  </inertial>
  <visual>
    <origin rpy="0 0 0" xyz="0.073499 0.067913 -0.059877"/>
    <geometry>
      <mesh filename="package://quadruped_description/meshes/leg_servo_arm_v1_2.stl" scale="0.001 0.001 0.001"/>
    </geometry>
    <material name="silver"/>
  </visual>
  <collision>
    <origin rpy="0 0 0" xyz="0.073499 0.067913 -0.059877"/>
    <geometry>
      <mesh filename="package://quadruped_description/meshes/leg_servo_arm_v1_2.stl" scale="0.001 0.001 0.001"/>
    </geometry>
  </collision>
</link>

<link name="leg_servo_arm_v1_3">
  <inertial>
    <origin rpy="0 0 0" xyz="0.009108665796976917 -0.0068550719856114994 4.051727155868212e-07"/>
    <mass value="0.01005919143698447"/>
    <inertia ixx="1e-06" ixy="1e-06" ixz="-0.0" iyy="1e-06" iyz="0.0" izz="1e-06"/>
  </inertial>
  <visual>
    <origin rpy="0 0 0" xyz="-0.069514 0.071901 -0.059877"/>
    <geometry>
      <mesh filename="package://quadruped_description/meshes/leg_servo_arm_v1_3.stl" scale="0.001 0.001 0.001"/>
    </geometry>
    <material name="silver"/>
  </visual>
  <collision>
    <origin rpy="0 0 0" xyz="-0.069514 0.071901 -0.059877"/>
    <geometry>
      <mesh filename="package://quadruped_description/meshes/leg_servo_arm_v1_3.stl" scale="0.001 0.001 0.001"/>
    </geometry>
  </collision>
</link>

<link name="leg_servo_arm_v1_4">
  <inertial>
    <origin rpy="0 0 0" xyz="-0.00910869063372105 0.006855243623324056 4.0517243608817477e-07"/>
    <mass value="0.01005919143698447"/>
    <inertia ixx="1e-06" ixy="1e-06" ixz="-0.0" iyy="1e-06" iyz="0.0" izz="1e-06"/>
  </inertial>
  <visual>
    <origin rpy="0 0 0" xyz="0.069514 -0.074973 -0.059877"/>
    <geometry>
      <mesh filename="package://quadruped_description/meshes/leg_servo_arm_v1_4.stl" scale="0.001 0.001 0.001"/>
    </geometry>
    <material name="silver"/>
  </visual>
  <collision>
    <origin rpy="0 0 0" xyz="0.069514 -0.074973 -0.059877"/>
    <geometry>
      <mesh filename="package://quadruped_description/meshes/leg_servo_arm_v1_4.stl" scale="0.001 0.001 0.001"/>
    </geometry>
  </collision>
</link>

<link name="leg_rev_v1_1">
  <inertial>
    <origin rpy="0 0 0" xyz="0.0017515473433343115 -0.0003754399481460391 -0.0070623052238462936"/>
    <mass value="0.02607369115545735"/>
    <inertia ixx="1.5e-05" ixy="-0.0" ixz="1e-06" iyy="1.5e-05" iyz="1e-06" izz="1e-06"/>
  </inertial>
  <visual>
    <origin rpy="0 0 0" xyz="-0.09153 -0.089142 -0.059877"/>
    <geometry>
      <mesh filename="package://quadruped_description/meshes/leg_rev_v1_1.stl" scale="0.001 0.001 0.001"/>
    </geometry>
    <material name="silver"/>
  </visual>
  <collision>
    <origin rpy="0 0 0" xyz="-0.09153 -0.089142 -0.059877"/>
    <geometry>
      <mesh filename="package://quadruped_description/meshes/leg_rev_v1_1.stl" scale="0.001 0.001 0.001"/>
    </geometry>
  </collision>
</link>

<link name="leg_rev_v1_2">
  <inertial>
    <origin rpy="0 0 0" xyz="-0.0017515721800784034 0.00037547404710240595 -0.0070623052238461825"/>
    <mass value="0.02607369115545735"/>
    <inertia ixx="1.5e-05" ixy="-0.0" ixz="-1e-06" iyy="1.5e-05" iyz="-1e-06" izz="1e-06"/>
  </inertial>
  <visual>
    <origin rpy="0 0 0" xyz="0.09153 0.085944 -0.059877"/>
    <geometry>
      <mesh filename="package://quadruped_description/meshes/leg_rev_v1_2.stl" scale="0.001 0.001 0.001"/>
    </geometry>
    <material name="silver"/>
  </visual>
  <collision>
    <origin rpy="0 0 0" xyz="0.09153 0.085944 -0.059877"/>
    <geometry>
      <mesh filename="package://quadruped_description/meshes/leg_rev_v1_2.stl" scale="0.001 0.001 0.001"/>
    </geometry>
  </collision>
</link>

<link name="leg_rev_v1_3">
  <inertial>
    <origin rpy="0 0 0" xyz="-0.00037603741148850567 -0.001751955959665083 -0.0070623052238464185"/>
    <mass value="0.02607369115545735"/>
    <inertia ixx="1.5e-05" ixy="0.0" ixz="1e-06" iyy="1.5e-05" iyz="-1e-06" izz="1e-06"/>
  </inertial>
  <visual>
    <origin rpy="0 0 0" xyz="-0.087545 0.089932 -0.059877"/>
    <geometry>
      <mesh filename="package://quadruped_description/meshes/leg_rev_v1_3.stl" scale="0.001 0.001 0.001"/>
    </geometry>
    <material name="silver"/>
  </visual>
  <collision>
    <origin rpy="0 0 0" xyz="-0.087545 0.089932 -0.059877"/>
    <geometry>
      <mesh filename="package://quadruped_description/meshes/leg_rev_v1_3.stl" scale="0.001 0.001 0.001"/>
    </geometry>
  </collision>
</link>

<link name="leg_rev_v1_4">
  <inertial>
    <origin rpy="0 0 0" xyz="0.0003760125747445664 0.0017521275973778477 -0.007062305223845974"/>
    <mass value="0.02607369115545735"/>
    <inertia ixx="1.5e-05" ixy="0.0" ixz="-1e-06" iyy="1.5e-05" iyz="1e-06" izz="1e-06"/>
  </inertial>
  <visual>
    <origin rpy="0 0 0" xyz="0.087545 -0.093004 -0.059877"/>
    <geometry>
      <mesh filename="package://quadruped_description/meshes/leg_rev_v1_4.stl" scale="0.001 0.001 0.001"/>
    </geometry>
    <material name="silver"/>
  </visual>
  <collision>
    <origin rpy="0 0 0" xyz="0.087545 -0.093004 -0.059877"/>
    <geometry>
      <mesh filename="package://quadruped_description/meshes/leg_rev_v1_4.stl" scale="0.001 0.001 0.001"/>
    </geometry>
  </collision>
</link>

<link name="bottom_pivot_plate_v1_1">
  <inertial>
    <origin rpy="0 0 0" xyz="0.01000675765330758 0.010047118194641713 -0.0015933444235057687"/>
    <mass value="0.02183354723813213"/>
    <inertia ixx="2e-06" ixy="-2e-06" ixz="-0.0" iyy="2e-06" iyz="-0.0" izz="5e-06"/>
  </inertial>
  <visual>
    <origin rpy="0 0 0" xyz="-0.045406 -0.047003 -0.048402"/>
    <geometry>
      <mesh filename="package://quadruped_description/meshes/bottom_pivot_plate_v1_1.stl" scale="0.001 0.001 0.001"/>
    </geometry>
    <material name="silver"/>
  </visual>
  <collision>
    <origin rpy="0 0 0" xyz="-0.045406 -0.047003 -0.048402"/>
    <geometry>
      <mesh filename="package://quadruped_description/meshes/bottom_pivot_plate_v1_1.stl" scale="0.001 0.001 0.001"/>
    </geometry>
  </collision>
</link>

<link name="bottom_pivot_plate_v1_2">
  <inertial>
    <origin rpy="0 0 0" xyz="-0.010006782490051352 -0.010047084095685513 -0.0015933444235059352"/>
    <mass value="0.02183354723813213"/>
    <inertia ixx="2e-06" ixy="-2e-06" ixz="-0.0" iyy="2e-06" iyz="-0.0" izz="5e-06"/>
  </inertial>
  <visual>
    <origin rpy="0 0 0" xyz="0.045406 0.043805 -0.048402"/>
    <geometry>
      <mesh filename="package://quadruped_description/meshes/bottom_pivot_plate_v1_2.stl" scale="0.001 0.001 0.001"/>
    </geometry>
    <material name="silver"/>
  </visual>
  <collision>
    <origin rpy="0 0 0" xyz="0.045406 0.043805 -0.048402"/>
    <geometry>
      <mesh filename="package://quadruped_description/meshes/bottom_pivot_plate_v1_2.stl" scale="0.001 0.001 0.001"/>
    </geometry>
  </collision>
</link>

<link name="bottom_pivot_plate_v1_3">
  <inertial>
    <origin rpy="0 0 0" xyz="0.010046520731299052 -0.01000716626963865 -0.0015933444235056785"/>
    <mass value="0.02183354723813213"/>
    <inertia ixx="2e-06" ixy="2e-06" ixz="-0.0" iyy="2e-06" iyz="0.0" izz="5e-06"/>
  </inertial>
  <visual>
    <origin rpy="0 0 0" xyz="-0.045406 0.043808 -0.048402"/>
    <geometry>
      <mesh filename="package://quadruped_description/meshes/bottom_pivot_plate_v1_3.stl" scale="0.001 0.001 0.001"/>
    </geometry>
    <material name="silver"/>
  </visual>
  <collision>
    <origin rpy="0 0 0" xyz="-0.045406 0.043808 -0.048402"/>
    <geometry>
      <mesh filename="package://quadruped_description/meshes/bottom_pivot_plate_v1_3.stl" scale="0.001 0.001 0.001"/>
    </geometry>
  </collision>
</link>

<link name="bottom_pivot_plate_v1_4">
  <inertial>
    <origin rpy="0 0 0" xyz="-0.010046545568043012 0.010007337907350838 -0.0015933444235043462"/>
    <mass value="0.02183354723813213"/>
    <inertia ixx="2e-06" ixy="2e-06" ixz="0.0" iyy="2e-06" iyz="-0.0" izz="5e-06"/>
  </inertial>
  <visual>
    <origin rpy="0 0 0" xyz="0.045406 -0.04688 -0.048402"/>
    <geometry>
      <mesh filename="package://quadruped_description/meshes/bottom_pivot_plate_v1_4.stl" scale="0.001 0.001 0.001"/>
    </geometry>
    <material name="silver"/>
  </visual>
  <collision>
    <origin rpy="0 0 0" xyz="0.045406 -0.04688 -0.048402"/>
    <geometry>
      <mesh filename="package://quadruped_description/meshes/bottom_pivot_plate_v1_4.stl" scale="0.001 0.001 0.001"/>
    </geometry>
  </collision>
</link>

<link name="leg_parallel_linkage_v1_1">
  <inertial>
    <origin rpy="0 0 0" xyz="-0.01014265742637048 -0.007889057535331243 -5.5744720088138355e-05"/>
    <mass value="0.00766074441602388"/>
    <inertia ixx="0.0" ixy="-0.0" ixz="-0.0" iyy="0.0" iyz="-0.0" izz="1e-06"/>
  </inertial>
  <visual>
    <origin rpy="0 0 0" xyz="-0.09153 -0.089143 -0.077727"/>
    <geometry>
      <mesh filename="package://quadruped_description/meshes/leg_parallel_linkage_v1_1.stl" scale="0.001 0.001 0.001"/>
    </geometry>
    <material name="silver"/>
  </visual>
  <collision>
    <origin rpy="0 0 0" xyz="-0.09153 -0.089143 -0.077727"/>
    <geometry>
      <mesh filename="package://quadruped_description/meshes/leg_parallel_linkage_v1_1.stl" scale="0.001 0.001 0.001"/>
    </geometry>
  </collision>
</link>

<link name="leg_parallel_plate_v1_1">
  <inertial>
    <origin rpy="0 0 0" xyz="-0.004995391768741642 -0.007248720766343711 -0.008862222322955887"/>
    <mass value="0.014417433544657016"/>
    <inertia ixx="2e-06" ixy="-0.0" ixz="-0.0" iyy="2e-06" iyz="-0.0" izz="1e-06"/>
  </inertial>
  <visual>
    <origin rpy="0 0 0" xyz="-0.074112 -0.070498 -0.077616"/>
    <geometry>
      <mesh filename="package://quadruped_description/meshes/leg_parallel_plate_v1_1.stl" scale="0.001 0.001 0.001"/>
    </geometry>
    <material name="silver"/>
  </visual>
  <collision>
    <origin rpy="0 0 0" xyz="-0.074112 -0.070498 -0.077616"/>
    <geometry>
      <mesh filename="package://quadruped_description/meshes/leg_parallel_plate_v1_1.stl" scale="0.001 0.001 0.001"/>
    </geometry>
  </collision>
</link>

<link name="leg_parallel_linkage_v1_2">
  <inertial>
    <origin rpy="0 0 0" xyz="0.010142632589629483 0.007888091634290925 -5.5744719077946425e-05"/>
    <mass value="0.00766074441602388"/>
    <inertia ixx="0.0" ixy="-0.0" ixz="0.0" iyy="0.0" iyz="0.0" izz="1e-06"/>
  </inertial>
  <visual>
    <origin rpy="0 0 0" xyz="0.09153 0.085944 -0.077727"/>
    <geometry>
      <mesh filename="package://quadruped_description/meshes/leg_parallel_linkage_v1_2.stl" scale="0.001 0.001 0.001"/>
    </geometry>
    <material name="silver"/>
  </visual>
  <collision>
    <origin rpy="0 0 0" xyz="0.09153 0.085944 -0.077727"/>
    <geometry>
      <mesh filename="package://quadruped_description/meshes/leg_parallel_linkage_v1_2.stl" scale="0.001 0.001 0.001"/>
    </geometry>
  </collision>
</link>

<link name="leg_parallel_plate_v1_2">
  <inertial>
    <origin rpy="0 0 0" xyz="0.004995366931997147 0.007248754865300626 -0.008862222322955901"/>
    <mass value="0.014417433544657016"/>
    <inertia ixx="2e-06" ixy="-0.0" ixz="0.0" iyy="2e-06" iyz="0.0" izz="1e-06"/>
  </inertial>
  <visual>
    <origin rpy="0 0 0" xyz="0.074112 0.0673 -0.077616"/>
    <geometry>
      <mesh filename="package://quadruped_description/meshes/leg_parallel_plate_v1_2.stl" scale="0.001 0.001 0.001"/>
    </geometry>
    <material name="silver"/>
  </visual>
  <collision>
    <origin rpy="0 0 0" xyz="0.074112 0.0673 -0.077616"/>
    <geometry>
      <mesh filename="package://quadruped_description/meshes/leg_parallel_plate_v1_2.stl" scale="0.001 0.001 0.001"/>
    </geometry>
  </collision>
</link>

<link name="leg_parallel_linkage_v1_3">
  <inertial>
    <origin rpy="0 0 0" xyz="-0.007888654998673209 0.010142248810039722 -5.574472008829101e-05"/>
    <mass value="0.00766074441602388"/>
    <inertia ixx="0.0" ixy="0.0" ixz="-0.0" iyy="0.0" iyz="0.0" izz="1e-06"/>
  </inertial>
  <visual>
    <origin rpy="0 0 0" xyz="-0.087545 0.089932 -0.077727"/>
    <geometry>
      <mesh filename="package://quadruped_description/meshes/leg_parallel_linkage_v1_3.stl" scale="0.001 0.001 0.001"/>
    </geometry>
    <material name="silver"/>
  </visual>
  <collision>
    <origin rpy="0 0 0" xyz="-0.087545 0.089932 -0.077727"/>
    <geometry>
      <mesh filename="package://quadruped_description/meshes/leg_parallel_linkage_v1_3.stl" scale="0.001 0.001 0.001"/>
    </geometry>
  </collision>
</link>

<link name="leg_parallel_plate_v1_3">
  <inertial>
    <origin rpy="0 0 0" xyz="-0.007249318229685893 0.004994983152410745 -0.008862222322955901"/>
    <mass value="0.014417433544657016"/>
    <inertia ixx="2e-06" ixy="0.0" ixz="-0.0" iyy="2e-06" iyz="0.0" izz="1e-06"/>
  </inertial>
  <visual>
    <origin rpy="0 0 0" xyz="-0.068901 0.072514 -0.077616"/>
    <geometry>
      <mesh filename="package://quadruped_description/meshes/leg_parallel_plate_v1_3.stl" scale="0.001 0.001 0.001"/>
    </geometry>
    <material name="silver"/>
  </visual>
  <collision>
    <origin rpy="0 0 0" xyz="-0.068901 0.072514 -0.077616"/>
    <geometry>
      <mesh filename="package://quadruped_description/meshes/leg_parallel_plate_v1_3.stl" scale="0.001 0.001 0.001"/>
    </geometry>
  </collision>
</link>

<link name="leg_parallel_linkage_v1_4">
  <inertial>
    <origin rpy="0 0 0" xyz="0.007888630161932808 -0.010142077172330191 -5.574471907779377e-05"/>
    <mass value="0.00766074441602388"/>
    <inertia ixx="0.0" ixy="0.0" ixz="0.0" iyy="0.0" iyz="-0.0" izz="1e-06"/>
  </inertial>
  <visual>
    <origin rpy="0 0 0" xyz="0.087545 -0.093004 -0.077727"/>
    <geometry>
      <mesh filename="package://quadruped_description/meshes/leg_parallel_linkage_v1_4.stl" scale="0.001 0.001 0.001"/>
    </geometry>
    <material name="silver"/>
  </visual>
  <collision>
    <origin rpy="0 0 0" xyz="0.087545 -0.093004 -0.077727"/>
    <geometry>
      <mesh filename="package://quadruped_description/meshes/leg_parallel_linkage_v1_4.stl" scale="0.001 0.001 0.001"/>
    </geometry>
  </collision>
</link>

<link name="leg_parallel_plate_v1_4">
  <inertial>
    <origin rpy="0 0 0" xyz="0.007249293392942328 -0.004994811514697772 -0.00886222232295586"/>
    <mass value="0.014417433544657016"/>
    <inertia ixx="2e-06" ixy="0.0" ixz="0.0" iyy="2e-06" iyz="-0.0" izz="1e-06"/>
  </inertial>
  <visual>
    <origin rpy="0 0 0" xyz="0.068901 -0.075586 -0.077616"/>
    <geometry>
      <mesh filename="package://quadruped_description/meshes/leg_parallel_plate_v1_4.stl" scale="0.001 0.001 0.001"/>
    </geometry>
    <material name="silver"/>
  </visual>
  <collision>
    <origin rpy="0 0 0" xyz="0.068901 -0.075586 -0.077616"/>
    <geometry>
      <mesh filename="package://quadruped_description/meshes/leg_parallel_plate_v1_4.stl" scale="0.001 0.001 0.001"/>
    </geometry>
  </collision>
</link>

<joint name="Rigid1" type="fixed">
  <origin rpy="0 0 0" xyz="0.0 -0.041434 0.05924"/>
  <parent link="base_link"/>
  <child link="body_spacer_v1_1"/>
</joint>

<joint name="Rigid2" type="fixed">
  <origin rpy="0 0 0" xyz="0.0 0.044629 0.05924"/>
  <parent link="base_link"/>
  <child link="body_spacer_v1_2"/>
</joint>

<joint name="Rigid3" type="fixed">
  <origin rpy="0 0 0" xyz="-0.043031 0.001598 0.05924"/>
  <parent link="base_link"/>
  <child link="body_spacer_v1_3"/>
</joint>

<joint name="Rigid4" type="fixed">
  <origin rpy="0 0 0" xyz="0.043031 0.001598 0.05924"/>
  <parent link="base_link"/>
  <child link="body_spacer_v1_4"/>
</joint>

<joint name="Rigid5" type="fixed">
  <origin rpy="0 0 0" xyz="-1e-05 0.001603 0.073902"/>
  <parent link="base_link"/>
  <child link="body_top_plate_v1_1"/>
</joint>

<joint name="Rigid6" type="fixed">
  <origin rpy="0 0 0" xyz="0.045406 0.047003 0.088004"/>
  <parent link="base_link"/>
  <child link="servo_motor_v1_1"/>
</joint>

<joint name="Rigid7" type="fixed">
  <origin rpy="0 0 0" xyz="-0.045406 -0.043805 0.088004"/>
  <parent link="base_link"/>
  <child link="servo_motor_v1_2"/>
</joint>

<joint name="Rigid8" type="fixed">
  <origin rpy="0 0 0" xyz="0.045406 -0.043808 0.088004"/>
  <parent link="base_link"/>
  <child link="servo_motor_v1_3"/>
</joint>

<joint name="Rigid9" type="fixed">
  <origin rpy="0 0 0" xyz="-0.045406 0.04688 0.088004"/>
  <parent link="base_link"/>
  <child link="servo_motor_v1_4"/>
</joint>

<joint name="Rigid10" type="fixed">
  <origin rpy="0 0 0" xyz="-0.012081 -0.012081 -0.00932"/>
  <parent link="servo_motor_v1_1"/>
  <child link="leg_servo_retainer_v1_1"/>
</joint>

<joint name="Rigid11" type="fixed">
  <origin rpy="0 0 0" xyz="0.012081 0.012081 -0.00932"/>
  <parent link="servo_motor_v1_2"/>
  <child link="leg_servo_retainer_v1_2"/>
</joint>

<joint name="Rigid12" type="fixed">
  <origin rpy="0 0 0" xyz="-0.012081 0.012081 -0.00932"/>
  <parent link="servo_motor_v1_3"/>
  <child link="leg_servo_retainer_v1_3"/>
</joint>

<joint name="Rigid13" type="fixed">
  <origin rpy="0 0 0" xyz="0.012081 -0.012081 -0.00932"/>
  <parent link="servo_motor_v1_4"/>
  <child link="leg_servo_retainer_v1_4"/>
</joint>

<joint name="Rev14" type="continuous">
  <origin rpy="0 0 0" xyz="0.0 0.0 0.0"/>
  <parent link="servo_motor_v1_1"/>
  <child link="leg_top_pivot_plate_v1_1"/>
  <axis xyz="0.0 -0.0 1.0"/>
</joint>

<joint name="Rev15" type="continuous">
  <origin rpy="0 0 0" xyz="0.0 0.0 0.0"/>
  <parent link="servo_motor_v1_2"/>
  <child link="leg_top_pivot_plate_v1_2"/>
  <axis xyz="-0.0 -0.0 1.0"/>
</joint>

<joint name="Rev16" type="continuous">
  <origin rpy="0 0 0" xyz="0.0 0.0 0.0"/>
  <parent link="servo_motor_v1_3"/>
  <child link="leg_top_pivot_plate_v1_3"/>
  <axis xyz="0.0 -0.0 1.0"/>
</joint>

<joint name="Rev17" type="continuous">
  <origin rpy="0 0 0" xyz="0.0 0.0 0.0"/>
  <parent link="servo_motor_v1_4"/>
  <child link="leg_top_pivot_plate_v1_4"/>
  <axis xyz="0.0 -0.0 1.0"/>
</joint>

<joint name="Rigid18" type="fixed">
  <origin rpy="0 0 0" xyz="0.012883 0.02208 -0.011475"/>
  <parent link="leg_top_pivot_plate_v1_1"/>
  <child link="leg_servo_mount_v1_1"/>
</joint>

<joint name="Rigid19" type="fixed">
  <origin rpy="0 0 0" xyz="-0.012883 -0.02208 -0.011475"/>
  <parent link="leg_top_pivot_plate_v1_2"/>
  <child link="leg_servo_mount_v1_2"/>
</joint>

<joint name="Rigid20" type="fixed">
  <origin rpy="0 0 0" xyz="0.022079 -0.012884 -0.011475"/>
  <parent link="leg_top_pivot_plate_v1_3"/>
  <child link="leg_servo_mount_v1_3"/>
</joint>

<joint name="Rigid21" type="fixed">
  <origin rpy="0 0 0" xyz="-0.022079 0.012884 -0.011475"/>
  <parent link="leg_top_pivot_plate_v1_4"/>
  <child link="leg_servo_mount_v1_4"/>
</joint>

<joint name="Rigid22" type="fixed">
  <origin rpy="0 0 0" xyz="0.008619 0.008619 0.000433"/>
  <parent link="leg_servo_mount_v1_1"/>
  <child link="servo_motor_v1_5"/>
</joint>

<joint name="Rigid23" type="fixed">
  <origin rpy="0 0 0" xyz="-0.008619 -0.008619 0.000433"/>
  <parent link="leg_servo_mount_v1_2"/>
  <child link="servo_motor_v1_6"/>
</joint>

<joint name="Rigid24" type="fixed">
  <origin rpy="0 0 0" xyz="0.008619 -0.008619 0.000433"/>
  <parent link="leg_servo_mount_v1_3"/>
  <child link="servo_motor_v1_7"/>
</joint>

<joint name="Rigid25" type="fixed">
  <origin rpy="0 0 0" xyz="-0.008619 0.008619 0.000433"/>
  <parent link="leg_servo_mount_v1_4"/>
  <child link="servo_motor_v1_8"/>
</joint>

<joint name="Rev26" type="continuous">
  <origin rpy="0 0 0" xyz="0.006591 -0.006591 -0.017085"/>
  <parent link="servo_motor_v1_5"/>
  <child link="leg_servo_arm_v1_1"/>
  <axis xyz="0.707107 -0.707107 -0.0"/>
</joint>

<joint name="Rev27" type="continuous">
  <origin rpy="0 0 0" xyz="-0.006591 0.006591 -0.017085"/>
  <parent link="servo_motor_v1_6"/>
  <child link="leg_servo_arm_v1_2"/>
  <axis xyz="-0.707107 0.707107 0.0"/>
</joint>

<joint name="Rev28" type="continuous">
  <origin rpy="0 0 0" xyz="-0.00659 -0.00659 -0.017085"/>
  <parent link="servo_motor_v1_7"/>
  <child link="leg_servo_arm_v1_3"/>
  <axis xyz="-0.707107 -0.707107 0.0"/>
</joint>

<joint name="Rev29" type="continuous">
  <origin rpy="0 0 0" xyz="0.00659 0.00659 -0.017085"/>
  <parent link="servo_motor_v1_8"/>
  <child link="leg_servo_arm_v1_4"/>
  <axis xyz="0.707107 0.707107 -0.0"/>
</joint>

<joint name="Rev30" type="continuous">
  <origin rpy="0 0 0" xyz="0.018031 0.018031 0.0"/>
  <parent link="leg_servo_arm_v1_1"/>
  <child link="leg_rev_v1_1"/>
  <axis xyz="-0.707107 0.707107 0.0"/>
</joint>

<joint name="Rev31" type="continuous">
  <origin rpy="0 0 0" xyz="-0.018031 -0.018031 0.0"/>
  <parent link="leg_servo_arm_v1_2"/>
  <child link="leg_rev_v1_2"/>
  <axis xyz="-0.707107 0.707107 0.0"/>
</joint>

<joint name="Rev32" type="continuous">
  <origin rpy="0 0 0" xyz="0.018031 -0.018031 0.0"/>
  <parent link="leg_servo_arm_v1_3"/>
  <child link="leg_rev_v1_3"/>
  <axis xyz="-0.707107 -0.707107 0.0"/>
</joint>

<joint name="Rev33" type="continuous">
  <origin rpy="0 0 0" xyz="-0.018031 0.018031 0.0"/>
  <parent link="leg_servo_arm_v1_4"/>
  <child link="leg_rev_v1_4"/>
  <axis xyz="-0.707107 -0.707107 0.0"/>
</joint>

<joint name="Rev34" type="continuous">
  <origin rpy="0 0 0" xyz="0.045406 0.047003 0.048402"/>
  <parent link="base_link"/>
  <child link="bottom_pivot_plate_v1_1"/>
  <axis xyz="-0.0 -0.0 1.0"/>
</joint>

<joint name="Rev35" type="continuous">
  <origin rpy="0 0 0" xyz="-0.045406 -0.043805 0.048402"/>
  <parent link="base_link"/>
  <child link="bottom_pivot_plate_v1_2"/>
  <axis xyz="-0.0 -0.0 1.0"/>
</joint>

<joint name="Rev36" type="continuous">
  <origin rpy="0 0 0" xyz="0.045406 -0.043808 0.048402"/>
  <parent link="base_link"/>
  <child link="bottom_pivot_plate_v1_3"/>
  <axis xyz="-0.0 -0.0 1.0"/>
</joint>

<joint name="Rev37" type="continuous">
  <origin rpy="0 0 0" xyz="-0.045406 0.04688 0.048402"/>
  <parent link="base_link"/>
  <child link="bottom_pivot_plate_v1_4"/>
  <axis xyz="-0.0 -0.0 1.0"/>
</joint>

<joint name="Rev42" type="continuous">
  <origin rpy="0 0 0" xyz="0.0 1e-06 0.01785"/>
  <parent link="leg_rev_v1_1"/>
  <child link="leg_parallel_linkage_v1_1"/>
  <axis xyz="0.707107 -0.707107 -0.0"/>
</joint>

<joint name="Rev43" type="continuous">
  <origin rpy="0 0 0" xyz="-0.017418 -0.018645 -0.000111"/>
  <parent link="leg_parallel_linkage_v1_1"/>
  <child link="leg_parallel_plate_v1_1"/>
  <axis xyz="0.707107 -0.707107 -0.0"/>
</joint>

<joint name="Rev44" type="continuous">
  <origin rpy="0 0 0" xyz="0.0 0.0 0.01785"/>
  <parent link="leg_rev_v1_2"/>
  <child link="leg_parallel_linkage_v1_2"/>
  <axis xyz="-0.707107 0.707107 0.0"/>
</joint>

<joint name="Rev45" type="continuous">
  <origin rpy="0 0 0" xyz="0.017418 0.018644 -0.000111"/>
  <parent link="leg_parallel_linkage_v1_2"/>
  <child link="leg_parallel_plate_v1_2"/>
  <axis xyz="0.707107 -0.707107 -0.0"/>
</joint>

<joint name="Rev46" type="continuous">
  <origin rpy="0 0 0" xyz="0.0 0.0 0.01785"/>
  <parent link="leg_rev_v1_3"/>
  <child link="leg_parallel_linkage_v1_3"/>
  <axis xyz="-0.707107 -0.707107 0.0"/>
</joint>

<joint name="Rev47" type="continuous">
  <origin rpy="0 0 0" xyz="-0.018644 0.017418 -0.000111"/>
  <parent link="leg_parallel_linkage_v1_3"/>
  <child link="leg_parallel_plate_v1_3"/>
  <axis xyz="-0.707107 -0.707107 0.0"/>
</joint>

<joint name="Rev48" type="continuous">
  <origin rpy="0 0 0" xyz="0.0 0.0 0.01785"/>
  <parent link="leg_rev_v1_4"/>
  <child link="leg_parallel_linkage_v1_4"/>
  <axis xyz="0.707107 0.707107 -0.0"/>
</joint>

<joint name="Rev49" type="continuous">
  <origin rpy="0 0 0" xyz="0.018644 -0.017418 -0.000111"/>
  <parent link="leg_parallel_linkage_v1_4"/>
  <child link="leg_parallel_plate_v1_4"/>
  <axis xyz="-0.707107 -0.707107 0.0"/>
</joint>

</robot>
