<?xml version="1.0" ?>
<sdf version="1.6">
	<model name="quadruped">
		<link name="quadruped_body">
			<self_collide>false</self_collide>
			<pose frame="">0.009054617693526444 0.010954550696905674 -0.05424821339808461 0.0 -0.0 0.0</pose>
			<inertial>
				<pose frame="">0.0 0.0 0.0 0 0 0</pose>
				<mass>0.0935834215818616</mass>
				<inertia>
					<ixx>0.00045713170993534694</ixx>
					<ixy>4.052495762946136e-05</ixy>
					<ixz>4.955015390422573e-05</ixz>
					<iyy>0.00045300290747356806</iyy>
					<iyz>6.061278298104605e-05</iyz>
					<izz>0.00013966679884245075</izz>
				</inertia>
			</inertial>
			<collision name="quadruped_body_collision">
				<geometry>
					<mesh>
						<uri>model://quadruped/meshes/CAD/quadruped_body.stl</uri>
						<scale>0.001 0.001 0.001</scale>
					</mesh>
				</geometry>
			</collision>
			<visual name="quadruped_body_visual">
				<geometry>
					<mesh>
						<uri>model://quadruped/meshes/CAD/quadruped_body.stl</uri>
						<scale>0.001 0.001 0.001</scale>
					</mesh>
				</geometry>
			</visual>
		</link>
		<link name="hip_servo_servo_mount_1">
			<self_collide>false</self_collide>
			<pose frame="">0.012890375611817766 0.014871195556350914 0.005375114470529469 0.0 -0.0 0.0</pose>
			<inertial>
				<pose frame="">0.0 0.0 0.0 0 0 0</pose>
				<mass>0.013632986173772196</mass>
				<inertia>
					<ixx>4.770315520251754e-06</ixx>
					<ixy>-2.8290059779284048e-06</ixy>
					<ixz>-9.790741818784368e-07</ixz>
					<iyy>4.022409904501968e-06</iyy>
					<iyz>-1.1249989284580146e-06</iyz>
					<izz>6.305847008255539e-06</izz>
				</inertia>
			</inertial>
			<collision name="hip_servo_servo_mount_1_collision">
				<geometry>
					<mesh>
						<uri>model://quadruped/meshes/CAD/hip_servo_servo_mount_1.stl</uri>
						<scale>0.001 0.001 0.001</scale>
					</mesh>
				</geometry>
			</collision>
			<visual name="hip_servo_servo_mount_1_visual">
				<geometry>
					<mesh>
						<uri>model://quadruped/meshes/CAD/hip_servo_servo_mount_1.stl</uri>
						<scale>0.001 0.001 0.001</scale>
					</mesh>
				</geometry>
			</visual>
		</link>
		<link name="hip_servo_servo_mount_2">
			<self_collide>false</self_collide>
			<pose frame="">-0.02620632332338188 0.059236573256571286 -0.053686074613440805 0.0 -0.0 0.0</pose>
			<inertial>
				<pose frame="">0.0 0.0 0.0 0 0 0</pose>
				<mass>0.013632986173875754</mass>
				<inertia>
					<ixx>8.827411643680424e-05</ixx>
					<ixy>2.1218168598137407e-05</ixy>
					<ixz>-1.9197254904825403e-05</ixz>
					<iyy>4.968616068294264e-05</iyy>
					<iyz>4.3334687147887475e-05</iyz>
					<izz>5.87768823095126e-05</izz>
				</inertia>
			</inertial>
			<collision name="hip_servo_servo_mount_2_collision">
				<geometry>
					<mesh>
						<uri>model://quadruped/meshes/CAD/hip_servo_servo_mount_2.stl</uri>
						<scale>0.001 0.001 0.001</scale>
					</mesh>
				</geometry>
			</collision>
			<visual name="hip_servo_servo_mount_2_visual">
				<geometry>
					<mesh>
						<uri>model://quadruped/meshes/CAD/hip_servo_servo_mount_2.stl</uri>
						<scale>0.001 0.001 0.001</scale>
					</mesh>
				</geometry>
			</visual>
		</link>
		<link name="hip_servo_servo_mount_3">
			<self_collide>false</self_collide>
			<pose frame="">0.018095238187563277 0.019844180002299153 -0.11277707275426496 0.0 -0.0 0.0</pose>
			<inertial>
				<pose frame="">0.0 0.0 0.0 0 0 0</pose>
				<mass>0.013632986173729874</mass>
				<inertia>
					<ixx>0.00018011641699017185</ixx>
					<ixy>-5.117862140018571e-06</ixy>
					<ixz>2.7865925192958343e-05</ixz>
					<iyy>0.0001792139882746836</iyy>
					<iyz>3.055380216979061e-05</iyz>
					<izz>1.0871770428207131e-05</izz>
				</inertia>
			</inertial>
			<collision name="hip_servo_servo_mount_3_collision">
				<geometry>
					<mesh>
						<uri>model://quadruped/meshes/CAD/hip_servo_servo_mount_3.stl</uri>
						<scale>0.001 0.001 0.001</scale>
					</mesh>
				</geometry>
			</collision>
			<visual name="hip_servo_servo_mount_3_visual">
				<geometry>
					<mesh>
						<uri>model://quadruped/meshes/CAD/hip_servo_servo_mount_3.stl</uri>
						<scale>0.001 0.001 0.001</scale>
					</mesh>
				</geometry>
			</visual>
		</link>
		<link name="hip_servo_servo_mount_4">
			<self_collide>false</self_collide>
			<pose frame="">0.05725081501790624 -0.024588009958613738 -0.0536269405918244 0.0 -0.0 0.0</pose>
			<inertial>
				<pose frame="">0.0 0.0 0.0 0 0 0</pose>
				<mass>0.013632986173875919</mass>
				<inertia>
					<ixx>4.847956572880788e-05</ixx>
					<ixy>1.924611994008176e-05</ixy>
					<ixz>4.183404976019748e-05</ixz>
					<iyy>8.50335336726935e-05</iyy>
					<iyz>-1.7992094998200576e-05</iyz>
					<izz>5.450269005330134e-05</izz>
				</inertia>
			</inertial>
			<collision name="hip_servo_servo_mount_4_collision">
				<geometry>
					<mesh>
						<uri>model://quadruped/meshes/CAD/hip_servo_servo_mount_4.stl</uri>
						<scale>0.001 0.001 0.001</scale>
					</mesh>
				</geometry>
			</collision>
			<visual name="hip_servo_servo_mount_4_visual">
				<geometry>
					<mesh>
						<uri>model://quadruped/meshes/CAD/hip_servo_servo_mount_4.stl</uri>
						<scale>0.001 0.001 0.001</scale>
					</mesh>
				</geometry>
			</visual>
		</link>
		<link name="thigh_1">
			<self_collide>false</self_collide>
			<pose frame="">0.004842947358440601 0.004025416538531608 0.03352698125834973 0.0 -0.0 0.0</pose>
			<inertial>
				<pose frame="">0.0 0.0 0.0 0 0 0</pose>
				<mass>0.05521421604479793</mass>
				<inertia>
					<ixx>8.12142496090186e-05</ixx>
					<ixy>-4.289284220261144e-06</ixy>
					<ixz>-1.2997402871583983e-05</ixz>
					<iyy>8.197817458363166e-05</iyy>
					<iyz>-8.580936505269728e-06</iyz>
					<izz>1.7016506462837022e-05</izz>
				</inertia>
			</inertial>
			<collision name="thigh_1_collision">
				<geometry>
					<mesh>
						<uri>model://quadruped/meshes/CAD/thigh_1.stl</uri>
						<scale>0.001 0.001 0.001</scale>
					</mesh>
				</geometry>
			</collision>
			<visual name="thigh_1_visual">
				<geometry>
					<mesh>
						<uri>model://quadruped/meshes/CAD/thigh_1.stl</uri>
						<scale>0.001 0.001 0.001</scale>
					</mesh>
				</geometry>
			</visual>
		</link>
		<link name="thigh_2">
			<self_collide>false</self_collide>
			<pose frame="">-0.054910586133422846 0.07145614961108687 -0.052393391524586094 0.0 -0.0 0.0</pose>
			<inertial>
				<pose frame="">0.0 0.0 0.0 0 0 0</pose>
				<mass>0.05521421601019442</mass>
				<inertia>
					<ixx>0.00045206492163734534</ixx>
					<ixy>0.00021641294327883327</ixy>
					<ixz>-0.00015776301586801415</ixz>
					<iyy>0.0003295821695272492</iyy>
					<iyz>0.00020462149987292915</iyz>
					<izz>0.00046999421699915367</izz>
				</inertia>
			</inertial>
			<collision name="thigh_2_collision">
				<geometry>
					<mesh>
						<uri>model://quadruped/meshes/CAD/thigh_2.stl</uri>
						<scale>0.001 0.001 0.001</scale>
					</mesh>
				</geometry>
			</collision>
			<visual name="thigh_2_visual">
				<geometry>
					<mesh>
						<uri>model://quadruped/meshes/CAD/thigh_2.stl</uri>
						<scale>0.001 0.001 0.001</scale>
					</mesh>
				</geometry>
			</visual>
		</link>
		<link name="thigh_3">
			<self_collide>false</self_collide>
			<pose frame="">0.00970961671144424 0.014320953108746983 -0.14234224145240565 0.0 -0.0 0.0</pose>
			<inertial>
				<pose frame="">0.0 0.0 0.0 0 0 0</pose>
				<mass>0.055214216042986965</mass>
				<inertia>
					<ixx>0.0011484291742198435</ixx>
					<ixy>-1.1336606396544214e-05</ixy>
					<ixz>7.744122923151141e-05</ixz>
					<iyy>0.0011415143913118115</iyy>
					<iyz>0.00011651204828828122</iyz>
					<izz>3.2241627968361466e-05</izz>
				</inertia>
			</inertial>
			<collision name="thigh_3_collision">
				<geometry>
					<mesh>
						<uri>model://quadruped/meshes/CAD/thigh_3.stl</uri>
						<scale>0.001 0.001 0.001</scale>
					</mesh>
				</geometry>
			</collision>
			<visual name="thigh_3_visual">
				<geometry>
					<mesh>
						<uri>model://quadruped/meshes/CAD/thigh_3.stl</uri>
						<scale>0.001 0.001 0.001</scale>
					</mesh>
				</geometry>
			</visual>
		</link>
		<link name="thigh_4">
			<self_collide>false</self_collide>
			<pose frame="">0.06951831849474113 -0.053171881524671026 -0.05634433518873474 0.0 -0.0 0.0</pose>
			<inertial>
				<pose frame="">0.0 0.0 0.0 0 0 0</pose>
				<mass>0.05521421601038229</mass>
				<inertia>
					<ixx>0.0003426437411902573</ixx>
					<ixy>0.0002038590127636044</ixy>
					<ixz>0.00021745761572754168</ixz>
					<iyy>0.0004609166183581892</iyy>
					<iyz>-0.00016678770737829675</iyz>
					<izz>0.00044460338465351673</izz>
				</inertia>
			</inertial>
			<collision name="thigh_4_collision">
				<geometry>
					<mesh>
						<uri>model://quadruped/meshes/CAD/thigh_4.stl</uri>
						<scale>0.001 0.001 0.001</scale>
					</mesh>
				</geometry>
			</collision>
			<visual name="thigh_4_visual">
				<geometry>
					<mesh>
						<uri>model://quadruped/meshes/CAD/thigh_4.stl</uri>
						<scale>0.001 0.001 0.001</scale>
					</mesh>
				</geometry>
			</visual>
		</link>
		<link name="servo_arm_1">
			<self_collide>false</self_collide>
			<pose frame="">-0.0038155932955904475 -0.0001595397539787395 0.057327534866425174 0.0 -0.0 0.0</pose>
			<inertial>
				<pose frame="">0.0 0.0 0.0 0 0 0</pose>
				<mass>0.0022438611558734008</mass>
				<inertia>
					<ixx>7.628003161628189e-06</ixx>
					<ixy>-5.708298101394665e-08</ixy>
					<ixz>5.719690192606934e-07</ixz>
					<iyy>7.656776136791976e-06</iyy>
					<iyz>1.0553943572059742e-07</iyz>
					<izz>1.4895110505216374e-07</izz>
				</inertia>
			</inertial>
			<collision name="servo_arm_1_collision">
				<geometry>
					<mesh>
						<uri>model://quadruped/meshes/CAD/servo_arm_1.stl</uri>
						<scale>0.001 0.001 0.001</scale>
					</mesh>
				</geometry>
			</collision>
			<visual name="servo_arm_1_visual">
				<geometry>
					<mesh>
						<uri>model://quadruped/meshes/CAD/servo_arm_1.stl</uri>
						<scale>0.001 0.001 0.001</scale>
					</mesh>
				</geometry>
			</visual>
		</link>
		<link name="leg_parallel_linkage_1">
			<self_collide>false</self_collide>
			<pose frame="">0.008722875425727018 0.012470639676602247 0.058378072879620053 0.0 -0.0 0.0</pose>
			<inertial>
				<pose frame="">0.0 0.0 0.0 0 0 0</pose>
				<mass>0.007982467116690367</mass>
				<inertia>
					<ixx>2.9231818847212213e-05</ixx>
					<ixy>-1.0326589470064662e-06</ixy>
					<ixz>-3.7867951165163097e-06</ixz>
					<iyy>2.8595493348213505e-05</iyy>
					<iyz>-5.530824270769201e-06</iyz>
					<izz>2.192019385321037e-06</izz>
				</inertia>
			</inertial>
			<collision name="leg_parallel_linkage_1_collision">
				<geometry>
					<mesh>
						<uri>model://quadruped/meshes/CAD/leg_parallel_linkage_1.stl</uri>
						<scale>0.001 0.001 0.001</scale>
					</mesh>
				</geometry>
			</collision>
			<visual name="leg_parallel_linkage_1_visual">
				<geometry>
					<mesh>
						<uri>model://quadruped/meshes/CAD/leg_parallel_linkage_1.stl</uri>
						<scale>0.001 0.001 0.001</scale>
					</mesh>
				</geometry>
			</visual>
		</link>
		<link name="rev_1">
			<self_collide>false</self_collide>
			<pose frame="">-0.014956736523691297 -0.006505495167599255 0.06774557776623814 0.0 -0.0 0.0</pose>
			<inertial>
				<pose frame="">0.0 0.0 0.0 0 0 0</pose>
				<mass>0.005624431830191916</mass>
				<inertia>
					<ixx>2.7664699935707817e-05</ixx>
					<ixy>-2.0546124685621124e-06</ixy>
					<ixz>5.702763789707963e-06</ixz>
					<iyy>2.868078623704316e-05</iyy>
					<iyz>2.48239388023016e-06</iyz>
					<izz>4.521308604942144e-06</izz>
				</inertia>
			</inertial>
			<collision name="rev_1_collision">
				<geometry>
					<mesh>
						<uri>model://quadruped/meshes/CAD/rev_1.stl</uri>
						<scale>0.001 0.001 0.001</scale>
					</mesh>
				</geometry>
			</collision>
			<visual name="rev_1_visual">
				<geometry>
					<mesh>
						<uri>model://quadruped/meshes/CAD/rev_1.stl</uri>
						<scale>0.001 0.001 0.001</scale>
					</mesh>
				</geometry>
			</visual>
		</link>
		<link name="leg_parallel_linkage_2">
			<self_collide>false</self_collide>
			<pose frame="">-0.0613832306482158 0.10207701283128444 -0.05461715389430609 0.0 -0.0 0.0</pose>
			<inertial>
				<pose frame="">0.0 0.0 0.0 0 0 0</pose>
				<mass>0.007982467055746728</mass>
				<inertia>
					<ixx>0.00010744877827830509</ixx>
					<ixy>5.0434906825768446e-05</ixy>
					<ixz>-2.6762834491072075e-05</ixz>
					<iyy>5.439145313859798e-05</iyy>
					<iyz>4.450036414485024e-05</iyz>
					<izz>0.00011420136152249155</izz>
				</inertia>
			</inertial>
			<collision name="leg_parallel_linkage_2_collision">
				<geometry>
					<mesh>
						<uri>model://quadruped/meshes/CAD/leg_parallel_linkage_2.stl</uri>
						<scale>0.001 0.001 0.001</scale>
					</mesh>
				</geometry>
			</collision>
			<visual name="leg_parallel_linkage_2_visual">
				<geometry>
					<mesh>
						<uri>model://quadruped/meshes/CAD/leg_parallel_linkage_2.stl</uri>
						<scale>0.001 0.001 0.001</scale>
					</mesh>
				</geometry>
			</visual>
		</link>
		<link name="servo_arm_2">
			<self_collide>false</self_collide>
			<pose frame="">-0.07403096483651968 0.08959456706172894 -0.055596059476907586 0.0 -0.0 0.0</pose>
			<inertial>
				<pose frame="">0.0 0.0 0.0 0 0 0</pose>
				<mass>0.00224386113073181</mass>
				<inertia>
					<ixx>2.5096354128403615e-05</ixx>
					<ixy>1.5006939654397603e-05</ixy>
					<ixz>-9.23425417836217e-06</ixz>
					<iyy>1.9396706507812125e-05</iyy>
					<iyz>1.1173600946845037e-05</iyz>
					<izz>3.06168814488621e-05</izz>
				</inertia>
			</inertial>
			<collision name="servo_arm_2_collision">
				<geometry>
					<mesh>
						<uri>model://quadruped/meshes/CAD/servo_arm_2.stl</uri>
						<scale>0.001 0.001 0.001</scale>
					</mesh>
				</geometry>
			</collision>
			<visual name="servo_arm_2_visual">
				<geometry>
					<mesh>
						<uri>model://quadruped/meshes/CAD/servo_arm_2.stl</uri>
						<scale>0.001 0.001 0.001</scale>
					</mesh>
				</geometry>
			</visual>
		</link>
		<link name="rev_2">
			<self_collide>false</self_collide>
			<pose frame="">-0.087048114238072 0.09502142118027308 -0.05929945349265844 0.0 -0.0 0.0</pose>
			<inertial>
				<pose frame="">0.0 0.0 0.0 0 0 0</pose>
				<mass>0.005624431830191929</mass>
				<inertia>
					<ixx>7.193152040041056e-05</ixx>
					<ixy>4.5080426226688786e-05</ixy>
					<ixz>-2.9163908227444e-05</ixz>
					<iyy>6.416538525055506e-05</iyy>
					<iyz>3.157756091344109e-05</iyz>
					<izz>9.651057777817644e-05</izz>
				</inertia>
			</inertial>
			<collision name="rev_2_collision">
				<geometry>
					<mesh>
						<uri>model://quadruped/meshes/CAD/rev_2.stl</uri>
						<scale>0.001 0.001 0.001</scale>
					</mesh>
				</geometry>
			</collision>
			<visual name="rev_2_visual">
				<geometry>
					<mesh>
						<uri>model://quadruped/meshes/CAD/rev_2.stl</uri>
						<scale>0.001 0.001 0.001</scale>
					</mesh>
				</geometry>
			</visual>
		</link>
		<link name="leg_parallel_linkage_3">
			<self_collide>false</self_collide>
			<pose frame="">0.025313599222881775 0.02526480371269189 -0.16751755105470573 0.0 -0.0 0.0</pose>
			<inertial>
				<pose frame="">0.0 0.0 0.0 0 0 0</pose>
				<mass>0.007982467096390607</mass>
				<inertia>
					<ixx>0.0002300237532206378</ixx>
					<ixy>-5.131107872748828e-06</ixy>
					<ixz>3.3884042916457697e-05</ixz>
					<iyy>0.00023004332571709767</iyy>
					<iyz>3.38226651292879e-05</iyz>
					<izz>1.0276824178552738e-05</izz>
				</inertia>
			</inertial>
			<collision name="leg_parallel_linkage_3_collision">
				<geometry>
					<mesh>
						<uri>model://quadruped/meshes/CAD/leg_parallel_linkage_3.stl</uri>
						<scale>0.001 0.001 0.001</scale>
					</mesh>
				</geometry>
			</collision>
			<visual name="leg_parallel_linkage_3_visual">
				<geometry>
					<mesh>
						<uri>model://quadruped/meshes/CAD/leg_parallel_linkage_3.stl</uri>
						<scale>0.001 0.001 0.001</scale>
					</mesh>
				</geometry>
			</visual>
		</link>
		<link name="servo_arm_3">
			<self_collide>false</self_collide>
			<pose frame="">0.012657356645934717 0.01280910745801404 -0.16867939764379017 0.0 -0.0 0.0</pose>
			<inertial>
				<pose frame="">0.0 0.0 0.0 0 0 0</pose>
				<mass>0.0022438611484091367</mass>
				<inertia>
					<ixx>6.450568659045674e-05</ixx>
					<ixy>-3.7781764429265974e-07</ixy>
					<ixz>4.798268887463355e-06</ixz>
					<iyy>6.449672515627232e-05</iyy>
					<iyz>4.8607265678922885e-06</iyz>
					<izz>7.604898387011911e-07</izz>
				</inertia>
			</inertial>
			<collision name="servo_arm_3_collision">
				<geometry>
					<mesh>
						<uri>model://quadruped/meshes/CAD/servo_arm_3.stl</uri>
						<scale>0.001 0.001 0.001</scale>
					</mesh>
				</geometry>
			</collision>
			<visual name="servo_arm_3_visual">
				<geometry>
					<mesh>
						<uri>model://quadruped/meshes/CAD/servo_arm_3.stl</uri>
						<scale>0.001 0.001 0.001</scale>
					</mesh>
				</geometry>
			</visual>
		</link>
		<link name="rev_3">
			<self_collide>false</self_collide>
			<pose frame="">0.011862439649475386 0.007264037751315852 -0.18201299683605737 0.0 -0.0 0.0</pose>
			<inertial>
				<pose frame="">0.0 0.0 0.0 0 0 0</pose>
				<mass>0.005624431830191915</mass>
				<inertia>
					<ixx>0.00018824726204434965</ixx>
					<ixy>-1.9683369115967987e-06</ixy>
					<ixz>1.1882190102463169e-05</ixz>
					<iyy>0.00018877173426364797</iyy>
					<iyz>7.177153678524456e-06</iyz>
					<izz>4.066118038621946e-06</izz>
				</inertia>
			</inertial>
			<collision name="rev_3_collision">
				<geometry>
					<mesh>
						<uri>model://quadruped/meshes/CAD/rev_3.stl</uri>
						<scale>0.001 0.001 0.001</scale>
					</mesh>
				</geometry>
			</collision>
			<visual name="rev_3_visual">
				<geometry>
					<mesh>
						<uri>model://quadruped/meshes/CAD/rev_3.stl</uri>
						<scale>0.001 0.001 0.001</scale>
					</mesh>
				</geometry>
			</visual>
		</link>
		<link name="leg_parallel_linkage_4">
			<self_collide>false</self_collide>
			<pose frame="">0.10008155633799799 -0.05981501205053356 -0.052063302584425895 0.0 -0.0 0.0</pose>
			<inertial>
				<pose frame="">0.0 0.0 0.0 0 0 0</pose>
				<mass>0.007982467055742806</mass>
				<inertia>
					<ixx>5.0680803262747654e-05</ixx>
					<ixy>4.820479141742971e-05</ixy>
					<ixz>4.1593481171961155e-05</ixz>
					<iyy>0.00010207254897915004</iyy>
					<iyz>-2.4863156929063334e-05</iyz>
					<izz>0.00010946404474064915</izz>
				</inertia>
			</inertial>
			<collision name="leg_parallel_linkage_4_collision">
				<geometry>
					<mesh>
						<uri>model://quadruped/meshes/CAD/leg_parallel_linkage_4.stl</uri>
						<scale>0.001 0.001 0.001</scale>
					</mesh>
				</geometry>
			</collision>
			<visual name="leg_parallel_linkage_4_visual">
				<geometry>
					<mesh>
						<uri>model://quadruped/meshes/CAD/leg_parallel_linkage_4.stl</uri>
						<scale>0.001 0.001 0.001</scale>
					</mesh>
				</geometry>
			</visual>
		</link>
		<link name="servo_arm_4">
			<self_collide>false</self_collide>
			<pose frame="">0.08755557564706509 -0.07239962553009151 -0.05324834673514424 0.0 -0.0 0.0</pose>
			<inertial>
				<pose frame="">0.0 0.0 0.0 0 0 0</pose>
				<mass>0.002243861130718795</mass>
				<inertia>
					<ixx>1.8281453799505345e-05</ixx>
					<ixy>1.4347932097826742e-05</ixy>
					<ixz>1.046279491938815e-05</ixz>
					<iyy>2.3718344534274156e-05</iyy>
					<iyz>-8.654305170783587e-06</iyz>
					<izz>2.927035429133502e-05</izz>
				</inertia>
			</inertial>
			<collision name="servo_arm_4_collision">
				<geometry>
					<mesh>
						<uri>model://quadruped/meshes/CAD/servo_arm_4.stl</uri>
						<scale>0.001 0.001 0.001</scale>
					</mesh>
				</geometry>
			</collision>
			<visual name="servo_arm_4_visual">
				<geometry>
					<mesh>
						<uri>model://quadruped/meshes/CAD/servo_arm_4.stl</uri>
						<scale>0.001 0.001 0.001</scale>
					</mesh>
				</geometry>
			</visual>
		</link>
		<link name="rev_4">
			<self_collide>false</self_collide>
			<pose frame="">0.09286785429371303 -0.08550958091810766 -0.05021434066417976 0.0 -0.0 0.0</pose>
			<inertial>
				<pose frame="">0.0 0.0 0.0 0 0 0</pose>
				<mass>0.005624431830191924</mass>
				<inertia>
					<ixx>5.706515076577209e-05</ixx>
					<ixy>4.322185594241186e-05</ixy>
					<ixz>2.6101901201254602e-05</ixz>
					<iyy>6.407279821793503e-05</iyy>
					<iyz>-2.4293476218170423e-05</iyz>
					<izz>9.273946707735293e-05</izz>
				</inertia>
			</inertial>
			<collision name="rev_4_collision">
				<geometry>
					<mesh>
						<uri>model://quadruped/meshes/CAD/rev_4.stl</uri>
						<scale>0.001 0.001 0.001</scale>
					</mesh>
				</geometry>
			</collision>
			<visual name="rev_4_visual">
				<geometry>
					<mesh>
						<uri>model://quadruped/meshes/CAD/rev_4.stl</uri>
						<scale>0.001 0.001 0.001</scale>
					</mesh>
				</geometry>
			</visual>
		</link>
		<joint name="servo_body_1" type="fixed">
			<parent>quadruped_body</parent>
			<child>hip_servo_servo_mount_1</child>
			<pose frame="">-0.01467974375814511 -0.014607744585693262 0.003774286589272561 0 0 0</pose>
		</joint>
		<joint name="servo_body_2" type="fixed">
			<parent>quadruped_body</parent>
			<child>hip_servo_servo_mount_2</child>
			<pose frame="">-0.018005185791200112 -0.010834195148664847 -0.0012489267097010347 0 0 0</pose>
		</joint>
		<joint name="servo_body_3" type="fixed">
			<parent>quadruped_body</parent>
			<child>hip_servo_servo_mount_3</child>
			<pose frame="">-0.014238059151254218 -0.014185050759453997 -0.006260057866255124 0 0 0</pose>
		</joint>
		<joint name="servo_body_4" type="fixed">
			<parent>quadruped_body</parent>
			<child>hip_servo_servo_mount_4</child>
			<pose frame="">-0.010912617101154964 -0.017958600205517428 -0.001236844567208948 0 0 0</pose>
		</joint>
		<joint name="hip_drive_1" type="revolute">
			<parent>hip_servo_servo_mount_1</parent>
			<child>thigh_1</child>
			<pose frame="">0.019124243226562438 0.021883251233004386 -0.02216354913384417 0 0 0</pose>
			<axis>
				<xyz>0.7073257189907829 0.7042680507738324 0.06080164400240357</xyz>
				<limit>
					<lower>-1.5707963267948966</lower>
					<upper>1.5707963267948966</upper>
				</limit>
				<use_parent_model_frame>0</use_parent_model_frame>
			</axis>
		</joint>
		<joint name="hip_drive_2" type="revolute">
			<parent>hip_servo_servo_mount_2</parent>
			<child>thigh_2</child>
			<pose frame="">0.03645563575017118 0.002591445297697916 -0.00032757873385219405 0 0 0</pose>
			<axis>
				<xyz>0.7073257189907826 0.7042680507738329 0.060801644002403746</xyz>
				<limit>
					<lower>-1.5707963267948966</lower>
					<upper>1.5707963267948966</upper>
				</limit>
				<use_parent_model_frame>0</use_parent_model_frame>
			</axis>
		</joint>
		<joint name="hip_drive_3" type="revolute">
			<parent>hip_servo_servo_mount_3</parent>
			<child>thigh_3</child>
			<pose frame="">0.019904121056195212 0.01698339293497652 0.025519141896589072 0 0 0</pose>
			<axis>
				<xyz>0.707325718990783 0.7042680507738329 0.06080164400240372</xyz>
				<limit>
					<lower>-1.5707963267948966</lower>
					<upper>1.5707963267948966</upper>
				</limit>
				<use_parent_model_frame>0</use_parent_model_frame>
			</axis>
		</joint>
		<joint name="hip_drive_4" type="revolute">
			<parent>hip_servo_servo_mount_4</parent>
			<child>thigh_4</child>
			<pose frame="">0.002576438153340588 0.0362704881614182 0.003694581094404912 0 0 0</pose>
			<axis>
				<xyz>0.7073257189907834 0.7042680507738325 0.06080164400240374</xyz>
				<limit>
					<lower>-1.5707963267948966</lower>
					<upper>1.5707963267948966</upper>
				</limit>
				<use_parent_model_frame>0</use_parent_model_frame>
			</axis>
		</joint>
		<joint name="knee_drive_1" type="revolute">
			<parent>thigh_1</parent>
			<child>servo_arm_1</child>
			<pose frame="">0.004282932026332 0.006699960549899786 -0.010833691639676025 0 0 0</pose>
			<axis>
				<xyz>-0.7055286400861118 0.7086806602216479 -0.0010294882473420707</xyz>
				<limit>
					<lower>-0.9599310885968813</lower>
					<upper>0.9599310885968813</upper>
				</limit>
				<use_parent_model_frame>0</use_parent_model_frame>
			</axis>
		</joint>
		<joint name="knee_drive_2" type="revolute">
			<parent>thigh_2</parent>
			<child>servo_arm_2</child>
			<pose frame="">0.00976330024829137 -0.009078184525388108 -0.0016930412630308568 0 0 0</pose>
			<axis>
				<xyz>0.04395680036480673 0.042025662415819745 -0.9981491088009847</xyz>
				<limit>
					<lower>-0.9599310885968813</lower>
					<upper>0.9599310885968813</upper>
				</limit>
				<use_parent_model_frame>0</use_parent_model_frame>
			</axis>
		</joint>
		<joint name="knee_drive_3" type="revolute">
			<parent>thigh_3</parent>
			<child>servo_arm_3</child>
			<pose frame="">0.0006724167217587618 -0.001759158136976331 0.01330620432525139 0 0 0</pose>
			<axis>
				<xyz>0.705519533657749 -0.7086893949019422 0.0012366005295526845</xyz>
				<limit>
					<lower>-0.9599310885968813</lower>
					<upper>0.9599310885968813</upper>
				</limit>
				<use_parent_model_frame>0</use_parent_model_frame>
			</axis>
		</joint>
		<joint name="knee_drive_4" type="revolute">
			<parent>thigh_4</parent>
			<child>servo_arm_4</child>
			<pose frame="">-0.009435511265804912 0.0094120354732717 0.0017281736851306473 0 0 0</pose>
			<axis>
				<xyz>-0.04360682783998562 -0.0423771965289127 0.9981495968942147</xyz>
				<limit>
					<lower>-0.9599310885968813</lower>
					<upper>0.9599310885968813</upper>
				</limit>
				<use_parent_model_frame>0</use_parent_model_frame>
			</axis>
		</joint>
		<joint name="body_leg_free_1" type="revolute">
			<parent>quadruped_body</parent>
			<child>thigh_1</child>
			<pose frame="">-0.008886916234051068 -0.006006819979715552 -0.024571385438805358 0 0 0</pose>
			<axis>
				<xyz>0.7073257189907839 0.7042680507738336 0.06080164400240378</xyz>
				<limit>
					<lower>0.0</lower>
					<upper>0.0</upper>
				</limit>
				<use_parent_model_frame>0</use_parent_model_frame>
			</axis>
		</joint>
		<joint name="body_leg_free_2" type="revolute">
			<parent>quadruped_body</parent>
			<child>thigh_2</child>
			<pose frame="">0.008444476289557726 -0.025298625915022032 -0.0027354150388134 0 0 0</pose>
			<axis>
				<xyz>0.7073257189907839 0.7042680507738336 0.06080164400240378</xyz>
				<limit>
					<lower>0.0</lower>
					<upper>0.0</upper>
				</limit>
				<use_parent_model_frame>0</use_parent_model_frame>
			</axis>
		</joint>
		<joint name="body_leg_free_3" type="revolute">
			<parent>quadruped_body</parent>
			<child>thigh_3</child>
			<pose frame="">-0.008107038404418305 -0.010906678277743423 0.023111305591627895 0 0 0</pose>
			<axis>
				<xyz>0.7073257189907839 0.7042680507738336 0.06080164400240378</xyz>
				<limit>
					<lower>0.0</lower>
					<upper>0.0</upper>
				</limit>
				<use_parent_model_frame>0</use_parent_model_frame>
			</axis>
		</joint>
		<joint name="body_leg_free_4" type="revolute">
			<parent>quadruped_body</parent>
			<child>thigh_4</child>
			<pose frame="">-0.02543472130727297 0.008380416948698262 0.0012867447894437233 0 0 0</pose>
			<axis>
				<xyz>0.7073257189907839 0.7042680507738336 0.06080164400240378</xyz>
				<limit>
					<lower>0.0</lower>
					<upper>0.0</upper>
				</limit>
				<use_parent_model_frame>0</use_parent_model_frame>
			</axis>
		</joint>
		<joint name="servo_arm_rev_1" type="revolute">
			<parent>servo_arm_1</parent>
			<child>rev_1</child>
			<pose frame="">0.0048823082538115474 0.002581851749461532 -0.0005243485909997503 0 0 0</pose>
			<axis>
				<xyz>-0.705528640086112 0.7086806602216473 -0.0010294882473423075</xyz>
				<limit>
					<lower>0.0</lower>
					<upper>0.0</upper>
				</limit>
				<use_parent_model_frame>0</use_parent_model_frame>
			</axis>
		</joint>
		<joint name="rev_leg_parallel_linkage_1" type="revolute">
			<parent>rev_1</parent>
			<child>leg_parallel_linkage_1</child>
			<pose frame="">-0.006174305137620013 -0.0038257745135149034 0.009981803698455964 0 0 0</pose>
			<axis>
				<xyz>0.7055288622879796 -0.7086804463438486 0.001024425943430311</xyz>
				<limit>
					<lower>0.0</lower>
					<upper>0.0</upper>
				</limit>
				<use_parent_model_frame>0</use_parent_model_frame>
			</axis>
		</joint>
		<joint name="linkage_plate_1" type="">
			<parent>leg_parallel_linkage_1</parent>
			<child>thigh_1</child>
			<pose frame="">0.008169693682831993 0.015006203732608294 0.014027401784915626 0 0 0</pose>
		</joint>
		<joint name="servo_arm_rev_2" type="revolute">
			<parent>servo_arm_2</parent>
			<child>rev_2</child>
			<pose frame="">0.004244061466140607 0.003006272238304657 0.0019308296889008238 0 0 0</pose>
			<axis>
				<xyz>-0.04395680036480672 -0.042025662415819676 0.9981491088009847</xyz>
				<limit>
					<lower>0.0</lower>
					<upper>0.0</upper>
				</limit>
				<use_parent_model_frame>0</use_parent_model_frame>
			</axis>
		</joint>
		<joint name="rev_leg_parallel_linkage_2" type="revolute">
			<parent>rev_2</parent>
			<child>leg_parallel_linkage_2</child>
			<pose frame="">-0.008785148619814364 0.008511170526218984 -0.0016661745320500554 0 0 0</pose>
			<axis>
				<xyz>-0.04395322218682839 -0.04202925666703037 0.9981491150341257</xyz>
				<limit>
					<lower>0.0</lower>
					<upper>0.0</upper>
				</limit>
				<use_parent_model_frame>0</use_parent_model_frame>
			</axis>
		</joint>
		<joint name="linkage_plate_2" type="">
			<parent>leg_parallel_linkage_2</parent>
			<child>thigh_2</child>
			<pose frame="">0.0032001020579447647 0.02153797579300435 -0.0038174840088388874 0 0 0</pose>
		</joint>
		<joint name="servo_arm_rev_3" type="revolute">
			<parent>servo_arm_3</parent>
			<child>rev_3</child>
			<pose frame="">0.0025267631515324875 0.004795474886833165 0.0011818300943742344 0 0 0</pose>
			<axis>
				<xyz>-0.7055195336577517 0.7086893949019445 -0.0012366005295526693</xyz>
				<limit>
					<lower>0.0</lower>
					<upper>0.0</upper>
				</limit>
				<use_parent_model_frame>0</use_parent_model_frame>
			</axis>
		</joint>
		<joint name="rev_leg_parallel_linkage_3" type="revolute">
			<parent>rev_3</parent>
			<child>leg_parallel_linkage_3</child>
			<pose frame="">0.0017002177202256742 -0.0006352205400598532 -0.01221068188095039 0 0 0</pose>
			<axis>
				<xyz>-0.7055197566020837 0.7086891817699308 -0.0012315382268389883</xyz>
				<limit>
					<lower>0.0</lower>
					<upper>0.0</upper>
				</limit>
				<use_parent_model_frame>0</use_parent_model_frame>
			</axis>
		</joint>
		<joint name="linkage_plate_3" type="">
			<parent>leg_parallel_linkage_3</parent>
			<child>thigh_3</child>
			<pose frame="">0.016164062982985863 0.00921852555552542 -0.011934826896065119 0 0 0</pose>
		</joint>
		<joint name="servo_arm_rev_4" type="revolute">
			<parent>servo_arm_4</parent>
			<child>rev_4</child>
			<pose frame="">0.0031625281387169402 0.004370671959217045 -0.001293629074534346 0 0 0</pose>
			<axis>
				<xyz>0.0436032495518704 0.04238079067395309 -0.9981496006162475</xyz>
				<limit>
					<lower>0.0</lower>
					<upper>0.0</upper>
				</limit>
				<use_parent_model_frame>0</use_parent_model_frame>
			</axis>
		</joint>
		<joint name="rev_leg_parallel_linkage_4" type="revolute">
			<parent>rev_4</parent>
			<child>leg_parallel_linkage_4</child>
			<pose frame="">0.008561821792450549 -0.008740631872575424 0.001640597338954981 0 0 0</pose>
			<axis>
				<xyz>0.04360324955187009 0.04238079067395281 -0.9981496006162387</xyz>
				<limit>
					<lower>0.0</lower>
					<upper>0.0</upper>
				</limit>
				<use_parent_model_frame>0</use_parent_model_frame>
			</axis>
		</joint>
		<joint name="linkage_plate_4" type="">
			<parent>leg_parallel_linkage_4</parent>
			<child>thigh_4</child>
			<pose frame="">0.021133767937719358 0.0026872939071444168 0.0059024813836571965 0 0 0</pose>
		</joint>
		<plugin filename="libcardsflow_gazebo_plugin.so" name="cardsflow_gazebo_plugin"/>
	</model>
</sdf>
