<?xml version="1.0" ?>
<robot name="Base_link" xmlns:xacro="http://www.ros.org/wiki/xacro">

<xacro:include filename="$(find Base_link_description)/urdf/materials.xacro" />
<xacro:include filename="$(find Base_link_description)/urdf/Base_link.trans" />
<xacro:include filename="$(find Base_link_description)/urdf/Base_link.gazebo" />
<link name="base_link">
  <inertial>
    <origin rpy="0 0 0" xyz="5.980213284278362e-06 0.0006166874935299565 -3.2509840552748e-05"/>
    <mass value="0.010011445945907986"/>
    <inertia ixx="2e-06" ixy="0.0" ixz="-0.0" iyy="2e-06" iyz="-0.0" izz="5e-06"/>
  </inertial>
  <visual>
    <origin rpy="0 0 0" xyz="0 0 0"/>
    <geometry>
      <mesh filename="package://Base_link_description/meshes/base_link.stl" scale="0.001 0.001 0.001"/>
    </geometry>
    <material name="silver"/>
  </visual>
  <collision>
    <origin rpy="0 0 0" xyz="0 0 0"/>
    <geometry>
      <mesh filename="package://Base_link_description/meshes/base_link.stl" scale="0.001 0.001 0.001"/>
    </geometry>
  </collision>
</link>

<link name="body_spacer_v1_1_1_1">
  <inertial>
    <origin rpy="0 0 0" xyz="-3.7504736663754464e-07 3.314338824084162e-07 0.0007504901296449267"/>
    <mass value="0.001198596877164021"/>
    <inertia ixx="0.0" ixy="0.0" ixz="0.0" iyy="0.0" iyz="-0.0" izz="0.0"/>
  </inertial>
  <visual>
    <origin rpy="0 0 0" xyz="-6e-06 0.016257 -0.003592"/>
    <geometry>
      <mesh filename="package://Base_link_description/meshes/body_spacer_v1_1_1_1.stl" scale="0.001 0.001 0.001"/>
    </geometry>
    <material name="silver"/>
  </visual>
  <collision>
    <origin rpy="0 0 0" xyz="-6e-06 0.016257 -0.003592"/>
    <geometry>
      <mesh filename="package://Base_link_description/meshes/body_spacer_v1_1_1_1.stl" scale="0.001 0.001 0.001"/>
    </geometry>
  </collision>
</link>

<link name="body_spacer_v1_2_1_1">
  <inertial>
    <origin rpy="0 0 0" xyz="-3.750473666318255e-07 3.3143388240017627e-07 0.0007504901296449293"/>
    <mass value="0.001198596877164021"/>
    <inertia ixx="0.0" ixy="0.0" ixz="0.0" iyy="0.0" iyz="-0.0" izz="0.0"/>
  </inertial>
  <visual>
    <origin rpy="0 0 0" xyz="-0.016881 -0.000618 -0.003592"/>
    <geometry>
      <mesh filename="package://Base_link_description/meshes/body_spacer_v1_2_1_1.stl" scale="0.001 0.001 0.001"/>
    </geometry>
    <material name="silver"/>
  </visual>
  <collision>
    <origin rpy="0 0 0" xyz="-0.016881 -0.000618 -0.003592"/>
    <geometry>
      <mesh filename="package://Base_link_description/meshes/body_spacer_v1_2_1_1.stl" scale="0.001 0.001 0.001"/>
    </geometry>
  </collision>
</link>

<link name="body_spacer_v1_3_1_1">
  <inertial>
    <origin rpy="0 0 0" xyz="-3.750473666300501e-07 3.3143388240494676e-07 0.0007504901892495743"/>
    <mass value="0.001198596877164021"/>
    <inertia ixx="0.0" ixy="-0.0" ixz="-0.0" iyy="0.0" iyz="0.0" izz="0.0"/>
  </inertial>
  <visual>
    <origin rpy="0 0 0" xyz="-6e-06 -0.017493 -0.003592"/>
    <geometry>
      <mesh filename="package://Base_link_description/meshes/body_spacer_v1_3_1_1.stl" scale="0.001 0.001 0.001"/>
    </geometry>
    <material name="silver"/>
  </visual>
  <collision>
    <origin rpy="0 0 0" xyz="-6e-06 -0.017493 -0.003592"/>
    <geometry>
      <mesh filename="package://Base_link_description/meshes/body_spacer_v1_3_1_1.stl" scale="0.001 0.001 0.001"/>
    </geometry>
  </collision>
</link>

<link name="body_spacer_v1_4_1_1">
  <inertial>
    <origin rpy="0 0 0" xyz="-3.750473666561116e-07 3.3143388241134355e-07 0.0007504901892495743"/>
    <mass value="0.001198596877164021"/>
    <inertia ixx="0.0" ixy="-0.0" ixz="0.0" iyy="0.0" iyz="0.0" izz="0.0"/>
  </inertial>
  <visual>
    <origin rpy="0 0 0" xyz="0.016869 -0.000618 -0.003592"/>
    <geometry>
      <mesh filename="package://Base_link_description/meshes/body_spacer_v1_4_1_1.stl" scale="0.001 0.001 0.001"/>
    </geometry>
    <material name="silver"/>
  </visual>
  <collision>
    <origin rpy="0 0 0" xyz="0.016869 -0.000618 -0.003592"/>
    <geometry>
      <mesh filename="package://Base_link_description/meshes/body_spacer_v1_4_1_1.stl" scale="0.001 0.001 0.001"/>
    </geometry>
  </collision>
</link>

<link name="body_top_plate_v1_1">
  <inertial>
    <origin rpy="0 0 0" xyz="0.01687261083716378 5.653301435611493e-07 0.0006254902190518993"/>
    <mass value="0.01473051492933994"/>
    <inertia ixx="2e-06" ixy="-0.0" ixz="-0.0" iyy="2e-06" iyz="-0.0" izz="4e-06"/>
  </inertial>
  <visual>
    <origin rpy="0 0 0" xyz="0.016869 -0.000618 -0.008092"/>
    <geometry>
      <mesh filename="package://Base_link_description/meshes/body_top_plate_v1_1.stl" scale="0.001 0.001 0.001"/>
    </geometry>
    <material name="silver"/>
  </visual>
  <collision>
    <origin rpy="0 0 0" xyz="0.016869 -0.000618 -0.008092"/>
    <geometry>
      <mesh filename="package://Base_link_description/meshes/body_top_plate_v1_1.stl" scale="0.001 0.001 0.001"/>
    </geometry>
  </collision>
</link>

<link name="body_top_plate_v1_1">
  <inertial>
    <origin rpy="0 0 0" xyz="-2.3891628362194406e-06 0.01687556533014356 0.0006254902190518993"/>
    <mass value="0.01473051492933994"/>
    <inertia ixx="2e-06" ixy="-0.0" ixz="-0.0" iyy="2e-06" iyz="-0.0" izz="4e-06"/>
  </inertial>
  <visual>
    <origin rpy="0 0 0" xyz="-6e-06 0.016257 -0.008092"/>
    <geometry>
      <mesh filename="package://Base_link_description/meshes/body_top_plate_v1_1.stl" scale="0.001 0.001 0.001"/>
    </geometry>
    <material name="silver"/>
  </visual>
  <collision>
    <origin rpy="0 0 0" xyz="-6e-06 0.016257 -0.008092"/>
    <geometry>
      <mesh filename="package://Base_link_description/meshes/body_top_plate_v1_1.stl" scale="0.001 0.001 0.001"/>
    </geometry>
  </collision>
</link>

<link name="body_top_plate_v1_1">
  <inertial>
    <origin rpy="0 0 0" xyz="-0.01687738916283622 5.653301435611493e-07 0.0006254902190518993"/>
    <mass value="0.01473051492933994"/>
    <inertia ixx="2e-06" ixy="-0.0" ixz="-0.0" iyy="2e-06" iyz="-0.0" izz="4e-06"/>
  </inertial>
  <visual>
    <origin rpy="0 0 0" xyz="-0.016881 -0.000618 -0.008092"/>
    <geometry>
      <mesh filename="package://Base_link_description/meshes/body_top_plate_v1_1.stl" scale="0.001 0.001 0.001"/>
    </geometry>
    <material name="silver"/>
  </visual>
  <collision>
    <origin rpy="0 0 0" xyz="-0.016881 -0.000618 -0.008092"/>
    <geometry>
      <mesh filename="package://Base_link_description/meshes/body_top_plate_v1_1.stl" scale="0.001 0.001 0.001"/>
    </geometry>
  </collision>
</link>

<link name="body_top_plate_v1_1">
  <inertial>
    <origin rpy="0 0 0" xyz="-2.3891628362194406e-06 -0.016874434669856442 0.0006254902190518993"/>
    <mass value="0.01473051492933994"/>
    <inertia ixx="2e-06" ixy="-0.0" ixz="-0.0" iyy="2e-06" iyz="-0.0" izz="4e-06"/>
  </inertial>
  <visual>
    <origin rpy="0 0 0" xyz="-6e-06 -0.017493 -0.008092"/>
    <geometry>
      <mesh filename="package://Base_link_description/meshes/body_top_plate_v1_1.stl" scale="0.001 0.001 0.001"/>
    </geometry>
    <material name="silver"/>
  </visual>
  <collision>
    <origin rpy="0 0 0" xyz="-6e-06 -0.017493 -0.008092"/>
    <geometry>
      <mesh filename="package://Base_link_description/meshes/body_top_plate_v1_1.stl" scale="0.001 0.001 0.001"/>
    </geometry>
  </collision>
</link>

<link name="servo_motor_v1_1">
  <inertial>
    <origin rpy="0 0 0" xyz="0.0013504414544246411 0.0013512721979105184 -0.006780457477401159"/>
    <mass value="0.0004848665871049835"/>
    <inertia ixx="0.0" ixy="-0.0" ixz="0.0" iyy="0.0" iyz="0.0" izz="0.0"/>
  </inertial>
  <visual>
    <origin rpy="0 0 0" xyz="0.0178 0.017187 -0.014892"/>
    <geometry>
      <mesh filename="package://Base_link_description/meshes/servo_motor_v1_1.stl" scale="0.001 0.001 0.001"/>
    </geometry>
    <material name="silver"/>
  </visual>
  <collision>
    <origin rpy="0 0 0" xyz="0.0178 0.017187 -0.014892"/>
    <geometry>
      <mesh filename="package://Base_link_description/meshes/servo_motor_v1_1.stl" scale="0.001 0.001 0.001"/>
    </geometry>
  </collision>
</link>

<link name="servo_motor_v1_2">
  <inertial>
    <origin rpy="0 0 0" xyz="0.03426079871094259 0.03426050645493063 -0.006780457477401155"/>
    <mass value="0.0004848665871049835"/>
    <inertia ixx="0.0" ixy="-0.0" ixz="-0.0" iyy="0.0" iyz="-0.0" izz="0.0"/>
  </inertial>
  <visual>
    <origin rpy="0 0 0" xyz="0.0178 0.017187 -0.014892"/>
    <geometry>
      <mesh filename="package://Base_link_description/meshes/servo_motor_v1_2.stl" scale="0.001 0.001 0.001"/>
    </geometry>
    <material name="silver"/>
  </visual>
  <collision>
    <origin rpy="0 0 0" xyz="0.0178 0.017187 -0.014892"/>
    <geometry>
      <mesh filename="package://Base_link_description/meshes/servo_motor_v1_2.stl" scale="0.001 0.001 0.001"/>
    </geometry>
  </collision>
</link>

<link name="servo_motor_v1_3">
  <inertial>
    <origin rpy="0 0 0" xyz="0.03426079878158869 0.0013501564834802887 -0.006780457477401159"/>
    <mass value="0.0004848665871049835"/>
    <inertia ixx="0.0" ixy="0.0" ixz="-0.0" iyy="0.0" iyz="0.0" izz="0.0"/>
  </inertial>
  <visual>
    <origin rpy="0 0 0" xyz="0.0178 0.017187 -0.014892"/>
    <geometry>
      <mesh filename="package://Base_link_description/meshes/servo_motor_v1_3.stl" scale="0.001 0.001 0.001"/>
    </geometry>
    <material name="silver"/>
  </visual>
  <collision>
    <origin rpy="0 0 0" xyz="0.0178 0.017187 -0.014892"/>
    <geometry>
      <mesh filename="package://Base_link_description/meshes/servo_motor_v1_3.stl" scale="0.001 0.001 0.001"/>
    </geometry>
  </collision>
</link>

<link name="servo_motor_v1_4">
  <inertial>
    <origin rpy="0 0 0" xyz="0.0013504413837785306 0.034212264341422036 -0.006780457477401155"/>
    <mass value="0.0004848665871049835"/>
    <inertia ixx="0.0" ixy="0.0" ixz="0.0" iyy="0.0" iyz="-0.0" izz="0.0"/>
  </inertial>
  <visual>
    <origin rpy="0 0 0" xyz="0.0178 0.017187 -0.014892"/>
    <geometry>
      <mesh filename="package://Base_link_description/meshes/servo_motor_v1_4.stl" scale="0.001 0.001 0.001"/>
    </geometry>
    <material name="silver"/>
  </visual>
  <collision>
    <origin rpy="0 0 0" xyz="0.0178 0.017187 -0.014892"/>
    <geometry>
      <mesh filename="package://Base_link_description/meshes/servo_motor_v1_4.stl" scale="0.001 0.001 0.001"/>
    </geometry>
  </collision>
</link>

<link name="leg_servo_retainer_v1_1">
  <inertial>
    <origin rpy="0 0 0" xyz="-0.003127499704082987 -0.0031271674859414435 4.901594472337539e-07"/>
    <mass value="0.0007120198480863978"/>
    <inertia ixx="0.0" ixy="-0.0" ixz="0.0" iyy="0.0" iyz="0.0" izz="0.0"/>
  </inertial>
  <visual>
    <origin rpy="0 0 0" xyz="0.013063 0.012449 -0.011237"/>
    <geometry>
      <mesh filename="package://Base_link_description/meshes/leg_servo_retainer_v1_1.stl" scale="0.001 0.001 0.001"/>
    </geometry>
    <material name="silver"/>
  </visual>
  <collision>
    <origin rpy="0 0 0" xyz="0.013063 0.012449 -0.011237"/>
    <geometry>
      <mesh filename="package://Base_link_description/meshes/leg_servo_retainer_v1_1.stl" scale="0.001 0.001 0.001"/>
    </geometry>
  </collision>
</link>

<link name="leg_servo_retainer_v1_2">
  <inertial>
    <origin rpy="0 0 0" xyz="0.029264739869450898 0.029262946138781908 4.901594472511012e-07"/>
    <mass value="0.0007120198480863978"/>
    <inertia ixx="0.0" ixy="-0.0" ixz="0.0" iyy="0.0" iyz="0.0" izz="0.0"/>
  </inertial>
  <visual>
    <origin rpy="0 0 0" xyz="0.013063 0.012449 -0.011237"/>
    <geometry>
      <mesh filename="package://Base_link_description/meshes/leg_servo_retainer_v1_2.stl" scale="0.001 0.001 0.001"/>
    </geometry>
    <material name="silver"/>
  </visual>
  <collision>
    <origin rpy="0 0 0" xyz="0.013063 0.012449 -0.011237"/>
    <geometry>
      <mesh filename="package://Base_link_description/meshes/leg_servo_retainer_v1_2.stl" scale="0.001 0.001 0.001"/>
    </geometry>
  </collision>
</link>

<link name="leg_servo_retainer_v1_3">
  <inertial>
    <origin rpy="0 0 0" xyz="0.029264238465440642 -0.003128784675027342 4.901594472476317e-07"/>
    <mass value="0.0007120198480863978"/>
    <inertia ixx="0.0" ixy="0.0" ixz="0.0" iyy="0.0" iyz="-0.0" izz="0.0"/>
  </inertial>
  <visual>
    <origin rpy="0 0 0" xyz="0.013063 0.012449 -0.011237"/>
    <geometry>
      <mesh filename="package://Base_link_description/meshes/leg_servo_retainer_v1_3.stl" scale="0.001 0.001 0.001"/>
    </geometry>
    <material name="silver"/>
  </visual>
  <collision>
    <origin rpy="0 0 0" xyz="0.013063 0.012449 -0.011237"/>
    <geometry>
      <mesh filename="package://Base_link_description/meshes/leg_servo_retainer_v1_3.stl" scale="0.001 0.001 0.001"/>
    </geometry>
  </collision>
</link>

<link name="leg_servo_retainer_v1_4">
  <inertial>
    <origin rpy="0 0 0" xyz="-0.0031269983000734077 0.029215205499929654 4.901594472493664e-07"/>
    <mass value="0.0007120198480863978"/>
    <inertia ixx="0.0" ixy="0.0" ixz="0.0" iyy="0.0" iyz="0.0" izz="0.0"/>
  </inertial>
  <visual>
    <origin rpy="0 0 0" xyz="0.013063 0.012449 -0.011237"/>
    <geometry>
      <mesh filename="package://Base_link_description/meshes/leg_servo_retainer_v1_4.stl" scale="0.001 0.001 0.001"/>
    </geometry>
    <material name="silver"/>
  </visual>
  <collision>
    <origin rpy="0 0 0" xyz="0.013063 0.012449 -0.011237"/>
    <geometry>
      <mesh filename="package://Base_link_description/meshes/leg_servo_retainer_v1_4.stl" scale="0.001 0.001 0.001"/>
    </geometry>
  </collision>
</link>

<link name="leg_top_pivot_plate_v1_1">
  <inertial>
    <origin rpy="0 0 0" xyz="-0.004176512002626424 -0.004147711074451138 -0.0006245098405527512"/>
    <mass value="0.0012497785111649892"/>
    <inertia ixx="0.0" ixy="-0.0" ixz="0.0" iyy="0.0" iyz="-0.0" izz="0.0"/>
  </inertial>
  <visual>
    <origin rpy="0 0 0" xyz="0.0178 0.017187 -0.014892"/>
    <geometry>
      <mesh filename="package://Base_link_description/meshes/leg_top_pivot_plate_v1_1.stl" scale="0.001 0.001 0.001"/>
    </geometry>
    <material name="silver"/>
  </visual>
  <collision>
    <origin rpy="0 0 0" xyz="0.0178 0.017187 -0.014892"/>
    <geometry>
      <mesh filename="package://Base_link_description/meshes/leg_top_pivot_plate_v1_1.stl" scale="0.001 0.001 0.001"/>
    </geometry>
  </collision>
</link>

<link name="leg_top_pivot_plate_v1_2">
  <inertial>
    <origin rpy="0 0 0" xyz="0.039787752167993656 0.03975948972729229 -0.0006245098405527599"/>
    <mass value="0.0012497785111649892"/>
    <inertia ixx="0.0" ixy="-0.0" ixz="0.0" iyy="0.0" iyz="0.0" izz="0.0"/>
  </inertial>
  <visual>
    <origin rpy="0 0 0" xyz="0.0178 0.017187 -0.014892"/>
    <geometry>
      <mesh filename="package://Base_link_description/meshes/leg_top_pivot_plate_v1_2.stl" scale="0.001 0.001 0.001"/>
    </geometry>
    <material name="silver"/>
  </visual>
  <collision>
    <origin rpy="0 0 0" xyz="0.0178 0.017187 -0.014892"/>
    <geometry>
      <mesh filename="package://Base_link_description/meshes/leg_top_pivot_plate_v1_2.stl" scale="0.001 0.001 0.001"/>
    </geometry>
  </collision>
</link>

<link name="leg_top_pivot_plate_v1_3">
  <inertial>
    <origin rpy="0 0 0" xyz="0.039759782053950345 -0.0041767969735707795 -0.0006245098405527529"/>
    <mass value="0.0012497785111649892"/>
    <inertia ixx="0.0" ixy="0.0" ixz="0.0" iyy="0.0" iyz="-0.0" izz="0.0"/>
  </inertial>
  <visual>
    <origin rpy="0 0 0" xyz="0.0178 0.017187 -0.014892"/>
    <geometry>
      <mesh filename="package://Base_link_description/meshes/leg_top_pivot_plate_v1_3.stl" scale="0.001 0.001 0.001"/>
    </geometry>
    <material name="silver"/>
  </visual>
  <collision>
    <origin rpy="0 0 0" xyz="0.0178 0.017187 -0.014892"/>
    <geometry>
      <mesh filename="package://Base_link_description/meshes/leg_top_pivot_plate_v1_3.stl" scale="0.001 0.001 0.001"/>
    </geometry>
  </collision>
</link>

<link name="leg_top_pivot_plate_v1_4">
  <inertial>
    <origin rpy="0 0 0" xyz="-0.004148541888583129 0.0397392177984731 -0.0006245098405527477"/>
    <mass value="0.0012497785111649892"/>
    <inertia ixx="0.0" ixy="0.0" ixz="0.0" iyy="0.0" iyz="0.0" izz="0.0"/>
  </inertial>
  <visual>
    <origin rpy="0 0 0" xyz="0.0178 0.017187 -0.014892"/>
    <geometry>
      <mesh filename="package://Base_link_description/meshes/leg_top_pivot_plate_v1_4.stl" scale="0.001 0.001 0.001"/>
    </geometry>
    <material name="silver"/>
  </visual>
  <collision>
    <origin rpy="0 0 0" xyz="0.0178 0.017187 -0.014892"/>
    <geometry>
      <mesh filename="package://Base_link_description/meshes/leg_top_pivot_plate_v1_4.stl" scale="0.001 0.001 0.001"/>
    </geometry>
  </collision>
</link>

<link name="leg_servo_mount_v1_1">
  <inertial>
    <origin rpy="0 0 0" xyz="-0.0025202441919865946 -0.002520657894471017 -0.0041132882595195765"/>
    <mass value="0.001144548758330191"/>
    <inertia ixx="0.0" ixy="-0.0" ixz="-0.0" iyy="0.0" iyz="-0.0" izz="0.0"/>
  </inertial>
  <visual>
    <origin rpy="0 0 0" xyz="0.022853 0.025845 -0.010392"/>
    <geometry>
      <mesh filename="package://Base_link_description/meshes/leg_servo_mount_v1_1.stl" scale="0.001 0.001 0.001"/>
    </geometry>
    <material name="silver"/>
  </visual>
  <collision>
    <origin rpy="0 0 0" xyz="0.022853 0.025845 -0.010392"/>
    <geometry>
      <mesh filename="package://Base_link_description/meshes/leg_servo_mount_v1_1.stl" scale="0.001 0.001 0.001"/>
    </geometry>
  </collision>
</link>

<link name="leg_servo_mount_v1_2">
  <inertial>
    <origin rpy="0 0 0" xyz="0.04823748435735383 0.05544843654731216 -0.004113288259519589"/>
    <mass value="0.001144548758330191"/>
    <inertia ixx="0.0" ixy="-0.0" ixz="0.0" iyy="0.0" iyz="0.0" izz="0.0"/>
  </inertial>
  <visual>
    <origin rpy="0 0 0" xyz="0.022853 0.025845 -0.010392"/>
    <geometry>
      <mesh filename="package://Base_link_description/meshes/leg_servo_mount_v1_2.stl" scale="0.001 0.001 0.001"/>
    </geometry>
    <material name="silver"/>
  </visual>
  <collision>
    <origin rpy="0 0 0" xyz="0.022853 0.025845 -0.010392"/>
    <geometry>
      <mesh filename="package://Base_link_description/meshes/leg_servo_mount_v1_2.stl" scale="0.001 0.001 0.001"/>
    </geometry>
  </collision>
</link>

<link name="leg_servo_mount_v1_3">
  <inertial>
    <origin rpy="0 0 0" xyz="0.051843728873970193 0.001084470837069064 -0.004113288259519591"/>
    <mass value="0.001144548758330191"/>
    <inertia ixx="0.0" ixy="0.0" ixz="0.0" iyy="0.0" iyz="-0.0" izz="0.0"/>
  </inertial>
  <visual>
    <origin rpy="0 0 0" xyz="0.022853 0.025845 -0.010392"/>
    <geometry>
      <mesh filename="package://Base_link_description/meshes/leg_servo_mount_v1_3.stl" scale="0.001 0.001 0.001"/>
    </geometry>
    <material name="silver"/>
  </visual>
  <collision>
    <origin rpy="0 0 0" xyz="0.022853 0.025845 -0.010392"/>
    <geometry>
      <mesh filename="package://Base_link_description/meshes/leg_servo_mount_v1_3.stl" scale="0.001 0.001 0.001"/>
    </geometry>
  </collision>
</link>

<link name="leg_servo_mount_v1_4">
  <inertial>
    <origin rpy="0 0 0" xyz="-0.006126488708603054 0.05179394998783325 -0.004113288259519528"/>
    <mass value="0.001144548758330191"/>
    <inertia ixx="0.0" ixy="0.0" ixz="-0.0" iyy="0.0" iyz="0.0" izz="0.0"/>
  </inertial>
  <visual>
    <origin rpy="0 0 0" xyz="0.022853 0.025845 -0.010392"/>
    <geometry>
      <mesh filename="package://Base_link_description/meshes/leg_servo_mount_v1_4.stl" scale="0.001 0.001 0.001"/>
    </geometry>
    <material name="silver"/>
  </visual>
  <collision>
    <origin rpy="0 0 0" xyz="0.022853 0.025845 -0.010392"/>
    <geometry>
      <mesh filename="package://Base_link_description/meshes/leg_servo_mount_v1_4.stl" scale="0.001 0.001 0.001"/>
    </geometry>
  </collision>
</link>

<link name="leg_parallel_plate_v1_1">
  <inertial>
    <origin rpy="0 0 0" xyz="-0.00031737993405022563 0.00031650773067368534 -0.00304974336712485"/>
    <mass value="0.000869495656702597"/>
    <inertia ixx="0.0" ixy="0.0" ixz="0.0" iyy="0.0" iyz="-0.0" izz="0.0"/>
  </inertial>
  <visual>
    <origin rpy="0 0 0" xyz="0.023853 -0.027357 -0.010392"/>
    <geometry>
      <mesh filename="package://Base_link_description/meshes/leg_parallel_plate_v1_1.stl" scale="0.001 0.001 0.001"/>
    </geometry>
    <material name="silver"/>
  </visual>
  <collision>
    <origin rpy="0 0 0" xyz="0.023853 -0.027357 -0.010392"/>
    <geometry>
      <mesh filename="package://Base_link_description/meshes/leg_parallel_plate_v1_1.stl" scale="0.001 0.001 0.001"/>
    </geometry>
  </collision>
</link>

<link name="leg_parallel_plate_v1_2">
  <inertial>
    <origin rpy="0 0 0" xyz="0.050962042100194206 -0.0025626722272406553 -0.0030497433671248806"/>
    <mass value="0.000869495656702597"/>
    <inertia ixx="0.0" ixy="-0.0" ixz="-0.0" iyy="0.0" iyz="-0.0" izz="0.0"/>
  </inertial>
  <visual>
    <origin rpy="0 0 0" xyz="0.023853 -0.027357 -0.010392"/>
    <geometry>
      <mesh filename="package://Base_link_description/meshes/leg_parallel_plate_v1_2.stl" scale="0.001 0.001 0.001"/>
    </geometry>
    <material name="silver"/>
  </visual>
  <collision>
    <origin rpy="0 0 0" xyz="0.023853 -0.027357 -0.010392"/>
    <geometry>
      <mesh filename="package://Base_link_description/meshes/leg_parallel_plate_v1_2.stl" scale="0.001 0.001 0.001"/>
    </geometry>
  </collision>
</link>

<link name="leg_parallel_plate_v1_3">
  <inertial>
    <origin rpy="0 0 0" xyz="0.048034620099417426 -0.053842086905771365 -0.0030497433671248632"/>
    <mass value="0.000869495656702597"/>
    <inertia ixx="0.0" ixy="0.0" ixz="-0.0" iyy="0.0" iyz="0.0" izz="0.0"/>
  </inertial>
  <visual>
    <origin rpy="0 0 0" xyz="0.023853 -0.027357 -0.010392"/>
    <geometry>
      <mesh filename="package://Base_link_description/meshes/leg_parallel_plate_v1_3.stl" scale="0.001 0.001 0.001"/>
    </geometry>
    <material name="silver"/>
  </visual>
  <collision>
    <origin rpy="0 0 0" xyz="0.023853 -0.027357 -0.010392"/>
    <geometry>
      <mesh filename="package://Base_link_description/meshes/leg_parallel_plate_v1_3.stl" scale="0.001 0.001 0.001"/>
    </geometry>
  </collision>
</link>

<link name="leg_parallel_plate_v1_4">
  <inertial>
    <origin rpy="0 0 0" xyz="-0.003244801934827013 -0.05091354911991822 -0.00304974336712485"/>
    <mass value="0.000869495656702597"/>
    <inertia ixx="0.0" ixy="-0.0" ixz="0.0" iyy="0.0" iyz="0.0" izz="0.0"/>
  </inertial>
  <visual>
    <origin rpy="0 0 0" xyz="0.023853 -0.027357 -0.010392"/>
    <geometry>
      <mesh filename="package://Base_link_description/meshes/leg_parallel_plate_v1_4.stl" scale="0.001 0.001 0.001"/>
    </geometry>
    <material name="silver"/>
  </visual>
  <collision>
    <origin rpy="0 0 0" xyz="0.023853 -0.027357 -0.010392"/>
    <geometry>
      <mesh filename="package://Base_link_description/meshes/leg_parallel_plate_v1_4.stl" scale="0.001 0.001 0.001"/>
    </geometry>
  </collision>
</link>

<link name="bottom_pivot_plate_v1_1">
  <inertial>
    <origin rpy="0 0 0" xyz="-0.0039248779846416705 -0.003939640534427909 -0.0006245098405527525"/>
    <mass value="0.00131675130911231"/>
    <inertia ixx="0.0" ixy="-0.0" ixz="-0.0" iyy="0.0" iyz="-0.0" izz="0.0"/>
  </inertial>
  <visual>
    <origin rpy="0 0 0" xyz="0.0178 0.017187 0.000658"/>
    <geometry>
      <mesh filename="package://Base_link_description/meshes/bottom_pivot_plate_v1_1.stl" scale="0.001 0.001 0.001"/>
    </geometry>
    <material name="silver"/>
  </visual>
  <collision>
    <origin rpy="0 0 0" xyz="0.0178 0.017187 0.000658"/>
    <geometry>
      <mesh filename="package://Base_link_description/meshes/bottom_pivot_plate_v1_1.stl" scale="0.001 0.001 0.001"/>
    </geometry>
  </collision>
</link>

<link name="bottom_pivot_plate_v1_2">
  <inertial>
    <origin rpy="0 0 0" xyz="0.0395361181500089 0.03955141918726905 -0.0006245098405527247"/>
    <mass value="0.00131675130911231"/>
    <inertia ixx="0.0" ixy="-0.0" ixz="-0.0" iyy="0.0" iyz="-0.0" izz="0.0"/>
  </inertial>
  <visual>
    <origin rpy="0 0 0" xyz="0.0178 0.017187 0.000658"/>
    <geometry>
      <mesh filename="package://Base_link_description/meshes/bottom_pivot_plate_v1_2.stl" scale="0.001 0.001 0.001"/>
    </geometry>
    <material name="silver"/>
  </visual>
  <collision>
    <origin rpy="0 0 0" xyz="0.0178 0.017187 0.000658"/>
    <geometry>
      <mesh filename="package://Base_link_description/meshes/bottom_pivot_plate_v1_2.stl" scale="0.001 0.001 0.001"/>
    </geometry>
  </collision>
</link>

<link name="bottom_pivot_plate_v1_3">
  <inertial>
    <origin rpy="0 0 0" xyz="0.03955171151392711 -0.003925162955586023 -0.0006245098405527516"/>
    <mass value="0.00131675130911231"/>
    <inertia ixx="0.0" ixy="0.0" ixz="0.0" iyy="0.0" iyz="-0.0" izz="0.0"/>
  </inertial>
  <visual>
    <origin rpy="0 0 0" xyz="0.0178 0.017187 0.000658"/>
    <geometry>
      <mesh filename="package://Base_link_description/meshes/bottom_pivot_plate_v1_3.stl" scale="0.001 0.001 0.001"/>
    </geometry>
    <material name="silver"/>
  </visual>
  <collision>
    <origin rpy="0 0 0" xyz="0.0178 0.017187 0.000658"/>
    <geometry>
      <mesh filename="package://Base_link_description/meshes/bottom_pivot_plate_v1_3.stl" scale="0.001 0.001 0.001"/>
    </geometry>
  </collision>
</link>

<link name="bottom_pivot_plate_v1_4">
  <inertial>
    <origin rpy="0 0 0" xyz="-0.003940471348559901 0.03948758378048834 -0.0006245098405527456"/>
    <mass value="0.00131675130911231"/>
    <inertia ixx="0.0" ixy="0.0" ixz="0.0" iyy="0.0" iyz="0.0" izz="0.0"/>
  </inertial>
  <visual>
    <origin rpy="0 0 0" xyz="0.0178 0.017187 0.000658"/>
    <geometry>
      <mesh filename="package://Base_link_description/meshes/bottom_pivot_plate_v1_4.stl" scale="0.001 0.001 0.001"/>
    </geometry>
    <material name="silver"/>
  </visual>
  <collision>
    <origin rpy="0 0 0" xyz="0.0178 0.017187 0.000658"/>
    <geometry>
      <mesh filename="package://Base_link_description/meshes/bottom_pivot_plate_v1_4.stl" scale="0.001 0.001 0.001"/>
    </geometry>
  </collision>
</link>

<joint name="Rigid10" type="fixed">
  <origin rpy="0 0 0" xyz="6e-06 -0.016257 0.003592"/>
  <parent link="base_link"/>
  <child link="body_spacer_v1_1_1_1"/>
</joint>

<joint name="Rigid11" type="fixed">
  <origin rpy="0 0 0" xyz="0.016881 0.000618 0.003592"/>
  <parent link="base_link"/>
  <child link="body_spacer_v1_2_1_1"/>
</joint>

<joint name="Rigid12" type="fixed">
  <origin rpy="0 0 0" xyz="6e-06 0.017493 0.003592"/>
  <parent link="base_link"/>
  <child link="body_spacer_v1_3_1_1"/>
</joint>

<joint name="Rigid17" type="fixed">
  <origin rpy="0 0 0" xyz="-0.016869 0.000618 0.003592"/>
  <parent link="base_link"/>
  <child link="body_spacer_v1_4_1_1"/>
</joint>

<joint name="Rigid31" type="fixed">
  <origin rpy="0 0 0" xyz="0.016875 0.016875 0.0045"/>
  <parent link="body_spacer_v1_4_1_1"/>
  <child link="body_top_plate_v1_1"/>
</joint>

<joint name="Rigid32" type="fixed">
  <origin rpy="0 0 0" xyz="0.0 0.03375 0.0045"/>
  <parent link="body_spacer_v1_1_1_1"/>
  <child link="body_top_plate_v1_1"/>
</joint>

<joint name="Rigid33" type="fixed">
  <origin rpy="0 0 0" xyz="-0.016875 0.016875 0.0045"/>
  <parent link="body_spacer_v1_2_1_1"/>
  <child link="body_top_plate_v1_1"/>
</joint>

<joint name="Rigid34" type="fixed">
  <origin rpy="0 0 0" xyz="0.0 0.0 0.0045"/>
  <parent link="body_spacer_v1_3_1_1"/>
  <child link="body_top_plate_v1_1"/>
</joint>

<joint name="Rigid35" type="fixed">
  <origin rpy="0 0 0" xyz="-0.0178 -0.017187 0.014892"/>
  <parent link="base_link"/>
  <child link="servo_motor_v1_1"/>
</joint>

<joint name="Rigid36" type="fixed">
  <origin rpy="0 0 0" xyz="-0.0178 -0.017187 0.014892"/>
  <parent link="base_link"/>
  <child link="servo_motor_v1_2"/>
</joint>

<joint name="Rigid37" type="fixed">
  <origin rpy="0 0 0" xyz="-0.0178 -0.017187 0.014892"/>
  <parent link="base_link"/>
  <child link="servo_motor_v1_3"/>
</joint>

<joint name="Rigid38" type="fixed">
  <origin rpy="0 0 0" xyz="-0.0178 -0.017187 0.014892"/>
  <parent link="base_link"/>
  <child link="servo_motor_v1_4"/>
</joint>

<joint name="Rigid39" type="fixed">
  <origin rpy="0 0 0" xyz="0.004737 0.004738 -0.003655"/>
  <parent link="servo_motor_v1_1"/>
  <child link="leg_servo_retainer_v1_1"/>
</joint>

<joint name="Rigid40" type="fixed">
  <origin rpy="0 0 0" xyz="0.004737 0.004738 -0.003655"/>
  <parent link="servo_motor_v1_2"/>
  <child link="leg_servo_retainer_v1_2"/>
</joint>

<joint name="Rigid41" type="fixed">
  <origin rpy="0 0 0" xyz="0.004737 0.004738 -0.003655"/>
  <parent link="servo_motor_v1_3"/>
  <child link="leg_servo_retainer_v1_3"/>
</joint>

<joint name="Rigid42" type="fixed">
  <origin rpy="0 0 0" xyz="0.004737 0.004738 -0.003655"/>
  <parent link="servo_motor_v1_4"/>
  <child link="leg_servo_retainer_v1_4"/>
</joint>

<joint name="Rev43" type="continuous">
  <origin rpy="0 0 0" xyz="0.0 0.0 0.0"/>
  <parent link="servo_motor_v1_1"/>
  <child link="leg_top_pivot_plate_v1_1"/>
  <axis xyz="-0.0 -0.0 1.0"/>
</joint>

<joint name="Rev44" type="continuous">
  <origin rpy="0 0 0" xyz="0.0 0.0 0.0"/>
  <parent link="servo_motor_v1_2"/>
  <child link="leg_top_pivot_plate_v1_2"/>
  <axis xyz="0.0 -0.0 1.0"/>
</joint>

<joint name="Rev45" type="continuous">
  <origin rpy="0 0 0" xyz="0.0 0.0 0.0"/>
  <parent link="servo_motor_v1_3"/>
  <child link="leg_top_pivot_plate_v1_3"/>
  <axis xyz="0.0 -0.0 1.0"/>
</joint>

<joint name="Rev46" type="continuous">
  <origin rpy="0 0 0" xyz="0.0 0.0 0.0"/>
  <parent link="servo_motor_v1_4"/>
  <child link="leg_top_pivot_plate_v1_4"/>
  <axis xyz="0.0 0.0 1.0"/>
</joint>

<joint name="Rigid47" type="fixed">
  <origin rpy="0 0 0" xyz="-0.005053 -0.008658 -0.0045"/>
  <parent link="leg_top_pivot_plate_v1_1"/>
  <child link="leg_servo_mount_v1_1"/>
</joint>

<joint name="Rigid48" type="fixed">
  <origin rpy="0 0 0" xyz="-0.005053 -0.008658 -0.0045"/>
  <parent link="leg_top_pivot_plate_v1_2"/>
  <child link="leg_servo_mount_v1_2"/>
</joint>

<joint name="Rigid49" type="fixed">
  <origin rpy="0 0 0" xyz="-0.005053 -0.008658 -0.0045"/>
  <parent link="leg_top_pivot_plate_v1_3"/>
  <child link="leg_servo_mount_v1_3"/>
</joint>

<joint name="Rigid50" type="fixed">
  <origin rpy="0 0 0" xyz="-0.005053 -0.008658 -0.0045"/>
  <parent link="leg_top_pivot_plate_v1_4"/>
  <child link="leg_servo_mount_v1_4"/>
</joint>

<joint name="Rigid51" type="fixed">
  <origin rpy="0 0 0" xyz="-0.006053 0.044544 -0.0045"/>
  <parent link="leg_top_pivot_plate_v1_4"/>
  <child link="leg_parallel_plate_v1_1"/>
</joint>

<joint name="Rigid52" type="fixed">
  <origin rpy="0 0 0" xyz="-0.006053 0.044544 -0.0045"/>
  <parent link="leg_top_pivot_plate_v1_2"/>
  <child link="leg_parallel_plate_v1_2"/>
</joint>

<joint name="Rigid53" type="fixed">
  <origin rpy="0 0 0" xyz="-0.006053 0.044544 -0.0045"/>
  <parent link="leg_top_pivot_plate_v1_3"/>
  <child link="leg_parallel_plate_v1_3"/>
</joint>

<joint name="Rigid54" type="fixed">
  <origin rpy="0 0 0" xyz="-0.006053 0.044544 -0.0045"/>
  <parent link="leg_top_pivot_plate_v1_1"/>
  <child link="leg_parallel_plate_v1_4"/>
</joint>

<joint name="Rev55" type="continuous">
  <origin rpy="0 0 0" xyz="-0.0178 -0.017187 -0.000658"/>
  <parent link="base_link"/>
  <child link="bottom_pivot_plate_v1_1"/>
  <axis xyz="-0.0 -0.0 1.0"/>
</joint>

<joint name="Rev57" type="continuous">
  <origin rpy="0 0 0" xyz="-0.0178 -0.017187 -0.000658"/>
  <parent link="base_link"/>
  <child link="bottom_pivot_plate_v1_2"/>
  <axis xyz="-0.0 -0.0 1.0"/>
</joint>

<joint name="Rev59" type="continuous">
  <origin rpy="0 0 0" xyz="-0.0178 -0.017187 -0.000658"/>
  <parent link="base_link"/>
  <child link="bottom_pivot_plate_v1_3"/>
  <axis xyz="-0.0 -0.0 1.0"/>
</joint>

<joint name="Rev60" type="continuous">
  <origin rpy="0 0 0" xyz="-0.0178 -0.017187 -0.000658"/>
  <parent link="base_link"/>
  <child link="bottom_pivot_plate_v1_4"/>
  <axis xyz="-0.0 -0.0 1.0"/>
</joint>

</robot>
