<?xml version="1.0" ?>
<!-- =================================================================================== -->
<!-- |    This document was autogenerated by xacro from /home/shandilya/Desktop/CNS/DDP/src/simulations/ws/src/quadruped/urdf/quadruped_model.xacro | -->
<!-- |    EDITING THIS FILE BY HAND IS NOT RECOMMENDED                                 | -->
<!-- =================================================================================== -->
<robot name="quadruped">
    <!-- Gazebo plugin for ROS Control -->
    <gazebo>
        <plugin filename="libgazebo_ros_control.so" name="gazebo_ros_control">
            <robotNamespace>/quadruped</robotNamespace>
        </plugin>
    </gazebo>
    <material name="black">
        <color rgba="0.0 0.0 0.0 1.0" />
    </material>
    <material name="blue">
        <color rgba="0.0 0.0 0.8 1.0" />
    </material>
    <material name="green">
        <color rgba="0.0 0.8 0.0 1.0" />
    </material>
    <material name="grey">
        <color rgba="0.2 0.2 0.2 1.0" />
    </material>
    <material name="orange">
        <color rgba="1.0 0.4235294117647059 0.0392156862745098 1.0" />
    </material>
    <material name="brown">
        <color rgba="0.8705882352941177 0.8117647058823529 0.7647058823529411 1.0" />
    </material>
    <material name="red">
        <color rgba="0.8 0.0 0.0 1.0" />
    </material>
    <material name="white">
        <color rgba="1.0 1.0 1.0 1.0" />
    </material>
    <!-- Dummmy -->
    <link name="dummy" />
    <!-- Quadruped -->
    <link name="dummy_link">
        <visual>
            <geometry>
                <box size="0.01 0.01 0.01" />
            </geometry>
            <material name="black" />
        </visual>
        
<inertial>
            <mass value="0.01" />
            <inertia ixx="0.00001" ixy="0.0" ixz="0.0" iyy="0.00001" iyz="0.0" izz="0.00001" />
        </inertial>

        <gazebo reference="dummy_link" />
    </link>
    <joint name="dummy_joint" type="fixed">
        <parent link="dummy" />
        <child link="dummy_link" />
    </joint>
    <link name="base_link">
        <visual>
            <geometry>
                <box size="0.2376 0.2376 0.12100000000000001" />
            </geometry>
            <material name="black" />
        </visual>
        <collision>
            <geometry>
                <box size="0.2376 0.2376 0.12100000000000001" />
            </geometry>
        </collision>
        
<inertial>
            <mass value="4.259200000000002" />
            <inertia ixx="0.04007464243200002" ixy="0.0" ixz="0.0" iyy="0.04007464243200002" iyz="0.0" izz="0.04007464243200002" />
        </inertial>

    </link>
    <joint name="dummy_base_joint" type="fixed">
        <parent link="dummy_link" />
        <child link="base_link" />
        <origin rpy="0 0 0" xyz="0 0 0.28600000000000003" />
    </joint>
    <gazebo reference="base_link">
        <mu1>100000.0</mu1>
        <mu2>100000.0</mu2>
        <material>Gazebo/Black</material>
    </gazebo>
    <gazebo reference="dummy_base_joint">
        <provideFeedback>true</provideFeedback>
        <disableFixedJointLumping>true</disableFixedJointLumping>
    </gazebo>
    <link name="imu_link">
        <visual>
            <geometry>
                <box size="0.044000000000000004 0.044000000000000004 0.044000000000000004" />
            </geometry>
            <material name="white" />
        </visual>
        <collision>
            <geometry>
                <box size="0.044000000000000004 0.044000000000000004 0.044000000000000004" />
            </geometry>
        </collision>
        
<inertial>
            <mass value="0.5324000000000002" />
            <inertia ixx="0.00017178773333333344" ixy="0.0" ixz="0.0" iyy="0.00017178773333333344" iyz="0.0" izz="0.00017178773333333344" />
        </inertial>

    </link>
    <joint name="base_imu_joint" type="fixed">
        <parent link="base_link" />
        <child link="imu_link" />
        <origin rpy="0 0 0" xyz="0 0 0.0825" />
        <dynamics damping="10" friction="0.5" />
    </joint>
    <gazebo reference="imu_link">
        <material>Gazebo/White</material>
        <gravity>true</gravity>
        <sensor name="imu_sensor" type="imu">
            <always_on>true</always_on>
            <update_rate>100</update_rate>
            <visualize>true</visualize>
            <topic>__default_topic__</topic>
            <plugin filename="libgazebo_ros_imu_sensor.so" name="imu_plugin">
                <robotNamespace>/quadruped</robotNamespace>
                <topicName>imu</topicName>
                <bodyName>imu_link</bodyName>
                <updateRateHZ>100.0</updateRateHZ>
                <gaussianNoise>0.0</gaussianNoise>
                <xyzOffset>0 0 0</xyzOffset>
                <rpyOffset>0 0 0</rpyOffset>
                <frameName>imu_link</frameName>
            </plugin>
            <pose>0 0 0 0 0 0</pose>
        </sensor>
    </gazebo>
    <gazebo reference="base_imu_joint">
        <provideFeedback>true</provideFeedback>
        <disableFixedJointLumping>true</disableFixedJointLumping>
    </gazebo>
    <link name="front_right_leg3">
        <visual>
            <origin rpy="0 0 0" xyz="0 0 0" />
            <geometry>
                <box size="0.033 0.033 0.1144" />
            </geometry>
            <material name="black" />
        </visual>
        <collision>
            <origin rpy="0 0 0" xyz="0 0 0" />
            <geometry>
                <box size="0.033 0.033 0.1144" />
            </geometry>
        </collision>
        
<inertial>
            <mass value="1.0648000000000004" />
            <inertia ixx="0.0001932612000000001" ixy="0.0" ixz="0.0" iyy="0.0001932612000000001" iyz="0.0" izz="0.0001932612000000001" />
        </inertial>

    </link>
    <joint name="front_right_leg3_joint" type="revolute">
        <axis xyz="0 0 1" />
        <parent link="base_link" />
        <child link="front_right_leg3" />
        <origin rpy="0 0 0.7853981633974483" xyz="0.1188 0.1188 0" />
        <limit effort="100.0" lower="-0.3490658503988659" upper="0.3490658503988659" velocity="10.0" />
        <dynamics damping="10" friction="0.5" />
    </joint>
    <gazebo reference="front_right_leg3">
        <mu1>100000.0</mu1>
        <mu2>100000.0</mu2>
        <material>Gazebo/White</material>
    </gazebo>
    <link name="front_right_leg2">
        <visual>
            <origin rpy="0 2.792526803190927 0" xyz="0.10336618828644993 0.011000000000000001 0.03762221576582357" />
            <geometry>
                <box size="0.22000000000000003 0.022000000000000002 0.05500000000000001" />
            </geometry>
            <material name="white" />
        </visual>
        <collision>
            <origin rpy="0 2.792526803190927 0" xyz="0.10336618828644993 0.011000000000000001 0.03762221576582357" />
            <geometry>
                <box size="0.22000000000000003 0.022000000000000002 0.05500000000000001" />
            </geometry>
        </collision>
        
<inertial>
            <mass value="0.5324000000000002" />
            <inertia ixx="0.0021688201333333345" ixy="0.0" ixz="0.0" iyy="0.0021688201333333345" iyz="0.0" izz="0.0021688201333333345" />
        </inertial>

    </link>
    <joint name="front_right_leg2_joint" type="revolute">
        <axis rpy="0 0 0" xyz="0 1 0" />
        <parent link="front_right_leg3" />
        <child link="front_right_leg2" />
        <origin xyz="0.0165 0.0165 0" />
        <limit effort="100.0" lower="-0.3490658503988659" upper="0.3490658503988659" velocity="10.0" />
        <dynamics damping="10" friction="0.5" />
    </joint>
    <gazebo reference="front_right_leg2">
        <mu1>100000.0</mu1>
        <mu2>100000.0</mu2>
        <material>Gazebo/Black</material>
    </gazebo>
    <link name="front_right_leg1">
        <visual>
            <origin rpy="0 0 0" xyz="0 -0.0165 -0.14300000000000002" />
            <geometry>
                <box size="0.033 0.033 0.28600000000000003" />
            </geometry>
            <material name="black" />
        </visual>
        <collision>
            <origin rpy="0 0 0" xyz="0 -0.0165 -0.14300000000000002" />
            <geometry>
                <box size="0.033 0.033 0.28600000000000003" />
            </geometry>
        </collision>
        
<inertial>
            <mass value="8.518400000000003" />
            <inertia ixx="0.05883729866666671" ixy="0.0" ixz="0.0" iyy="0.05883729866666671" iyz="0.0" izz="0.05883729866666671" />
        </inertial>

    </link>
    <joint name="front_right_leg1_joint" type="revolute">
        <axis xyz="0 1 0" />
        <parent link="front_right_leg2" />
        <child link="front_right_leg1" />
        <origin rpy="0 -0.34906585039886595 0" xyz="0.20673237657289986 0 0.07524443153164714" />
        <limit effort="100.0" lower="-0.3490658503988659" upper="0.3490658503988659" velocity="10.0" />
        <dynamics damping="10" friction="0.5" />
    </joint>
    <gazebo reference="front_right_leg1">
        <mu1>100000.0</mu1>
        <mu2>100000.0</mu2>
        <material>Gazebo/White</material>
    </gazebo>
    <link name="front_right_leg_tip">
        <visual>
            <origin rpy="0 0 0" xyz="0 0 0" />
            <geometry>
                <sphere radius="0.023265" />
            </geometry>
            <material name="black" />
        </visual>
        <collision name="front_right_leg_tip">
            <origin rpy="0 0 0" xyz="0 0 0" />
            <geometry>
                <sphere radius="0.0165" />
            </geometry>
        </collision>
        
<inertial>
            <mass value="0.21296000000000007" />
            <inertia ixx="0.1" ixy="0.0" ixz="0.0" iyy="0.1" iyz="0.0" izz="0.1" />
        </inertial>

    </link>
    <joint name="front_right_leg_tip_joint" type="fixed">
        <parent link="front_right_leg1" />
        <child link="front_right_leg_tip" />
        <origin rpy="0 0 0" xyz="0 -0.0165 -0.2976325" />
        <dynamics damping="10" friction="0.5" />
    </joint>
    <gazebo reference="front_right_leg_tip">
        <minDepth>0.0002</minDepth>
        <collision name="front_right_leg_tip_collision">
            <geometry>
                <sphere>
                    <radius>0.0165</radius>
                </sphere>
            </geometry>
            <surface>
                <friction>
                    <ode>
                        <mu>100000.0</mu>
                        <mu2>100000.0</mu2>
                    </ode>
                    <torsional>
                        <coefficient>1000000</coefficient>
                        <use_patch_radius>true</use_patch_radius>
                        <surface_radius>0.0165</surface_radius>
                        <patch_radius>0.0165</patch_radius>
                    </torsional>
                </friction>
            </surface>
        </collision>
        <sensor name="front_right_leg_tip_contact_sensor" type="contact">
            <plugin filename="libgazebo_ros_bumper.so" name="gazebo_ros_bumper_controller">
                <robotNamespace>/quadruped</robotNamespace>
                <bumperTopicName>front_right_leg_tip_contact_sensor</bumperTopicName>
                <frameName>front_right_leg_tip</frameName>
                <alwayson>true</alwayson>
                <updaterate>100</updaterate>
            </plugin>
            <always_on>true</always_on>
            <update_rate>100</update_rate>
            <contact>
                <collision>front_right_leg_tip_collision</collision>
            </contact>
        </sensor>
        <material>Gazebo/Black</material>
    </gazebo>
    <gazebo reference="front_right_leg_tip_joint">
        <provideFeedback>true</provideFeedback>
        <disableFixedJointLumping>true</disableFixedJointLumping>
    </gazebo>
    <link name="front_left_leg3">
        <visual>
            <origin rpy="0 0 0" xyz="0 0 0" />
            <geometry>
                <box size="0.033 0.033 0.1144" />
            </geometry>
            <material name="black" />
        </visual>
        <collision>
            <origin rpy="0 0 0" xyz="0 0 0" />
            <geometry>
                <box size="0.033 0.033 0.1144" />
            </geometry>
        </collision>
        
<inertial>
            <mass value="1.0648000000000004" />
            <inertia ixx="0.0001932612000000001" ixy="0.0" ixz="0.0" iyy="0.0001932612000000001" iyz="0.0" izz="0.0001932612000000001" />
        </inertial>

    </link>
    <joint name="front_left_leg3_joint" type="revolute">
        <axis xyz="0 0 1" />
        <parent link="base_link" />
        <child link="front_left_leg3" />
        <origin rpy="0 0 2.356194490192345" xyz="-0.1188 0.1188 0" />
        <limit effort="100.0" lower="-0.3490658503988659" upper="0.3490658503988659" velocity="10.0" />
        <dynamics damping="10" friction="0.5" />
    </joint>
    <gazebo reference="front_left_leg3">
        <mu1>100000.0</mu1>
        <mu2>100000.0</mu2>
        <material>Gazebo/White</material>
    </gazebo>
    <link name="front_left_leg2">
        <visual>
            <origin rpy="0 2.792526803190927 0" xyz="0.10336618828644993 -0.011000000000000001 0.03762221576582357" />
            <geometry>
                <box size="0.22000000000000003 0.022000000000000002 0.05500000000000001" />
            </geometry>
            <material name="white" />
        </visual>
        <collision>
            <origin rpy="0 2.792526803190927 0" xyz="0.10336618828644993 -0.011000000000000001 0.03762221576582357" />
            <geometry>
                <box size="0.22000000000000003 0.022000000000000002 0.05500000000000001" />
            </geometry>
        </collision>
        
<inertial>
            <mass value="0.5324000000000002" />
            <inertia ixx="0.0021688201333333345" ixy="0.0" ixz="0.0" iyy="0.0021688201333333345" iyz="0.0" izz="0.0021688201333333345" />
        </inertial>

    </link>
    <joint name="front_left_leg2_joint" type="revolute">
        <axis rpy="0 0 0" xyz="0 1 0" />
        <parent link="front_left_leg3" />
        <child link="front_left_leg2" />
        <origin xyz="0.0165 -0.0165 0" />
        <limit effort="100.0" lower="-0.3490658503988659" upper="0.3490658503988659" velocity="10.0" />
        <dynamics damping="10" friction="0.5" />
    </joint>
    <gazebo reference="front_left_leg2">
        <mu1>100000.0</mu1>
        <mu2>100000.0</mu2>
        <material>Gazebo/Black</material>
    </gazebo>
    <link name="front_left_leg1">
        <visual>
            <origin rpy="0 0 0" xyz="0 0.0165 -0.14300000000000002" />
            <geometry>
                <box size="0.033 0.033 0.28600000000000003" />
            </geometry>
            <material name="black" />
        </visual>
        <collision>
            <origin rpy="0 0 0" xyz="0 0.0165 -0.14300000000000002" />
            <geometry>
                <box size="0.033 0.033 0.28600000000000003" />
            </geometry>
        </collision>
        
<inertial>
            <mass value="8.518400000000003" />
            <inertia ixx="0.05883729866666671" ixy="0.0" ixz="0.0" iyy="0.05883729866666671" iyz="0.0" izz="0.05883729866666671" />
        </inertial>

    </link>
    <joint name="front_left_leg1_joint" type="revolute">
        <axis xyz="0 1 0" />
        <parent link="front_left_leg2" />
        <child link="front_left_leg1" />
        <origin rpy="0 -0.34906585039886595 0" xyz="0.20673237657289986 0 0.07524443153164714" />
        <limit effort="100.0" lower="-0.3490658503988659" upper="0.3490658503988659" velocity="10.0" />
        <dynamics damping="10" friction="0.5" />
    </joint>
    <gazebo reference="front_left_leg1">
        <mu1>100000.0</mu1>
        <mu2>100000.0</mu2>
        <material>Gazebo/White</material>
    </gazebo>
    <link name="front_left_leg_tip">
        <visual>
            <origin rpy="0 0 0" xyz="0 0 0" />
            <geometry>
                <sphere radius="0.023265" />
            </geometry>
            <material name="black" />
        </visual>
        <collision name="front_left_leg_tip">
            <origin rpy="0 0 0" xyz="0 0 0" />
            <geometry>
                <sphere radius="0.0165" />
            </geometry>
        </collision>
        
<inertial>
            <mass value="0.21296000000000007" />
            <inertia ixx="0.1" ixy="0.0" ixz="0.0" iyy="0.1" iyz="0.0" izz="0.1" />
        </inertial>

    </link>
    <joint name="front_left_leg_tip_joint" type="fixed">
        <parent link="front_left_leg1" />
        <child link="front_left_leg_tip" />
        <origin rpy="0 0 0" xyz="0 0.0165 -0.2976325" />
        <dynamics damping="10" friction="0.5" />
    </joint>
    <gazebo reference="front_left_leg_tip">
        <minDepth>0.0002</minDepth>
        <collision name="front_left_leg_tip_collision">
            <geometry>
                <sphere>
                    <radius>0.0165</radius>
                </sphere>
            </geometry>
            <surface>
                <friction>
                    <ode>
                        <mu>100000.0</mu>
                        <mu2>100000.0</mu2>
                    </ode>
                    <torsional>
                        <coefficient>1000000</coefficient>
                        <use_patch_radius>true</use_patch_radius>
                        <surface_radius>0.0165</surface_radius>
                        <patch_radius>0.0165</patch_radius>
                    </torsional>
                </friction>
            </surface>
        </collision>
        <sensor name="front_left_leg_tip_contact_sensor" type="contact">
            <plugin filename="libgazebo_ros_bumper.so" name="gazebo_ros_bumper_controller">
                <robotNamespace>/quadruped</robotNamespace>
                <bumperTopicName>front_left_leg_tip_contact_sensor</bumperTopicName>
                <frameName>front_left_leg_tip</frameName>
                <alwayson>true</alwayson>
                <updaterate>100</updaterate>
            </plugin>
            <always_on>true</always_on>
            <update_rate>100</update_rate>
            <contact>
                <collision>front_left_leg_tip_collision</collision>
            </contact>
        </sensor>
        <material>Gazebo/Black</material>
    </gazebo>
    <gazebo reference="front_left_leg_tip_joint">
        <provideFeedback>true</provideFeedback>
        <disableFixedJointLumping>true</disableFixedJointLumping>
    </gazebo>
    <link name="back_right_leg3">
        <visual>
            <origin rpy="0 0 0" xyz="0 0 0" />
            <geometry>
                <box size="0.033 0.033 0.1144" />
            </geometry>
            <material name="black" />
        </visual>
        <collision>
            <origin rpy="0 0 0" xyz="0 0 0" />
            <geometry>
                <box size="0.033 0.033 0.1144" />
            </geometry>
        </collision>
        
<inertial>
            <mass value="1.0648000000000004" />
            <inertia ixx="0.0001932612000000001" ixy="0.0" ixz="0.0" iyy="0.0001932612000000001" iyz="0.0" izz="0.0001932612000000001" />
        </inertial>

    </link>
    <joint name="back_right_leg3_joint" type="revolute">
        <axis xyz="0 0 1" />
        <parent link="base_link" />
        <child link="back_right_leg3" />
        <origin rpy="0 0 -0.7853981633974483" xyz="0.1188 -0.1188 0" />
        <limit effort="100.0" lower="-0.3490658503988659" upper="0.3490658503988659" velocity="10.0" />
        <dynamics damping="10" friction="0.5" />
    </joint>
    <gazebo reference="back_right_leg3">
        <mu1>100000.0</mu1>
        <mu2>100000.0</mu2>
        <material>Gazebo/White</material>
    </gazebo>
    <link name="back_right_leg2">
        <visual>
            <origin rpy="0 2.792526803190927 0" xyz="0.10336618828644993 0.011000000000000001 0.03762221576582357" />
            <geometry>
                <box size="0.22000000000000003 0.022000000000000002 0.05500000000000001" />
            </geometry>
            <material name="white" />
        </visual>
        <collision>
            <origin rpy="0 2.792526803190927 0" xyz="0.10336618828644993 0.011000000000000001 0.03762221576582357" />
            <geometry>
                <box size="0.22000000000000003 0.022000000000000002 0.05500000000000001" />
            </geometry>
        </collision>
        
<inertial>
            <mass value="0.5324000000000002" />
            <inertia ixx="0.0021688201333333345" ixy="0.0" ixz="0.0" iyy="0.0021688201333333345" iyz="0.0" izz="0.0021688201333333345" />
        </inertial>

    </link>
    <joint name="back_right_leg2_joint" type="revolute">
        <axis rpy="0 0 0" xyz="0 1 0" />
        <parent link="back_right_leg3" />
        <child link="back_right_leg2" />
        <origin xyz="0.0165 0.0165 0" />
        <limit effort="100.0" lower="-0.3490658503988659" upper="0.3490658503988659" velocity="10.0" />
        <dynamics damping="10" friction="0.5" />
    </joint>
    <gazebo reference="back_right_leg2">
        <mu1>100000.0</mu1>
        <mu2>100000.0</mu2>
        <material>Gazebo/Black</material>
    </gazebo>
    <link name="back_right_leg1">
        <visual>
            <origin rpy="0 0 0" xyz="0 -0.0165 -0.14300000000000002" />
            <geometry>
                <box size="0.033 0.033 0.28600000000000003" />
            </geometry>
            <material name="black" />
        </visual>
        <collision>
            <origin rpy="0 0 0" xyz="0 -0.0165 -0.14300000000000002" />
            <geometry>
                <box size="0.033 0.033 0.28600000000000003" />
            </geometry>
        </collision>
        
<inertial>
            <mass value="8.518400000000003" />
            <inertia ixx="0.05883729866666671" ixy="0.0" ixz="0.0" iyy="0.05883729866666671" iyz="0.0" izz="0.05883729866666671" />
        </inertial>

    </link>
    <joint name="back_right_leg1_joint" type="revolute">
        <axis xyz="0 1 0" />
        <parent link="back_right_leg2" />
        <child link="back_right_leg1" />
        <origin rpy="0 -0.34906585039886595 0" xyz="0.20673237657289986 0 0.07524443153164714" />
        <limit effort="100.0" lower="-0.3490658503988659" upper="0.3490658503988659" velocity="10.0" />
        <dynamics damping="10" friction="0.5" />
    </joint>
    <gazebo reference="back_right_leg1">
        <mu1>100000.0</mu1>
        <mu2>100000.0</mu2>
        <material>Gazebo/White</material>
    </gazebo>
    <link name="back_right_leg_tip">
        <visual>
            <origin rpy="0 0 0" xyz="0 0 0" />
            <geometry>
                <sphere radius="0.023265" />
            </geometry>
            <material name="black" />
        </visual>
        <collision name="back_right_leg_tip">
            <origin rpy="0 0 0" xyz="0 0 0" />
            <geometry>
                <sphere radius="0.0165" />
            </geometry>
        </collision>
        
<inertial>
            <mass value="0.21296000000000007" />
            <inertia ixx="0.1" ixy="0.0" ixz="0.0" iyy="0.1" iyz="0.0" izz="0.1" />
        </inertial>

    </link>
    <joint name="back_right_leg_tip_joint" type="fixed">
        <parent link="back_right_leg1" />
        <child link="back_right_leg_tip" />
        <origin rpy="0 0 0" xyz="0 -0.0165 -0.2976325" />
        <dynamics damping="10" friction="0.5" />
    </joint>
    <gazebo reference="back_right_leg_tip">
        <minDepth>0.0002</minDepth>
        <collision name="back_right_leg_tip_collision">
            <geometry>
                <sphere>
                    <radius>0.0165</radius>
                </sphere>
            </geometry>
            <surface>
                <friction>
                    <ode>
                        <mu>100000.0</mu>
                        <mu2>100000.0</mu2>
                    </ode>
                    <torsional>
                        <coefficient>1000000</coefficient>
                        <use_patch_radius>true</use_patch_radius>
                        <surface_radius>0.0165</surface_radius>
                        <patch_radius>0.0165</patch_radius>
                    </torsional>
                </friction>
            </surface>
        </collision>
        <sensor name="back_right_leg_tip_contact_sensor" type="contact">
            <plugin filename="libgazebo_ros_bumper.so" name="gazebo_ros_bumper_controller">
                <robotNamespace>/quadruped</robotNamespace>
                <bumperTopicName>back_right_leg_tip_contact_sensor</bumperTopicName>
                <frameName>back_right_leg_tip</frameName>
                <alwayson>true</alwayson>
                <updaterate>100</updaterate>
            </plugin>
            <always_on>true</always_on>
            <update_rate>100</update_rate>
            <contact>
                <collision>back_right_leg_tip_collision</collision>
            </contact>
        </sensor>
        <material>Gazebo/Black</material>
    </gazebo>
    <gazebo reference="back_right_leg_tip_joint">
        <provideFeedback>true</provideFeedback>
        <disableFixedJointLumping>true</disableFixedJointLumping>
    </gazebo>
    <link name="back_left_leg3">
        <visual>
            <origin rpy="0 0 0" xyz="0 0 0" />
            <geometry>
                <box size="0.033 0.033 0.1144" />
            </geometry>
            <material name="black" />
        </visual>
        <collision>
            <origin rpy="0 0 0" xyz="0 0 0" />
            <geometry>
                <box size="0.033 0.033 0.1144" />
            </geometry>
        </collision>
        
<inertial>
            <mass value="1.0648000000000004" />
            <inertia ixx="0.0001932612000000001" ixy="0.0" ixz="0.0" iyy="0.0001932612000000001" iyz="0.0" izz="0.0001932612000000001" />
        </inertial>

    </link>
    <joint name="back_left_leg3_joint" type="revolute">
        <axis xyz="0 0 1" />
        <parent link="base_link" />
        <child link="back_left_leg3" />
        <origin rpy="0 0 -2.356194490192345" xyz="-0.1188 -0.1188 0" />
        <limit effort="100.0" lower="-0.3490658503988659" upper="0.3490658503988659" velocity="10.0" />
        <dynamics damping="10" friction="0.5" />
    </joint>
    <gazebo reference="back_left_leg3">
        <mu1>100000.0</mu1>
        <mu2>100000.0</mu2>
        <material>Gazebo/White</material>
    </gazebo>
    <link name="back_left_leg2">
        <visual>
            <origin rpy="0 2.792526803190927 0" xyz="0.10336618828644993 -0.011000000000000001 0.03762221576582357" />
            <geometry>
                <box size="0.22000000000000003 0.022000000000000002 0.05500000000000001" />
            </geometry>
            <material name="white" />
        </visual>
        <collision>
            <origin rpy="0 2.792526803190927 0" xyz="0.10336618828644993 -0.011000000000000001 0.03762221576582357" />
            <geometry>
                <box size="0.22000000000000003 0.022000000000000002 0.05500000000000001" />
            </geometry>
        </collision>
        
<inertial>
            <mass value="0.5324000000000002" />
            <inertia ixx="0.0021688201333333345" ixy="0.0" ixz="0.0" iyy="0.0021688201333333345" iyz="0.0" izz="0.0021688201333333345" />
        </inertial>

    </link>
    <joint name="back_left_leg2_joint" type="revolute">
        <axis rpy="0 0 0" xyz="0 1 0" />
        <parent link="back_left_leg3" />
        <child link="back_left_leg2" />
        <origin xyz="0.0165 -0.0165 0" />
        <limit effort="100.0" lower="-0.3490658503988659" upper="0.3490658503988659" velocity="10.0" />
        <dynamics damping="10" friction="0.5" />
    </joint>
    <gazebo reference="back_left_leg2">
        <mu1>100000.0</mu1>
        <mu2>100000.0</mu2>
        <material>Gazebo/Black</material>
    </gazebo>
    <link name="back_left_leg1">
        <visual>
            <origin rpy="0 0 0" xyz="0 0.0165 -0.14300000000000002" />
            <geometry>
                <box size="0.033 0.033 0.28600000000000003" />
            </geometry>
            <material name="black" />
        </visual>
        <collision>
            <origin rpy="0 0 0" xyz="0 0.0165 -0.14300000000000002" />
            <geometry>
                <box size="0.033 0.033 0.28600000000000003" />
            </geometry>
        </collision>
        
<inertial>
            <mass value="8.518400000000003" />
            <inertia ixx="0.05883729866666671" ixy="0.0" ixz="0.0" iyy="0.05883729866666671" iyz="0.0" izz="0.05883729866666671" />
        </inertial>

    </link>
    <joint name="back_left_leg1_joint" type="revolute">
        <axis xyz="0 1 0" />
        <parent link="back_left_leg2" />
        <child link="back_left_leg1" />
        <origin rpy="0 -0.34906585039886595 0" xyz="0.20673237657289986 0 0.07524443153164714" />
        <limit effort="100.0" lower="-0.3490658503988659" upper="0.3490658503988659" velocity="10.0" />
        <dynamics damping="10" friction="0.5" />
    </joint>
    <gazebo reference="back_left_leg1">
        <mu1>100000.0</mu1>
        <mu2>100000.0</mu2>
        <material>Gazebo/White</material>
    </gazebo>
    <link name="back_left_leg_tip">
        <visual>
            <origin rpy="0 0 0" xyz="0 0 0" />
            <geometry>
                <sphere radius="0.023265" />
            </geometry>
            <material name="black" />
        </visual>
        <collision name="back_left_leg_tip">
            <origin rpy="0 0 0" xyz="0 0 0" />
            <geometry>
                <sphere radius="0.0165" />
            </geometry>
        </collision>
        
<inertial>
            <mass value="0.21296000000000007" />
            <inertia ixx="0.1" ixy="0.0" ixz="0.0" iyy="0.1" iyz="0.0" izz="0.1" />
        </inertial>

    </link>
    <joint name="back_left_leg_tip_joint" type="fixed">
        <parent link="back_left_leg1" />
        <child link="back_left_leg_tip" />
        <origin rpy="0 0 0" xyz="0 0.0165 -0.2976325" />
        <dynamics damping="10" friction="0.5" />
    </joint>
    <gazebo reference="back_left_leg_tip">
        <minDepth>0.0002</minDepth>
        <collision name="back_left_leg_tip_collision">
            <geometry>
                <sphere>
                    <radius>0.0165</radius>
                </sphere>
            </geometry>
            <surface>
                <friction>
                    <ode>
                        <mu>100000.0</mu>
                        <mu2>100000.0</mu2>
                    </ode>
                    <torsional>
                        <coefficient>1000000</coefficient>
                        <use_patch_radius>true</use_patch_radius>
                        <surface_radius>0.0165</surface_radius>
                        <patch_radius>0.0165</patch_radius>
                    </torsional>
                </friction>
            </surface>
        </collision>
        <sensor name="back_left_leg_tip_contact_sensor" type="contact">
            <plugin filename="libgazebo_ros_bumper.so" name="gazebo_ros_bumper_controller">
                <robotNamespace>/quadruped</robotNamespace>
                <bumperTopicName>back_left_leg_tip_contact_sensor</bumperTopicName>
                <frameName>back_left_leg_tip</frameName>
                <alwayson>true</alwayson>
                <updaterate>100</updaterate>
            </plugin>
            <always_on>true</always_on>
            <update_rate>100</update_rate>
            <contact>
                <collision>back_left_leg_tip_collision</collision>
            </contact>
        </sensor>
        <material>Gazebo/Black</material>
    </gazebo>
    <gazebo reference="back_left_leg_tip_joint">
        <provideFeedback>true</provideFeedback>
        <disableFixedJointLumping>true</disableFixedJointLumping>
    </gazebo>
    <!-- gazebo ros joint state pub plugin -->
    <gazebo>
        <plugin filename="libgazebo_ros_joint_state_publisher.so" name="joint_state_publisher">
            <robotNamespace>/quadruped</robotNamespace>
            <jointName>front_right_leg1_joint, front_right_leg2_joint, front_right_leg3_joint, front_left_leg1_joint, front_left_leg2_joint, front_left_leg3_joint, back_right_leg1_joint, back_right_leg2_joint, back_right_leg3_joint, back_left_leg1_joint, back_left_leg2_joint, back_left_leg3_joint</jointName>
            <updateRate>60.0</updateRate>
            <alwaysOn>true</alwaysOn>
        </plugin>
    </gazebo>
    
<transmission name="tran1">
        <joint name="front_right_leg1_joint">
            <hardwareInterface>hardware_interface/PositionJointInterface</hardwareInterface>
        </joint>
        <type>transmission_interface/SimpleTransmission</type>
        <actuator name="servo1">
            <hardwareInterface>hardware_interface/PositionJointInterface</hardwareInterface>
            <mechanicalReduction>1</mechanicalReduction>
        </actuator>
    </transmission>
    <transmission name="tran2">
        <joint name="front_right_leg2_joint">
            <hardwareInterface>hardware_interface/PositionJointInterface</hardwareInterface>
        </joint>
        <type>transmission_interface/SimpleTransmission</type>
        <actuator name="servo2">
            <hardwareInterface>hardware_interface/PositionJointInterface</hardwareInterface>
            <mechanicalReduction>1</mechanicalReduction>
        </actuator>
    </transmission>
    <transmission name="tran3">
        <joint name="front_right_leg3_joint">
            <hardwareInterface>hardware_interface/PositionJointInterface</hardwareInterface>
        </joint>
        <type>transmission_interface/SimpleTransmission</type>
        <actuator name="servo3">
            <hardwareInterface>hardware_interface/PositionJointInterface</hardwareInterface>
            <mechanicalReduction>1</mechanicalReduction>
        </actuator>
    </transmission>
    <transmission name="tran4">
        <joint name="front_left_leg1_joint">
            <hardwareInterface>hardware_interface/PositionJointInterface</hardwareInterface>
        </joint>
        <type>transmission_interface/SimpleTransmission</type>
        <actuator name="servo4">
            <hardwareInterface>hardware_interface/PositionJointInterface</hardwareInterface>
            <mechanicalReduction>1</mechanicalReduction>
        </actuator>
    </transmission>
    <transmission name="tran5">
        <joint name="front_left_leg2_joint">
            <hardwareInterface>hardware_interface/PositionJointInterface</hardwareInterface>
        </joint>
        <type>transmission_interface/SimpleTransmission</type>
        <actuator name="servo5">
            <hardwareInterface>hardware_interface/PositionJointInterface</hardwareInterface>
            <mechanicalReduction>1</mechanicalReduction>
        </actuator>
    </transmission>
    <transmission name="tran6">
        <joint name="front_left_leg3_joint">
            <hardwareInterface>hardware_interface/PositionJointInterface</hardwareInterface>
        </joint>
        <type>transmission_interface/SimpleTransmission</type>
        <actuator name="servo6">
            <hardwareInterface>hardware_interface/PositionJointInterface</hardwareInterface>
            <mechanicalReduction>1</mechanicalReduction>
        </actuator>
    </transmission>
    <transmission name="tran7">
        <joint name="back_right_leg1_joint">
            <hardwareInterface>hardware_interface/PositionJointInterface</hardwareInterface>
        </joint>
        <type>transmission_interface/SimpleTransmission</type>
        <actuator name="servo7">
            <hardwareInterface>hardware_interface/PositionJointInterface</hardwareInterface>
            <mechanicalReduction>1</mechanicalReduction>
        </actuator>
    </transmission>
    <transmission name="tran8">
        <joint name="back_right_leg2_joint">
            <hardwareInterface>hardware_interface/PositionJointInterface</hardwareInterface>
        </joint>
        <type>transmission_interface/SimpleTransmission</type>
        <actuator name="servo8">
            <hardwareInterface>hardware_interface/PositionJointInterface</hardwareInterface>
            <mechanicalReduction>1</mechanicalReduction>
        </actuator>
    </transmission>
    <transmission name="tran9">
        <joint name="back_right_leg3_joint">
            <hardwareInterface>hardware_interface/PositionJointInterface</hardwareInterface>
        </joint>
        <type>transmission_interface/SimpleTransmission</type>
        <actuator name="servo9">
            <hardwareInterface>hardware_interface/PositionJointInterface</hardwareInterface>
            <mechanicalReduction>1</mechanicalReduction>
        </actuator>
    </transmission>
    <transmission name="tran10">
        <joint name="back_left_leg1_joint">
            <hardwareInterface>hardware_interface/PositionJointInterface</hardwareInterface>
        </joint>
        <type>transmission_interface/SimpleTransmission</type>
        <actuator name="servo10">
            <hardwareInterface>hardware_interface/PositionJointInterface</hardwareInterface>
            <mechanicalReduction>1</mechanicalReduction>
        </actuator>
    </transmission>
    <transmission name="tran11">
        <joint name="back_left_leg2_joint">
            <hardwareInterface>hardware_interface/PositionJointInterface</hardwareInterface>
        </joint>
        <type>transmission_interface/SimpleTransmission</type>
        <actuator name="servo11">
            <hardwareInterface>hardware_interface/PositionJointInterface</hardwareInterface>
            <mechanicalReduction>1</mechanicalReduction>
        </actuator>
    </transmission>
    <transmission name="tran12">
        <joint name="back_left_leg3_joint">
            <hardwareInterface>hardware_interface/PositionJointInterface</hardwareInterface>
        </joint>
        <type>transmission_interface/SimpleTransmission</type>
        <actuator name="servo12">
            <hardwareInterface>hardware_interface/PositionJointInterface</hardwareInterface>
            <mechanicalReduction>1</mechanicalReduction>
        </actuator>
    </transmission>
    <transmission name="trans_front_right_leg3_joint">
        <type>transmission_interface/SimpleTransmission</type>
        <joint name="front_right_leg3_joint">
            <hardwareInterface>hardware_interface/PositionJointInterface</hardwareInterface>
        </joint>
        <actuator name="front_right_leg3_joint_motor">
            <hardwareInterface>hardware_interface/PositionJointInterface</hardwareInterface>
            <mechanicalReduction>1</mechanicalReduction>
        </actuator>
    </transmission>
    <transmission name="trans_front_right_leg2_joint">
        <type>transmission_interface/SimpleTransmission</type>
        <joint name="front_right_leg2_joint">
            <hardwareInterface>hardware_interface/PositionJointInterface</hardwareInterface>
        </joint>
        <actuator name="front_right_leg2_joint_motor">
            <hardwareInterface>hardware_interface/PositionJointInterface</hardwareInterface>
            <mechanicalReduction>1</mechanicalReduction>
        </actuator>
    </transmission>
    <transmission name="trans_front_right_leg1_joint">
        <type>transmission_interface/SimpleTransmission</type>
        <joint name="front_right_leg1_joint">
            <hardwareInterface>hardware_interface/PositionJointInterface</hardwareInterface>
        </joint>
        <actuator name="front_right_leg1_joint_motor">
            <hardwareInterface>hardware_interface/PositionJointInterface</hardwareInterface>
            <mechanicalReduction>1</mechanicalReduction>
        </actuator>
    </transmission>
    <transmission name="trans_front_left_leg3_joint">
        <type>transmission_interface/SimpleTransmission</type>
        <joint name="front_left_leg3_joint">
            <hardwareInterface>hardware_interface/PositionJointInterface</hardwareInterface>
        </joint>
        <actuator name="front_left_leg3_joint_motor">
            <hardwareInterface>hardware_interface/PositionJointInterface</hardwareInterface>
            <mechanicalReduction>1</mechanicalReduction>
        </actuator>
    </transmission>
    <transmission name="trans_front_left_leg2_joint">
        <type>transmission_interface/SimpleTransmission</type>
        <joint name="front_left_leg2_joint">
            <hardwareInterface>hardware_interface/PositionJointInterface</hardwareInterface>
        </joint>
        <actuator name="front_left_leg2_joint_motor">
            <hardwareInterface>hardware_interface/PositionJointInterface</hardwareInterface>
            <mechanicalReduction>1</mechanicalReduction>
        </actuator>
    </transmission>
    <transmission name="trans_front_left_leg1_joint">
        <type>transmission_interface/SimpleTransmission</type>
        <joint name="front_left_leg1_joint">
            <hardwareInterface>hardware_interface/PositionJointInterface</hardwareInterface>
        </joint>
        <actuator name="front_left_leg1_joint_motor">
            <hardwareInterface>hardware_interface/PositionJointInterface</hardwareInterface>
            <mechanicalReduction>1</mechanicalReduction>
        </actuator>
    </transmission>
    <transmission name="trans_back_right_leg3_joint">
        <type>transmission_interface/SimpleTransmission</type>
        <joint name="back_right_leg3_joint">
            <hardwareInterface>hardware_interface/PositionJointInterface</hardwareInterface>
        </joint>
        <actuator name="back_right_leg3_joint_motor">
            <hardwareInterface>hardware_interface/PositionJointInterface</hardwareInterface>
            <mechanicalReduction>1</mechanicalReduction>
        </actuator>
    </transmission>
    <transmission name="trans_back_right_leg2_joint">
        <type>transmission_interface/SimpleTransmission</type>
        <joint name="back_right_leg2_joint">
            <hardwareInterface>hardware_interface/PositionJointInterface</hardwareInterface>
        </joint>
        <actuator name="back_right_leg2_joint_motor">
            <hardwareInterface>hardware_interface/PositionJointInterface</hardwareInterface>
            <mechanicalReduction>1</mechanicalReduction>
        </actuator>
    </transmission>
    <transmission name="trans_back_right_leg1_joint">
        <type>transmission_interface/SimpleTransmission</type>
        <joint name="back_right_leg1_joint">
            <hardwareInterface>hardware_interface/PositionJointInterface</hardwareInterface>
        </joint>
        <actuator name="back_right_leg1_joint_motor">
            <hardwareInterface>hardware_interface/PositionJointInterface</hardwareInterface>
            <mechanicalReduction>1</mechanicalReduction>
        </actuator>
    </transmission>
    <transmission name="trans_back_left_leg3_joint">
        <type>transmission_interface/SimpleTransmission</type>
        <joint name="back_left_leg3_joint">
            <hardwareInterface>hardware_interface/PositionJointInterface</hardwareInterface>
        </joint>
        <actuator name="back_left_leg3_joint_motor">
            <hardwareInterface>hardware_interface/PositionJointInterface</hardwareInterface>
            <mechanicalReduction>1</mechanicalReduction>
        </actuator>
    </transmission>
    <transmission name="trans_back_left_leg2_joint">
        <type>transmission_interface/SimpleTransmission</type>
        <joint name="back_left_leg2_joint">
            <hardwareInterface>hardware_interface/PositionJointInterface</hardwareInterface>
        </joint>
        <actuator name="back_left_leg2_joint_motor">
            <hardwareInterface>hardware_interface/PositionJointInterface</hardwareInterface>
            <mechanicalReduction>1</mechanicalReduction>
        </actuator>
    </transmission>
    <transmission name="trans_back_left_leg1_joint">
        <type>transmission_interface/SimpleTransmission</type>
        <joint name="back_left_leg1_joint">
            <hardwareInterface>hardware_interface/PositionJointInterface</hardwareInterface>
        </joint>
        <actuator name="back_left_leg1_joint_motor">
            <hardwareInterface>hardware_interface/PositionJointInterface</hardwareInterface>
            <mechanicalReduction>1</mechanicalReduction>
        </actuator>
    </transmission>
    <gazebo>
        <plugin name="gazebo_ros_control" filename="libgazebo_ros_control.so">
            <robotNamespace>/</robotNamespace>
        </plugin>
    </gazebo>
</robot>
