<?xml version="1.0" ?>
<robot name="quadruped">

<material name="silver">
  <color rgba="0.700 0.700 0.700 1.000"/>
</material>

<link name="base_link">
  <inertial>
    <origin rpy="0 0 0" xyz="9.059146598001685e-07 0.0015934023756066099 0.049996155576494214"/>
    <mass value="0.1660035395213305"/>
    <inertia ixx="0.00025709826617585223" ixy="4.218846787590979e-09" ixz="1.879354351720479e-20" iyy="0.0002571008959510167" iyz="-3.5575383784680614e-20" izz="0.0005139180584769373"/>
  </inertial>
  <visual>
    <origin rpy="0 0 0" xyz="0 0 0"/>
    <geometry>
      <mesh filename="package://quadruped_description/meshes/base_link.stl" scale="0.001 0.001 0.001"/>
    </geometry>
    <material name="silver"/>
    <material/>
  </visual>
  <collision>
    <origin rpy="0 0 0" xyz="9.059146598001685e-07 0.0015934023756066099 0.049996155576494214"/>
    <geometry>
      <box size="0.113187997 0.113187997 0.003188"/>
    </geometry>
  </collision>
</link>

<link name="body_spacer_v11">
  <inertial>
    <origin rpy="0 0 0" xyz="-2.3037127760971997e-17 3.4442350579921843e-07 0.0019124056524901095"/>
    <mass value="0.01987438429408557"/>
    <inertia ixx="9.045460492552543e-07" ixy="1.187813172238301e-22" ixz="3.208094714967838e-22" iyy="3.5199940199070806e-06" iyz="1.3552527156068805e-20" izz="2.6491024456185857e-06"/>
  </inertial>
  <visual>
    <origin rpy="0 0 0" xyz="0.0 0.041434 -0.05924"/>
    <geometry>
      <mesh filename="package://quadruped_description/meshes/body_spacer_v11.stl" scale="0.001 0.001 0.001"/>
    </geometry>
    <material name="silver"/>
    <material/>
  </visual>
  <collision>
    <origin rpy="0 0 0" xyz="-2.3037127760971997e-17 3.4442350579921843e-07 0.0019124056524901095"/>
    <geometry>
      <box size="0.03825 0.003188 0.019125"/>
    </geometry>
  </collision>
</link>

<link name="body_spacer_v12">
  <inertial>
    <origin rpy="0 0 0" xyz="-1.762479051592436e-17 0.08606284442350577 0.0019124056524901373"/>
    <mass value="0.01987438429408557"/>
    <inertia ixx="9.045460492552407e-07" ixy="1.1536192923691965e-22" ixz="1.9841293516984235e-22" iyy="3.5199940199070806e-06" iyz="6.776263578034403e-21" izz="2.649102445618572e-06"/>
  </inertial>
  <visual>
    <origin rpy="0 0 0" xyz="0.0 0.041434 -0.05924"/>
    <geometry>
      <mesh filename="package://quadruped_description/meshes/body_spacer_v12.stl" scale="0.001 0.001 0.001"/>
    </geometry>
    <material name="silver"/>
    <material/>
  </visual>
  <collision>
    <origin rpy="0 0 0" xyz="-1.762479051592436e-17 0.08606284442350577 0.0019124056524901373"/>
    <geometry>
      <box size="0.03825 0.003188 0.019125"/>
    </geometry>
  </collision>
</link>

<link name="body_spacer_v13">
  <inertial>
    <origin rpy="0 0 0" xyz="-0.04303125000000001 0.04303159442350578 0.0019124056524901165"/>
    <mass value="0.01987438429408557"/>
    <inertia ixx="3.5199940199070806e-06" ixy="2.117582368135751e-22" ixz="-6.776263578034403e-21" iyy="9.045460492552678e-07" iyz="-1.2705494208814505e-21" izz="2.649102445618572e-06"/>
  </inertial>
  <visual>
    <origin rpy="0 0 0" xyz="0.0 0.041434 -0.05924"/>
    <geometry>
      <mesh filename="package://quadruped_description/meshes/body_spacer_v13.stl" scale="0.001 0.001 0.001"/>
    </geometry>
    <material name="silver"/>
    <material/>
  </visual>
  <collision>
    <origin rpy="0 0 0" xyz="-0.04303125000000001 0.04303159442350578 0.0019124056524901165"/>
    <geometry>
      <box size="0.003188 0.03825 0.019125"/>
    </geometry>
  </collision>
</link>

<link name="body_spacer_v14">
  <inertial>
    <origin rpy="0 0 0" xyz="0.04303124999999997 0.04303159442350577 0.0019124056524901165"/>
    <mass value="0.01987438429408557"/>
    <inertia ixx="3.5199940199070806e-06" ixy="4.235164736271502e-22" ixz="0.0" iyy="9.045460492552543e-07" iyz="-1.2705494208814505e-21" izz="2.6491024456185653e-06"/>
  </inertial>
  <visual>
    <origin rpy="0 0 0" xyz="0.0 0.041434 -0.05924"/>
    <geometry>
      <mesh filename="package://quadruped_description/meshes/body_spacer_v14.stl" scale="0.001 0.001 0.001"/>
    </geometry>
    <material name="silver"/>
    <material/>
  </visual>
  <collision>
    <origin rpy="0 0 0" xyz="0.04303124999999997 0.04303159442350577 0.0019124056524901165"/>
    <geometry>
      <box size="0.003188 0.03825 0.019125"/>
    </geometry>
  </collision>
</link>

<link name="body_top_plate_v11">
  <inertial>
    <origin rpy="0 0 0" xyz="-6.217287019304255e-06 -7.919011395336392e-07 -0.0015933444235057687"/>
    <mass value="0.2442521638475155"/>
    <inertia ixx="0.00024636058368875027" ixy="-1.5462840425163707e-08" ixz="3.801060350803673e-20" iyy="0.00023570693205579888" iyz="-2.0328790734103208e-20" izz="0.0004816539090530351"/>
  </inertial>
  <visual>
    <origin rpy="0 0 0" xyz="1e-05 -0.001603 -0.073902"/>
    <geometry>
      <mesh filename="package://quadruped_description/meshes/body_top_plate_v11.stl" scale="0.001 0.001 0.001"/>
    </geometry>
    <material name="silver"/>
    <material/>
  </visual>
  <collision>
    <origin rpy="0 0 0" xyz="-6.217287019304255e-06 -7.919011395336392e-07 -0.0015933444235057687"/>
    <geometry>
      <box size="0.113187997 0.113187997 0.003188"/>
    </geometry>
  </collision>
</link>

<link name="servo_motor_v11">
  <inertial>
    <origin rpy="0 0 0" xyz="-0.0034453069163115357 -0.003444709272821242 -0.017291510897469234"/>
    <mass value="0.008039754705757893"/>
    <inertia ixx="6.933505671789865e-07" ixy="-1.5816887278955772e-07" ixz="-3.5143282431257484e-08" iyy="6.933505682155583e-07" iyz="-3.514328063131586e-08" izz="5.198658008256423e-07"/>
  </inertial>
  <visual>
    <origin rpy="0 0 0" xyz="-0.045406 -0.047003 -0.088004"/>
    <geometry>
      <mesh filename="package://quadruped_description/meshes/servo_motor_v11.stl" scale="0.001 0.001 0.001"/>
    </geometry>
    <material name="silver"/>
    <material/>
  </visual>
  <collision>
    <origin rpy="0 0 0" xyz="-0.045406 -0.047003 -0.088004"/>
    <geometry>
      <mesh filename="package://quadruped_description/meshes/servo_motor_v11.stl" scale="0.001 0.001 0.001"/>
    </geometry>
  </collision>
</link>

<link name="servo_motor_v12">
  <inertial>
    <origin rpy="0 0 0" xyz="-0.08736671792043224 -0.08736325662822253 -0.017291510897469248"/>
    <mass value="0.008039754705757893"/>
    <inertia ixx="6.933505671789865e-07" ixy="-1.5816887278954925e-07" ixz="3.5143282431257484e-08" iyy="6.933505682155651e-07" iyz="3.514328063131247e-08" izz="5.198658008256288e-07"/>
  </inertial>
  <visual>
    <origin rpy="0 0 0" xyz="-0.045406 -0.047003 -0.088004"/>
    <geometry>
      <mesh filename="package://quadruped_description/meshes/servo_motor_v12.stl" scale="0.001 0.001 0.001"/>
    </geometry>
    <material name="silver"/>
    <material/>
  </visual>
  <collision>
    <origin rpy="0 0 0" xyz="-0.045406 -0.047003 -0.088004"/>
    <geometry>
      <mesh filename="package://quadruped_description/meshes/servo_motor_v12.stl" scale="0.001 0.001 0.001"/>
    </geometry>
  </collision>
</link>

<link name="servo_motor_v13">
  <inertial>
    <origin rpy="0 0 0" xyz="-0.0034453067361639236 -0.08736610170001957 -0.01729151089746929"/>
    <mass value="0.008039754705757893"/>
    <inertia ixx="6.933505682155583e-07" ixy="1.581688727895594e-07" ixz="-3.514328063131586e-08" iyy="6.933505671789865e-07" iyz="3.514328243126087e-08" izz="5.198658008256423e-07"/>
  </inertial>
  <visual>
    <origin rpy="0 0 0" xyz="-0.045406 -0.047003 -0.088004"/>
    <geometry>
      <mesh filename="package://quadruped_description/meshes/servo_motor_v13.stl" scale="0.001 0.001 0.001"/>
    </geometry>
    <material name="silver"/>
    <material/>
  </visual>
  <collision>
    <origin rpy="0 0 0" xyz="-0.045406 -0.047003 -0.088004"/>
    <geometry>
      <mesh filename="package://quadruped_description/meshes/servo_motor_v13.stl" scale="0.001 0.001 0.001"/>
    </geometry>
  </collision>
</link>

<link name="servo_motor_v14">
  <inertial>
    <origin rpy="0 0 0" xyz="-0.08736671810057986 -0.0035677266622682127 -0.017291510897469248"/>
    <mass value="0.008039754705757893"/>
    <inertia ixx="6.933505682155447e-07" ixy="1.5816887278955433e-07" ixz="3.514328063131586e-08" iyy="6.933505671789865e-07" iyz="-3.5143282431257484e-08" izz="5.198658008256389e-07"/>
  </inertial>
  <visual>
    <origin rpy="0 0 0" xyz="-0.045406 -0.047003 -0.088004"/>
    <geometry>
      <mesh filename="package://quadruped_description/meshes/servo_motor_v14.stl" scale="0.001 0.001 0.001"/>
    </geometry>
    <material name="silver"/>
    <material/>
  </visual>
  <collision>
    <origin rpy="0 0 0" xyz="-0.045406 -0.047003 -0.088004"/>
    <geometry>
      <mesh filename="package://quadruped_description/meshes/servo_motor_v14.stl" scale="0.001 0.001 0.001"/>
    </geometry>
  </collision>
</link>

<link name="leg_servo_retainer_v11">
  <inertial>
    <origin rpy="0 0 0" xyz="0.007924108380789864 0.007923419580222718 -3.4442350579921843e-07"/>
    <mass value="0.011735752466802122"/>
    <inertia ixx="1.0587162227223e-06" ixy="-2.4853849465264854e-07" ixz="-6.776263578034403e-21" iyy="1.0584789299731293e-06" iyz="0.0" izz="2.0973223062330845e-06"/>
  </inertial>
  <visual>
    <origin rpy="0 0 0" xyz="-0.033325 -0.034922 -0.078684"/>
    <geometry>
      <mesh filename="package://quadruped_description/meshes/leg_servo_retainer_v11.stl" scale="0.001 0.001 0.001"/>
    </geometry>
    <material name="silver"/>
    <material/>
  </visual>
  <collision>
    <origin rpy="0 0 0" xyz="-0.033325 -0.034922 -0.078684"/>
    <geometry>
      <mesh filename="package://quadruped_description/meshes/leg_servo_retainer_v11.stl" scale="0.001 0.001 0.001"/>
    </geometry>
  </collision>
</link>

<link name="leg_servo_retainer_v12">
  <inertial>
    <origin rpy="0 0 0" xyz="-0.07457413321753362 -0.07456938548126654 -3.444235058408518e-07"/>
    <mass value="0.011735752466802122"/>
    <inertia ixx="1.0587162227223136e-06" ixy="-2.485384946526519e-07" ixz="0.0" iyy="1.0584789299731293e-06" iyz="-6.776263578034403e-21" izz="2.0973223062330845e-06"/>
  </inertial>
  <visual>
    <origin rpy="0 0 0" xyz="-0.033325 -0.034922 -0.078684"/>
    <geometry>
      <mesh filename="package://quadruped_description/meshes/leg_servo_retainer_v12.stl" scale="0.001 0.001 0.001"/>
    </geometry>
    <material name="silver"/>
    <material/>
  </visual>
  <collision>
    <origin rpy="0 0 0" xyz="-0.033325 -0.034922 -0.078684"/>
    <geometry>
      <mesh filename="package://quadruped_description/meshes/leg_servo_retainer_v12.stl" scale="0.001 0.001 0.001"/>
    </geometry>
  </collision>
</link>

<link name="leg_servo_retainer_v13">
  <inertial>
    <origin rpy="0 0 0" xyz="0.007922822116880023 -0.07457351699712099 -3.444235058547296e-07"/>
    <mass value="0.011735752466802122"/>
    <inertia ixx="1.0584789299731428e-06" ixy="2.485384946526519e-07" ixz="0.0" iyy="1.0587162227222865e-06" iyz="-6.776263578034403e-21" izz="2.0973223062330912e-06"/>
  </inertial>
  <visual>
    <origin rpy="0 0 0" xyz="-0.033325 -0.034922 -0.078684"/>
    <geometry>
      <mesh filename="package://quadruped_description/meshes/leg_servo_retainer_v13.stl" scale="0.001 0.001 0.001"/>
    </geometry>
    <material name="silver"/>
    <material/>
  </visual>
  <collision>
    <origin rpy="0 0 0" xyz="-0.033325 -0.034922 -0.078684"/>
    <geometry>
      <mesh filename="package://quadruped_description/meshes/leg_servo_retainer_v13.stl" scale="0.001 0.001 0.001"/>
    </geometry>
  </collision>
</link>

<link name="leg_servo_retainer_v14">
  <inertial>
    <origin rpy="0 0 0" xyz="-0.07457284695362379 0.007801688634833152 -3.444235058130962e-07"/>
    <mass value="0.011735752466802122"/>
    <inertia ixx="1.0584789299731157e-06" ixy="2.4853849465264515e-07" ixz="0.0" iyy="1.0587162227222594e-06" iyz="0.0" izz="2.0973223062330777e-06"/>
  </inertial>
  <visual>
    <origin rpy="0 0 0" xyz="-0.033325 -0.034922 -0.078684"/>
    <geometry>
      <mesh filename="package://quadruped_description/meshes/leg_servo_retainer_v14.stl" scale="0.001 0.001 0.001"/>
    </geometry>
    <material name="silver"/>
    <material/>
  </visual>
  <collision>
    <origin rpy="0 0 0" xyz="-0.033325 -0.034922 -0.078684"/>
    <geometry>
      <mesh filename="package://quadruped_description/meshes/leg_servo_retainer_v14.stl" scale="0.001 0.001 0.001"/>
    </geometry>
  </collision>
</link>

<link name="leg_top_pivot_plate_v11">
  <inertial>
    <origin rpy="0 0 0" xyz="0.010648424399168653 0.010577698071700968 -0.0015938444235058108"/>
    <mass value="0.020723046160568363"/>
    <inertia ixx="2.208794909615877e-06" ixy="-1.4903944877974097e-06" ixz="-2.710505431213761e-20" iyy="2.2591948027366653e-06" iyz="-1.3552527156068805e-20" izz="4.432898147857994e-06"/>
  </inertial>
  <visual>
    <origin rpy="0 0 0" xyz="-0.045406 -0.047003 -0.088004"/>
    <geometry>
      <mesh filename="package://quadruped_description/meshes/leg_top_pivot_plate_v11.stl" scale="0.001 0.001 0.001"/>
    </geometry>
    <material name="silver"/>
    <material/>
  </visual>
  <collision>
    <origin rpy="0 0 0.785398163" xyz="0.010648424399168653 0.010577698071700968 -0.0015938444235058108"/>
    <geometry>
     <box size="0.048442 0.02040  0.003188"/>
    </geometry>
  </collision>
</link>

<link name="leg_top_pivot_plate_v12">
  <inertial>
    <origin rpy="0 0 0" xyz="-0.10146044923591255 -0.1013856639727447 -0.0015938444235058524"/>
    <mass value="0.020723046160568363"/>
    <inertia ixx="2.2087949096158226e-06" ixy="-1.4903944877974097e-06" ixz="-2.710505431213761e-20" iyy="2.259194802736557e-06" iyz="-1.3552527156068805e-20" izz="4.432898147857967e-06"/>
  </inertial>
  <visual>
    <origin rpy="0 0 0" xyz="-0.045406 -0.047003 -0.088004"/>
    <geometry>
      <mesh filename="package://quadruped_description/meshes/leg_top_pivot_plate_v12.stl" scale="0.001 0.001 0.001"/>
    </geometry>
    <material name="silver"/>
    <material/>
  </visual>
  <collision>
    <origin rpy="0 0 0.785398163" xyz="-0.10146044923591255 -0.1013856639727447 -0.0015938444235058524"/>
    <geometry>
      <box size="0.048442 0.02040  0.003188"/>
    </geometry>
  </collision>
</link>

<link name="leg_top_pivot_plate_v13">
  <inertial>
    <origin rpy="0 0 0" xyz="0.010577100608358335 -0.10145983301549982 -0.001593844423505894"/>
    <mass value="0.020723046160568363"/>
    <inertia ixx="2.2591948027366653e-06" ixy="1.4903944877974233e-06" ixz="0.0" iyy="2.208794909615931e-06" iyz="0.0" izz="4.432898147857967e-06"/>
  </inertial>
  <visual>
    <origin rpy="0 0 0" xyz="-0.045406 -0.047003 -0.088004"/>
    <geometry>
      <mesh filename="package://quadruped_description/meshes/leg_top_pivot_plate_v13.stl" scale="0.001 0.001 0.001"/>
    </geometry>
    <material name="silver"/>
    <material/>
  </visual>
  <collision>
    <origin rpy="0 0 -0.785398163" xyz="0.010577100608358335 -0.10145983301549982 -0.001593844423505894"/>
    <geometry>
      <box size="0.048442 0.02040  0.003188"/>
    </geometry>
  </collision>
</link>

<link name="leg_top_pivot_plate_v14">
  <inertial>
    <origin rpy="0 0 0" xyz="-0.10138912544510212 0.010526004653212018 -0.0015938444235058247"/>
    <mass value="0.020723046160568363"/>
    <inertia ixx="2.2591948027367195e-06" ixy="1.4903944877974233e-06" ixz="2.710505431213761e-20" iyy="2.208794909615931e-06" iyz="0.0" izz="4.432898147857994e-06"/>
  </inertial>
  <visual>
    <origin rpy="0 0 0" xyz="-0.045406 -0.047003 -0.088004"/>
    <geometry>
      <mesh filename="package://quadruped_description/meshes/leg_top_pivot_plate_v14.stl" scale="0.001 0.001 0.001"/>
    </geometry>
    <material name="silver"/>
    <material/>
  </visual>
  <collision>
    <origin rpy="0 0 -0.785398163" xyz="-0.10138912544510212 0.010526004653212018 -0.0015938444235058247"/>
    <geometry>
      <box size="0.048442 0.02040  0.003188"/>
    </geometry>
  </collision>
</link>

<link name="leg_servo_mount_v11">
  <inertial>
    <origin rpy="0 0 0" xyz="0.006427091482037052 0.006426612462751641 -0.009351515125044133"/>
    <mass value="0.018978192167657257"/>
    <inertia ixx="3.4099288150504596e-06" ixy="-8.932533906415378e-07" ixz="-2.5996070057598855e-08" iyy="3.4099288150504867e-06" iyz="-2.599607005762596e-08" izz="1.818643680910739e-06"/>
  </inertial>
  <visual>
    <origin rpy="0 0 0" xyz="-0.058289 -0.069083 -0.076529"/>
    <geometry>
      <mesh filename="package://quadruped_description/meshes/leg_servo_mount_v11.stl" scale="0.001 0.001 0.001"/>
    </geometry>
    <material name="silver"/>
    <material/>
  </visual>
  <collision>
    <origin rpy="0 0 0" xyz="-0.058289 -0.069083 -0.076529"/>
    <geometry>
      <mesh filename="package://quadruped_description/meshes/leg_servo_mount_v11.stl" scale="0.001 0.001 0.001"/>
    </geometry>
  </collision>
</link>

<link name="leg_servo_mount_v12">
  <inertial>
    <origin rpy="0 0 0" xyz="-0.12300511631878094 -0.14139457836379538 -0.009351515125044202"/>
    <mass value="0.018978192167657257"/>
    <inertia ixx="3.4099288150504867e-06" ixy="-8.932533906415378e-07" ixz="2.5996070057612407e-08" iyy="3.4099288150504596e-06" iyz="2.599607005762596e-08" izz="1.818643680910739e-06"/>
  </inertial>
  <visual>
    <origin rpy="0 0 0" xyz="-0.058289 -0.069083 -0.076529"/>
    <geometry>
      <mesh filename="package://quadruped_description/meshes/leg_servo_mount_v12.stl" scale="0.001 0.001 0.001"/>
    </geometry>
    <material name="silver"/>
    <material/>
  </visual>
  <collision>
    <origin rpy="0 0 0" xyz="-0.058289 -0.069083 -0.076529"/>
    <geometry>
      <mesh filename="package://quadruped_description/meshes/leg_servo_mount_v12.stl" scale="0.001 0.001 0.001"/>
    </geometry>
  </collision>
</link>

<link name="leg_servo_mount_v13">
  <inertial>
    <origin rpy="0 0 0" xyz="0.015623014999408984 -0.13220150009836815 -0.009351515125044257"/>
    <mass value="0.018978192167657257"/>
    <inertia ixx="3.4099288150504325e-06" ixy="8.932533906415242e-07" ixz="-2.5996070057612407e-08" iyy="3.4099288150504596e-06" iyz="2.5996070057612407e-08" izz="1.818643680910739e-06"/>
  </inertial>
  <visual>
    <origin rpy="0 0 0" xyz="-0.058289 -0.069083 -0.076529"/>
    <geometry>
      <mesh filename="package://quadruped_description/meshes/leg_servo_mount_v13.stl" scale="0.001 0.001 0.001"/>
    </geometry>
    <material name="silver"/>
    <material/>
  </visual>
  <collision>
    <origin rpy="0 0 0" xyz="-0.058289 -0.069083 -0.076529"/>
    <geometry>
      <mesh filename="package://quadruped_description/meshes/leg_servo_mount_v13.stl" scale="0.001 0.001 0.001"/>
    </geometry>
  </collision>
</link>

<link name="leg_servo_mount_v14">
  <inertial>
    <origin rpy="0 0 0" xyz="-0.132201039836153 -0.002892328263919511 -0.009351515125044133"/>
    <mass value="0.018978192167657257"/>
    <inertia ixx="3.4099288150504867e-06" ixy="8.932533906415242e-07" ixz="2.5996070057639513e-08" iyy="3.4099288150504867e-06" iyz="-2.5996070057639513e-08" izz="1.818643680910712e-06"/>
  </inertial>
  <visual>
    <origin rpy="0 0 0" xyz="-0.058289 -0.069083 -0.076529"/>
    <geometry>
      <mesh filename="package://quadruped_description/meshes/leg_servo_mount_v14.stl" scale="0.001 0.001 0.001"/>
    </geometry>
    <material name="silver"/>
    <material/>
  </visual>
  <collision>
    <origin rpy="0 0 0" xyz="-0.058289 -0.069083 -0.076529"/>
    <geometry>
      <mesh filename="package://quadruped_description/meshes/leg_servo_mount_v14.stl" scale="0.001 0.001 0.001"/>
    </geometry>
  </collision>
</link>

<link name="servo_motor_v15">
  <inertial>
    <origin rpy="0 0 0" xyz="0.027946655456124396 0.04841610817225183 -0.013934864453551216"/>
    <mass value="0.008039754705757893"/>
    <inertia ixx="6.856926219289921e-07" ixy="1.658268198306015e-07" ixz="3.5143281164800927e-08" iyy="6.856926193835023e-07" iyz="-3.5143281897775805e-08" izz="5.351816949077299e-07"/>
  </inertial>
  <visual>
    <origin rpy="0 0 0" xyz="-0.033325 -0.034922 -0.078684"/>
    <geometry>
      <mesh filename="package://quadruped_description/meshes/servo_motor_v15.stl" scale="0.001 0.001 0.001"/>
    </geometry>
    <material name="silver"/>
    <material/>
  </visual>
  <collision>
    <origin rpy="0 0 0" xyz="-0.033325 -0.034922 -0.078684"/>
    <geometry>
      <mesh filename="package://quadruped_description/meshes/servo_motor_v15.stl" scale="0.001 0.001 0.001"/>
    </geometry>
  </collision>
</link>

<link name="servo_motor_v16">
  <inertial>
    <origin rpy="0 0 0" xyz="-0.09459668029286844 -0.11506207407329555 -0.013934864453551313"/>
    <mass value="0.008039754705757893"/>
    <inertia ixx="6.856926219289921e-07" ixy="1.6582681983059474e-07" ixz="-3.5143281164800927e-08" iyy="6.856926193834752e-07" iyz="3.514328189776225e-08" izz="5.351816949077164e-07"/>
  </inertial>
  <visual>
    <origin rpy="0 0 0" xyz="-0.033325 -0.034922 -0.078684"/>
    <geometry>
      <mesh filename="package://quadruped_description/meshes/servo_motor_v16.stl" scale="0.001 0.001 0.001"/>
    </geometry>
    <material name="silver"/>
    <material/>
  </visual>
  <collision>
    <origin rpy="0 0 0" xyz="-0.033325 -0.034922 -0.078684"/>
    <geometry>
      <mesh filename="package://quadruped_description/meshes/servo_motor_v16.stl" scale="0.001 0.001 0.001"/>
    </geometry>
  </collision>
</link>

<link name="servo_motor_v17">
  <inertial>
    <origin rpy="0 0 0" xyz="0.048415510708909044 -0.09459606407245555 -0.013934864453551354"/>
    <mass value="0.008039754705757893"/>
    <inertia ixx="6.856926193835023e-07" ixy="-1.658268198306015e-07" ixz="-3.514328189776225e-08" iyy="6.85692621928965e-07" iyz="-3.5143281164800927e-08" izz="5.351816949077028e-07"/>
  </inertial>
  <visual>
    <origin rpy="0 0 0" xyz="-0.033325 -0.034922 -0.078684"/>
    <geometry>
      <mesh filename="package://quadruped_description/meshes/servo_motor_v17.stl" scale="0.001 0.001 0.001"/>
    </geometry>
    <material name="silver"/>
    <material/>
  </visual>
  <collision>
    <origin rpy="0 0 0" xyz="-0.033325 -0.034922 -0.078684"/>
    <geometry>
      <mesh filename="package://quadruped_description/meshes/servo_motor_v17.stl" scale="0.001 0.001 0.001"/>
    </geometry>
  </collision>
</link>

<link name="servo_motor_v18">
  <inertial>
    <origin rpy="0 0 0" xyz="-0.11506553554565327 0.027824235710167892 -0.013934864453551118"/>
    <mass value="0.008039754705757893"/>
    <inertia ixx="6.856926193834752e-07" ixy="-1.658268198306015e-07" ixz="3.514328189778258e-08" iyy="6.856926219289921e-07" iyz="3.5143281164800927e-08" izz="5.351816949077164e-07"/>
  </inertial>
  <visual>
    <origin rpy="0 0 0" xyz="-0.033325 -0.034922 -0.078684"/>
    <geometry>
      <mesh filename="package://quadruped_description/meshes/servo_motor_v18.stl" scale="0.001 0.001 0.001"/>
    </geometry>
    <material name="silver"/>
    <material/>
  </visual>
  <collision>
    <origin rpy="0 0 0" xyz="-0.033325 -0.034922 -0.078684"/>
    <geometry>
      <mesh filename="package://quadruped_description/meshes/servo_motor_v18.stl" scale="0.001 0.001 0.001"/>
    </geometry>
  </collision>
</link>

<link name="leg_servo_arm_v11">
  <inertial>
    <origin rpy="0 0 0" xyz="0.006854663369280534 0.009109263260319467 4.051724359702136e-07"/>
    <mass value="0.01005919143698447"/>
    <inertia ixx="7.37904947339249e-07" ixy="-5.760670437510195e-07" ixz="8.610598128608316e-17" iyy="7.379049473392083e-07" iyz="8.609242875892709e-17" izz="1.1691679136267982e-06"/>
  </inertial>
  <visual>
    <origin rpy="0 0 0" xyz="-0.073499 -0.071111 -0.059877"/>
    <geometry>
      <mesh filename="package://quadruped_description/meshes/leg_servo_arm_v11.stl" scale="0.001 0.001 0.001"/>
    </geometry>
    <material name="silver"/>
    <material/>
  </visual>
  <collision>
    <origin rpy="0 0 0" xyz="-0.073499 -0.071111 -0.059877"/>
    <geometry>
      <mesh filename="package://quadruped_description/meshes/leg_servo_arm_v11.stl" scale="0.001 0.001 0.001"/>
    </geometry>
  </collision>
</link>

<link name="leg_servo_arm_v12">
  <inertial>
    <origin rpy="0 0 0" xyz="-0.1515986882060246 -0.15038722916136313 4.051727157394769e-07"/>
    <mass value="0.01005919143698447"/>
    <inertia ixx="7.379049473392219e-07" ixy="-5.76067043751006e-07" ixz="8.609242875892709e-17" iyy="7.379049473392219e-07" iyz="8.609920502250512e-17" izz="1.169167913626771e-06"/>
  </inertial>
  <visual>
    <origin rpy="0 0 0" xyz="-0.071245 -0.073365 -0.059877"/>
    <geometry>
      <mesh filename="package://quadruped_description/meshes/leg_servo_arm_v12.stl" scale="0.001 0.001 0.001"/>
    </geometry>
    <material name="silver"/>
    <material/>
  </visual>
  <collision>
    <origin rpy="0 0 0" xyz="-0.071245 -0.073365 -0.059877"/>
    <geometry>
      <mesh filename="package://quadruped_description/meshes/leg_servo_arm_v12.stl" scale="0.001 0.001 0.001"/>
    </geometry>
  </collision>
</link>

<link name="leg_servo_arm_v13">
  <inertial>
    <origin rpy="0 0 0" xyz="0.0073776657969769205 -0.1521210719856115 4.051727155868212e-07"/>
    <mass value="0.01005919143698447"/>
    <inertia ixx="7.379049473391948e-07" ixy="5.760670437510195e-07" ixz="-8.609920502250512e-17" iyy="7.37904947339249e-07" iyz="8.609920502250512e-17" izz="1.169167913626771e-06"/>
  </inertial>
  <visual>
    <origin rpy="0 0 0" xyz="-0.071245 -0.073365 -0.059877"/>
    <geometry>
      <mesh filename="package://quadruped_description/meshes/leg_servo_arm_v13.stl" scale="0.001 0.001 0.001"/>
    </geometry>
    <material name="silver"/>
    <material/>
  </visual>
  <collision>
    <origin rpy="0 0 0" xyz="-0.071245 -0.073365 -0.059877"/>
    <geometry>
      <mesh filename="package://quadruped_description/meshes/leg_servo_arm_v13.stl" scale="0.001 0.001 0.001"/>
    </geometry>
  </collision>
</link>

<link name="leg_servo_arm_v14">
  <inertial>
    <origin rpy="0 0 0" xyz="-0.15212169063372105 0.01071724362332406 4.0517243608817477e-07"/>
    <mass value="0.01005919143698447"/>
    <inertia ixx="7.379049473392083e-07" ixy="5.760670437510195e-07" ixz="-8.609920502250512e-17" iyy="7.379049473392219e-07" iyz="8.609920502250512e-17" izz="1.169167913626771e-06"/>
  </inertial>
  <visual>
    <origin rpy="0 0 0" xyz="-0.073499 -0.071111 -0.059877"/>
    <geometry>
      <mesh filename="package://quadruped_description/meshes/leg_servo_arm_v14.stl" scale="0.001 0.001 0.001"/>
    </geometry>
    <material name="silver"/>
    <material/>
  </visual>
  <collision>
    <origin rpy="0 0 0" xyz="-0.073499 -0.071111 -0.059877"/>
    <geometry>
      <mesh filename="package://quadruped_description/meshes/leg_servo_arm_v14.stl" scale="0.001 0.001 0.001"/>
    </geometry>
  </collision>
</link>

<link name="leg_rev_v11">
  <inertial>
    <origin rpy="0 0 0" xyz="0.0017515473433343115 -0.0003754399481460391 -0.0070623052238462936"/>
    <mass value="0.02607369115545735"/>
    <inertia ixx="1.5004588508372942e-05" ixy="-2.7879896393143166e-07" ixz="6.744760153939999e-07" iyy="1.5004588508373104e-05" iyz="6.744760153939863e-07" izz="5.96943480288205e-07"/>
  </inertial>
  <visual>
    <origin rpy="0 0 0" xyz="-0.09153 -0.089142 -0.059877"/>
    <geometry>
      <mesh filename="package://quadruped_description/meshes/leg_rev_v11.stl" scale="0.001 0.001 0.001"/>
    </geometry>
    <material name="silver"/>
    <material/>
  </visual>
  <collision>
    <origin rpy="0 0 0" xyz="-0.09153 -0.089142 -0.059877"/>
    <geometry>
      <mesh filename="package://quadruped_description/meshes/leg_rev_v11.stl" scale="0.001 0.001 0.001"/>
    </geometry>
  </collision>
</link>

<link name="leg_rev_v12">
  <inertial>
    <origin rpy="0 0 0" xyz="-0.1848115721800784 -0.1747105259528976 -0.0070623052238461825"/>
    <mass value="0.02607369115545735"/>
    <inertia ixx="1.5004588508372942e-05" ixy="-2.7879896393148587e-07" ixz="-6.744760153939728e-07" iyy="1.5004588508373104e-05" iyz="-6.744760153939592e-07" izz="5.96943480288205e-07"/>
  </inertial>
  <visual>
    <origin rpy="0 0 0" xyz="-0.09153 -0.089142 -0.059877"/>
    <geometry>
      <mesh filename="package://quadruped_description/meshes/leg_rev_v12.stl" scale="0.001 0.001 0.001"/>
    </geometry>
    <material name="silver"/>
    <material/>
  </visual>
  <collision>
    <origin rpy="0 0 0" xyz="-0.09153 -0.089142 -0.059877"/>
    <geometry>
      <mesh filename="package://quadruped_description/meshes/leg_rev_v12.stl" scale="0.001 0.001 0.001"/>
    </geometry>
  </collision>
</link>

<link name="leg_rev_v13">
  <inertial>
    <origin rpy="0 0 0" xyz="-0.004361037411488508 -0.18082595595966508 -0.0070623052238464185"/>
    <mass value="0.02607369115545735"/>
    <inertia ixx="1.5004588508373213e-05" ixy="2.7879896393145876e-07" ixz="6.744760153938508e-07" iyy="1.5004588508372942e-05" iyz="-6.744760153938915e-07" izz="5.969434802882592e-07"/>
  </inertial>
  <visual>
    <origin rpy="0 0 0" xyz="-0.09153 -0.089142 -0.059877"/>
    <geometry>
      <mesh filename="package://quadruped_description/meshes/leg_rev_v13.stl" scale="0.001 0.001 0.001"/>
    </geometry>
    <material name="silver"/>
    <material/>
  </visual>
  <collision>
    <origin rpy="0 0 0" xyz="-0.09153 -0.089142 -0.059877"/>
    <geometry>
      <mesh filename="package://quadruped_description/meshes/leg_rev_v13.stl" scale="0.001 0.001 0.001"/>
    </geometry>
  </collision>
</link>

<link name="leg_rev_v14">
  <inertial>
    <origin rpy="0 0 0" xyz="-0.17869898742525542 0.005614127597377852 -0.007062305223845974"/>
    <mass value="0.02607369115545735"/>
    <inertia ixx="1.5004588508373267e-05" ixy="2.787989639315672e-07" ixz="-6.74476015394027e-07" iyy="1.5004588508372887e-05" iyz="6.744760153939457e-07" izz="5.969434802883134e-07"/>
  </inertial>
  <visual>
    <origin rpy="0 0 0" xyz="-0.09153 -0.089142 -0.059877"/>
    <geometry>
      <mesh filename="package://quadruped_description/meshes/leg_rev_v14.stl" scale="0.001 0.001 0.001"/>
    </geometry>
    <material name="silver"/>
    <material/>
  </visual>
  <collision>
    <origin rpy="0 0 0" xyz="-0.09153 -0.089142 -0.059877"/>
    <geometry>
      <mesh filename="package://quadruped_description/meshes/leg_rev_v14.stl" scale="0.001 0.001 0.001"/>
    </geometry>
  </collision>
</link>

<link name="bottom_pivot_plate_v11">
  <inertial>
    <origin rpy="0 0 0" xyz="0.01000675765330758 0.010047118194641713 -0.0015933444235057687"/>
    <mass value="0.02183354723813213"/>
    <inertia ixx="2.3227089177674888e-06" ixy="-1.578481244283238e-06" ixz="-1.3552527156068805e-20" iyy="2.326148215223492e-06" iyz="-6.776263578034403e-21" izz="4.611885091085777e-06"/>
  </inertial>
  <visual>
    <origin rpy="0 0 0" xyz="-0.045406 -0.047003 -0.048402"/>
    <geometry>
      <mesh filename="package://quadruped_description/meshes/bottom_pivot_plate_v11.stl" scale="0.001 0.001 0.001"/>
    </geometry>
    <material name="silver"/>
    <material/>
  </visual>
  <collision>
    <origin rpy="0 0 0.785398163" xyz="0.01000675765330758 0.010047118194641713 -0.0015933444235057687"/>
    <geometry>
      <box size="0.048442 0.02040  0.003188"/>
    </geometry>
  </collision>
</link>

<link name="bottom_pivot_plate_v12">
  <inertial>
    <origin rpy="0 0 0" xyz="-0.10081878249005136 -0.10085508409568551 -0.0015933444235059352"/>
    <mass value="0.02183354723813213"/>
    <inertia ixx="2.3227089177674752e-06" ixy="-1.578481244283211e-06" ixz="-3.3881317890172014e-20" iyy="2.3261482152234784e-06" iyz="-2.710505431213761e-20" izz="4.61188509108575e-06"/>
  </inertial>
  <visual>
    <origin rpy="0 0 0" xyz="-0.045406 -0.047003 -0.048402"/>
    <geometry>
      <mesh filename="package://quadruped_description/meshes/bottom_pivot_plate_v12.stl" scale="0.001 0.001 0.001"/>
    </geometry>
    <material name="silver"/>
    <material/>
  </visual>
  <collision>
    <origin rpy="0 0 0.785398163" xyz="-0.10081878249005136 -0.10085508409568551 -0.0015933444235059352"/>
    <geometry>
      <box size="0.048442 0.02040  0.003188"/>
    </geometry>
  </collision>
</link>

<link name="bottom_pivot_plate_v13">
  <inertial>
    <origin rpy="0 0 0" xyz="0.010046520731299052 -0.10081816626963866 -0.0015933444235056785"/>
    <mass value="0.02183354723813213"/>
    <inertia ixx="2.3261482152234784e-06" ixy="1.578481244283211e-06" ixz="-2.710505431213761e-20" iyy="2.3227089177675023e-06" iyz="2.710505431213761e-20" izz="4.611885091085723e-06"/>
  </inertial>
  <visual>
    <origin rpy="0 0 0" xyz="-0.045406 -0.047003 -0.048402"/>
    <geometry>
      <mesh filename="package://quadruped_description/meshes/bottom_pivot_plate_v13.stl" scale="0.001 0.001 0.001"/>
    </geometry>
    <material name="silver"/>
    <material/>
  </visual>
  <collision>
    <origin rpy="0 0 -0.785398163" xyz="0.010046520731299052 -0.10081816626963866 -0.0015933444235056785"/>
    <geometry>
      <box size="0.048442 0.02040  0.003188"/>
    </geometry>
  </collision>
</link>

<link name="bottom_pivot_plate_v14">
  <inertial>
    <origin rpy="0 0 0" xyz="-0.10085854556804302 0.009884337907350833 -0.0015933444235043462"/>
    <mass value="0.02183354723813213"/>
    <inertia ixx="2.326148215223465e-06" ixy="1.5784812442831974e-06" ixz="3.2526065174565133e-19" iyy="2.3227089177674617e-06" iyz="-2.371692252312041e-19" izz="4.61188509108575e-06"/>
  </inertial>
  <visual>
    <origin rpy="0 0 0" xyz="-0.045406 -0.047003 -0.048402"/>
    <geometry>
      <mesh filename="package://quadruped_description/meshes/bottom_pivot_plate_v14.stl" scale="0.001 0.001 0.001"/>
    </geometry>
    <material name="silver"/>
    <material/>
  </visual>
  <collision>
    <origin rpy="0 0 -0.785398163" xyz="-0.10085854556804302 0.009884337907350833 -0.0015933444235043462"/>
    <geometry>
      <box size="0.048442 0.02040  0.003188"/>
    </geometry>
  </collision>
</link>

<link name="leg_parallel_linkage_v11">
  <inertial>
    <origin rpy="0 0 0" xyz="-0.01014265742637048 -0.007889057535331243 -5.5744720088138355e-05"/>
    <mass value="0.00766074441602388"/>
    <inertia ixx="4.803493674771365e-07" ixy="-4.1813467774842706e-07" ixz="-2.4283040679434157e-09" iyy="4.803493674771907e-07" iyz="-2.428304067950192e-09" izz="8.492417488732034e-07"/>
  </inertial>
  <visual>
    <origin rpy="0 0 0" xyz="-0.09153 -0.089143 -0.077727"/>
    <geometry>
      <mesh filename="package://quadruped_description/meshes/leg_parallel_linkage_v11.stl" scale="0.001 0.001 0.001"/>
    </geometry>
    <material name="silver"/>
    <material/>
  </visual>
  <collision>
    <origin rpy="0 0 0" xyz="-0.09153 -0.089143 -0.077727"/>
    <geometry>
      <mesh filename="package://quadruped_description/meshes/leg_parallel_linkage_v11.stl" scale="0.001 0.001 0.001"/>
    </geometry>
  </collision>
</link>

<link name="leg_parallel_plate_v11">
  <inertial>
    <origin rpy="0 0 0" xyz="-0.004995391768741642 -0.007248720766343711 -0.008862222322955887"/>
    <mass value="0.014417433544657016"/>
    <inertia ixx="2.1697871012962757e-06" ixy="-2.761349788279961e-07" ixz="-1.8802402014866872e-07" iyy="2.1697871012962757e-06" iyz="-1.8802402014865517e-07" izz="5.766838539122889e-07"/>
  </inertial>
  <visual>
    <origin rpy="0 0 0" xyz="-0.074112 -0.070498 -0.077616"/>
    <geometry>C
      <mesh filename="package://quadruped_description/meshes/leg_parallel_plate_v11.stl" scale="0.001 0.001 0.001"/>
    </geometry>
    <material name="silver"/>
    <material/>
  </visual>
  <collision>
    <origin rpy="0 0 0.785398163" xyz="-0.007137392 -0.009390721 -0.011004222"/>
    <geometry>
      <box size="0.024137 0.003188 0.036414"/>
    </geometry>
  </collision>
</link>

<link name="leg_parallel_linkage_v12">
  <inertial>
    <origin rpy="0 0 0" xyz="-0.17066336741037053 -0.1694519083657091 -5.5744719077946425e-05"/>
    <mass value="0.00766074441602388"/>
    <inertia ixx="4.803493674771636e-07" ixy="-4.1813467774843384e-07" ixz="2.4283040679434157e-09" iyy="4.803493674771501e-07" iyz="2.4283040679366394e-09" izz="8.492417488732169e-07"/>
  </inertial>
  <visual>
    <origin rpy="0 0 0" xyz="-0.089276 -0.091396 -0.077727"/>
    <geometry>
      <mesh filename="package://quadruped_description/meshes/leg_parallel_linkage_v12.stl" scale="0.001 0.001 0.001"/>
    </geometry>
    <material name="silver"/>
    <material/>
  </visual>
  <collision>
   <origin rpy="0 0 0" xyz="-0.089276 -0.091396 -0.077727"/>
    <geometry>
      <mesh filename="package://quadruped_description/meshes/leg_parallel_linkage_v12.stl" scale="0.001 0.001 0.001"/>
    </geometry>
  </collision>
</link>

<link name="leg_parallel_plate_v12">
  <inertial>
    <origin rpy="0 0 0" xyz="-0.14322863306800285 -0.13054924513469937 -0.008862222322955901"/>
    <mass value="0.014417433544657016"/>
    <inertia ixx="2.169787101296262e-06" ixy="-2.7613497882801645e-07" ixz="1.8802402014866872e-07" iyy="2.1697871012962486e-06" iyz="1.8802402014866872e-07" izz="5.766838539123024e-07"/>
  </inertial>
  <visual>
    <origin rpy="0 0 0" xyz="-0.074112 -0.070498 -0.077616"/>
    <geometry>
      <mesh filename="package://quadruped_description/meshes/leg_parallel_plate_v12.stl" scale="0.001 0.001 0.001"/>
    </geometry>
    <material name="silver"/>
    <material/>
  </visual>
  <collision>
    <origin rpy="0 0 3.926990817" xyz="-0.141144233 -0.128464845 -0.011004222"/>
    <geometry>
      <box size="0.024137 0.003188 0.036414"/>
    </geometry>
  </collision>
</link>

<link name="leg_parallel_linkage_v13">
  <inertial>
    <origin rpy="0 0 0" xyz="-0.011873654998673211 -0.16893275118996026 -5.574472008829101e-05"/>
    <mass value="0.00766074441602388"/>
    <inertia ixx="4.803493674771907e-07" ixy="4.181346777484406e-07" ixz="-2.4283040679366394e-09" iyy="4.80349367477123e-07" iyz="2.4283040679366394e-09" izz="8.492417488732305e-07"/>
  </inertial>
  <visual>
    <origin rpy="0 0 0" xyz="-0.09153 -0.089143 -0.077727"/>
    <geometry>
      <mesh filename="package://quadruped_description/meshes/leg_parallel_linkage_v13.stl" scale="0.001 0.001 0.001"/>
    </geometry>
    <material name="silver"/>
    <material/>
  </visual>
  <collision>
    <origin rpy="0 0 0" xyz="-0.09153 -0.089143 -0.077727"/>
    <geometry>
      <mesh filename="package://quadruped_description/meshes/leg_parallel_linkage_v13.stl" scale="0.001 0.001 0.001"/>
    </geometry>
  </collision>
</link>

<link name="leg_parallel_plate_v13">
  <inertial>
    <origin rpy="0 0 0" xyz="-0.012460318229685886 -0.13801701684758927 -0.008862222322955901"/>
    <mass value="0.014417433544657016"/>
    <inertia ixx="2.1697871012962757e-06" ixy="2.7613497882802323e-07" ixz="-1.8802402014868227e-07" iyy="2.1697871012962486e-06" iyz="1.8802402014866872e-07" izz="5.766838539123431e-07"/>
  </inertial>
  <visual>
    <origin rpy="0 0 0" xyz="-0.074112 -0.070498 -0.077616"/>
    <geometry>
      <mesh filename="package://quadruped_description/meshes/leg_parallel_plate_v13.stl" scale="0.001 0.001 0.001"/>
    </geometry>
    <material name="silver"/>
    <material/>
  </visual>
  <collision>
    <origin rpy="0 0 2.35619449" xyz="-0.010375918 -0.140101417 -0.011004222"/>
    <geometry>
      <box size="0.024137 0.003188 0.036414"/>
    </geometry>
  </collision>
</link>

<link name="leg_parallel_linkage_v14">
  <inertial>
    <origin rpy="0 0 0" xyz="-0.1689323698380672 -0.008534077172330193 -5.574471907779377e-05"/>
    <mass value="0.00766074441602388"/>
    <inertia ixx="4.803493674771772e-07" ixy="4.181346777484474e-07" ixz="2.428304067950192e-09" iyy="4.803493674771365e-07" iyz="-2.4283040679434157e-09" izz="8.492417488732169e-07"/>
  </inertial>
  <visual>
    <origin rpy="0 0 0" xyz="-0.089276 -0.091396 -0.077727"/>
    <geometry>
      <mesh filename="package://quadruped_description/meshes/leg_parallel_linkage_v14.stl" scale="0.001 0.001 0.001"/>
    </geometry>
    <material name="silver"/>
    <material/>
  </visual>
  <collision>
    <origin rpy="0 0 0" xyz="-0.089276 -0.091396 -0.077727"/>
    <geometry>
      <mesh filename="package://quadruped_description/meshes/leg_parallel_linkage_v14.stl" scale="0.001 0.001 0.001"/>
    </geometry>
  </collision>
</link>

<link name="leg_parallel_plate_v14">
  <inertial>
    <origin rpy="0 0 0" xyz="-0.13576370660705767 9.318848530222301e-05 -0.00886222232295586"/>
    <mass value="0.014417433544657016"/>
    <inertia ixx="2.1697871012962486e-06" ixy="2.761349788280097e-07" ixz="1.8802402014866872e-07" iyy="2.16978710129633e-06" iyz="-1.8802402014866872e-07" izz="5.766838539122889e-07"/>
  </inertial>
  <visual>
    <origin rpy="0 0 0" xyz="-0.074112 -0.070498 -0.077616"/>
    <geometry>
      <mesh filename="package://quadruped_description/meshes/leg_parallel_plate_v14.stl" scale="0.001 0.001 0.001"/>
    </geometry>
    <material name="silver"/>
    <material/>
  </visual>
  <collision>
    <origin rpy="0 0 0" xyz="-0.074112 -0.070498 -0.077616"/>
    <geometry>
      <mesh filename="package://quadruped_description/meshes/leg_parallel_plate_v14.stl" scale="0.001 0.001 0.001"/>
    </geometry>
  </collision>
</link>

<joint name="Rigid1" type="fixed">
  <origin rpy="0 0 0" xyz="0.0 -0.041434 0.05924"/>
  <parent link="base_link"/>
  <child link="body_spacer_v11"/>
</joint>

<joint name="Rigid2" type="fixed">
  <origin rpy="0 0 0" xyz="0.0 -0.041434 0.05924"/>
  <parent link="base_link"/>
  <child link="body_spacer_v12"/>
</joint>

<joint name="Rigid3" type="fixed">
  <origin rpy="0 0 0" xyz="0.0 -0.041434 0.05924"/>
  <parent link="base_link"/>
  <child link="body_spacer_v13"/>
</joint>

<joint name="Rigid4" type="fixed">
  <origin rpy="0 0 0" xyz="0.0 -0.041434 0.05924"/>
  <parent link="base_link"/>
  <child link="body_spacer_v14"/>
</joint>

<joint name="Rigid5" type="fixed">
  <origin rpy="0 0 0" xyz="-1e-05 0.001603 0.073902"/>
  <parent link="base_link"/>
  <child link="body_top_plate_v11"/>
</joint>

<joint name="Rigid6" type="fixed">
  <origin rpy="0 0 0" xyz="0.045406 0.047003 0.088004"/>
  <parent link="base_link"/>
  <child link="servo_motor_v11"/>
</joint>

<joint name="Rigid7" type="fixed">
  <origin rpy="0 0 0" xyz="0.045406 0.047003 0.088004"/>
  <parent link="base_link"/>
  <child link="servo_motor_v12"/>
</joint>

<joint name="Rigid8" type="fixed">
  <origin rpy="0 0 0" xyz="0.045406 0.047003 0.088004"/>
  <parent link="base_link"/>
  <child link="servo_motor_v13"/>
</joint>

<joint name="Rigid9" type="fixed">
  <origin rpy="0 0 0" xyz="0.045406 0.047003 0.088004"/>
  <parent link="base_link"/>
  <child link="servo_motor_v14"/>
</joint>

<joint name="Rigid10" type="fixed">
  <origin rpy="0 0 0" xyz="-0.012081 -0.012081 -0.00932"/>
  <parent link="servo_motor_v11"/>
  <child link="leg_servo_retainer_v11"/>
</joint>

<joint name="Rigid11" type="fixed">
  <origin rpy="0 0 0" xyz="-0.012081 -0.012081 -0.00932"/>
  <parent link="servo_motor_v12"/>
  <child link="leg_servo_retainer_v12"/>
</joint>

<joint name="Rigid12" type="fixed">
  <origin rpy="0 0 0" xyz="-0.012081 -0.012081 -0.00932"/>
  <parent link="servo_motor_v13"/>
  <child link="leg_servo_retainer_v13"/>
</joint>

<joint name="Rigid13" type="fixed">
  <origin rpy="0 0 0" xyz="-0.012081 -0.012081 -0.00932"/>
  <parent link="servo_motor_v14"/>
  <child link="leg_servo_retainer_v14"/>
</joint>

<joint name="Rev14" type="continuous">
  <origin rpy="0 0 0" xyz="0.0 0.0 0.0"/>
  <parent link="servo_motor_v11"/>
  <child link="leg_top_pivot_plate_v11"/>
  <axis xyz="0.0 -0.0 1.0"/>
</joint>
<transmission name="Rev14_tran">
  <type>transmission_interface/SimpleTransmission</type>
  <joint name="Rev14">
    <hardwareInterface>PositionJointInterface</hardwareInterface>
  </joint>
  <actuator name="Rev14_actr">
    <hardwareInterface>PositionJointInterface</hardwareInterface>
    <mechanicalReduction>1</mechanicalReduction>
  </actuator>
</transmission>

<joint name="Rev15" type="continuous">
  <origin rpy="0 0 0" xyz="0.0 0.0 0.0"/>
  <parent link="servo_motor_v12"/>
  <child link="leg_top_pivot_plate_v12"/>
  <axis xyz="-0.0 -0.0 1.0"/>
</joint>
<transmission name="Rev15_tran">
  <type>transmission_interface/SimpleTransmission</type>
  <joint name="Rev15">
    <hardwareInterface>PositionJointInterface</hardwareInterface>
  </joint>
  <actuator name="Rev15_actr">
    <hardwareInterface>PositionJointInterface</hardwareInterface>
    <mechanicalReduction>1</mechanicalReduction>
  </actuator>
</transmission>

<joint name="Rev16" type="continuous">
  <origin rpy="0 0 0" xyz="0.0 0.0 0.0"/>
  <parent link="servo_motor_v13"/>
  <child link="leg_top_pivot_plate_v13"/>
  <axis xyz="0.0 -0.0 1.0"/>
</joint>
<transmission name="Rev16_tran">
  <type>transmission_interface/SimpleTransmission</type>
  <joint name="Rev16">
    <hardwareInterface>PositionJointInterface</hardwareInterface>
  </joint>
  <actuator name="Rev16_actr">
    <hardwareInterface>PositionJointInterface</hardwareInterface>
    <mechanicalReduction>1</mechanicalReduction>
  </actuator>
</transmission>

<joint name="Rev17" type="continuous">
  <origin rpy="0 0 0" xyz="0.0 0.0 0.0"/>
  <parent link="servo_motor_v14"/>
  <child link="leg_top_pivot_plate_v14"/>
  <axis xyz="0.0 -0.0 1.0"/>
</joint>
<transmission name="Rev17_tran">
  <type>transmission_interface/SimpleTransmission</type>
  <joint name="Rev17">
    <hardwareInterface>PositionJointInterface</hardwareInterface>
  </joint>
  <actuator name="Rev17_actr">
    <hardwareInterface>PositionJointInterface</hardwareInterface>
    <mechanicalReduction>1</mechanicalReduction>
  </actuator>
</transmission>

<joint name="Rigid18" type="fixed">
  <origin rpy="0 0 0" xyz="0.012883 0.02208 -0.011475"/>
  <parent link="leg_top_pivot_plate_v11"/>
  <child link="leg_servo_mount_v11"/>
</joint>

<joint name="Rigid19" type="fixed">
  <origin rpy="0 0 0" xyz="0.012883 0.02208 -0.011475"/>
  <parent link="leg_top_pivot_plate_v12"/>
  <child link="leg_servo_mount_v12"/>
</joint>

<joint name="Rigid20" type="fixed">
  <origin rpy="0 0 0" xyz="0.012883 0.02208 -0.011475"/>
  <parent link="leg_top_pivot_plate_v13"/>
  <child link="leg_servo_mount_v13"/>
</joint>

<joint name="Rigid21" type="fixed">
  <origin rpy="0 0 0" xyz="0.012883 0.02208 -0.011475"/>
  <parent link="leg_top_pivot_plate_v14"/>
  <child link="leg_servo_mount_v14"/>
</joint>

<joint name="Rigid22" type="fixed">
  <origin rpy="0 0 0" xyz="-0.024964 -0.034161 0.002155"/>
  <parent link="leg_servo_mount_v11"/>
  <child link="servo_motor_v15"/>
</joint>

<joint name="Rigid23" type="fixed">
  <origin rpy="0 0 0" xyz="-0.024964 -0.034161 0.002155"/>
  <parent link="leg_servo_mount_v12"/>
  <child link="servo_motor_v16"/>
</joint>

<joint name="Rigid24" type="fixed">
  <origin rpy="0 0 0" xyz="-0.024964 -0.034161 0.002155"/>
  <parent link="leg_servo_mount_v13"/>
  <child link="servo_motor_v17"/>
</joint>

<joint name="Rigid25" type="fixed">
  <origin rpy="0 0 0" xyz="-0.024964 -0.034161 0.002155"/>
  <parent link="leg_servo_mount_v14"/>
  <child link="servo_motor_v18"/>
</joint>

<joint name="Rev26" type="continuous">
  <origin rpy="0 0 0" xyz="0.040174 0.036189 -0.018807"/>
  <parent link="servo_motor_v15"/>
  <child link="leg_servo_arm_v11"/>
  <axis xyz="0.707107 -0.707107 -0.0"/>
</joint>
<transmission name="Rev26_tran">
  <type>transmission_interface/SimpleTransmission</type>
  <joint name="Rev26">
    <hardwareInterface>PositionJointInterface</hardwareInterface>
  </joint>
  <actuator name="Rev26_actr">
    <hardwareInterface>PositionJointInterface</hardwareInterface>
    <mechanicalReduction>1</mechanicalReduction>
  </actuator>
</transmission>

<joint name="Rev27" type="continuous">
  <origin rpy="0 0 0" xyz="0.03792 0.038443 -0.018807"/>
  <parent link="servo_motor_v16"/>
  <child link="leg_servo_arm_v12"/>
  <axis xyz="-0.707107 0.707107 0.0"/>
</joint>
<transmission name="Rev27_tran">
  <type>transmission_interface/SimpleTransmission</type>
  <joint name="Rev27">
    <hardwareInterface>PositionJointInterface</hardwareInterface>
  </joint>
  <actuator name="Rev27_actr">
    <hardwareInterface>PositionJointInterface</hardwareInterface>
    <mechanicalReduction>1</mechanicalReduction>
  </actuator>
</transmission>

<joint name="Rev28" type="continuous">
  <origin rpy="0 0 0" xyz="0.03792 0.038443 -0.018807"/>
  <parent link="servo_motor_v17"/>
  <child link="leg_servo_arm_v13"/>
  <axis xyz="-0.707107 -0.707107 0.0"/>
</joint>
<transmission name="Rev28_tran">
  <type>transmission_interface/SimpleTransmission</type>
  <joint name="Rev28">
    <hardwareInterface>PositionJointInterface</hardwareInterface>
  </joint>
  <actuator name="Rev28_actr">
    <hardwareInterface>PositionJointInterface</hardwareInterface>
    <mechanicalReduction>1</mechanicalReduction>
  </actuator>
</transmission>

<joint name="Rev29" type="continuous">
  <origin rpy="0 0 0" xyz="0.040174 0.036189 -0.018807"/>
  <parent link="servo_motor_v18"/>
  <child link="leg_servo_arm_v14"/>
  <axis xyz="0.707107 0.707107 -0.0"/>
</joint>
<transmission name="Rev29_tran">
  <type>transmission_interface/SimpleTransmission</type>
  <joint name="Rev29">
    <hardwareInterface>PositionJointInterface</hardwareInterface>
  </joint>
  <actuator name="Rev29_actr">
    <hardwareInterface>PositionJointInterface</hardwareInterface>
    <mechanicalReduction>1</mechanicalReduction>
  </actuator>
</transmission>

<joint name="Rev30" type="continuous">
  <origin rpy="0 0 0" xyz="0.018031 0.018031 0.0"/>
  <parent link="leg_servo_arm_v11"/>
  <child link="leg_rev_v11"/>
  <axis xyz="-0.707107 0.707107 0.0"/>
</joint>
<transmission name="Rev30_tran">
  <type>transmission_interface/SimpleTransmission</type>
  <joint name="Rev30">
    <hardwareInterface>PositionJointInterface</hardwareInterface>
  </joint>
  <actuator name="Rev30_actr">
    <hardwareInterface>PositionJointInterface</hardwareInterface>
    <mechanicalReduction>1</mechanicalReduction>
  </actuator>
</transmission>

<joint name="Rev31" type="continuous">
  <origin rpy="0 0 0" xyz="0.020285 0.015777 0.0"/>
  <parent link="leg_servo_arm_v12"/>
  <child link="leg_rev_v12"/>
  <axis xyz="-0.707107 0.707107 0.0"/>
</joint>
<transmission name="Rev31_tran">
  <type>transmission_interface/SimpleTransmission</type>
  <joint name="Rev31">
    <hardwareInterface>PositionJointInterface</hardwareInterface>
  </joint>
  <actuator name="Rev31_actr">
    <hardwareInterface>PositionJointInterface</hardwareInterface>
    <mechanicalReduction>1</mechanicalReduction>
  </actuator>
</transmission>

<joint name="Rev32" type="continuous">
  <origin rpy="0 0 0" xyz="0.020285 0.015777 0.0"/>
  <parent link="leg_servo_arm_v13"/>
  <child link="leg_rev_v13"/>
  <axis xyz="-0.707107 -0.707107 0.0"/>
</joint>
<transmission name="Rev32_tran">
  <type>transmission_interface/SimpleTransmission</type>
  <joint name="Rev32">
    <hardwareInterface>PositionJointInterface</hardwareInterface>
  </joint>
  <actuator name="Rev32_actr">
    <hardwareInterface>PositionJointInterface</hardwareInterface>
    <mechanicalReduction>1</mechanicalReduction>
  </actuator>
</transmission>

<joint name="Rev33" type="continuous">
  <origin rpy="0 0 0" xyz="0.018031 0.018031 0.0"/>
  <parent link="leg_servo_arm_v14"/>
  <child link="leg_rev_v14"/>
  <axis xyz="-0.707107 -0.707107 0.0"/>
</joint>
<transmission name="Rev33_tran">
  <type>transmission_interface/SimpleTransmission</type>
  <joint name="Rev33">
    <hardwareInterface>PositionJointInterface</hardwareInterface>
  </joint>
  <actuator name="Rev33_actr">
    <hardwareInterface>PositionJointInterface</hardwareInterface>
    <mechanicalReduction>1</mechanicalReduction>
  </actuator>
</transmission>

<joint name="Rev34" type="continuous">
  <origin rpy="0 0 0" xyz="0.045406 0.047003 0.048402"/>
  <parent link="base_link"/>
  <child link="bottom_pivot_plate_v11"/>
  <axis xyz="-0.0 -0.0 1.0"/>
</joint>
<transmission name="Rev34_tran">
  <type>transmission_interface/SimpleTransmission</type>
  <joint name="Rev34">
    <hardwareInterface>PositionJointInterface</hardwareInterface>
  </joint>
  <actuator name="Rev34_actr">
    <hardwareInterface>PositionJointInterface</hardwareInterface>
    <mechanicalReduction>1</mechanicalReduction>
  </actuator>
</transmission>

<joint name="Rev35" type="continuous">
  <origin rpy="0 0 0" xyz="0.045406 0.047003 0.048402"/>
  <parent link="base_link"/>
  <child link="bottom_pivot_plate_v12"/>
  <axis xyz="-0.0 -0.0 1.0"/>
</joint>
<transmission name="Rev35_tran">
  <type>transmission_interface/SimpleTransmission</type>
  <joint name="Rev35">
    <hardwareInterface>PositionJointInterface</hardwareInterface>
  </joint>
  <actuator name="Rev35_actr">
    <hardwareInterface>PositionJointInterface</hardwareInterface>
    <mechanicalReduction>1</mechanicalReduction>
  </actuator>
</transmission>

<joint name="Rev36" type="continuous">
  <origin rpy="0 0 0" xyz="0.045406 0.047003 0.048402"/>
  <parent link="base_link"/>
  <child link="bottom_pivot_plate_v13"/>
  <axis xyz="-0.0 -0.0 1.0"/>
</joint>
<transmission name="Rev36_tran">
  <type>transmission_interface/SimpleTransmission</type>
  <joint name="Rev36">
    <hardwareInterface>PositionJointInterface</hardwareInterface>
  </joint>
  <actuator name="Rev36_actr">
    <hardwareInterface>PositionJointInterface</hardwareInterface>
    <mechanicalReduction>1</mechanicalReduction>
  </actuator>
</transmission>

<joint name="Rev37" type="continuous">
  <origin rpy="0 0 0" xyz="0.045406 0.047003 0.048402"/>
  <parent link="base_link"/>
  <child link="bottom_pivot_plate_v14"/>
  <axis xyz="-0.0 -0.0 1.0"/>
</joint>
<transmission name="Rev37_tran">
  <type>transmission_interface/SimpleTransmission</type>
  <joint name="Rev37">
    <hardwareInterface>PositionJointInterface</hardwareInterface>
  </joint>
  <actuator name="Rev37_actr">
    <hardwareInterface>PositionJointInterface</hardwareInterface>
    <mechanicalReduction>1</mechanicalReduction>
  </actuator>
</transmission>

<joint name="Rev42" type="continuous">
  <origin rpy="0 0 0" xyz="0.0 1e-06 0.01785"/>
  <parent link="leg_rev_v11"/>
  <child link="leg_parallel_linkage_v11"/>
  <axis xyz="0.707107 -0.707107 -0.0"/>
</joint>
<transmission name="Rev42_tran">
  <type>transmission_interface/SimpleTransmission</type>
  <joint name="Rev42">
    <hardwareInterface>PositionJointInterface</hardwareInterface>
  </joint>
  <actuator name="Rev42_actr">
    <hardwareInterface>PositionJointInterface</hardwareInterface>
    <mechanicalReduction>1</mechanicalReduction>
  </actuator>
</transmission>

<joint name="Rev43" type="continuous">
  <origin rpy="0 0 0" xyz="-0.017418 -0.018645 -0.000111"/>
  <parent link="leg_parallel_linkage_v11"/>
  <child link="leg_parallel_plate_v11"/>
  <axis xyz="0.707107 -0.707107 -0.0"/>
</joint>
<transmission name="Rev43_tran">
  <type>transmission_interface/SimpleTransmission</type>
  <joint name="Rev43">
    <hardwareInterface>PositionJointInterface</hardwareInterface>
  </joint>
  <actuator name="Rev43_actr">
    <hardwareInterface>PositionJointInterface</hardwareInterface>
    <mechanicalReduction>1</mechanicalReduction>
  </actuator>
</transmission>

<joint name="Rev44" type="continuous">
  <origin rpy="0 0 0" xyz="-0.002254 0.002254 0.01785"/>
  <parent link="leg_rev_v12"/>
  <child link="leg_parallel_linkage_v12"/>
  <axis xyz="-0.707107 0.707107 0.0"/>
</joint>
<transmission name="Rev44_tran">
  <type>transmission_interface/SimpleTransmission</type>
  <joint name="Rev44">
    <hardwareInterface>PositionJointInterface</hardwareInterface>
  </joint>
  <actuator name="Rev44_actr">
    <hardwareInterface>PositionJointInterface</hardwareInterface>
    <mechanicalReduction>1</mechanicalReduction>
  </actuator>
</transmission>

<joint name="Rev45" type="continuous">
  <origin rpy="0 0 0" xyz="-0.015164 -0.020898 -0.000111"/>
  <parent link="leg_parallel_linkage_v12"/>
  <child link="leg_parallel_plate_v12"/>
  <axis xyz="0.707107 -0.707107 -0.0"/>
</joint>
<transmission name="Rev45_tran">
  <type>transmission_interface/SimpleTransmission</type>
  <joint name="Rev45">
    <hardwareInterface>PositionJointInterface</hardwareInterface>
  </joint>
  <actuator name="Rev45_actr">
    <hardwareInterface>PositionJointInterface</hardwareInterface>
    <mechanicalReduction>1</mechanicalReduction>
  </actuator>
</transmission>

<joint name="Rev46" type="continuous">
  <origin rpy="0 0 0" xyz="0.0 1e-06 0.01785"/>
  <parent link="leg_rev_v13"/>
  <child link="leg_parallel_linkage_v13"/>
  <axis xyz="-0.707107 -0.707107 0.0"/>
</joint>
<transmission name="Rev46_tran">
  <type>transmission_interface/SimpleTransmission</type>
  <joint name="Rev46">
    <hardwareInterface>PositionJointInterface</hardwareInterface>
  </joint>
  <actuator name="Rev46_actr">
    <hardwareInterface>PositionJointInterface</hardwareInterface>
    <mechanicalReduction>1</mechanicalReduction>
  </actuator>
</transmission>

<joint name="Rev47" type="continuous">
  <origin rpy="0 0 0" xyz="-0.017418 -0.018645 -0.000111"/>
  <parent link="leg_parallel_linkage_v13"/>
  <child link="leg_parallel_plate_v13"/>
  <axis xyz="-0.707107 -0.707107 0.0"/>
</joint>
<transmission name="Rev47_tran">
  <type>transmission_interface/SimpleTransmission</type>
  <joint name="Rev47">
    <hardwareInterface>PositionJointInterface</hardwareInterface>
  </joint>
  <actuator name="Rev47_actr">
    <hardwareInterface>PositionJointInterface</hardwareInterface>
    <mechanicalReduction>1</mechanicalReduction>
  </actuator>
</transmission>

<joint name="Rev48" type="continuous">
  <origin rpy="0 0 0" xyz="-0.002254 0.002254 0.01785"/>
  <parent link="leg_rev_v14"/>
  <child link="leg_parallel_linkage_v14"/>
  <axis xyz="0.707107 0.707107 -0.0"/>
</joint>
<transmission name="Rev48_tran">
  <type>transmission_interface/SimpleTransmission</type>
  <joint name="Rev48">
    <hardwareInterface>PositionJointInterface</hardwareInterface>
  </joint>
  <actuator name="Rev48_actr">
    <hardwareInterface>PositionJointInterface</hardwareInterface>
    <mechanicalReduction>1</mechanicalReduction>
  </actuator>
</transmission>

<joint name="Rev49" type="continuous">
  <origin rpy="0 0 0" xyz="-0.015164 -0.020898 -0.000111"/>
  <parent link="leg_parallel_linkage_v14"/>
  <child link="leg_parallel_plate_v14"/>
  <axis xyz="-0.707107 -0.707107 0.0"/>
</joint>
<transmission name="Rev49_tran">
  <type>transmission_interface/SimpleTransmission</type>
  <joint name="Rev49">
    <hardwareInterface>PositionJointInterface</hardwareInterface>
  </joint>
  <actuator name="Rev49_actr">
    <hardwareInterface>PositionJointInterface</hardwareInterface>
    <mechanicalReduction>1</mechanicalReduction>
  </actuator>
</transmission>

</robot>
