<?xml version="1.0" ?>
<robot name="Base_link" xmlns:xacro="http://www.ros.org/wiki/xacro">

<xacro:include filename="$(find Base_link_description)/urdf/materials.xacro" />
<xacro:include filename="$(find Base_link_description)/urdf/Base_link.trans" />
<xacro:include filename="$(find Base_link_description)/urdf/Base_link.gazebo" />
<link name="base_link">
  <inertial>
    <origin rpy="0 0 0" xyz="3.5526065091306917e-07 0.009375000059604646 -1.6439403524500656e-06"/>
    <mass value="0.010011445945907986"/>
    <inertia ixx="2e-06" ixy="0.0" ixz="0.0" iyy="5e-06" iyz="-0.0" izz="2e-06"/>
  </inertial>
  <visual>
    <origin rpy="0 0 0" xyz="0 0 0"/>
    <geometry>
      <mesh filename="package://Base_link_description/meshes/base_link.stl" scale="0.001 0.001 0.001"/>
    </geometry>
    <material name="silver"/>
  </visual>
  <collision>
    <origin rpy="0 0 0" xyz="0 0 0"/>
    <geometry>
      <mesh filename="package://Base_link_description/meshes/base_link.stl" scale="0.001 0.001 0.001"/>
    </geometry>
  </collision>
</link>

<link name="body_spacer_v1_1_1_1">
  <inertial>
    <origin rpy="0 0 0" xyz="1.910704176693586e-18 -0.000749999970197676 6.938893903907228e-18"/>
    <mass value="0.001198596877164021"/>
    <inertia ixx="0.0" ixy="-0.0" ixz="0.0" iyy="0.0" iyz="-0.0" izz="0.0"/>
  </inertial>
  <visual>
    <origin rpy="0 0 0" xyz="-0.0 -0.00575 0.016875"/>
    <geometry>
      <mesh filename="package://Base_link_description/meshes/body_spacer_v1_1_1_1.stl" scale="0.001 0.001 0.001"/>
    </geometry>
    <material name="silver"/>
  </visual>
  <collision>
    <origin rpy="0 0 0" xyz="-0.0 -0.00575 0.016875"/>
    <geometry>
      <mesh filename="package://Base_link_description/meshes/body_spacer_v1_1_1_1.stl" scale="0.001 0.001 0.001"/>
    </geometry>
  </collision>
</link>

<link name="body_spacer_v1_2_1_1">
  <inertial>
    <origin rpy="0 0 0" xyz="-6.938893903907228e-18 -0.0007499999701976769 -9.714451465470119e-19"/>
    <mass value="0.001198596877164021"/>
    <inertia ixx="0.0" ixy="0.0" ixz="0.0" iyy="0.0" iyz="0.0" izz="0.0"/>
  </inertial>
  <visual>
    <origin rpy="0 0 0" xyz="-0.016875 -0.00575 0.0"/>
    <geometry>
      <mesh filename="package://Base_link_description/meshes/body_spacer_v1_2_1_1.stl" scale="0.001 0.001 0.001"/>
    </geometry>
    <material name="silver"/>
  </visual>
  <collision>
    <origin rpy="0 0 0" xyz="-0.016875 -0.00575 0.0"/>
    <geometry>
      <mesh filename="package://Base_link_description/meshes/body_spacer_v1_2_1_1.stl" scale="0.001 0.001 0.001"/>
    </geometry>
  </collision>
</link>

<link name="body_spacer_v1_3_1_1">
  <inertial>
    <origin rpy="0 0 0" xyz="-2.150717161437114e-18 -0.0007499999701976751 0.0"/>
    <mass value="0.001198596877164021"/>
    <inertia ixx="0.0" ixy="0.0" ixz="-0.0" iyy="0.0" iyz="0.0" izz="0.0"/>
  </inertial>
  <visual>
    <origin rpy="0 0 0" xyz="0.0 -0.00575 -0.016875"/>
    <geometry>
      <mesh filename="package://Base_link_description/meshes/body_spacer_v1_3_1_1.stl" scale="0.001 0.001 0.001"/>
    </geometry>
    <material name="silver"/>
  </visual>
  <collision>
    <origin rpy="0 0 0" xyz="0.0 -0.00575 -0.016875"/>
    <geometry>
      <mesh filename="package://Base_link_description/meshes/body_spacer_v1_3_1_1.stl" scale="0.001 0.001 0.001"/>
    </geometry>
  </collision>
</link>

<link name="body_spacer_v1_4_1_1">
  <inertial>
    <origin rpy="0 0 0" xyz="0.0 -0.0007499999701976769 1.8041124150158794e-18"/>
    <mass value="0.001198596877164021"/>
    <inertia ixx="0.0" ixy="-0.0" ixz="-0.0" iyy="0.0" iyz="-0.0" izz="0.0"/>
  </inertial>
  <visual>
    <origin rpy="0 0 0" xyz="0.016875 -0.00575 -0.0"/>
    <geometry>
      <mesh filename="package://Base_link_description/meshes/body_spacer_v1_4_1_1.stl" scale="0.001 0.001 0.001"/>
    </geometry>
    <material name="silver"/>
  </visual>
  <collision>
    <origin rpy="0 0 0" xyz="0.016875 -0.00575 -0.0"/>
    <geometry>
      <mesh filename="package://Base_link_description/meshes/body_spacer_v1_4_1_1.stl" scale="0.001 0.001 0.001"/>
    </geometry>
  </collision>
</link>

<link name="body_top_plate_v1_1">
  <inertial>
    <origin rpy="0 0 0" xyz="4.934952913861729e-07 0.0006250000596046458 2.662875822643262e-06"/>
    <mass value="0.01473051492933994"/>
    <inertia ixx="2e-06" ixy="0.0" ixz="-0.0" iyy="4e-06" iyz="0.0" izz="2e-06"/>
  </inertial>
  <visual>
    <origin rpy="0 0 0" xyz="4e-06 -0.0 -2e-06"/>
    <geometry>
      <mesh filename="package://Base_link_description/meshes/body_top_plate_v1_1.stl" scale="0.001 0.001 0.001"/>
    </geometry>
    <material name="silver"/>
  </visual>
  <collision>
    <origin rpy="0 0 0" xyz="4e-06 -0.0 -2e-06"/>
    <geometry>
      <mesh filename="package://Base_link_description/meshes/body_top_plate_v1_1.stl" scale="0.001 0.001 0.001"/>
    </geometry>
  </collision>
</link>

<link name="servo_motor_v1_1">
  <inertial>
    <origin rpy="0 0 0" xyz="-0.0013508261710446674 0.006780947696453059 0.0013508250495978952"/>
    <mass value="0.0004848665871049835"/>
    <inertia ixx="0.0" ixy="0.0" ixz="0.0" iyy="0.0" iyz="-0.0" izz="0.0"/>
  </inertial>
  <visual>
    <origin rpy="0 0 0" xyz="-0.017806 0.00555 0.017806"/>
    <geometry>
      <mesh filename="package://Base_link_description/meshes/servo_motor_v1_1.stl" scale="0.001 0.001 0.001"/>
    </geometry>
    <material name="silver"/>
  </visual>
  <collision>
    <origin rpy="0 0 0" xyz="-0.017806 0.00555 0.017806"/>
    <geometry>
      <mesh filename="package://Base_link_description/meshes/servo_motor_v1_1.stl" scale="0.001 0.001 0.001"/>
    </geometry>
  </collision>
</link>

<link name="servo_motor_v1_2">
  <inertial>
    <origin rpy="0 0 0" xyz="-0.0013508262416907883 0.006780947696453066 0.034261175021048224"/>
    <mass value="0.0004848665871049835"/>
    <inertia ixx="0.0" ixy="0.0" ixz="-0.0" iyy="0.0" iyz="0.0" izz="0.0"/>
  </inertial>
  <visual>
    <origin rpy="0 0 0" xyz="-0.017806 0.00555 0.017806"/>
    <geometry>
      <mesh filename="package://Base_link_description/meshes/servo_motor_v1_2.stl" scale="0.001 0.001 0.001"/>
    </geometry>
    <material name="silver"/>
  </visual>
  <collision>
    <origin rpy="0 0 0" xyz="-0.017806 0.00555 0.017806"/>
    <geometry>
      <mesh filename="package://Base_link_description/meshes/servo_motor_v1_2.stl" scale="0.001 0.001 0.001"/>
    </geometry>
  </collision>
</link>

<link name="servo_motor_v1_3">
  <inertial>
    <origin rpy="0 0 0" xyz="-0.03426118356885484 0.006780947696453063 0.034212932907539614"/>
    <mass value="0.0004848665871049835"/>
    <inertia ixx="0.0" ixy="-0.0" ixz="0.0" iyy="0.0" iyz="0.0" izz="0.0"/>
  </inertial>
  <visual>
    <origin rpy="0 0 0" xyz="-0.017806 0.00555 0.017806"/>
    <geometry>
      <mesh filename="package://Base_link_description/meshes/servo_motor_v1_3.stl" scale="0.001 0.001 0.001"/>
    </geometry>
    <material name="silver"/>
  </visual>
  <collision>
    <origin rpy="0 0 0" xyz="-0.017806 0.00555 0.017806"/>
    <geometry>
      <mesh filename="package://Base_link_description/meshes/servo_motor_v1_3.stl" scale="0.001 0.001 0.001"/>
    </geometry>
  </collision>
</link>

<link name="servo_motor_v1_4">
  <inertial>
    <origin rpy="0 0 0" xyz="-0.034261183498208725 0.006780947696453061 0.001351940764028104"/>
    <mass value="0.0004848665871049835"/>
    <inertia ixx="0.0" ixy="-0.0" ixz="-0.0" iyy="0.0" iyz="-0.0" izz="0.0"/>
  </inertial>
  <visual>
    <origin rpy="0 0 0" xyz="-0.017806 0.00555 0.017806"/>
    <geometry>
      <mesh filename="package://Base_link_description/meshes/servo_motor_v1_4.stl" scale="0.001 0.001 0.001"/>
    </geometry>
    <material name="silver"/>
  </visual>
  <collision>
    <origin rpy="0 0 0" xyz="-0.017806 0.00555 0.017806"/>
    <geometry>
      <mesh filename="package://Base_link_description/meshes/servo_motor_v1_4.stl" scale="0.001 0.001 0.001"/>
    </geometry>
  </collision>
</link>

<link name="leg_servo_retainer_v1_1">
  <inertial>
    <origin rpy="0 0 0" xyz="-7.358861605038722e-05 -0.0006249999403953553 7.439445171635722e-05"/>
    <mass value="0.0007120198480863978"/>
    <inertia ixx="0.0" ixy="0.0" ixz="0.0" iyy="0.0" iyz="-0.0" izz="0.0"/>
  </inertial>
  <visual>
    <origin rpy="0 0 0" xyz="-0.016321 0.00127 0.016323"/>
    <geometry>
      <mesh filename="package://Base_link_description/meshes/leg_servo_retainer_v1_1.stl" scale="0.001 0.001 0.001"/>
    </geometry>
    <material name="silver"/>
  </visual>
  <collision>
    <origin rpy="0 0 0" xyz="-0.016321 0.00127 0.016323"/>
    <geometry>
      <mesh filename="package://Base_link_description/meshes/leg_servo_retainer_v1_1.stl" scale="0.001 0.001 0.001"/>
    </geometry>
  </collision>
</link>

<link name="leg_servo_retainer_v1_2">
  <inertial>
    <origin rpy="0 0 0" xyz="-7.409009750477397e-05 -0.0006249999403953553 0.032576253306189185"/>
    <mass value="0.0007120198480863978"/>
    <inertia ixx="0.0" ixy="0.0" ixz="-0.0" iyy="0.0" iyz="0.0" izz="0.0"/>
  </inertial>
  <visual>
    <origin rpy="0 0 0" xyz="-0.016321 0.00127 0.016323"/>
    <geometry>
      <mesh filename="package://Base_link_description/meshes/leg_servo_retainer_v1_2.stl" scale="0.001 0.001 0.001"/>
    </geometry>
    <material name="silver"/>
  </visual>
  <collision>
    <origin rpy="0 0 0" xyz="-0.016321 0.00127 0.016323"/>
    <geometry>
      <mesh filename="package://Base_link_description/meshes/leg_servo_retainer_v1_2.stl" scale="0.001 0.001 0.001"/>
    </geometry>
  </collision>
</link>

<link name="leg_servo_retainer_v1_3">
  <inertial>
    <origin rpy="0 0 0" xyz="-0.032575948951977615 -0.0006249999403953564 0.03257575182473469"/>
    <mass value="0.0007120198480863978"/>
    <inertia ixx="0.0" ixy="0.0" ixz="0.0" iyy="0.0" iyz="-0.0" izz="0.0"/>
  </inertial>
  <visual>
    <origin rpy="0 0 0" xyz="-0.016321 0.00127 0.016323"/>
    <geometry>
      <mesh filename="package://Base_link_description/meshes/leg_servo_retainer_v1_3.stl" scale="0.001 0.001 0.001"/>
    </geometry>
    <material name="silver"/>
  </visual>
  <collision>
    <origin rpy="0 0 0" xyz="-0.016321 0.00127 0.016323"/>
    <geometry>
      <mesh filename="package://Base_link_description/meshes/leg_servo_retainer_v1_3.stl" scale="0.001 0.001 0.001"/>
    </geometry>
  </collision>
</link>

<link name="leg_servo_retainer_v1_4">
  <inertial>
    <origin rpy="0 0 0" xyz="-0.03255044747052323 -0.0006249999403953551 9.889297026197119e-05"/>
    <mass value="0.0007120198480863978"/>
    <inertia ixx="0.0" ixy="0.0" ixz="-0.0" iyy="0.0" iyz="-0.0" izz="0.0"/>
  </inertial>
  <visual>
    <origin rpy="0 0 0" xyz="-0.016321 0.00127 0.016323"/>
    <geometry>
      <mesh filename="package://Base_link_description/meshes/leg_servo_retainer_v1_4.stl" scale="0.001 0.001 0.001"/>
    </geometry>
    <material name="silver"/>
  </visual>
  <collision>
    <origin rpy="0 0 0" xyz="-0.016321 0.00127 0.016323"/>
    <geometry>
      <mesh filename="package://Base_link_description/meshes/leg_servo_retainer_v1_4.stl" scale="0.001 0.001 0.001"/>
    </geometry>
  </collision>
</link>

<link name="leg_top_pivot_plate_v1_1">
  <inertial>
    <origin rpy="0 0 0" xyz="0.004176127215360273 0.0006250000596046473 -0.004148158293409882"/>
    <mass value="0.0012497785111649892"/>
    <inertia ixx="0.0" ixy="0.0" ixz="0.0" iyy="0.0" iyz="0.0" izz="0.0"/>
  </inertial>
  <visual>
    <origin rpy="0 0 0" xyz="-0.017806 0.00555 0.017806"/>
    <geometry>
      <mesh filename="package://Base_link_description/meshes/leg_top_pivot_plate_v1_1.stl" scale="0.001 0.001 0.001"/>
    </geometry>
    <material name="silver"/>
  </visual>
  <collision>
    <origin rpy="0 0 0" xyz="-0.017806 0.00555 0.017806"/>
    <geometry>
      <mesh filename="package://Base_link_description/meshes/leg_top_pivot_plate_v1_1.stl" scale="0.001 0.001 0.001"/>
    </geometry>
  </collision>
</link>

<link name="leg_top_pivot_plate_v1_2">
  <inertial>
    <origin rpy="0 0 0" xyz="0.004148157101316982 0.0006250000596046568 0.03978812840745315"/>
    <mass value="0.0012497785111649892"/>
    <inertia ixx="0.0" ixy="0.0" ixz="-0.0" iyy="0.0" iyz="0.0" izz="0.0"/>
  </inertial>
  <visual>
    <origin rpy="0 0 0" xyz="-0.017806 0.00555 0.017806"/>
    <geometry>
      <mesh filename="package://Base_link_description/meshes/leg_top_pivot_plate_v1_2.stl" scale="0.001 0.001 0.001"/>
    </geometry>
    <material name="silver"/>
  </visual>
  <collision>
    <origin rpy="0 0 0" xyz="-0.017806 0.00555 0.017806"/>
    <geometry>
      <mesh filename="package://Base_link_description/meshes/leg_top_pivot_plate_v1_2.stl" scale="0.001 0.001 0.001"/>
    </geometry>
  </collision>
</link>

<link name="leg_top_pivot_plate_v1_3">
  <inertial>
    <origin rpy="0 0 0" xyz="-0.039788136955259776 0.0006250000596046508 0.0397119162505474"/>
    <mass value="0.0012497785111649892"/>
    <inertia ixx="0.0" ixy="-0.0" ixz="0.0" iyy="0.0" iyz="0.0" izz="0.0"/>
  </inertial>
  <visual>
    <origin rpy="0 0 0" xyz="-0.017806 0.00555 0.017806"/>
    <geometry>
      <mesh filename="package://Base_link_description/meshes/leg_top_pivot_plate_v1_3.stl" scale="0.001 0.001 0.001"/>
    </geometry>
    <material name="silver"/>
  </visual>
  <collision>
    <origin rpy="0 0 0" xyz="-0.017806 0.00555 0.017806"/>
    <geometry>
      <mesh filename="package://Base_link_description/meshes/leg_top_pivot_plate_v1_3.stl" scale="0.001 0.001 0.001"/>
    </geometry>
  </collision>
</link>

<link name="leg_top_pivot_plate_v1_4">
  <inertial>
    <origin rpy="0 0 0" xyz="-0.039760166841216506 0.0006250000596046508 -0.004175012622376836"/>
    <mass value="0.0012497785111649892"/>
    <inertia ixx="0.0" ixy="-0.0" ixz="-0.0" iyy="0.0" iyz="-0.0" izz="0.0"/>
  </inertial>
  <visual>
    <origin rpy="0 0 0" xyz="-0.017806 0.00555 0.017806"/>
    <geometry>
      <mesh filename="package://Base_link_description/meshes/leg_top_pivot_plate_v1_4.stl" scale="0.001 0.001 0.001"/>
    </geometry>
    <material name="silver"/>
  </visual>
  <collision>
    <origin rpy="0 0 0" xyz="-0.017806 0.00555 0.017806"/>
    <geometry>
      <mesh filename="package://Base_link_description/meshes/leg_top_pivot_plate_v1_4.stl" scale="0.001 0.001 0.001"/>
    </geometry>
  </collision>
</link>

<link name="leg_servo_mount_v1_1">
  <inertial>
    <origin rpy="0 0 0" xyz="0.00251985940472043 0.004113778478571477 -0.002520105113429757"/>
    <mass value="0.001144548758330191"/>
    <inertia ixx="0.0" ixy="-0.0" ixz="0.0" iyy="0.0" iyz="0.0" izz="0.0"/>
  </inertial>
  <visual>
    <origin rpy="0 0 0" xyz="-0.022859 0.00105 0.026465"/>
    <geometry>
      <mesh filename="package://Base_link_description/meshes/leg_servo_mount_v1_1.stl" scale="0.001 0.001 0.001"/>
    </geometry>
    <material name="silver"/>
  </visual>
  <collision>
    <origin rpy="0 0 0" xyz="-0.022859 0.00105 0.026465"/>
    <geometry>
      <mesh filename="package://Base_link_description/meshes/leg_servo_mount_v1_1.stl" scale="0.001 0.001 0.001"/>
    </geometry>
  </collision>
</link>

<link name="leg_servo_mount_v1_2">
  <inertial>
    <origin rpy="0 0 0" xyz="0.006126103921336862 0.004113778478571479 0.051843860596813285"/>
    <mass value="0.001144548758330191"/>
    <inertia ixx="0.0" ixy="-0.0" ixz="-0.0" iyy="0.0" iyz="-0.0" izz="0.0"/>
  </inertial>
  <visual>
    <origin rpy="0 0 0" xyz="-0.022859 0.00105 0.026465"/>
    <geometry>
      <mesh filename="package://Base_link_description/meshes/leg_servo_mount_v1_2.stl" scale="0.001 0.001 0.001"/>
    </geometry>
    <material name="silver"/>
  </visual>
  <collision>
    <origin rpy="0 0 0" xyz="-0.022859 0.00105 0.026465"/>
    <geometry>
      <mesh filename="package://Base_link_description/meshes/leg_servo_mount_v1_2.stl" scale="0.001 0.001 0.001"/>
    </geometry>
  </collision>
</link>

<link name="leg_servo_mount_v1_3">
  <inertial>
    <origin rpy="0 0 0" xyz="-0.051844113661236396 0.00411377847857148 0.0010872551882629977"/>
    <mass value="0.001144548758330191"/>
    <inertia ixx="0.0" ixy="0.0" ixz="-0.0" iyy="0.0" iyz="0.0" izz="0.0"/>
  </inertial>
  <visual>
    <origin rpy="0 0 0" xyz="-0.022859 0.00105 0.026465"/>
    <geometry>
      <mesh filename="package://Base_link_description/meshes/leg_servo_mount_v1_3.stl" scale="0.001 0.001 0.001"/>
    </geometry>
    <material name="silver"/>
  </visual>
  <collision>
    <origin rpy="0 0 0" xyz="-0.022859 0.00105 0.026465"/>
    <geometry>
      <mesh filename="package://Base_link_description/meshes/leg_servo_mount_v1_3.stl" scale="0.001 0.001 0.001"/>
    </geometry>
  </collision>
</link>

<link name="leg_servo_mount_v1_4">
  <inertial>
    <origin rpy="0 0 0" xyz="-0.04823786914461993 0.004113778478571477 0.05540186307056726"/>
    <mass value="0.001144548758330191"/>
    <inertia ixx="0.0" ixy="0.0" ixz="0.0" iyy="0.0" iyz="-0.0" izz="0.0"/>
  </inertial>
  <visual>
    <origin rpy="0 0 0" xyz="-0.022859 0.00105 0.026465"/>
    <geometry>
      <mesh filename="package://Base_link_description/meshes/leg_servo_mount_v1_4.stl" scale="0.001 0.001 0.001"/>
    </geometry>
    <material name="silver"/>
  </visual>
  <collision>
    <origin rpy="0 0 0" xyz="-0.022859 0.00105 0.026465"/>
    <geometry>
      <mesh filename="package://Base_link_description/meshes/leg_servo_mount_v1_4.stl" scale="0.001 0.001 0.001"/>
    </geometry>
  </collision>
</link>

<link name="leg_parallel_plate_v1_1">
  <inertial>
    <origin rpy="0 0 0" xyz="0.00031741714756083547 0.003050233586176742 -0.0003169963388769473"/>
    <mass value="0.000869495656702597"/>
    <inertia ixx="0.0" ixy="0.0" ixz="0.0" iyy="0.0" iyz="-0.0" izz="0.0"/>
  </inertial>
  <visual>
    <origin rpy="0 0 0" xyz="-0.026786 0.00105 0.023859"/>
    <geometry>
      <mesh filename="package://Base_link_description/meshes/leg_parallel_plate_v1_1.stl" scale="0.001 0.001 0.001"/>
    </geometry>
    <material name="silver"/>
  </visual>
  <collision>
    <origin rpy="0 0 0" xyz="-0.026786 0.00105 0.023859"/>
    <geometry>
      <mesh filename="package://Base_link_description/meshes/leg_parallel_plate_v1_1.stl" scale="0.001 0.001 0.001"/>
    </geometry>
  </collision>
</link>

<link name="leg_parallel_plate_v1_2">
  <inertial>
    <origin rpy="0 0 0" xyz="-0.0026100048532159345 0.0030502335861767515 0.05096241833965374"/>
    <mass value="0.000869495656702597"/>
    <inertia ixx="0.0" ixy="0.0" ixz="-0.0" iyy="0.0" iyz="0.0" izz="0.0"/>
  </inertial>
  <visual>
    <origin rpy="0 0 0" xyz="-0.026786 0.00105 0.023859"/>
    <geometry>
      <mesh filename="package://Base_link_description/meshes/leg_parallel_plate_v1_2.stl" scale="0.001 0.001 0.001"/>
    </geometry>
    <material name="silver"/>
  </visual>
  <collision>
    <origin rpy="0 0 0" xyz="-0.026786 0.00105 0.023859"/>
    <geometry>
      <mesh filename="package://Base_link_description/meshes/leg_parallel_plate_v1_2.stl" scale="0.001 0.001 0.001"/>
    </geometry>
  </collision>
</link>

<link name="leg_parallel_plate_v1_3">
  <inertial>
    <origin rpy="0 0 0" xyz="-0.05096200488668359 0.0030502335861767454 -0.0032433025545774118"/>
    <mass value="0.000869495656702597"/>
    <inertia ixx="0.0" ixy="-0.0" ixz="-0.0" iyy="0.0" iyz="-0.0" izz="0.0"/>
  </inertial>
  <visual>
    <origin rpy="0 0 0" xyz="-0.026786 0.00105 0.023859"/>
    <geometry>
      <mesh filename="package://Base_link_description/meshes/leg_parallel_plate_v1_3.stl" scale="0.001 0.001 0.001"/>
    </geometry>
    <material name="silver"/>
  </visual>
  <collision>
    <origin rpy="0 0 0" xyz="-0.026786 0.00105 0.023859"/>
    <geometry>
      <mesh filename="package://Base_link_description/meshes/leg_parallel_plate_v1_3.stl" scale="0.001 0.001 0.001"/>
    </geometry>
  </collision>
</link>

<link name="leg_parallel_plate_v1_4">
  <inertial>
    <origin rpy="0 0 0" xyz="-0.053889426887460366 0.0030502335861767446 0.04798675429601447"/>
    <mass value="0.000869495656702597"/>
    <inertia ixx="0.0" ixy="-0.0" ixz="0.0" iyy="0.0" iyz="0.0" izz="0.0"/>
  </inertial>
  <visual>
    <origin rpy="0 0 0" xyz="-0.026786 0.00105 0.023859"/>
    <geometry>
      <mesh filename="package://Base_link_description/meshes/leg_parallel_plate_v1_4.stl" scale="0.001 0.001 0.001"/>
    </geometry>
    <material name="silver"/>
  </visual>
  <collision>
    <origin rpy="0 0 0" xyz="-0.026786 0.00105 0.023859"/>
    <geometry>
      <mesh filename="package://Base_link_description/meshes/leg_parallel_plate_v1_4.stl" scale="0.001 0.001 0.001"/>
    </geometry>
  </collision>
</link>

<link name="bottom_pivot_plate_v1_1">
  <inertial>
    <origin rpy="0 0 0" xyz="0.003924493197375523 0.0006250000596046482 -0.0039400877533866535"/>
    <mass value="0.00131675130911231"/>
    <inertia ixx="0.0" ixy="0.0" ixz="0.0" iyy="0.0" iyz="0.0" izz="0.0"/>
  </inertial>
  <visual>
    <origin rpy="0 0 0" xyz="-0.017806 -0.01 0.017806"/>
    <geometry>
      <mesh filename="package://Base_link_description/meshes/bottom_pivot_plate_v1_1.stl" scale="0.001 0.001 0.001"/>
    </geometry>
    <material name="silver"/>
  </visual>
  <collision>
    <origin rpy="0 0 0" xyz="-0.017806 -0.01 0.017806"/>
    <geometry>
      <mesh filename="package://Base_link_description/meshes/bottom_pivot_plate_v1_1.stl" scale="0.001 0.001 0.001"/>
    </geometry>
  </collision>
</link>

<joint name="Rigid10" type="fixed">
  <origin rpy="0 0 0" xyz="0.0 0.00575 -0.016875"/>
  <parent link="base_link"/>
  <child link="body_spacer_v1_1_1_1"/>
</joint>

<joint name="Rigid11" type="fixed">
  <origin rpy="0 0 0" xyz="0.016875 0.00575 0.0"/>
  <parent link="base_link"/>
  <child link="body_spacer_v1_2_1_1"/>
</joint>

<joint name="Rigid12" type="fixed">
  <origin rpy="0 0 0" xyz="0.0 0.00575 0.016875"/>
  <parent link="base_link"/>
  <child link="body_spacer_v1_3_1_1"/>
</joint>

<joint name="Rigid17" type="fixed">
  <origin rpy="0 0 0" xyz="-0.016875 0.00575 0.0"/>
  <parent link="base_link"/>
  <child link="body_spacer_v1_4_1_1"/>
</joint>

<joint name="Rigid63" type="fixed">
  <origin rpy="0 0 0" xyz="-4e-06 0.0 2e-06"/>
  <parent link="base_link"/>
  <child link="body_top_plate_v1_1"/>
</joint>

<joint name="Rigid64" type="fixed">
  <origin rpy="0 0 0" xyz="0.017806 -0.00555 -0.017806"/>
  <parent link="base_link"/>
  <child link="servo_motor_v1_1"/>
</joint>

<joint name="Rigid65" type="fixed">
  <origin rpy="0 0 0" xyz="0.017806 -0.00555 -0.017806"/>
  <parent link="base_link"/>
  <child link="servo_motor_v1_2"/>
</joint>

<joint name="Rigid66" type="fixed">
  <origin rpy="0 0 0" xyz="0.017806 -0.00555 -0.017806"/>
  <parent link="base_link"/>
  <child link="servo_motor_v1_3"/>
</joint>

<joint name="Rigid67" type="fixed">
  <origin rpy="0 0 0" xyz="0.017806 -0.00555 -0.017806"/>
  <parent link="base_link"/>
  <child link="servo_motor_v1_4"/>
</joint>

<joint name="Rigid68" type="fixed">
  <origin rpy="0 0 0" xyz="0.016325 -0.00127 -0.016325"/>
  <parent link="body_top_plate_v1_1"/>
  <child link="leg_servo_retainer_v1_1"/>
</joint>

<joint name="Rigid69" type="fixed">
  <origin rpy="0 0 0" xyz="0.016325 -0.00127 -0.016325"/>
  <parent link="body_top_plate_v1_1"/>
  <child link="leg_servo_retainer_v1_2"/>
</joint>

<joint name="Rigid70" type="fixed">
  <origin rpy="0 0 0" xyz="0.016325 -0.00127 -0.016325"/>
  <parent link="body_top_plate_v1_1"/>
  <child link="leg_servo_retainer_v1_3"/>
</joint>

<joint name="Rigid71" type="fixed">
  <origin rpy="0 0 0" xyz="0.016325 -0.00127 -0.016325"/>
  <parent link="body_top_plate_v1_1"/>
  <child link="leg_servo_retainer_v1_4"/>
</joint>

<joint name="Rev72" type="continuous">
  <origin rpy="0 0 0" xyz="0.0 0.0 0.0"/>
  <parent link="servo_motor_v1_1"/>
  <child link="leg_top_pivot_plate_v1_1"/>
  <axis xyz="0.0 -1.0 0.0"/>
</joint>

<joint name="Rev73" type="continuous">
  <origin rpy="0 0 0" xyz="0.0 0.0 0.0"/>
  <parent link="servo_motor_v1_2"/>
  <child link="leg_top_pivot_plate_v1_2"/>
  <axis xyz="0.0 -1.0 -0.0"/>
</joint>

<joint name="Rev74" type="continuous">
  <origin rpy="0 0 0" xyz="0.0 0.0 0.0"/>
  <parent link="servo_motor_v1_3"/>
  <child link="leg_top_pivot_plate_v1_3"/>
  <axis xyz="0.0 -1.0 0.0"/>
</joint>

<joint name="Rev75" type="continuous">
  <origin rpy="0 0 0" xyz="0.0 0.0 0.0"/>
  <parent link="servo_motor_v1_4"/>
  <child link="leg_top_pivot_plate_v1_4"/>
  <axis xyz="0.0 -1.0 0.0"/>
</joint>

<joint name="Rigid76" type="fixed">
  <origin rpy="0 0 0" xyz="0.005053 0.0045 -0.008659"/>
  <parent link="leg_top_pivot_plate_v1_1"/>
  <child link="leg_servo_mount_v1_1"/>
</joint>

<joint name="Rigid77" type="fixed">
  <origin rpy="0 0 0" xyz="0.005053 0.0045 -0.008659"/>
  <parent link="leg_top_pivot_plate_v1_2"/>
  <child link="leg_servo_mount_v1_2"/>
</joint>

<joint name="Rigid78" type="fixed">
  <origin rpy="0 0 0" xyz="0.005053 0.0045 -0.008659"/>
  <parent link="leg_top_pivot_plate_v1_4"/>
  <child link="leg_servo_mount_v1_3"/>
</joint>

<joint name="Rigid79" type="fixed">
  <origin rpy="0 0 0" xyz="0.005053 0.0045 -0.008659"/>
  <parent link="leg_top_pivot_plate_v1_3"/>
  <child link="leg_servo_mount_v1_4"/>
</joint>

<joint name="Rigid80" type="fixed">
  <origin rpy="0 0 0" xyz="0.00898 0.0045 -0.006053"/>
  <parent link="leg_top_pivot_plate_v1_1"/>
  <child link="leg_parallel_plate_v1_1"/>
</joint>

<joint name="Rigid81" type="fixed">
  <origin rpy="0 0 0" xyz="0.00898 0.0045 -0.006053"/>
  <parent link="leg_top_pivot_plate_v1_2"/>
  <child link="leg_parallel_plate_v1_2"/>
</joint>

<joint name="Rigid82" type="fixed">
  <origin rpy="0 0 0" xyz="0.00898 0.0045 -0.006053"/>
  <parent link="leg_top_pivot_plate_v1_4"/>
  <child link="leg_parallel_plate_v1_3"/>
</joint>

<joint name="Rigid83" type="fixed">
  <origin rpy="0 0 0" xyz="0.00898 0.0045 -0.006053"/>
  <parent link="leg_top_pivot_plate_v1_3"/>
  <child link="leg_parallel_plate_v1_4"/>
</joint>

<joint name="Rev84" type="continuous">
  <origin rpy="0 0 0" xyz="0.017806 0.01 -0.017806"/>
  <parent link="base_link"/>
  <child link="bottom_pivot_plate_v1_1"/>
  <axis xyz="0.0 -1.0 0.0"/>
</joint>

</robot>
